Workbook

Sheet S-ASIG-05
A1: =LIDER!B2 -> TECNOLOGÍA EN GESTIÓN DE NEGOCIOS INTERN | I1: =LIDER!E2 -> SEMESTRE: | J1: =LIDER!F2 -> SEM-06 | K1: =LIDER!G2 -> SECCIÓN: | L1: =LIDER!H2 -> 3
B2: =LIDER!G4 -> D.F.I. | F2: CRITERIOS DE EVALUACIÓN
B3: Estudiantes | F3: =LIDER!E9 -> PRESENTACIÓN GENERAL: Adopta la norma APA, tamaño de la hoja, margenes, titulo, portadas, numeración de paginas, tabla de contenido automatizada, ortografia, justificacion del texto, citas automatizadas, listas, figuras,etc. | G3: =LIDER!E10 -> ANTEPROYECTO: Portada, planteamiento del problema, justificacion del trabajo o proyecto de aula, objetivos, marco teorico, diseño metodologico. | H3: =LIDER!E11 -> RESULTADOS: Analiza, integra y aplica de manera coherente los aspectos para la Construcción de la marca empresarial (Branding) | I3: =LIDER!E12 -> RESULTADOS: Analiza, integra y aplica de manera coherente los aspectos del Plan de distribución. | J3: =LIDER!E13 -> RESULTADOS: Analiza, integra y aplica de manera coherente los aspectos para el Análisis ambiental y social. | K3: =LIDER!E14 -> BILIOGRAFIA: Las referencias bibliograficas: adoptan las normas APA. El documento es producto de un rastreo bibliografico que muestra analisis y sistensis. | L3: =LIDER!E15 -> ASESORIAS: Anexó la hoja de tutoria firmada ( 3 fimas minmimo).
F4: =CONCATENATE(LIDER!G4," - ",LIDER!G6," - ",LIDER!G5) -> D.F.I. - 1450 - RAFAEL UGARRIZA DIAZ
B5: GRUPO#1 | C5: G01 | D5: LIST | E5: DEF | F5: =LIDER!$E$29 -> GRUPO#1
A6: 1 | B6: =LIDER!E43 -> SANTIAGO AVILA MONTERROSA | C6: =C5 -> G01 | E6: =IF(B6=0,0,IF(D6="",$F$6*LIDER!$H$9+$G$6*LIDER!$H$10+$H$6*LIDER!$H$11+$I$6*LIDER!$H$12+$J$6*LIDER!$H$13+$K$6*LIDER!$H$14+$L$6*LIDER!$H$15,"N")) -> 3.23 | F6: 3.3 | G6: 3.1 | H6: 3 | I6: 3 | J6: 3 | K6: 3 | L6: 4.5
A7: 2 | B7: =LIDER!E44 -> FEDERICO GALLEGO TROCONIS | C7: =C6 -> G01 | E7: =IF(B7=0,0,IF(D7="",$F$6*LIDER!$H$9+$G$6*LIDER!$H$10+$H$6*LIDER!$H$11+$I$6*LIDER!$H$12+$J$6*LIDER!$H$13+$K$6*LIDER!$H$14+$L$6*LIDER!$H$15,"N")) -> 3.23
A8: 3 | B8: =LIDER!E45 -> FERNANDO ANTONIO UPEGUI MARTINEZ | C8: =C7 -> G01 | E8: =IF(B8=0,0,IF(D8="",$F$6*LIDER!$H$9+$G$6*LIDER!$H$10+$H$6*LIDER!$H$11+$I$6*LIDER!$H$12+$J$6*LIDER!$H$13+$K$6*LIDER!$H$14+$L$6*LIDER!$H$15,"N")) -> 3.23
A9: 4 | B9: =LIDER!E46 -> 0 | C9: =C8 -> G01 | E9: =IF(B9=0,0,IF(D9="",$F$6*LIDER!$H$9+$G$6*LIDER!$H$10+$H$6*LIDER!$H$11+$I$6*LIDER!$H$12+$J$6*LIDER!$H$13+$K$6*LIDER!$H$14+$L$6*LIDER!$H$15,"N")) -> 0
A10: 5 | B10: =LIDER!E47 -> 0 | C10: =C9 -> G01 | E10: =IF(B10=0,0,IF(D10="",$F$6*LIDER!$H$9+$G$6*LIDER!$H$10+$H$6*LIDER!$H$11+$I$6*LIDER!$H$12+$J$6*LIDER!$H$13+$K$6*LIDER!$H$14+$L$6*LIDER!$H$15,"N")) -> 0
A11: 6 | B11: =LIDER!E48 -> 0 | C11: =C10 -> G01 | E11: =IF(B11=0,0,IF(D11="",$F$6*LIDER!$H$9+$G$6*LIDER!$H$10+$H$6*LIDER!$H$11+$I$6*LIDER!$H$12+$J$6*LIDER!$H$13+$K$6*LIDER!$H$14+$L$6*LIDER!$H$15,"N")) -> 0
B12: GRUPO#2 | C12: G02 | D12: =D5 -> LIST | E12: DEF | F12: =LIDER!$E$30 -> GRUPO#2
A13: 1 | B13: =LIDER!F43 -> LERCY MARCELA CHAVEZ CASTELLAR | C13: =C12 -> G02 | E13: =IF(B13=0,0,IF(D13="",$F$13*LIDER!$H$9+$G$13*LIDER!$H$10+$H$13*LIDER!$H$11+$I$13*LIDER!$H$12+$J$13*LIDER!$H$13+$K$13*LIDER!$H$14+$L$13*LIDER!$H$15,"N")) -> 2.9 | F13: 3.5 | G13: 3.5 | H13: 3 | I13: 3 | J13: 3 | K13: 2 | L13: 2
A14: 2 | B14: =LIDER!F44 -> JUAN DAVID DEVOZ GONZALEZ | C14: =C13 -> G02 | E14: =IF(B14=0,0,IF(D14="",$F$13*LIDER!$H$9+$G$13*LIDER!$H$10+$H$13*LIDER!$H$11+$I$13*LIDER!$H$12+$J$13*LIDER!$H$13+$K$13*LIDER!$H$14+$L$13*LIDER!$H$15,"N")) -> 2.9
A15: 3 | B15: =LIDER!F45 -> SANTIAGO HERNÁNDEZ BARBOZA | C15: =C14 -> G02 | E15: =IF(B15=0,0,IF(D15="",$F$13*LIDER!$H$9+$G$13*LIDER!$H$10+$H$13*LIDER!$H$11+$I$13*LIDER!$H$12+$J$13*LIDER!$H$13+$K$13*LIDER!$H$14+$L$13*LIDER!$H$15,"N")) -> 2.9
A16: 4 | B16: =LIDER!F46 -> DIEGO JACOME PERALTA | C16: =C15 -> G02 | E16: =IF(B16=0,0,IF(D16="",$F$13*LIDER!$H$9+$G$13*LIDER!$H$10+$H$13*LIDER!$H$11+$I$13*LIDER!$H$12+$J$13*LIDER!$H$13+$K$13*LIDER!$H$14+$L$13*LIDER!$H$15,"N")) -> 2.9
A17: 5 | B17: =LIDER!F47 -> JESUS ALBERTO MADRID BORDA | C17: =C16 -> G02 | E17: =IF(B17=0,0,IF(D17="",$F$13*LIDER!$H$9+$G$13*LIDER!$H$10+$H$13*LIDER!$H$11+$I$13*LIDER!$H$12+$J$13*LIDER!$H$13+$K$13*LIDER!$H$14+$L$13*LIDER!$H$15,"N")) -> 2.9
A18: 6 | B18: =LIDER!F48 -> JUAN ANDRES REYES GOMEZ | C18: =C17 -> G02 | E18: =IF(B18=0,0,IF(D18="",$F$13*LIDER!$H$9+$G$13*LIDER!$H$10+$H$13*LIDER!$H$11+$I$13*LIDER!$H$12+$J$13*LIDER!$H$13+$K$13*LIDER!$H$14+$L$13*LIDER!$H$15,"N")) -> 2.9
B19: GRUPO#3 | C19: G03 | D19: =D12 -> LIST | E19: DEF | F19: =LIDER!$E$31 -> GRUPO#3
A20: 1 | B20: =LIDER!G43 -> ANDREA CAROLINA GONZALEZ PEREZ | C20: =C19 -> G03 | E20: =IF(B20=0,0,IF(D20="",$F$20*LIDER!$H$9+$G$20*LIDER!$H$10+$H$20*LIDER!$H$11+$I$20*LIDER!$H$12+$J$20*LIDER!$H$13+$K$20*LIDER!$H$14+$L$20*LIDER!$H$15,"N")) -> 4.08 | F20: 4.2 | G20: 4.2 | H20: 4 | I20: 4 | J20: 4 | K20: 4 | L20: 4
A21: 2 | B21: =LIDER!G44 -> SHEIDY ALEJANDRA HERNANDEZ NIEVES | C21: =C20 -> G03 | E21: =IF(B21=0,0,IF(D21="",$F$20*LIDER!$H$9+$G$20*LIDER!$H$10+$H$20*LIDER!$H$11+$I$20*LIDER!$H$12+$J$20*LIDER!$H$13+$K$20*LIDER!$H$14+$L$20*LIDER!$H$15,"N")) -> 4.08
A22: 3 | B22: =LIDER!G45 -> 0 | C22: =C21 -> G03 | E22: =IF(B22=0,0,IF(D22="",$F$20*LIDER!$H$9+$G$20*LIDER!$H$10+$H$20*LIDER!$H$11+$I$20*LIDER!$H$12+$J$20*LIDER!$H$13+$K$20*LIDER!$H$14+$L$20*LIDER!$H$15,"N")) -> 0
A23: 4 | B23: =LIDER!G46 -> 0 | C23: =C22 -> G03 | E23: =IF(B23=0,0,IF(D23="",$F$20*LIDER!$H$9+$G$20*LIDER!$H$10+$H$20*LIDER!$H$11+$I$20*LIDER!$H$12+$J$20*LIDER!$H$13+$K$20*LIDER!$H$14+$L$20*LIDER!$H$15,"N")) -> 0
A24: 5 | B24: =LIDER!G47 -> 0 | C24: =C23 -> G03 | E24: =IF(B24=0,0,IF(D24="",$F$20*LIDER!$H$9+$G$20*LIDER!$H$10+$H$20*LIDER!$H$11+$I$20*LIDER!$H$12+$J$20*LIDER!$H$13+$K$20*LIDER!$H$14+$L$20*LIDER!$H$15,"N")) -> 0
A25: 6 | B25: =LIDER!G48 -> 0 | C25: =C24 -> G03 | E25: =IF(B25=0,0,IF(D25="",$F$20*LIDER!$H$9+$G$20*LIDER!$H$10+$H$20*LIDER!$H$11+$I$20*LIDER!$H$12+$J$20*LIDER!$H$13+$K$20*LIDER!$H$14+$L$20*LIDER!$H$15,"N")) -> 0
B26: GRUPO#4 | C26: G04 | D26: =D19 -> LIST | E26: DEF | F26: =LIDER!$E$32 -> GRUPO#4
A27: 1 | B27: =LIDER!H43 -> ZHEYLA MARCELA AFANADOR TORRES | C27: =C26 -> G04 | E27: =IF(B27=0,0,IF(D27="",$F$27*LIDER!$H$9+$G$27*LIDER!$H$10+$H$27*LIDER!$H$11+$I$27*LIDER!$H$12+$J$27*LIDER!$H$13+$K$27*LIDER!$H$14+$L$27*LIDER!$H$15,"N")) -> 4.48 | F27: 4.5 | G27: 4.4 | H27: 4 | I27: 4 | J27: 4 | K27: 5 | L27: 5
A28: 2 | B28: =LIDER!H44 -> NATALI AGRESOTT GOMEZ | C28: =C27 -> G04 | E28: =IF(B28=0,0,IF(D28="",$F$27*LIDER!$H$9+$G$27*LIDER!$H$10+$H$27*LIDER!$H$11+$I$27*LIDER!$H$12+$J$27*LIDER!$H$13+$K$27*LIDER!$H$14+$L$27*LIDER!$H$15,"N")) -> 4.48
A29: 3 | B29: =LIDER!H45 -> DAYLETH CONEO OSPINO | C29: =C28 -> G04 | E29: =IF(B29=0,0,IF(D29="",$F$27*LIDER!$H$9+$G$27*LIDER!$H$10+$H$27*LIDER!$H$11+$I$27*LIDER!$H$12+$J$27*LIDER!$H$13+$K$27*LIDER!$H$14+$L$27*LIDER!$H$15,"N")) -> 4.48
A30: 4 | B30: =LIDER!H46 -> NATHALIA JULIETH ORTEGA ROMERO | C30: =C29 -> G04 | E30: =IF(B30=0,0,IF(D30="",$F$27*LIDER!$H$9+$G$27*LIDER!$H$10+$H$27*LIDER!$H$11+$I$27*LIDER!$H$12+$J$27*LIDER!$H$13+$K$27*LIDER!$H$14+$L$27*LIDER!$H$15,"N")) -> 4.48
A31: 5 | B31: =LIDER!H47 -> YURIDIS ORTIZ TORRES | C31: =C30 -> G04 | E31: =IF(B31=0,0,IF(D31="",$F$27*LIDER!$H$9+$G$27*LIDER!$H$10+$H$27*LIDER!$H$11+$I$27*LIDER!$H$12+$J$27*LIDER!$H$13+$K$27*LIDER!$H$14+$L$27*LIDER!$H$15,"N")) -> 4.48
A32: 6 | B32: =LIDER!H48 -> 0 | C32: =C31 -> G04 | E32: =IF(B32=0,0,IF(D32="",$F$27*LIDER!$H$9+$G$27*LIDER!$H$10+$H$27*LIDER!$H$11+$I$27*LIDER!$H$12+$J$27*LIDER!$H$13+$K$27*LIDER!$H$14+$L$27*LIDER!$H$15,"N")) -> 0
B33: GRUPO#5 | C33: G05 | D33: =D26 -> LIST | E33: DEF | F33: =LIDER!$E$33 -> GRUPO#5
A34: 1 | B34: =LIDER!E51 -> MARIA JOSE ACEVEDO QUINTANA | C34: =C33 -> G05 | E34: =IF(B34=0,0,IF(D34="",$F$34*LIDER!$H$9+$G$34*LIDER!$H$10+$H$34*LIDER!$H$11+$I$34*LIDER!$H$12+$J$34*LIDER!$H$13+$K$34*LIDER!$H$14+$L$34*LIDER!$H$15,"N")) -> 3.89 | F34: 4 | G34: 3.5 | H34: 3.8 | I34: 3.8 | J34: 3.8 | K34: 4 | L34: 4.5
A35: 2 | B35: =LIDER!E52 -> YEIDYS FAINORYS ARROYO GRANADOS | C35: =C34 -> G05 | E35: =IF(B35=0,0,IF(D35="",$F$34*LIDER!$H$9+$G$34*LIDER!$H$10+$H$34*LIDER!$H$11+$I$34*LIDER!$H$12+$J$34*LIDER!$H$13+$K$34*LIDER!$H$14+$L$34*LIDER!$H$15,"N")) -> 3.89
A36: 3 | B36: =LIDER!E53 -> ANGELICA NAVARRO TORRES | C36: =C35 -> G05 | E36: =IF(B36=0,0,IF(D36="",$F$34*LIDER!$H$9+$G$34*LIDER!$H$10+$H$34*LIDER!$H$11+$I$34*LIDER!$H$12+$J$34*LIDER!$H$13+$K$34*LIDER!$H$14+$L$34*LIDER!$H$15,"N")) -> 3.89
A37: 4 | B37: =LIDER!E54 -> ISABELLA OLIVARES LLANOS | C37: =C36 -> G05 | E37: =IF(B37=0,0,IF(D37="",$F$34*LIDER!$H$9+$G$34*LIDER!$H$10+$H$34*LIDER!$H$11+$I$34*LIDER!$H$12+$J$34*LIDER!$H$13+$K$34*LIDER!$H$14+$L$34*LIDER!$H$15,"N")) -> 3.89
A38: 5 | B38: =LIDER!E55 -> SAMARA ELIZABETH SUAREZ NAVARRO | C38: =C37 -> G05 | E38: =IF(B38=0,0,IF(D38="",$F$34*LIDER!$H$9+$G$34*LIDER!$H$10+$H$34*LIDER!$H$11+$I$34*LIDER!$H$12+$J$34*LIDER!$H$13+$K$34*LIDER!$H$14+$L$34*LIDER!$H$15,"N")) -> 3.89
A39: 6 | B39: =LIDER!E56 -> 0 | C39: =C38 -> G05 | E39: =IF(B39=0,0,IF(D39="",$F$34*LIDER!$H$9+$G$34*LIDER!$H$10+$H$34*LIDER!$H$11+$I$34*LIDER!$H$12+$J$34*LIDER!$H$13+$K$34*LIDER!$H$14+$L$34*LIDER!$H$15,"N")) -> 0
B40: GRUPO#6 | C40: G06 | D40: =D33 -> LIST | E40: DEF | F40: =LIDER!$E$34 -> GRUPO#6
...

Sheet LIDER
B2: TECNOLOGÍA EN GESTIÓN DE NEGOCIOS INTERN | E2: SEMESTRE: | F2: SEM-06 | G2: SECCIÓN: | H2: 3
C3: DISCIPLINAR#1 | D3: DISCIPLINAR#2 | E3: DISCIPLINAR#3 | F3: DISCIPLINAR#4 | G3: DISCIPLINAR#5 | H3: DISCIPLINAR#6 | I3: DISCIPLINAR#7
C4: INNOVACION Y EMPRENDIMIENTO | D4: ELECTIVA DE PROFUNDIZACION III | E4: AMBIENTE Y DESARROLLO | F4: FINANZAS INTERNACIONALES | G4: D.F.I. | H4: ELECTIVA LIBRE SOCIOHUMANÍ II
C5: EDUARDO JESUS CARDENAS RODRIGUEZ | D5: HERNANDO RAFAEL ARMESTO ABUABARA | E5: MARIANO BELTRAN PADILLA | F5: MADELCY DEL CARMEN PEDROZA TORRES | G5: RAFAEL UGARRIZA DIAZ | H5: EBERTO JESUS POSADA AMANTE
C6: 2304 | D6: 2320 | E6: 1086 | F6: 1444 | G6: 1450 | H6: 2121
C8: LISTA DE ESTUDIANTES | E8: SEGUNDA ENTREGA - CRITERIO DE EVALUACIÓN DOCUMENTO - SEGUNDO CORTE | H8: PONDERACIÓN | I8: ADMINISTRACIÓN DE EMPRESAS C.I
B9: 1 | C9: SANTIAGO AVILA MONTERROSA | E9: PRESENTACIÓN GENERAL: Adopta la norma APA, tamaño de la hoja, margenes, titulo, portadas, numeración de paginas, tabla de contenido automatizada, ortografia, justificacion del texto, citas automatizadas, listas, figuras,etc. | H9: 0.2 | I9: ADMINTRACIÓN EN SEGURIDAD Y SALUD EN EL TRABAJO
B10: 2 | C10: FEDERICO GALLEGO TROCONIS | E10: ANTEPROYECTO: Portada, planteamiento del problema, justificacion del trabajo o proyecto de aula, objetivos, marco teorico, diseño metodologico. | H10: 0.2 | I10: CONTADURÍA PÚBLICA
B11: 3 | C11: FERNANDO ANTONIO UPEGUI MARTINEZ | E11: RESULTADOS: Analiza, integra y aplica de manera coherente los aspectos para la Construcción de la marca empresarial (Branding) | H11: 0.1 | I11: NEGOCIOS INTERNACIONALES PROFESIONAL
B12: 4 | C12: LERCY MARCELA CHAVEZ CASTELLAR | E12: RESULTADOS: Analiza, integra y aplica de manera coherente los aspectos del Plan de distribución. | H12: 0.1 | I12: TECNOLOGÍA EN GESTIÓN DE NEGOCIOS INTERN
B13: 5 | C13: JUAN DAVID DEVOZ GONZALEZ | E13: RESULTADOS: Analiza, integra y aplica de manera coherente los aspectos para el Análisis ambiental y social. | H13: 0.1 | I13: TECNOLOGíA EN GESTION CONTABLE
B14: 6 | C14: SANTIAGO HERNÁNDEZ BARBOZA | E14: BILIOGRAFIA: Las referencias bibliograficas: adoptan las normas APA. El documento es producto de un rastreo bibliografico que muestra analisis y sistensis. | H14: 0.2 | I14: TECNOLOGÍA EN GESTIÓN DE MARKETING
B15: 7 | C15: DIEGO JACOME PERALTA | E15: ASESORIAS: Anexó la hoja de tutoria firmada ( 3 fimas minmimo). | H15: 0.1 | I15: TECNOLOGÍA EN GESTIÓN DEL TALENTO HUMANO
B16: 8 | C16: JESUS ALBERTO MADRID BORDA | H16: =IF(SUM(H9:H15)>1,"Más del 100%",SUM(H9:H15)) -> 1 | I16: TECNOLOGÍA EN GESTIÓN FINANCIERA
B17: 9 | C17: JUAN ANDRES REYES GOMEZ | I17: TECNOLOGÍA EN GESTIÓN LOGISTICA Y PORTUARIA
B18: 10 | C18: ERNESTO JOSE RIOS HERNANDEZ | E18: ENTREGA FINAL - CRITERIO DE EVALUACIÓN SUSTENTACIÓN - TERCER CORTE | H18: PONDERACIÓN | I18: TECNOLOGÍA EN GESTIÓN TURISTICA Y HOTELERA
B19: 11 | C19: ANDREA CAROLINA GONZALEZ PEREZ | E19: Evaluación del Documento Final | H19: 0.5
B20: 12 | C20: SHEIDY ALEJANDRA HERNANDEZ NIEVES | E20: Sustentación de los Resultados: Se refleja un dominio del tema, la información está delimitada y es clara. Hay una jerarquía y fluidez en las ideas que presenta. | H20: 0.2
B21: 13 | C21: ZHEYLA MARCELA AFANADOR TORRES | E21: Expresión Oral: Se oberva buena vocalización y buen tono de voz durante toda la presentación empleando un lenguaje técnico pertinente con su nivel academico. Su discurso es adecuado en la presentacion de la sustentación de los resultados | H21: 0.1
B22: 14 | C22: NATALI AGRESOTT GOMEZ | E22: Lenguaje no verbal: Tiene una adecuada presentación personal para la ocación, opta por una buena postura y demuestra seguridad en sí mismo(a) durante la sustentación de los resultados. Además, demuestra asertividad y seguridad en las orientaciones o preguntas que hace el colectivo docente | H22: 0.05
B23: 15 | C23: DAYLETH CONEO OSPINO | E23: Tiempo: El uso del tiempo fue apropiado, se ajusta al previsto. Ofrece una conclusión donde condensa las ideas principales del objetivo general y los específicos. | H23: 0.05
B24: 16 | C24: NATHALIA JULIETH ORTEGA ROMERO | E24: Uso de Recursos Audiovisuales Tecnológicos: La sustentación se acompaña de recursos visuales pertinentes, atractivos y de gran calidad | H24: 0.1
B25: 17 | C25: YURIDIS ORTIZ TORRES
B26: 18 | C26: MARIA JOSE ACEVEDO QUINTANA | H26: =IF(SUM(H19:H25)>1,"Más del 100%",SUM(H19:H25)) -> 1
B27: 19 | C27: YEIDYS FAINORYS ARROYO GRANADOS
B28: 20 | C28: ANGELICA NAVARRO TORRES | E28: TITULOS DE LOS PROYECTOS DE AULA
B29: 21 | C29: ISABELLA OLIVARES LLANOS | E29: GRUPO#1
B30: 22 | C30: SAMARA ELIZABETH SUAREZ NAVARRO | E30: GRUPO#2
B31: 23 | C31: YEIFEL ANDRES AGUILAR ALCALA | E31: GRUPO#3
B32: 24 | C32: JHOAN ARTURO POSADA FRANCO | E32: GRUPO#4
B33: 25 | C33: GRISSELL TAYMARA RODRIGUEZ SOLARTE | E33: GRUPO#5
B34: 26 | C34: KATERIN SOFIA CEBALLOS FERNANDEZ | E34: GRUPO#6
B35: 27 | C35: JULIANA DIAZ PEREZ | E35: GRUPO#7
B36: 28 | C36: RUT ELENA MONTOYA AVILA | E36: GRUPO#8
B37: 29 | C37: DANIELA RAMIREZ AGUIRRE | E37: GRUPO#9
B38: 30 | C38: JHOINY LUZ VALDES GONZALEZ | E38: GRUPO#10
B39: 31 | C39: YORGEL GREGORIO BELTRAN MORENO | E39: GRUPO#11
B40: 32 | C40: LUISA FERNANDA CASTILLO CHACON | E40: GRUPO#12
B41: 33 | C41: MARIA JOSE GALVAN BUELVAS
B42: 34 | C42: SANTIAGO MARTINEZ MORA | E42: =MID(E29,1,20) -> GRUPO#1 | F42: =MID(E30,1,20) -> GRUPO#2 | G42: =MID(E31,1,20) -> GRUPO#3 | H42: =MID(E32,1,20) -> GRUPO#4
...

Sheet S-ASIG-01
A1: =LIDER!B2 -> TECNOLOGÍA EN GESTIÓN DE NEGOCIOS INTERN | I1: =LIDER!E2 -> SEMESTRE: | J1: =LIDER!F2 -> SEM-06 | K1: =LIDER!G2 -> SECCIÓN: | L1: =LIDER!H2 -> 3
B2: =LIDER!C4 -> INNOVACION Y EMPRENDIMIENTO | F2: CRITERIOS DE EVALUACIÓN
B3: Estudiantes | F3: =LIDER!E9 -> PRESENTACIÓN GENERAL: Adopta la norma APA, tamaño de la hoja, margenes, titulo, portadas, numeración de paginas, tabla de contenido automatizada, ortografia, justificacion del texto, citas automatizadas, listas, figuras,etc. | G3: =LIDER!E10 -> ANTEPROYECTO: Portada, planteamiento del problema, justificacion del trabajo o proyecto de aula, objetivos, marco teorico, diseño metodologico. | H3: =LIDER!E11 -> RESULTADOS: Analiza, integra y aplica de manera coherente los aspectos para la Construcción de la marca empresarial (Branding) | I3: =LIDER!E12 -> RESULTADOS: Analiza, integra y aplica de manera coherente los aspectos del Plan de distribución. | J3: =LIDER!E13 -> RESULTADOS: Analiza, integra y aplica de manera coherente los aspectos para el Análisis ambiental y social. | K3: =LIDER!E14 -> BILIOGRAFIA: Las referencias bibliograficas: adoptan las normas APA. El documento es producto de un rastreo bibliografico que muestra analisis y sistensis. | L3: =LIDER!E15 -> ASESORIAS: Anexó la hoja de tutoria firmada ( 3 fimas minmimo).
F4: =CONCATENATE(LIDER!C4," - ",LIDER!C6," - ",LIDER!C5) -> INNOVACION Y EMPRENDIMIENTO - 2304 - EDUARDO JESUS CARDENAS RODRIGUEZ
B5: GRUPO#1 | C5: G01 | D5: LIST | E5: DEF | F5: =LIDER!$E$29 -> GRUPO#1
A6: 1 | B6: =LIDER!E43 -> SANTIAGO AVILA MONTERROSA | C6: =C5 -> G01 | E6: =IF(B6=0,0,IF(D6="",$F$6*LIDER!$H$9+$G$6*LIDER!$H$10+$H$6*LIDER!$H$11+$I$6*LIDER!$H$12+$J$6*LIDER!$H$13+$K$6*LIDER!$H$14+$L$6*LIDER!$H$15,"N")) -> 3.33 | F6: 3 | G6: 3 | H6: 3.5 | I6: 3.6 | J6: 3.2 | K6: 3 | L6: 5
A7: 2 | B7: =LIDER!E44 -> FEDERICO GALLEGO TROCONIS | C7: =C6 -> G01 | E7: =IF(B7=0,0,IF(D7="",$F$6*LIDER!$H$9+$G$6*LIDER!$H$10+$H$6*LIDER!$H$11+$I$6*LIDER!$H$12+$J$6*LIDER!$H$13+$K$6*LIDER!$H$14+$L$6*LIDER!$H$15,"N")) -> 3.33
A8: 3 | B8: =LIDER!E45 -> FERNANDO ANTONIO UPEGUI MARTINEZ | C8: =C7 -> G01 | E8: =IF(B8=0,0,IF(D8="",$F$6*LIDER!$H$9+$G$6*LIDER!$H$10+$H$6*LIDER!$H$11+$I$6*LIDER!$H$12+$J$6*LIDER!$H$13+$K$6*LIDER!$H$14+$L$6*LIDER!$H$15,"N")) -> 3.33
A9: 4 | B9: =LIDER!E46 -> 0 | C9: =C8 -> G01 | E9: =IF(B9=0,0,IF(D9="",$F$6*LIDER!$H$9+$G$6*LIDER!$H$10+$H$6*LIDER!$H$11+$I$6*LIDER!$H$12+$J$6*LIDER!$H$13+$K$6*LIDER!$H$14+$L$6*LIDER!$H$15,"N")) -> 0
A10: 5 | B10: =LIDER!E47 -> 0 | C10: =C9 -> G01 | E10: =IF(B10=0,0,IF(D10="",$F$6*LIDER!$H$9+$G$6*LIDER!$H$10+$H$6*LIDER!$H$11+$I$6*LIDER!$H$12+$J$6*LIDER!$H$13+$K$6*LIDER!$H$14+$L$6*LIDER!$H$15,"N")) -> 0
A11: 6 | B11: =LIDER!E48 -> 0 | C11: =C10 -> G01 | E11: =IF(B11=0,0,IF(D11="",$F$6*LIDER!$H$9+$G$6*LIDER!$H$10+$H$6*LIDER!$H$11+$I$6*LIDER!$H$12+$J$6*LIDER!$H$13+$K$6*LIDER!$H$14+$L$6*LIDER!$H$15,"N")) -> 0
B12: GRUPO#2 | C12: G02 | D12: =D5 -> LIST | E12: DEF | F12: =LIDER!$E$30 -> GRUPO#2
A13: 1 | B13: =LIDER!F43 -> LERCY MARCELA CHAVEZ CASTELLAR | C13: =C12 -> G02 | E13: =IF(B13=0,0,IF(D13="",$F$13*LIDER!$H$9+$G$13*LIDER!$H$10+$H$13*LIDER!$H$11+$I$13*LIDER!$H$12+$J$13*LIDER!$H$13+$K$13*LIDER!$H$14+$L$13*LIDER!$H$15,"N")) -> 2.37 | F13: 3.2 | G13: 3.5 | H13: 3.3 | I13: 3.5 | J13: 3.5 | K13: 0 | L13: 0
A14: 2 | B14: =LIDER!F44 -> JUAN DAVID DEVOZ GONZALEZ | C14: =C13 -> G02 | E14: =IF(B14=0,0,IF(D14="",$F$13*LIDER!$H$9+$G$13*LIDER!$H$10+$H$13*LIDER!$H$11+$I$13*LIDER!$H$12+$J$13*LIDER!$H$13+$K$13*LIDER!$H$14+$L$13*LIDER!$H$15,"N")) -> 2.37
A15: 3 | B15: =LIDER!F45 -> SANTIAGO HERNÁNDEZ BARBOZA | C15: =C14 -> G02 | E15: =IF(B15=0,0,IF(D15="",$F$13*LIDER!$H$9+$G$13*LIDER!$H$10+$H$13*LIDER!$H$11+$I$13*LIDER!$H$12+$J$13*LIDER!$H$13+$K$13*LIDER!$H$14+$L$13*LIDER!$H$15,"N")) -> 2.37
A16: 4 | B16: =LIDER!F46 -> DIEGO JACOME PERALTA | C16: =C15 -> G02 | E16: =IF(B16=0,0,IF(D16="",$F$13*LIDER!$H$9+$G$13*LIDER!$H$10+$H$13*LIDER!$H$11+$I$13*LIDER!$H$12+$J$13*LIDER!$H$13+$K$13*LIDER!$H$14+$L$13*LIDER!$H$15,"N")) -> 2.37
A17: 5 | B17: =LIDER!F47 -> JESUS ALBERTO MADRID BORDA | C17: =C16 -> G02 | E17: =IF(B17=0,0,IF(D17="",$F$13*LIDER!$H$9+$G$13*LIDER!$H$10+$H$13*LIDER!$H$11+$I$13*LIDER!$H$12+$J$13*LIDER!$H$13+$K$13*LIDER!$H$14+$L$13*LIDER!$H$15,"N")) -> 2.37
A18: 6 | B18: =LIDER!F48 -> JUAN ANDRES REYES GOMEZ | C18: =C17 -> G02 | E18: =IF(B18=0,0,IF(D18="",$F$13*LIDER!$H$9+$G$13*LIDER!$H$10+$H$13*LIDER!$H$11+$I$13*LIDER!$H$12+$J$13*LIDER!$H$13+$K$13*LIDER!$H$14+$L$13*LIDER!$H$15,"N")) -> 2.37
B19: GRUPO#3 | C19: G03 | D19: =D12 -> LIST | E19: DEF | F19: =LIDER!$E$31 -> GRUPO#3
A20: 1 | B20: =LIDER!G43 -> ANDREA CAROLINA GONZALEZ PEREZ | C20: =C19 -> G03 | E20: =IF(B20=0,0,IF(D20="",$F$20*LIDER!$H$9+$G$20*LIDER!$H$10+$H$20*LIDER!$H$11+$I$20*LIDER!$H$12+$J$20*LIDER!$H$13+$K$20*LIDER!$H$14+$L$20*LIDER!$H$15,"N")) -> 3.26 | F20: 3 | G20: 3.5 | H20: 3.8 | I20: 3.5 | J20: 4 | K20: 2.5 | L20: 3.3
A21: 2 | B21: =LIDER!G44 -> SHEIDY ALEJANDRA HERNANDEZ NIEVES | C21: =C20 -> G03 | E21: =IF(B21=0,0,IF(D21="",$F$20*LIDER!$H$9+$G$20*LIDER!$H$10+$H$20*LIDER!$H$11+$I$20*LIDER!$H$12+$J$20*LIDER!$H$13+$K$20*LIDER!$H$14+$L$20*LIDER!$H$15,"N")) -> 3.26
A22: 3 | B22: =LIDER!G45 -> 0 | C22: =C21 -> G03 | E22: =IF(B22=0,0,IF(D22="",$F$20*LIDER!$H$9+$G$20*LIDER!$H$10+$H$20*LIDER!$H$11+$I$20*LIDER!$H$12+$J$20*LIDER!$H$13+$K$20*LIDER!$H$14+$L$20*LIDER!$H$15,"N")) -> 0
A23: 4 | B23: =LIDER!G46 -> 0 | C23: =C22 -> G03 | E23: =IF(B23=0,0,IF(D23="",$F$20*LIDER!$H$9+$G$20*LIDER!$H$10+$H$20*LIDER!$H$11+$I$20*LIDER!$H$12+$J$20*LIDER!$H$13+$K$20*LIDER!$H$14+$L$20*LIDER!$H$15,"N")) -> 0
A24: 5 | B24: =LIDER!G47 -> 0 | C24: =C23 -> G03 | E24: =IF(B24=0,0,IF(D24="",$F$20*LIDER!$H$9+$G$20*LIDER!$H$10+$H$20*LIDER!$H$11+$I$20*LIDER!$H$12+$J$20*LIDER!$H$13+$K$20*LIDER!$H$14+$L$20*LIDER!$H$15,"N")) -> 0
A25: 6 | B25: =LIDER!G48 -> 0 | C25: =C24 -> G03 | E25: =IF(B25=0,0,IF(D25="",$F$20*LIDER!$H$9+$G$20*LIDER!$H$10+$H$20*LIDER!$H$11+$I$20*LIDER!$H$12+$J$20*LIDER!$H$13+$K$20*LIDER!$H$14+$L$20*LIDER!$H$15,"N")) -> 0
B26: GRUPO#4 | C26: G04 | D26: =D19 -> LIST | E26: DEF | F26: =LIDER!$E$32 -> GRUPO#4
A27: 1 | B27: =LIDER!H43 -> ZHEYLA MARCELA AFANADOR TORRES | C27: =C26 -> G04 | E27: =IF(B27=0,0,IF(D27="",$F$27*LIDER!$H$9+$G$27*LIDER!$H$10+$H$27*LIDER!$H$11+$I$27*LIDER!$H$12+$J$27*LIDER!$H$13+$K$27*LIDER!$H$14+$L$27*LIDER!$H$15,"N")) -> 4 | F27: 4 | G27: 4 | H27: 4.4 | I27: 4 | J27: 4.6 | K27: 3 | L27: 5
A28: 2 | B28: =LIDER!H44 -> NATALI AGRESOTT GOMEZ | C28: =C27 -> G04 | E28: =IF(B28=0,0,IF(D28="",$F$27*LIDER!$H$9+$G$27*LIDER!$H$10+$H$27*LIDER!$H$11+$I$27*LIDER!$H$12+$J$27*LIDER!$H$13+$K$27*LIDER!$H$14+$L$27*LIDER!$H$15,"N")) -> 4
A29: 3 | B29: =LIDER!H45 -> DAYLETH CONEO OSPINO | C29: =C28 -> G04 | E29: =IF(B29=0,0,IF(D29="",$F$27*LIDER!$H$9+$G$27*LIDER!$H$10+$H$27*LIDER!$H$11+$I$27*LIDER!$H$12+$J$27*LIDER!$H$13+$K$27*LIDER!$H$14+$L$27*LIDER!$H$15,"N")) -> 4
A30: 4 | B30: =LIDER!H46 -> NATHALIA JULIETH ORTEGA ROMERO | C30: =C29 -> G04 | E30: =IF(B30=0,0,IF(D30="",$F$27*LIDER!$H$9+$G$27*LIDER!$H$10+$H$27*LIDER!$H$11+$I$27*LIDER!$H$12+$J$27*LIDER!$H$13+$K$27*LIDER!$H$14+$L$27*LIDER!$H$15,"N")) -> 4
A31: 5 | B31: =LIDER!H47 -> YURIDIS ORTIZ TORRES | C31: =C30 -> G04 | E31: =IF(B31=0,0,IF(D31="",$F$27*LIDER!$H$9+$G$27*LIDER!$H$10+$H$27*LIDER!$H$11+$I$27*LIDER!$H$12+$J$27*LIDER!$H$13+$K$27*LIDER!$H$14+$L$27*LIDER!$H$15,"N")) -> 4
A32: 6 | B32: =LIDER!H48 -> 0 | C32: =C31 -> G04 | E32: =IF(B32=0,0,IF(D32="",$F$27*LIDER!$H$9+$G$27*LIDER!$H$10+$H$27*LIDER!$H$11+$I$27*LIDER!$H$12+$J$27*LIDER!$H$13+$K$27*LIDER!$H$14+$L$27*LIDER!$H$15,"N")) -> 0
B33: GRUPO#5 | C33: G05 | D33: =D26 -> LIST | E33: DEF | F33: =LIDER!$E$33 -> GRUPO#5
A34: 1 | B34: =LIDER!E51 -> MARIA JOSE ACEVEDO QUINTANA | C34: =C33 -> G05 | E34: =IF(B34=0,0,IF(D34="",$F$34*LIDER!$H$9+$G$34*LIDER!$H$10+$H$34*LIDER!$H$11+$I$34*LIDER!$H$12+$J$34*LIDER!$H$13+$K$34*LIDER!$H$14+$L$34*LIDER!$H$15,"N")) -> 3.48 | F34: 3.8 | G34: 3 | H34: 4.3 | I34: 4 | J34: 4.2 | K34: 3.5 | L34: 1.7
A35: 2 | B35: =LIDER!E52 -> YEIDYS FAINORYS ARROYO GRANADOS | C35: =C34 -> G05 | E35: =IF(B35=0,0,IF(D35="",$F$34*LIDER!$H$9+$G$34*LIDER!$H$10+$H$34*LIDER!$H$11+$I$34*LIDER!$H$12+$J$34*LIDER!$H$13+$K$34*LIDER!$H$14+$L$34*LIDER!$H$15,"N")) -> 3.48
A36: 3 | B36: =LIDER!E53 -> ANGELICA NAVARRO TORRES | C36: =C35 -> G05 | E36: =IF(B36=0,0,IF(D36="",$F$34*LIDER!$H$9+$G$34*LIDER!$H$10+$H$34*LIDER!$H$11+$I$34*LIDER!$H$12+$J$34*LIDER!$H$13+$K$34*LIDER!$H$14+$L$34*LIDER!$H$15,"N")) -> 3.48
A37: 4 | B37: =LIDER!E54 -> ISABELLA OLIVARES LLANOS | C37: =C36 -> G05 | E37: =IF(B37=0,0,IF(D37="",$F$34*LIDER!$H$9+$G$34*LIDER!$H$10+$H$34*LIDER!$H$11+$I$34*LIDER!$H$12+$J$34*LIDER!$H$13+$K$34*LIDER!$H$14+$L$34*LIDER!$H$15,"N")) -> 3.48
A38: 5 | B38: =LIDER!E55 -> SAMARA ELIZABETH SUAREZ NAVARRO | C38: =C37 -> G05 | E38: =IF(B38=0,0,IF(D38="",$F$34*LIDER!$H$9+$G$34*LIDER!$H$10+$H$34*LIDER!$H$11+$I$34*LIDER!$H$12+$J$34*LIDER!$H$13+$K$34*LIDER!$H$14+$L$34*LIDER!$H$15,"N")) -> 3.48
A39: 6 | B39: =LIDER!E56 -> 0 | C39: =C38 -> G05 | E39: =IF(B39=0,0,IF(D39="",$F$34*LIDER!$H$9+$G$34*LIDER!$H$10+$H$34*LIDER!$H$11+$I$34*LIDER!$H$12+$J$34*LIDER!$H$13+$K$34*LIDER!$H$14+$L$34*LIDER!$H$15,"N")) -> 0
B40: GRUPO#6 | C40: G06 | D40: =D33 -> LIST | E40: DEF | F40: =LIDER!$E$34 -> GRUPO#6
...

Sheet S-ASIG-02
A1: =LIDER!B2 -> TECNOLOGÍA EN GESTIÓN DE NEGOCIOS INTERN | I1: =LIDER!E2 -> SEMESTRE: | J1: =LIDER!F2 -> SEM-06 | K1: =LIDER!G2 -> SECCIÓN: | L1: =LIDER!H2 -> 3
B2: =LIDER!D4 -> ELECTIVA DE PROFUNDIZACION III | F2: CRITERIOS DE EVALUACIÓN
B3: Estudiantes | F3: =LIDER!E9 -> PRESENTACIÓN GENERAL: Adopta la norma APA, tamaño de la hoja, margenes, titulo, portadas, numeración de paginas, tabla de contenido automatizada, ortografia, justificacion del texto, citas automatizadas, listas, figuras,etc. | G3: =LIDER!E10 -> ANTEPROYECTO: Portada, planteamiento del problema, justificacion del trabajo o proyecto de aula, objetivos, marco teorico, diseño metodologico. | H3: =LIDER!E11 -> RESULTADOS: Analiza, integra y aplica de manera coherente los aspectos para la Construcción de la marca empresarial (Branding) | I3: =LIDER!E12 -> RESULTADOS: Analiza, integra y aplica de manera coherente los aspectos del Plan de distribución. | J3: =LIDER!E13 -> RESULTADOS: Analiza, integra y aplica de manera coherente los aspectos para el Análisis ambiental y social. | K3: =LIDER!E14 -> BILIOGRAFIA: Las referencias bibliograficas: adoptan las normas APA. El documento es producto de un rastreo bibliografico que muestra analisis y sistensis. | L3: =LIDER!E15 -> ASESORIAS: Anexó la hoja de tutoria firmada ( 3 fimas minmimo).
F4: =CONCATENATE(LIDER!D4," - ",LIDER!D6," - ",LIDER!D5) -> ELECTIVA DE PROFUNDIZACION III - 2320 - HERNANDO RAFAEL ARMESTO ABUABARA
B5: GRUPO#1 | C5: G01 | D5: LIST | E5: DEF | F5: =LIDER!$E$29 -> GRUPO#1
A6: 1 | B6: =LIDER!E43 -> SANTIAGO AVILA MONTERROSA | C6: =C5 -> G01 | E6: =IF(B6=0,0,IF(D6="",$F$6*LIDER!$H$9+$G$6*LIDER!$H$10+$H$6*LIDER!$H$11+$I$6*LIDER!$H$12+$J$6*LIDER!$H$13+$K$6*LIDER!$H$14+$L$6*LIDER!$H$15,"N")) -> 3.95 | F6: 3.5 | G6: 4.5 | H6: 3.8 | I6: 4.2 | J6: 3.5 | K6: 3.5 | L6: 5
A7: 2 | B7: =LIDER!E44 -> FEDERICO GALLEGO TROCONIS | C7: =C6 -> G01 | E7: =IF(B7=0,0,IF(D7="",$F$6*LIDER!$H$9+$G$6*LIDER!$H$10+$H$6*LIDER!$H$11+$I$6*LIDER!$H$12+$J$6*LIDER!$H$13+$K$6*LIDER!$H$14+$L$6*LIDER!$H$15,"N")) -> 3.95
A8: 3 | B8: =LIDER!E45 -> FERNANDO ANTONIO UPEGUI MARTINEZ | C8: =C7 -> G01 | E8: =IF(B8=0,0,IF(D8="",$F$6*LIDER!$H$9+$G$6*LIDER!$H$10+$H$6*LIDER!$H$11+$I$6*LIDER!$H$12+$J$6*LIDER!$H$13+$K$6*LIDER!$H$14+$L$6*LIDER!$H$15,"N")) -> 3.95
A9: 4 | B9: =LIDER!E46 -> 0 | C9: =C8 -> G01 | E9: =IF(B9=0,0,IF(D9="",$F$6*LIDER!$H$9+$G$6*LIDER!$H$10+$H$6*LIDER!$H$11+$I$6*LIDER!$H$12+$J$6*LIDER!$H$13+$K$6*LIDER!$H$14+$L$6*LIDER!$H$15,"N")) -> 0
A10: 5 | B10: =LIDER!E47 -> 0 | C10: =C9 -> G01 | E10: =IF(B10=0,0,IF(D10="",$F$6*LIDER!$H$9+$G$6*LIDER!$H$10+$H$6*LIDER!$H$11+$I$6*LIDER!$H$12+$J$6*LIDER!$H$13+$K$6*LIDER!$H$14+$L$6*LIDER!$H$15,"N")) -> 0
A11: 6 | B11: =LIDER!E48 -> 0 | C11: =C10 -> G01 | E11: =IF(B11=0,0,IF(D11="",$F$6*LIDER!$H$9+$G$6*LIDER!$H$10+$H$6*LIDER!$H$11+$I$6*LIDER!$H$12+$J$6*LIDER!$H$13+$K$6*LIDER!$H$14+$L$6*LIDER!$H$15,"N")) -> 0
B12: GRUPO#2 | C12: G02 | D12: =D5 -> LIST | E12: DEF | F12: =LIDER!$E$30 -> GRUPO#2
A13: 1 | B13: =LIDER!F43 -> LERCY MARCELA CHAVEZ CASTELLAR | C13: =C12 -> G02 | E13: =IF(B13=0,0,IF(D13="",$F$13*LIDER!$H$9+$G$13*LIDER!$H$10+$H$13*LIDER!$H$11+$I$13*LIDER!$H$12+$J$13*LIDER!$H$13+$K$13*LIDER!$H$14+$L$13*LIDER!$H$15,"N")) -> 2.86 | F13: 3 | G13: 4 | H13: 4.3 | I13: 3.5 | J13: 3.8 | K13: 1 | L13: 1
A14: 2 | B14: =LIDER!F44 -> JUAN DAVID DEVOZ GONZALEZ | C14: =C13 -> G02 | E14: =IF(B14=0,0,IF(D14="",$F$13*LIDER!$H$9+$G$13*LIDER!$H$10+$H$13*LIDER!$H$11+$I$13*LIDER!$H$12+$J$13*LIDER!$H$13+$K$13*LIDER!$H$14+$L$13*LIDER!$H$15,"N")) -> 2.86
A15: 3 | B15: =LIDER!F45 -> SANTIAGO HERNÁNDEZ BARBOZA | C15: =C14 -> G02 | E15: =IF(B15=0,0,IF(D15="",$F$13*LIDER!$H$9+$G$13*LIDER!$H$10+$H$13*LIDER!$H$11+$I$13*LIDER!$H$12+$J$13*LIDER!$H$13+$K$13*LIDER!$H$14+$L$13*LIDER!$H$15,"N")) -> 2.86
A16: 4 | B16: =LIDER!F46 -> DIEGO JACOME PERALTA | C16: =C15 -> G02 | E16: =IF(B16=0,0,IF(D16="",$F$13*LIDER!$H$9+$G$13*LIDER!$H$10+$H$13*LIDER!$H$11+$I$13*LIDER!$H$12+$J$13*LIDER!$H$13+$K$13*LIDER!$H$14+$L$13*LIDER!$H$15,"N")) -> 2.86
A17: 5 | B17: =LIDER!F47 -> JESUS ALBERTO MADRID BORDA | C17: =C16 -> G02 | E17: =IF(B17=0,0,IF(D17="",$F$13*LIDER!$H$9+$G$13*LIDER!$H$10+$H$13*LIDER!$H$11+$I$13*LIDER!$H$12+$J$13*LIDER!$H$13+$K$13*LIDER!$H$14+$L$13*LIDER!$H$15,"N")) -> 2.86
A18: 6 | B18: =LIDER!F48 -> JUAN ANDRES REYES GOMEZ | C18: =C17 -> G02 | E18: =IF(B18=0,0,IF(D18="",$F$13*LIDER!$H$9+$G$13*LIDER!$H$10+$H$13*LIDER!$H$11+$I$13*LIDER!$H$12+$J$13*LIDER!$H$13+$K$13*LIDER!$H$14+$L$13*LIDER!$H$15,"N")) -> 2.86
B19: GRUPO#3 | C19: G03 | D19: =D12 -> LIST | E19: DEF | F19: =LIDER!$E$31 -> GRUPO#3
A20: 1 | B20: =LIDER!G43 -> ANDREA CAROLINA GONZALEZ PEREZ | C20: =C19 -> G03 | E20: =IF(B20=0,0,IF(D20="",$F$20*LIDER!$H$9+$G$20*LIDER!$H$10+$H$20*LIDER!$H$11+$I$20*LIDER!$H$12+$J$20*LIDER!$H$13+$K$20*LIDER!$H$14+$L$20*LIDER!$H$15,"N")) -> 3.44 | F20: 3.3 | G20: 4 | H20: 4.5 | I20: 3.5 | J20: 3.8 | K20: 2.5 | L20: 3
A21: 2 | B21: =LIDER!G44 -> SHEIDY ALEJANDRA HERNANDEZ NIEVES | C21: =C20 -> G03 | E21: =IF(B21=0,0,IF(D21="",$F$20*LIDER!$H$9+$G$20*LIDER!$H$10+$H$20*LIDER!$H$11+$I$20*LIDER!$H$12+$J$20*LIDER!$H$13+$K$20*LIDER!$H$14+$L$20*LIDER!$H$15,"N")) -> 3.44
A22: 3 | B22: =LIDER!G45 -> 0 | C22: =C21 -> G03 | E22: =IF(B22=0,0,IF(D22="",$F$20*LIDER!$H$9+$G$20*LIDER!$H$10+$H$20*LIDER!$H$11+$I$20*LIDER!$H$12+$J$20*LIDER!$H$13+$K$20*LIDER!$H$14+$L$20*LIDER!$H$15,"N")) -> 0
A23: 4 | B23: =LIDER!G46 -> 0 | C23: =C22 -> G03 | E23: =IF(B23=0,0,IF(D23="",$F$20*LIDER!$H$9+$G$20*LIDER!$H$10+$H$20*LIDER!$H$11+$I$20*LIDER!$H$12+$J$20*LIDER!$H$13+$K$20*LIDER!$H$14+$L$20*LIDER!$H$15,"N")) -> 0
A24: 5 | B24: =LIDER!G47 -> 0 | C24: =C23 -> G03 | E24: =IF(B24=0,0,IF(D24="",$F$20*LIDER!$H$9+$G$20*LIDER!$H$10+$H$20*LIDER!$H$11+$I$20*LIDER!$H$12+$J$20*LIDER!$H$13+$K$20*LIDER!$H$14+$L$20*LIDER!$H$15,"N")) -> 0
A25: 6 | B25: =LIDER!G48 -> 0 | C25: =C24 -> G03 | E25: =IF(B25=0,0,IF(D25="",$F$20*LIDER!$H$9+$G$20*LIDER!$H$10+$H$20*LIDER!$H$11+$I$20*LIDER!$H$12+$J$20*LIDER!$H$13+$K$20*LIDER!$H$14+$L$20*LIDER!$H$15,"N")) -> 0
B26: GRUPO#4 | C26: G04 | D26: =D19 -> LIST | E26: DEF | F26: =LIDER!$E$32 -> GRUPO#4
A27: 1 | B27: =LIDER!H43 -> ZHEYLA MARCELA AFANADOR TORRES | C27: =C26 -> G04 | E27: =IF(B27=0,0,IF(D27="",$F$27*LIDER!$H$9+$G$27*LIDER!$H$10+$H$27*LIDER!$H$11+$I$27*LIDER!$H$12+$J$27*LIDER!$H$13+$K$27*LIDER!$H$14+$L$27*LIDER!$H$15,"N")) -> 4.3 | F27: 4.3 | G27: 4.5 | H27: 4.7 | I27: 4.5 | J27: 4.2 | K27: 3.5 | L27: 5
A28: 2 | B28: =LIDER!H44 -> NATALI AGRESOTT GOMEZ | C28: =C27 -> G04 | E28: =IF(B28=0,0,IF(D28="",$F$27*LIDER!$H$9+$G$27*LIDER!$H$10+$H$27*LIDER!$H$11+$I$27*LIDER!$H$12+$J$27*LIDER!$H$13+$K$27*LIDER!$H$14+$L$27*LIDER!$H$15,"N")) -> 4.3
A29: 3 | B29: =LIDER!H45 -> DAYLETH CONEO OSPINO | C29: =C28 -> G04 | E29: =IF(B29=0,0,IF(D29="",$F$27*LIDER!$H$9+$G$27*LIDER!$H$10+$H$27*LIDER!$H$11+$I$27*LIDER!$H$12+$J$27*LIDER!$H$13+$K$27*LIDER!$H$14+$L$27*LIDER!$H$15,"N")) -> 4.3
A30: 4 | B30: =LIDER!H46 -> NATHALIA JULIETH ORTEGA ROMERO | C30: =C29 -> G04 | E30: =IF(B30=0,0,IF(D30="",$F$27*LIDER!$H$9+$G$27*LIDER!$H$10+$H$27*LIDER!$H$11+$I$27*LIDER!$H$12+$J$27*LIDER!$H$13+$K$27*LIDER!$H$14+$L$27*LIDER!$H$15,"N")) -> 4.3
A31: 5 | B31: =LIDER!H47 -> YURIDIS ORTIZ TORRES | C31: =C30 -> G04 | E31: =IF(B31=0,0,IF(D31="",$F$27*LIDER!$H$9+$G$27*LIDER!$H$10+$H$27*LIDER!$H$11+$I$27*LIDER!$H$12+$J$27*LIDER!$H$13+$K$27*LIDER!$H$14+$L$27*LIDER!$H$15,"N")) -> 4.3
A32: 6 | B32: =LIDER!H48 -> 0 | C32: =C31 -> G04 | E32: =IF(B32=0,0,IF(D32="",$F$27*LIDER!$H$9+$G$27*LIDER!$H$10+$H$27*LIDER!$H$11+$I$27*LIDER!$H$12+$J$27*LIDER!$H$13+$K$27*LIDER!$H$14+$L$27*LIDER!$H$15,"N")) -> 0
B33: GRUPO#5 | C33: G05 | D33: =D26 -> LIST | E33: DEF | F33: =LIDER!$E$33 -> GRUPO#5
A34: 1 | B34: =LIDER!E51 -> MARIA JOSE ACEVEDO QUINTANA | C34: =C33 -> G05 | E34: =IF(B34=0,0,IF(D34="",$F$34*LIDER!$H$9+$G$34*LIDER!$H$10+$H$34*LIDER!$H$11+$I$34*LIDER!$H$12+$J$34*LIDER!$H$13+$K$34*LIDER!$H$14+$L$34*LIDER!$H$15,"N")) -> 4.35 | F34: 4.2 | G34: 4 | H34: 4.5 | I34: 4.6 | J34: 4 | K34: 4.5 | L34: 5
A35: 2 | B35: =LIDER!E52 -> YEIDYS FAINORYS ARROYO GRANADOS | C35: =C34 -> G05 | E35: =IF(B35=0,0,IF(D35="",$F$34*LIDER!$H$9+$G$34*LIDER!$H$10+$H$34*LIDER!$H$11+$I$34*LIDER!$H$12+$J$34*LIDER!$H$13+$K$34*LIDER!$H$14+$L$34*LIDER!$H$15,"N")) -> 4.35
A36: 3 | B36: =LIDER!E53 -> ANGELICA NAVARRO TORRES | C36: =C35 -> G05 | E36: =IF(B36=0,0,IF(D36="",$F$34*LIDER!$H$9+$G$34*LIDER!$H$10+$H$34*LIDER!$H$11+$I$34*LIDER!$H$12+$J$34*LIDER!$H$13+$K$34*LIDER!$H$14+$L$34*LIDER!$H$15,"N")) -> 4.35
A37: 4 | B37: =LIDER!E54 -> ISABELLA OLIVARES LLANOS | C37: =C36 -> G05 | E37: =IF(B37=0,0,IF(D37="",$F$34*LIDER!$H$9+$G$34*LIDER!$H$10+$H$34*LIDER!$H$11+$I$34*LIDER!$H$12+$J$34*LIDER!$H$13+$K$34*LIDER!$H$14+$L$34*LIDER!$H$15,"N")) -> 4.35
A38: 5 | B38: =LIDER!E55 -> SAMARA ELIZABETH SUAREZ NAVARRO | C38: =C37 -> G05 | E38: =IF(B38=0,0,IF(D38="",$F$34*LIDER!$H$9+$G$34*LIDER!$H$10+$H$34*LIDER!$H$11+$I$34*LIDER!$H$12+$J$34*LIDER!$H$13+$K$34*LIDER!$H$14+$L$34*LIDER!$H$15,"N")) -> 4.35
A39: 6 | B39: =LIDER!E56 -> 0 | C39: =C38 -> G05 | E39: =IF(B39=0,0,IF(D39="",$F$34*LIDER!$H$9+$G$34*LIDER!$H$10+$H$34*LIDER!$H$11+$I$34*LIDER!$H$12+$J$34*LIDER!$H$13+$K$34*LIDER!$H$14+$L$34*LIDER!$H$15,"N")) -> 0
B40: GRUPO#6 | C40: G06 | D40: =D33 -> LIST | E40: DEF | F40: =LIDER!$E$34 -> GRUPO#6
...

Sheet S-ASIG-03
A1: =LIDER!B2 -> TECNOLOGÍA EN GESTIÓN DE NEGOCIOS INTERN | I1: =LIDER!E2 -> SEMESTRE: | J1: =LIDER!F2 -> SEM-06 | K1: =LIDER!G2 -> SECCIÓN: | L1: =LIDER!H2 -> 3
B2: =LIDER!E4 -> AMBIENTE Y DESARROLLO | F2: CRITERIOS DE EVALUACIÓN
B3: Estudiantes | F3: =LIDER!E9 -> PRESENTACIÓN GENERAL: Adopta la norma APA, tamaño de la hoja, margenes, titulo, portadas, numeración de paginas, tabla de contenido automatizada, ortografia, justificacion del texto, citas automatizadas, listas, figuras,etc. | G3: =LIDER!E10 -> ANTEPROYECTO: Portada, planteamiento del problema, justificacion del trabajo o proyecto de aula, objetivos, marco teorico, diseño metodologico. | H3: =LIDER!E11 -> RESULTADOS: Analiza, integra y aplica de manera coherente los aspectos para la Construcción de la marca empresarial (Branding) | I3: =LIDER!E12 -> RESULTADOS: Analiza, integra y aplica de manera coherente los aspectos del Plan de distribución. | J3: =LIDER!E13 -> RESULTADOS: Analiza, integra y aplica de manera coherente los aspectos para el Análisis ambiental y social. | K3: =LIDER!E14 -> BILIOGRAFIA: Las referencias bibliograficas: adoptan las normas APA. El documento es producto de un rastreo bibliografico que muestra analisis y sistensis. | L3: =LIDER!E15 -> ASESORIAS: Anexó la hoja de tutoria firmada ( 3 fimas minmimo).
F4: =CONCATENATE(LIDER!E4," - ",LIDER!E6," - ",LIDER!E5) -> AMBIENTE Y DESARROLLO - 1086 - MARIANO BELTRAN PADILLA
B5: GRUPO#1 | C5: G01 | D5: LIST | E5: DEF | F5: =LIDER!$E$29 -> GRUPO#1
A6: 1 | B6: =LIDER!E43 -> SANTIAGO AVILA MONTERROSA | C6: =C5 -> G01 | E6: =IF(B6=0,0,IF(D6="",$F$6*LIDER!$H$9+$G$6*LIDER!$H$10+$H$6*LIDER!$H$11+$I$6*LIDER!$H$12+$J$6*LIDER!$H$13+$K$6*LIDER!$H$14+$L$6*LIDER!$H$15,"N")) -> 4.05 | F6: 4 | G6: 4 | H6: 4.5 | I6: 4 | J6: 4 | K6: 4 | L6: 4
A7: 2 | B7: =LIDER!E44 -> FEDERICO GALLEGO TROCONIS | C7: =C6 -> G01 | E7: =IF(B7=0,0,IF(D7="",$F$6*LIDER!$H$9+$G$6*LIDER!$H$10+$H$6*LIDER!$H$11+$I$6*LIDER!$H$12+$J$6*LIDER!$H$13+$K$6*LIDER!$H$14+$L$6*LIDER!$H$15,"N")) -> 4.05
A8: 3 | B8: =LIDER!E45 -> FERNANDO ANTONIO UPEGUI MARTINEZ | C8: =C7 -> G01 | E8: =IF(B8=0,0,IF(D8="",$F$6*LIDER!$H$9+$G$6*LIDER!$H$10+$H$6*LIDER!$H$11+$I$6*LIDER!$H$12+$J$6*LIDER!$H$13+$K$6*LIDER!$H$14+$L$6*LIDER!$H$15,"N")) -> 4.05
A9: 4 | B9: =LIDER!E46 -> 0 | C9: =C8 -> G01 | E9: =IF(B9=0,0,IF(D9="",$F$6*LIDER!$H$9+$G$6*LIDER!$H$10+$H$6*LIDER!$H$11+$I$6*LIDER!$H$12+$J$6*LIDER!$H$13+$K$6*LIDER!$H$14+$L$6*LIDER!$H$15,"N")) -> 0
A10: 5 | B10: =LIDER!E47 -> 0 | C10: =C9 -> G01 | E10: =IF(B10=0,0,IF(D10="",$F$6*LIDER!$H$9+$G$6*LIDER!$H$10+$H$6*LIDER!$H$11+$I$6*LIDER!$H$12+$J$6*LIDER!$H$13+$K$6*LIDER!$H$14+$L$6*LIDER!$H$15,"N")) -> 0
A11: 6 | B11: =LIDER!E48 -> 0 | C11: =C10 -> G01 | E11: =IF(B11=0,0,IF(D11="",$F$6*LIDER!$H$9+$G$6*LIDER!$H$10+$H$6*LIDER!$H$11+$I$6*LIDER!$H$12+$J$6*LIDER!$H$13+$K$6*LIDER!$H$14+$L$6*LIDER!$H$15,"N")) -> 0
B12: GRUPO#2 | C12: G02 | D12: =D5 -> LIST | E12: DEF | F12: =LIDER!$E$30 -> GRUPO#2
A13: 1 | B13: =LIDER!F43 -> LERCY MARCELA CHAVEZ CASTELLAR | C13: =C12 -> G02 | E13: =IF(B13=0,0,IF(D13="",$F$13*LIDER!$H$9+$G$13*LIDER!$H$10+$H$13*LIDER!$H$11+$I$13*LIDER!$H$12+$J$13*LIDER!$H$13+$K$13*LIDER!$H$14+$L$13*LIDER!$H$15,"N")) -> 2.67 | F13: 4 | G13: 3.5 | H13: 4 | I13: 4.2 | J13: 3.5 | K13: 0 | L13: 0
A14: 2 | B14: =LIDER!F44 -> JUAN DAVID DEVOZ GONZALEZ | C14: =C13 -> G02 | E14: =IF(B14=0,0,IF(D14="",$F$13*LIDER!$H$9+$G$13*LIDER!$H$10+$H$13*LIDER!$H$11+$I$13*LIDER!$H$12+$J$13*LIDER!$H$13+$K$13*LIDER!$H$14+$L$13*LIDER!$H$15,"N")) -> 2.67
A15: 3 | B15: =LIDER!F45 -> SANTIAGO HERNÁNDEZ BARBOZA | C15: =C14 -> G02 | E15: =IF(B15=0,0,IF(D15="",$F$13*LIDER!$H$9+$G$13*LIDER!$H$10+$H$13*LIDER!$H$11+$I$13*LIDER!$H$12+$J$13*LIDER!$H$13+$K$13*LIDER!$H$14+$L$13*LIDER!$H$15,"N")) -> 2.67
A16: 4 | B16: =LIDER!F46 -> DIEGO JACOME PERALTA | C16: =C15 -> G02 | E16: =IF(B16=0,0,IF(D16="",$F$13*LIDER!$H$9+$G$13*LIDER!$H$10+$H$13*LIDER!$H$11+$I$13*LIDER!$H$12+$J$13*LIDER!$H$13+$K$13*LIDER!$H$14+$L$13*LIDER!$H$15,"N")) -> 2.67
A17: 5 | B17: =LIDER!F47 -> JESUS ALBERTO MADRID BORDA | C17: =C16 -> G02 | E17: =IF(B17=0,0,IF(D17="",$F$13*LIDER!$H$9+$G$13*LIDER!$H$10+$H$13*LIDER!$H$11+$I$13*LIDER!$H$12+$J$13*LIDER!$H$13+$K$13*LIDER!$H$14+$L$13*LIDER!$H$15,"N")) -> 2.67
A18: 6 | B18: =LIDER!F48 -> JUAN ANDRES REYES GOMEZ | C18: =C17 -> G02 | E18: =IF(B18=0,0,IF(D18="",$F$13*LIDER!$H$9+$G$13*LIDER!$H$10+$H$13*LIDER!$H$11+$I$13*LIDER!$H$12+$J$13*LIDER!$H$13+$K$13*LIDER!$H$14+$L$13*LIDER!$H$15,"N")) -> 2.67
B19: GRUPO#3 | C19: G03 | D19: =D12 -> LIST | E19: DEF | F19: =LIDER!$E$31 -> GRUPO#3
A20: 1 | B20: =LIDER!G43 -> ANDREA CAROLINA GONZALEZ PEREZ | C20: =C19 -> G03 | E20: =IF(B20=0,0,IF(D20="",$F$20*LIDER!$H$9+$G$20*LIDER!$H$10+$H$20*LIDER!$H$11+$I$20*LIDER!$H$12+$J$20*LIDER!$H$13+$K$20*LIDER!$H$14+$L$20*LIDER!$H$15,"N")) -> 3.88 | F20: 3.5 | G20: 3.5 | H20: 4.2 | I20: 4.2 | J20: 4.5 | K20: 4.2 | L20: 3.5
A21: 2 | B21: =LIDER!G44 -> SHEIDY ALEJANDRA HERNANDEZ NIEVES | C21: =C20 -> G03 | E21: =IF(B21=0,0,IF(D21="",$F$20*LIDER!$H$9+$G$20*LIDER!$H$10+$H$20*LIDER!$H$11+$I$20*LIDER!$H$12+$J$20*LIDER!$H$13+$K$20*LIDER!$H$14+$L$20*LIDER!$H$15,"N")) -> 3.88
A22: 3 | B22: =LIDER!G45 -> 0 | C22: =C21 -> G03 | E22: =IF(B22=0,0,IF(D22="",$F$20*LIDER!$H$9+$G$20*LIDER!$H$10+$H$20*LIDER!$H$11+$I$20*LIDER!$H$12+$J$20*LIDER!$H$13+$K$20*LIDER!$H$14+$L$20*LIDER!$H$15,"N")) -> 0
A23: 4 | B23: =LIDER!G46 -> 0 | C23: =C22 -> G03 | E23: =IF(B23=0,0,IF(D23="",$F$20*LIDER!$H$9+$G$20*LIDER!$H$10+$H$20*LIDER!$H$11+$I$20*LIDER!$H$12+$J$20*LIDER!$H$13+$K$20*LIDER!$H$14+$L$20*LIDER!$H$15,"N")) -> 0
A24: 5 | B24: =LIDER!G47 -> 0 | C24: =C23 -> G03 | E24: =IF(B24=0,0,IF(D24="",$F$20*LIDER!$H$9+$G$20*LIDER!$H$10+$H$20*LIDER!$H$11+$I$20*LIDER!$H$12+$J$20*LIDER!$H$13+$K$20*LIDER!$H$14+$L$20*LIDER!$H$15,"N")) -> 0
A25: 6 | B25: =LIDER!G48 -> 0 | C25: =C24 -> G03 | E25: =IF(B25=0,0,IF(D25="",$F$20*LIDER!$H$9+$G$20*LIDER!$H$10+$H$20*LIDER!$H$11+$I$20*LIDER!$H$12+$J$20*LIDER!$H$13+$K$20*LIDER!$H$14+$L$20*LIDER!$H$15,"N")) -> 0
B26: GRUPO#4 | C26: G04 | D26: =D19 -> LIST | E26: DEF | F26: =LIDER!$E$32 -> GRUPO#4
A27: 1 | B27: =LIDER!H43 -> ZHEYLA MARCELA AFANADOR TORRES | C27: =C26 -> G04 | E27: =IF(B27=0,0,IF(D27="",$F$27*LIDER!$H$9+$G$27*LIDER!$H$10+$H$27*LIDER!$H$11+$I$27*LIDER!$H$12+$J$27*LIDER!$H$13+$K$27*LIDER!$H$14+$L$27*LIDER!$H$15,"N")) -> 4.09 | F27: 4 | G27: 3.5 | H27: 4.2 | I27: 4.2 | J27: 4.5 | K27: 4.5 | L27: 4
A28: 2 | B28: =LIDER!H44 -> NATALI AGRESOTT GOMEZ | C28: =C27 -> G04 | E28: =IF(B28=0,0,IF(D28="",$F$27*LIDER!$H$9+$G$27*LIDER!$H$10+$H$27*LIDER!$H$11+$I$27*LIDER!$H$12+$J$27*LIDER!$H$13+$K$27*LIDER!$H$14+$L$27*LIDER!$H$15,"N")) -> 4.09
A29: 3 | B29: =LIDER!H45 -> DAYLETH CONEO OSPINO | C29: =C28 -> G04 | E29: =IF(B29=0,0,IF(D29="",$F$27*LIDER!$H$9+$G$27*LIDER!$H$10+$H$27*LIDER!$H$11+$I$27*LIDER!$H$12+$J$27*LIDER!$H$13+$K$27*LIDER!$H$14+$L$27*LIDER!$H$15,"N")) -> 4.09
A30: 4 | B30: =LIDER!H46 -> NATHALIA JULIETH ORTEGA ROMERO | C30: =C29 -> G04 | E30: =IF(B30=0,0,IF(D30="",$F$27*LIDER!$H$9+$G$27*LIDER!$H$10+$H$27*LIDER!$H$11+$I$27*LIDER!$H$12+$J$27*LIDER!$H$13+$K$27*LIDER!$H$14+$L$27*LIDER!$H$15,"N")) -> 4.09
A31: 5 | B31: =LIDER!H47 -> YURIDIS ORTIZ TORRES | C31: =C30 -> G04 | E31: =IF(B31=0,0,IF(D31="",$F$27*LIDER!$H$9+$G$27*LIDER!$H$10+$H$27*LIDER!$H$11+$I$27*LIDER!$H$12+$J$27*LIDER!$H$13+$K$27*LIDER!$H$14+$L$27*LIDER!$H$15,"N")) -> 4.09
A32: 6 | B32: =LIDER!H48 -> 0 | C32: =C31 -> G04 | E32: =IF(B32=0,0,IF(D32="",$F$27*LIDER!$H$9+$G$27*LIDER!$H$10+$H$27*LIDER!$H$11+$I$27*LIDER!$H$12+$J$27*LIDER!$H$13+$K$27*LIDER!$H$14+$L$27*LIDER!$H$15,"N")) -> 0
B33: GRUPO#5 | C33: G05 | D33: =D26 -> LIST | E33: DEF | F33: =LIDER!$E$33 -> GRUPO#5
A34: 1 | B34: =LIDER!E51 -> MARIA JOSE ACEVEDO QUINTANA | C34: =C33 -> G05 | E34: =IF(B34=0,0,IF(D34="",$F$34*LIDER!$H$9+$G$34*LIDER!$H$10+$H$34*LIDER!$H$11+$I$34*LIDER!$H$12+$J$34*LIDER!$H$13+$K$34*LIDER!$H$14+$L$34*LIDER!$H$15,"N")) -> 4.04 | F34: 3.5 | G34: 3.5 | H34: 4.2 | I34: 4.2 | J34: 4.5 | K34: 4.5 | L34: 4.5
A35: 2 | B35: =LIDER!E52 -> YEIDYS FAINORYS ARROYO GRANADOS | C35: =C34 -> G05 | E35: =IF(B35=0,0,IF(D35="",$F$34*LIDER!$H$9+$G$34*LIDER!$H$10+$H$34*LIDER!$H$11+$I$34*LIDER!$H$12+$J$34*LIDER!$H$13+$K$34*LIDER!$H$14+$L$34*LIDER!$H$15,"N")) -> 4.04
A36: 3 | B36: =LIDER!E53 -> ANGELICA NAVARRO TORRES | C36: =C35 -> G05 | E36: =IF(B36=0,0,IF(D36="",$F$34*LIDER!$H$9+$G$34*LIDER!$H$10+$H$34*LIDER!$H$11+$I$34*LIDER!$H$12+$J$34*LIDER!$H$13+$K$34*LIDER!$H$14+$L$34*LIDER!$H$15,"N")) -> 4.04
A37: 4 | B37: =LIDER!E54 -> ISABELLA OLIVARES LLANOS | C37: =C36 -> G05 | E37: =IF(B37=0,0,IF(D37="",$F$34*LIDER!$H$9+$G$34*LIDER!$H$10+$H$34*LIDER!$H$11+$I$34*LIDER!$H$12+$J$34*LIDER!$H$13+$K$34*LIDER!$H$14+$L$34*LIDER!$H$15,"N")) -> 4.04
A38: 5 | B38: =LIDER!E55 -> SAMARA ELIZABETH SUAREZ NAVARRO | C38: =C37 -> G05 | E38: =IF(B38=0,0,IF(D38="",$F$34*LIDER!$H$9+$G$34*LIDER!$H$10+$H$34*LIDER!$H$11+$I$34*LIDER!$H$12+$J$34*LIDER!$H$13+$K$34*LIDER!$H$14+$L$34*LIDER!$H$15,"N")) -> 4.04
A39: 6 | B39: =LIDER!E56 -> 0 | C39: =C38 -> G05 | E39: =IF(B39=0,0,IF(D39="",$F$34*LIDER!$H$9+$G$34*LIDER!$H$10+$H$34*LIDER!$H$11+$I$34*LIDER!$H$12+$J$34*LIDER!$H$13+$K$34*LIDER!$H$14+$L$34*LIDER!$H$15,"N")) -> 0
B40: GRUPO#6 | C40: G06 | D40: =D33 -> LIST | E40: DEF | F40: =LIDER!$E$34 -> GRUPO#6
...

Sheet S-ASIG-04
A1: =LIDER!B2 -> TECNOLOGÍA EN GESTIÓN DE NEGOCIOS INTERN | I1: =LIDER!E2 -> SEMESTRE: | J1: =LIDER!F2 -> SEM-06 | K1: =LIDER!G2 -> SECCIÓN: | L1: =LIDER!H2 -> 3
B2: =LIDER!F4 -> FINANZAS INTERNACIONALES | F2: CRITERIOS DE EVALUACIÓN
B3: Estudiantes | F3: =LIDER!E9 -> PRESENTACIÓN GENERAL: Adopta la norma APA, tamaño de la hoja, margenes, titulo, portadas, numeración de paginas, tabla de contenido automatizada, ortografia, justificacion del texto, citas automatizadas, listas, figuras,etc. | G3: =LIDER!E10 -> ANTEPROYECTO: Portada, planteamiento del problema, justificacion del trabajo o proyecto de aula, objetivos, marco teorico, diseño metodologico. | H3: =LIDER!E11 -> RESULTADOS: Analiza, integra y aplica de manera coherente los aspectos para la Construcción de la marca empresarial (Branding) | I3: =LIDER!E12 -> RESULTADOS: Analiza, integra y aplica de manera coherente los aspectos del Plan de distribución. | J3: =LIDER!E13 -> RESULTADOS: Analiza, integra y aplica de manera coherente los aspectos para el Análisis ambiental y social. | K3: =LIDER!E14 -> BILIOGRAFIA: Las referencias bibliograficas: adoptan las normas APA. El documento es producto de un rastreo bibliografico que muestra analisis y sistensis. | L3: =LIDER!E15 -> ASESORIAS: Anexó la hoja de tutoria firmada ( 3 fimas minmimo).
F4: =CONCATENATE(LIDER!F4," - ",LIDER!F6," - ",LIDER!F5) -> FINANZAS INTERNACIONALES - 1444 - MADELCY DEL CARMEN PEDROZA TORRES
B5: GRUPO#1 | C5: G01 | D5: LIST | E5: DEF | F5: =LIDER!$E$29 -> GRUPO#1
A6: 1 | B6: =LIDER!E43 -> SANTIAGO AVILA MONTERROSA | C6: =C5 -> G01 | E6: =IF(B6=0,0,IF(D6="",$F$6*LIDER!$H$9+$G$6*LIDER!$H$10+$H$6*LIDER!$H$11+$I$6*LIDER!$H$12+$J$6*LIDER!$H$13+$K$6*LIDER!$H$14+$L$6*LIDER!$H$15,"N")) -> 3.51 | F6: 3.3 | G6: 3.3 | H6: 3.3 | I6: 3.5 | J6: 3.5 | K6: 3.3 | L6: 5
A7: 2 | B7: =LIDER!E44 -> FEDERICO GALLEGO TROCONIS | C7: =C6 -> G01 | E7: =IF(B7=0,0,IF(D7="",$F$6*LIDER!$H$9+$G$6*LIDER!$H$10+$H$6*LIDER!$H$11+$I$6*LIDER!$H$12+$J$6*LIDER!$H$13+$K$6*LIDER!$H$14+$L$6*LIDER!$H$15,"N")) -> 3.51
A8: 3 | B8: =LIDER!E45 -> FERNANDO ANTONIO UPEGUI MARTINEZ | C8: =C7 -> G01 | E8: =IF(B8=0,0,IF(D8="",$F$6*LIDER!$H$9+$G$6*LIDER!$H$10+$H$6*LIDER!$H$11+$I$6*LIDER!$H$12+$J$6*LIDER!$H$13+$K$6*LIDER!$H$14+$L$6*LIDER!$H$15,"N")) -> 3.51
A9: 4 | B9: =LIDER!E46 -> 0 | C9: =C8 -> G01 | E9: =IF(B9=0,0,IF(D9="",$F$6*LIDER!$H$9+$G$6*LIDER!$H$10+$H$6*LIDER!$H$11+$I$6*LIDER!$H$12+$J$6*LIDER!$H$13+$K$6*LIDER!$H$14+$L$6*LIDER!$H$15,"N")) -> 0
A10: 5 | B10: =LIDER!E47 -> 0 | C10: =C9 -> G01 | E10: =IF(B10=0,0,IF(D10="",$F$6*LIDER!$H$9+$G$6*LIDER!$H$10+$H$6*LIDER!$H$11+$I$6*LIDER!$H$12+$J$6*LIDER!$H$13+$K$6*LIDER!$H$14+$L$6*LIDER!$H$15,"N")) -> 0
A11: 6 | B11: =LIDER!E48 -> 0 | C11: =C10 -> G01 | E11: =IF(B11=0,0,IF(D11="",$F$6*LIDER!$H$9+$G$6*LIDER!$H$10+$H$6*LIDER!$H$11+$I$6*LIDER!$H$12+$J$6*LIDER!$H$13+$K$6*LIDER!$H$14+$L$6*LIDER!$H$15,"N")) -> 0
B12: GRUPO#2 | C12: G02 | D12: =D5 -> LIST | E12: DEF | F12: =LIDER!$E$30 -> GRUPO#2
A13: 1 | B13: =LIDER!F43 -> LERCY MARCELA CHAVEZ CASTELLAR | C13: =C12 -> G02 | E13: =IF(B13=0,0,IF(D13="",$F$13*LIDER!$H$9+$G$13*LIDER!$H$10+$H$13*LIDER!$H$11+$I$13*LIDER!$H$12+$J$13*LIDER!$H$13+$K$13*LIDER!$H$14+$L$13*LIDER!$H$15,"N")) -> 2.23 | F13: 3 | G13: 3.4 | H13: 3 | I13: 3.2 | J13: 3.3 | K13: 0 | L13: 0
A14: 2 | B14: =LIDER!F44 -> JUAN DAVID DEVOZ GONZALEZ | C14: =C13 -> G02 | E14: =IF(B14=0,0,IF(D14="",$F$13*LIDER!$H$9+$G$13*LIDER!$H$10+$H$13*LIDER!$H$11+$I$13*LIDER!$H$12+$J$13*LIDER!$H$13+$K$13*LIDER!$H$14+$L$13*LIDER!$H$15,"N")) -> 2.23
A15: 3 | B15: =LIDER!F45 -> SANTIAGO HERNÁNDEZ BARBOZA | C15: =C14 -> G02 | E15: =IF(B15=0,0,IF(D15="",$F$13*LIDER!$H$9+$G$13*LIDER!$H$10+$H$13*LIDER!$H$11+$I$13*LIDER!$H$12+$J$13*LIDER!$H$13+$K$13*LIDER!$H$14+$L$13*LIDER!$H$15,"N")) -> 2.23
A16: 4 | B16: =LIDER!F46 -> DIEGO JACOME PERALTA | C16: =C15 -> G02 | E16: =IF(B16=0,0,IF(D16="",$F$13*LIDER!$H$9+$G$13*LIDER!$H$10+$H$13*LIDER!$H$11+$I$13*LIDER!$H$12+$J$13*LIDER!$H$13+$K$13*LIDER!$H$14+$L$13*LIDER!$H$15,"N")) -> 2.23
A17: 5 | B17: =LIDER!F47 -> JESUS ALBERTO MADRID BORDA | C17: =C16 -> G02 | E17: =IF(B17=0,0,IF(D17="",$F$13*LIDER!$H$9+$G$13*LIDER!$H$10+$H$13*LIDER!$H$11+$I$13*LIDER!$H$12+$J$13*LIDER!$H$13+$K$13*LIDER!$H$14+$L$13*LIDER!$H$15,"N")) -> 2.23
A18: 6 | B18: =LIDER!F48 -> JUAN ANDRES REYES GOMEZ | C18: =C17 -> G02 | E18: =IF(B18=0,0,IF(D18="",$F$13*LIDER!$H$9+$G$13*LIDER!$H$10+$H$13*LIDER!$H$11+$I$13*LIDER!$H$12+$J$13*LIDER!$H$13+$K$13*LIDER!$H$14+$L$13*LIDER!$H$15,"N")) -> 2.23
B19: GRUPO#3 | C19: G03 | D19: =D12 -> LIST | E19: DEF | F19: =LIDER!$E$31 -> GRUPO#3
A20: 1 | B20: =LIDER!G43 -> ANDREA CAROLINA GONZALEZ PEREZ | C20: =C19 -> G03 | E20: =IF(B20=0,0,IF(D20="",$F$20*LIDER!$H$9+$G$20*LIDER!$H$10+$H$20*LIDER!$H$11+$I$20*LIDER!$H$12+$J$20*LIDER!$H$13+$K$20*LIDER!$H$14+$L$20*LIDER!$H$15,"N")) -> 4.35 | F20: 4.3 | G20: 4.4 | H20: 4.2 | I20: 4.2 | J20: 4.2 | K20: 4.5 | L20: 4.5
A21: 2 | B21: =LIDER!G44 -> SHEIDY ALEJANDRA HERNANDEZ NIEVES | C21: =C20 -> G03 | E21: =IF(B21=0,0,IF(D21="",$F$20*LIDER!$H$9+$G$20*LIDER!$H$10+$H$20*LIDER!$H$11+$I$20*LIDER!$H$12+$J$20*LIDER!$H$13+$K$20*LIDER!$H$14+$L$20*LIDER!$H$15,"N")) -> 4.35
A22: 3 | B22: =LIDER!G45 -> 0 | C22: =C21 -> G03 | E22: =IF(B22=0,0,IF(D22="",$F$20*LIDER!$H$9+$G$20*LIDER!$H$10+$H$20*LIDER!$H$11+$I$20*LIDER!$H$12+$J$20*LIDER!$H$13+$K$20*LIDER!$H$14+$L$20*LIDER!$H$15,"N")) -> 0
A23: 4 | B23: =LIDER!G46 -> 0 | C23: =C22 -> G03 | E23: =IF(B23=0,0,IF(D23="",$F$20*LIDER!$H$9+$G$20*LIDER!$H$10+$H$20*LIDER!$H$11+$I$20*LIDER!$H$12+$J$20*LIDER!$H$13+$K$20*LIDER!$H$14+$L$20*LIDER!$H$15,"N")) -> 0
A24: 5 | B24: =LIDER!G47 -> 0 | C24: =C23 -> G03 | E24: =IF(B24=0,0,IF(D24="",$F$20*LIDER!$H$9+$G$20*LIDER!$H$10+$H$20*LIDER!$H$11+$I$20*LIDER!$H$12+$J$20*LIDER!$H$13+$K$20*LIDER!$H$14+$L$20*LIDER!$H$15,"N")) -> 0
A25: 6 | B25: =LIDER!G48 -> 0 | C25: =C24 -> G03 | E25: =IF(B25=0,0,IF(D25="",$F$20*LIDER!$H$9+$G$20*LIDER!$H$10+$H$20*LIDER!$H$11+$I$20*LIDER!$H$12+$J$20*LIDER!$H$13+$K$20*LIDER!$H$14+$L$20*LIDER!$H$15,"N")) -> 0
B26: GRUPO#4 | C26: G04 | D26: =D19 -> LIST | E26: DEF | F26: =LIDER!$E$32 -> GRUPO#4
A27: 1 | B27: =LIDER!H43 -> ZHEYLA MARCELA AFANADOR TORRES | C27: =C26 -> G04 | E27: =IF(B27=0,0,IF(D27="",$F$27*LIDER!$H$9+$G$27*LIDER!$H$10+$H$27*LIDER!$H$11+$I$27*LIDER!$H$12+$J$27*LIDER!$H$13+$K$27*LIDER!$H$14+$L$27*LIDER!$H$15,"N")) -> 4.71 | F27: 4.7 | G27: 4.9 | H27: 4.3 | I27: 4.3 | J27: 4.3 | K27: 5 | L27: 5
A28: 2 | B28: =LIDER!H44 -> NATALI AGRESOTT GOMEZ | C28: =C27 -> G04 | E28: =IF(B28=0,0,IF(D28="",$F$27*LIDER!$H$9+$G$27*LIDER!$H$10+$H$27*LIDER!$H$11+$I$27*LIDER!$H$12+$J$27*LIDER!$H$13+$K$27*LIDER!$H$14+$L$27*LIDER!$H$15,"N")) -> 4.71
A29: 3 | B29: =LIDER!H45 -> DAYLETH CONEO OSPINO | C29: =C28 -> G04 | E29: =IF(B29=0,0,IF(D29="",$F$27*LIDER!$H$9+$G$27*LIDER!$H$10+$H$27*LIDER!$H$11+$I$27*LIDER!$H$12+$J$27*LIDER!$H$13+$K$27*LIDER!$H$14+$L$27*LIDER!$H$15,"N")) -> 4.71
A30: 4 | B30: =LIDER!H46 -> NATHALIA JULIETH ORTEGA ROMERO | C30: =C29 -> G04 | E30: =IF(B30=0,0,IF(D30="",$F$27*LIDER!$H$9+$G$27*LIDER!$H$10+$H$27*LIDER!$H$11+$I$27*LIDER!$H$12+$J$27*LIDER!$H$13+$K$27*LIDER!$H$14+$L$27*LIDER!$H$15,"N")) -> 4.71
A31: 5 | B31: =LIDER!H47 -> YURIDIS ORTIZ TORRES | C31: =C30 -> G04 | E31: =IF(B31=0,0,IF(D31="",$F$27*LIDER!$H$9+$G$27*LIDER!$H$10+$H$27*LIDER!$H$11+$I$27*LIDER!$H$12+$J$27*LIDER!$H$13+$K$27*LIDER!$H$14+$L$27*LIDER!$H$15,"N")) -> 4.71
A32: 6 | B32: =LIDER!H48 -> 0 | C32: =C31 -> G04 | E32: =IF(B32=0,0,IF(D32="",$F$27*LIDER!$H$9+$G$27*LIDER!$H$10+$H$27*LIDER!$H$11+$I$27*LIDER!$H$12+$J$27*LIDER!$H$13+$K$27*LIDER!$H$14+$L$27*LIDER!$H$15,"N")) -> 0
B33: GRUPO#5 | C33: G05 | D33: =D26 -> LIST | E33: DEF | F33: =LIDER!$E$33 -> GRUPO#5
A34: 1 | B34: =LIDER!E51 -> MARIA JOSE ACEVEDO QUINTANA | C34: =C33 -> G05 | E34: =IF(B34=0,0,IF(D34="",$F$34*LIDER!$H$9+$G$34*LIDER!$H$10+$H$34*LIDER!$H$11+$I$34*LIDER!$H$12+$J$34*LIDER!$H$13+$K$34*LIDER!$H$14+$L$34*LIDER!$H$15,"N")) -> 4.07 | F34: 4 | G34: 3.6 | H34: 3.9 | I34: 3.9 | J34: 3.9 | K34: 4.4 | L34: 5
A35: 2 | B35: =LIDER!E52 -> YEIDYS FAINORYS ARROYO GRANADOS | C35: =C34 -> G05 | E35: =IF(B35=0,0,IF(D35="",$F$34*LIDER!$H$9+$G$34*LIDER!$H$10+$H$34*LIDER!$H$11+$I$34*LIDER!$H$12+$J$34*LIDER!$H$13+$K$34*LIDER!$H$14+$L$34*LIDER!$H$15,"N")) -> 4.07
A36: 3 | B36: =LIDER!E53 -> ANGELICA NAVARRO TORRES | C36: =C35 -> G05 | E36: =IF(B36=0,0,IF(D36="",$F$34*LIDER!$H$9+$G$34*LIDER!$H$10+$H$34*LIDER!$H$11+$I$34*LIDER!$H$12+$J$34*LIDER!$H$13+$K$34*LIDER!$H$14+$L$34*LIDER!$H$15,"N")) -> 4.07
A37: 4 | B37: =LIDER!E54 -> ISABELLA OLIVARES LLANOS | C37: =C36 -> G05 | E37: =IF(B37=0,0,IF(D37="",$F$34*LIDER!$H$9+$G$34*LIDER!$H$10+$H$34*LIDER!$H$11+$I$34*LIDER!$H$12+$J$34*LIDER!$H$13+$K$34*LIDER!$H$14+$L$34*LIDER!$H$15,"N")) -> 4.07
A38: 5 | B38: =LIDER!E55 -> SAMARA ELIZABETH SUAREZ NAVARRO | C38: =C37 -> G05 | E38: =IF(B38=0,0,IF(D38="",$F$34*LIDER!$H$9+$G$34*LIDER!$H$10+$H$34*LIDER!$H$11+$I$34*LIDER!$H$12+$J$34*LIDER!$H$13+$K$34*LIDER!$H$14+$L$34*LIDER!$H$15,"N")) -> 4.07
A39: 6 | B39: =LIDER!E56 -> 0 | C39: =C38 -> G05 | E39: =IF(B39=0,0,IF(D39="",$F$34*LIDER!$H$9+$G$34*LIDER!$H$10+$H$34*LIDER!$H$11+$I$34*LIDER!$H$12+$J$34*LIDER!$H$13+$K$34*LIDER!$H$14+$L$34*LIDER!$H$15,"N")) -> 0
B40: GRUPO#6 | C40: G06 | D40: =D33 -> LIST | E40: DEF | F40: =LIDER!$E$34 -> GRUPO#6
...

Sheet S-ASIG-06
A1: =LIDER!B2 -> TECNOLOGÍA EN GESTIÓN DE NEGOCIOS INTERN | I1: =LIDER!E2 -> SEMESTRE: | J1: =LIDER!F2 -> SEM-06 | K1: =LIDER!G2 -> SECCIÓN: | L1: =LIDER!H2 -> 3
B2: =LIDER!H4 -> ELECTIVA LIBRE SOCIOHUMANÍ II | F2: CRITERIOS DE EVALUACIÓN
B3: Estudiantes | F3: =LIDER!E9 -> PRESENTACIÓN GENERAL: Adopta la norma APA, tamaño de la hoja, margenes, titulo, portadas, numeración de paginas, tabla de contenido automatizada, ortografia, justificacion del texto, citas automatizadas, listas, figuras,etc. | G3: =LIDER!E10 -> ANTEPROYECTO: Portada, planteamiento del problema, justificacion del trabajo o proyecto de aula, objetivos, marco teorico, diseño metodologico. | H3: =LIDER!E11 -> RESULTADOS: Analiza, integra y aplica de manera coherente los aspectos para la Construcción de la marca empresarial (Branding) | I3: =LIDER!E12 -> RESULTADOS: Analiza, integra y aplica de manera coherente los aspectos del Plan de distribución. | J3: =LIDER!E13 -> RESULTADOS: Analiza, integra y aplica de manera coherente los aspectos para el Análisis ambiental y social. | K3: =LIDER!E14 -> BILIOGRAFIA: Las referencias bibliograficas: adoptan las normas APA. El documento es producto de un rastreo bibliografico que muestra analisis y sistensis. | L3: =LIDER!E15 -> ASESORIAS: Anexó la hoja de tutoria firmada ( 3 fimas minmimo).
F4: =CONCATENATE(LIDER!H4," - ",LIDER!H6," - ",LIDER!H5) -> ELECTIVA LIBRE SOCIOHUMANÍ II - 2121 - EBERTO JESUS POSADA AMANTE
B5: GRUPO#1 | C5: G01 | D5: LIST | E5: DEF | F5: =LIDER!$E$29 -> GRUPO#1
A6: 1 | B6: =LIDER!E43 -> SANTIAGO AVILA MONTERROSA | C6: =C5 -> G01 | E6: =IF(B6=0,0,IF(D6="",$F$6*LIDER!$H$9+$G$6*LIDER!$H$10+$H$6*LIDER!$H$11+$I$6*LIDER!$H$12+$J$6*LIDER!$H$13+$K$6*LIDER!$H$14+$L$6*LIDER!$H$15,"N")) -> 3.72 | F6: 3.6 | G6: 4.4 | H6: 3.6 | I6: 3.6 | J6: 3.6 | K6: 3.2 | L6: 4
A7: 2 | B7: =LIDER!E44 -> FEDERICO GALLEGO TROCONIS | C7: =C6 -> G01 | E7: =IF(B7=0,0,IF(D7="",$F$6*LIDER!$H$9+$G$6*LIDER!$H$10+$H$6*LIDER!$H$11+$I$6*LIDER!$H$12+$J$6*LIDER!$H$13+$K$6*LIDER!$H$14+$L$6*LIDER!$H$15,"N")) -> 3.72
A8: 3 | B8: =LIDER!E45 -> FERNANDO ANTONIO UPEGUI MARTINEZ | C8: =C7 -> G01 | E8: =IF(B8=0,0,IF(D8="",$F$6*LIDER!$H$9+$G$6*LIDER!$H$10+$H$6*LIDER!$H$11+$I$6*LIDER!$H$12+$J$6*LIDER!$H$13+$K$6*LIDER!$H$14+$L$6*LIDER!$H$15,"N")) -> 3.72
A9: 4 | B9: =LIDER!E46 -> 0 | C9: =C8 -> G01 | E9: =IF(B9=0,0,IF(D9="",$F$6*LIDER!$H$9+$G$6*LIDER!$H$10+$H$6*LIDER!$H$11+$I$6*LIDER!$H$12+$J$6*LIDER!$H$13+$K$6*LIDER!$H$14+$L$6*LIDER!$H$15,"N")) -> 0
A10: 5 | B10: =LIDER!E47 -> 0 | C10: =C9 -> G01 | E10: =IF(B10=0,0,IF(D10="",$F$6*LIDER!$H$9+$G$6*LIDER!$H$10+$H$6*LIDER!$H$11+$I$6*LIDER!$H$12+$J$6*LIDER!$H$13+$K$6*LIDER!$H$14+$L$6*LIDER!$H$15,"N")) -> 0
A11: 6 | B11: =LIDER!E48 -> 0 | C11: =C10 -> G01 | E11: =IF(B11=0,0,IF(D11="",$F$6*LIDER!$H$9+$G$6*LIDER!$H$10+$H$6*LIDER!$H$11+$I$6*LIDER!$H$12+$J$6*LIDER!$H$13+$K$6*LIDER!$H$14+$L$6*LIDER!$H$15,"N")) -> 0
B12: GRUPO#2 | C12: G02 | D12: =D5 -> LIST | E12: DEF | F12: =LIDER!$E$30 -> GRUPO#2
A13: 1 | B13: =LIDER!F43 -> LERCY MARCELA CHAVEZ CASTELLAR | C13: =C12 -> G02 | E13: =IF(B13=0,0,IF(D13="",$F$13*LIDER!$H$9+$G$13*LIDER!$H$10+$H$13*LIDER!$H$11+$I$13*LIDER!$H$12+$J$13*LIDER!$H$13+$K$13*LIDER!$H$14+$L$13*LIDER!$H$15,"N")) -> 2.89 | F13: 3.5 | G13: 4.5 | H13: 3.8 | I13: 3.8 | J13: 3.8 | K13: 0.5 | L13: 0.5
A14: 2 | B14: =LIDER!F44 -> JUAN DAVID DEVOZ GONZALEZ | C14: =C13 -> G02 | E14: =IF(B14=0,0,IF(D14="",$F$13*LIDER!$H$9+$G$13*LIDER!$H$10+$H$13*LIDER!$H$11+$I$13*LIDER!$H$12+$J$13*LIDER!$H$13+$K$13*LIDER!$H$14+$L$13*LIDER!$H$15,"N")) -> 2.89
A15: 3 | B15: =LIDER!F45 -> SANTIAGO HERNÁNDEZ BARBOZA | C15: =C14 -> G02 | E15: =IF(B15=0,0,IF(D15="",$F$13*LIDER!$H$9+$G$13*LIDER!$H$10+$H$13*LIDER!$H$11+$I$13*LIDER!$H$12+$J$13*LIDER!$H$13+$K$13*LIDER!$H$14+$L$13*LIDER!$H$15,"N")) -> 2.89
A16: 4 | B16: =LIDER!F46 -> DIEGO JACOME PERALTA | C16: =C15 -> G02 | E16: =IF(B16=0,0,IF(D16="",$F$13*LIDER!$H$9+$G$13*LIDER!$H$10+$H$13*LIDER!$H$11+$I$13*LIDER!$H$12+$J$13*LIDER!$H$13+$K$13*LIDER!$H$14+$L$13*LIDER!$H$15,"N")) -> 2.89
A17: 5 | B17: =LIDER!F47 -> JESUS ALBERTO MADRID BORDA | C17: =C16 -> G02 | E17: =IF(B17=0,0,IF(D17="",$F$13*LIDER!$H$9+$G$13*LIDER!$H$10+$H$13*LIDER!$H$11+$I$13*LIDER!$H$12+$J$13*LIDER!$H$13+$K$13*LIDER!$H$14+$L$13*LIDER!$H$15,"N")) -> 2.89
A18: 6 | B18: =LIDER!F48 -> JUAN ANDRES REYES GOMEZ | C18: =C17 -> G02 | E18: =IF(B18=0,0,IF(D18="",$F$13*LIDER!$H$9+$G$13*LIDER!$H$10+$H$13*LIDER!$H$11+$I$13*LIDER!$H$12+$J$13*LIDER!$H$13+$K$13*LIDER!$H$14+$L$13*LIDER!$H$15,"N")) -> 2.89
B19: GRUPO#3 | C19: G03 | D19: =D12 -> LIST | E19: DEF | F19: =LIDER!$E$31 -> GRUPO#3
A20: 1 | B20: =LIDER!G43 -> ANDREA CAROLINA GONZALEZ PEREZ | C20: =C19 -> G03 | E20: =IF(B20=0,0,IF(D20="",$F$20*LIDER!$H$9+$G$20*LIDER!$H$10+$H$20*LIDER!$H$11+$I$20*LIDER!$H$12+$J$20*LIDER!$H$13+$K$20*LIDER!$H$14+$L$20*LIDER!$H$15,"N")) -> 3.38 | F20: 3.2 | G20: 4.5 | H20: 3.8 | I20: 3.8 | J20: 3.8 | K20: 2 | L20: 3
A21: 2 | B21: =LIDER!G44 -> SHEIDY ALEJANDRA HERNANDEZ NIEVES | C21: =C20 -> G03 | E21: =IF(B21=0,0,IF(D21="",$F$20*LIDER!$H$9+$G$20*LIDER!$H$10+$H$20*LIDER!$H$11+$I$20*LIDER!$H$12+$J$20*LIDER!$H$13+$K$20*LIDER!$H$14+$L$20*LIDER!$H$15,"N")) -> 3.38
A22: 3 | B22: =LIDER!G45 -> 0 | C22: =C21 -> G03 | E22: =IF(B22=0,0,IF(D22="",$F$20*LIDER!$H$9+$G$20*LIDER!$H$10+$H$20*LIDER!$H$11+$I$20*LIDER!$H$12+$J$20*LIDER!$H$13+$K$20*LIDER!$H$14+$L$20*LIDER!$H$15,"N")) -> 0
A23: 4 | B23: =LIDER!G46 -> 0 | C23: =C22 -> G03 | E23: =IF(B23=0,0,IF(D23="",$F$20*LIDER!$H$9+$G$20*LIDER!$H$10+$H$20*LIDER!$H$11+$I$20*LIDER!$H$12+$J$20*LIDER!$H$13+$K$20*LIDER!$H$14+$L$20*LIDER!$H$15,"N")) -> 0
A24: 5 | B24: =LIDER!G47 -> 0 | C24: =C23 -> G03 | E24: =IF(B24=0,0,IF(D24="",$F$20*LIDER!$H$9+$G$20*LIDER!$H$10+$H$20*LIDER!$H$11+$I$20*LIDER!$H$12+$J$20*LIDER!$H$13+$K$20*LIDER!$H$14+$L$20*LIDER!$H$15,"N")) -> 0
A25: 6 | B25: =LIDER!G48 -> 0 | C25: =C24 -> G03 | E25: =IF(B25=0,0,IF(D25="",$F$20*LIDER!$H$9+$G$20*LIDER!$H$10+$H$20*LIDER!$H$11+$I$20*LIDER!$H$12+$J$20*LIDER!$H$13+$K$20*LIDER!$H$14+$L$20*LIDER!$H$15,"N")) -> 0
B26: GRUPO#4 | C26: G04 | D26: =D19 -> LIST | E26: DEF | F26: =LIDER!$E$32 -> GRUPO#4
A27: 1 | B27: =LIDER!H43 -> ZHEYLA MARCELA AFANADOR TORRES | C27: =C26 -> G04 | E27: =IF(B27=0,0,IF(D27="",$F$27*LIDER!$H$9+$G$27*LIDER!$H$10+$H$27*LIDER!$H$11+$I$27*LIDER!$H$12+$J$27*LIDER!$H$13+$K$27*LIDER!$H$14+$L$27*LIDER!$H$15,"N")) -> 4.06 | F27: 4 | G27: 4.8 | H27: 4 | I27: 4 | J27: 4 | K27: 3 | L27: 5
A28: 2 | B28: =LIDER!H44 -> NATALI AGRESOTT GOMEZ | C28: =C27 -> G04 | E28: =IF(B28=0,0,IF(D28="",$F$27*LIDER!$H$9+$G$27*LIDER!$H$10+$H$27*LIDER!$H$11+$I$27*LIDER!$H$12+$J$27*LIDER!$H$13+$K$27*LIDER!$H$14+$L$27*LIDER!$H$15,"N")) -> 4.06
A29: 3 | B29: =LIDER!H45 -> DAYLETH CONEO OSPINO | C29: =C28 -> G04 | E29: =IF(B29=0,0,IF(D29="",$F$27*LIDER!$H$9+$G$27*LIDER!$H$10+$H$27*LIDER!$H$11+$I$27*LIDER!$H$12+$J$27*LIDER!$H$13+$K$27*LIDER!$H$14+$L$27*LIDER!$H$15,"N")) -> 4.06
A30: 4 | B30: =LIDER!H46 -> NATHALIA JULIETH ORTEGA ROMERO | C30: =C29 -> G04 | E30: =IF(B30=0,0,IF(D30="",$F$27*LIDER!$H$9+$G$27*LIDER!$H$10+$H$27*LIDER!$H$11+$I$27*LIDER!$H$12+$J$27*LIDER!$H$13+$K$27*LIDER!$H$14+$L$27*LIDER!$H$15,"N")) -> 4.06
A31: 5 | B31: =LIDER!H47 -> YURIDIS ORTIZ TORRES | C31: =C30 -> G04 | E31: =IF(B31=0,0,IF(D31="",$F$27*LIDER!$H$9+$G$27*LIDER!$H$10+$H$27*LIDER!$H$11+$I$27*LIDER!$H$12+$J$27*LIDER!$H$13+$K$27*LIDER!$H$14+$L$27*LIDER!$H$15,"N")) -> 4.06
A32: 6 | B32: =LIDER!H48 -> 0 | C32: =C31 -> G04 | E32: =IF(B32=0,0,IF(D32="",$F$27*LIDER!$H$9+$G$27*LIDER!$H$10+$H$27*LIDER!$H$11+$I$27*LIDER!$H$12+$J$27*LIDER!$H$13+$K$27*LIDER!$H$14+$L$27*LIDER!$H$15,"N")) -> 0
B33: GRUPO#5 | C33: G05 | D33: =D26 -> LIST | E33: DEF | F33: =LIDER!$E$33 -> GRUPO#5
A34: 1 | B34: =LIDER!E51 -> MARIA JOSE ACEVEDO QUINTANA | C34: =C33 -> G05 | E34: =IF(B34=0,0,IF(D34="",$F$34*LIDER!$H$9+$G$34*LIDER!$H$10+$H$34*LIDER!$H$11+$I$34*LIDER!$H$12+$J$34*LIDER!$H$13+$K$34*LIDER!$H$14+$L$34*LIDER!$H$15,"N")) -> 3.9 | F34: 4.5 | G34: 4 | H34: 4 | I34: 4 | J34: 4 | K34: 2.5 | L34: 5
A35: 2 | B35: =LIDER!E52 -> YEIDYS FAINORYS ARROYO GRANADOS | C35: =C34 -> G05 | E35: =IF(B35=0,0,IF(D35="",$F$34*LIDER!$H$9+$G$34*LIDER!$H$10+$H$34*LIDER!$H$11+$I$34*LIDER!$H$12+$J$34*LIDER!$H$13+$K$34*LIDER!$H$14+$L$34*LIDER!$H$15,"N")) -> 3.9
