Workbook

Sheet LIDER
B2: TECNOLOGÍA EN GESTIÓN DE NEGOCIOS INTERN | E2: SEMESTRE: | F2: SEM-01 | G2: SECCIÓN: | H2: 5
C3: DISCIPLINAR#1 | D3: DISCIPLINAR#2 | E3: DISCIPLINAR#3 | F3: DISCIPLINAR#4 | G3: DISCIPLINAR#5 | H3: DISCIPLINAR#6 | I3: DISCIPLINAR#7
C4: MATEMATICA | D4: CULTURA Y DEPORTE | E4: COMUNICACION ORAL Y ESCRITA | F4: PROYECTO DE VIDA | G4: CONTABILIDAD GENERAL | H4: FUNDAMENTOS DE DERECHO | I4: FUNDAMENTOS ADMINISTRACIÓN
C5: CECILIA PAILLIER GONZALEZ | D5: EDWIN FRANCO OSPINO | E5: YASMIN GOMEZ MORENO | F5: MARINA LLAMAS DURAN | G5: ANTONIO CARLOS CANTILLO BELTRAN | H5: MELISSA LOPEZ ROMERO | I5: AMALIO SEGUNDO OTERO TAPIA
C6: 2157 | D6: 2172 | E6: 2196 | F6: 3248 | G6: 1401 | H6: 3243 | I6: 1313
C8: LISTA DE ESTUDIANTES | E8: SEGUNDA ENTREGA - CRITERIOS DE EVALUACIÓN DOCUMENTO - SEGUNDO CORTE | H8: PONDERACIÓN | I8: ADMINISTRACIÓN DE EMPRESAS C.I
B9: 1 | C9: JULIANA SOFIA CARCAMO BLANCO | E9: Calidad de la información recopilada (20%): Se evaluará la calidad de la información recopilada a través del rastreo bibliográfico por medio de fichas bibliográficas para la redacción del resumen. | H9: 0.2 | I9: ADMINTRACIÓN EN SEGURIDAD Y SALUD EN EL TRABAJO
B10: 2 | C10: NATHALY SOFIA SEGOVIA ALVAREZ | E10: Estructura del Documento (30%): El documento debe incluir los siguientes aspectos: Portada, Introducción, cuerpo del resumen, Bibliografía y Anexos. | H10: 0.3 | I10: CONTADURÍA PÚBLICA
B11: 3 | C11: CARLOS ANDRES VERBEL MEDRANO | E11: Claridad de la información recopilada (20%): Se evaluará la claridad de la información recopilada a través del rastreo bibliográfico por medio de fichas bibliográficas para la redacción del resumen. | H11: 0.2 | I11: NEGOCIOS INTERNACIONALES PROFESIONAL
B12: 4 | C12: VALERIA MEZA RODRIGUEZ | E12: Coherencia de la información recopilada (20%): Se evaluará la coherencia de la información recopilada a través del rastreo de fichas de revisión bibliográfica para la redacción del resumen. | H12: 0.2 | I12: TECNOLOGÍA EN GESTIÓN DE NEGOCIOS INTERN
B13: 5 | C13: GINA LISSETH RAMIREZ SOTO | E13: Asesorias individuales (10%): Anexo de la hoja de tutoria firmada por docentes del colectivo (3 fimas minimo). | H13: 0.1 | I13: TECNOLOGíA EN GESTION CONTABLE
B14: 6 | C14: ANGGELA LUCIA UPARELA RAMIREZ | H14: 0 | I14: TECNOLOGÍA EN GESTIÓN DE MARKETING
B15: 7 | C15: YILBER YESID ANGULO ORTEGA | H15: 0 | I15: TECNOLOGÍA EN GESTIÓN DEL TALENTO HUMANO
B16: 8 | C16: LINDA SOFIA CANTILLO YANGUEZ | H16: =IF(SUM(H9:H15)>1,"Más del 100%",SUM(H9:H15)) -> 1 | I16: TECNOLOGÍA EN GESTIÓN FINANCIERA
B17: 9 | C17: DAVID SAM SILVA HERNANDEZ | I17: TECNOLOGÍA EN GESTIÓN LOGISTICA Y PORTUARIA
B18: 10 | C18: ADRIAN CAMILO ANGULO LAGARES | E18: ENTREGA FINAL - CRITERIO DE EVALUACIÓN SUSTENTACIÓN - TERCER CORTE | H18: PONDERACIÓN | I18: TECNOLOGÍA EN GESTIÓN TURISTICA Y HOTELERA
B19: 11 | C19: JEISON SAMUEL BELTRAN PEREZ | E19: Evaluación del Documento Final | H19: 0.5
B20: 12 | C20: ANDREA CAROLINA BUELVAS GUARDO | E20: Sustentación de los Resultados: Se refleja un dominio del tema, la información está delimitada y es clara. Hay una jerarquía y fluidez en las ideas que presenta. | H20: 0.2
B21: 13 | C21: MARIA DEL CARMEN NOEL GARCIA | E21: Expresión Oral: Se oberva buena vocalización y buen tono de voz durante toda la presentación empleando un lenguaje técnico pertinente con su nivel academico. Su discurso es adecuado en la presentacion de la sustentación de los resultados | H21: 0.1
B22: 14 | C22: ANDRY JOSE RUBIO CABEZA | E22: Lenguaje no verbal: Tiene una adecuada presentación personal para la ocación, opta por una buena postura y demuestra seguridad en sí mismo(a) durante la sustentación de los resultados. Además, demuestra asertividad y seguridad en las orientaciones o preguntas que hace el colectivo docente | H22: 0.05
B23: 15 | C23: DANETH MICHELL AGAMEZ VIVANCO | E23: Tiempo: El uso del tiempo fue apropiado, se ajusta al previsto. Ofrece una conclusión donde condensa las ideas principales del objetivo general y los específicos. | H23: 0.05
B24: 16 | C24: YULEIMIS ALEXANDRA BARÓN SILVA | E24: Uso de Recursos Audiovisuales Tecnológicos: La sustentación se acompaña de recursos visuales pertinentes, atractivos y de gran calidad | H24: 0.1
B25: 17 | C25: MARIA CARIDAD CASTILLA OROZCO
B26: 18 | C26: ANDRES CAMILO PAEZ DE LA HOZ | H26: =IF(SUM(H19:H25)>1,"Más del 100%",SUM(H19:H25)) -> 1
B27: 19 | C27: KATTY JULIETH BUSTOS MACEA
B28: 20 | C28: LILIANA PATRICIA PUELLO OROZCO | E28: TITULOS DE LOS PROYECTOS DE AULA
B29: 21 | C29: SEBASTIAN ANDRES RAMOS GALLEGO | E29: GRUPO#1
B30: 22 | C30: HANNA SOFIA ROSALES RODRIGUEZ | E30: GRUPO#2
B31: 23 | E31: GRUPO#3
B32: 24 | E32: GRUPO#4
B33: 25 | E33: GRUPO#5
B34: 26 | E34: GRUPO#6
B35: 27 | E35: GRUPO#7
B36: 28 | E36: GRUPO#8
B37: 29 | E37: GRUPO#9
B38: 30 | E38: GRUPO#10
B39: 31 | E39: GRUPO#11
B40: 32 | E40: GRUPO#12
B41: 33
B42: 34 | E42: =MID(E29,1,20) -> GRUPO#1 | F42: =MID(E30,1,20) -> GRUPO#2 | G42: =MID(E31,1,20) -> GRUPO#3 | H42: =MID(E32,1,20) -> GRUPO#4
...

Sheet S-ASIG-01
A1: =LIDER!B2 -> TECNOLOGÍA EN GESTIÓN DE NEGOCIOS INTERN | I1: =LIDER!E2 -> SEMESTRE: | J1: =LIDER!F2 -> SEM-01 | K1: =LIDER!G2 -> SECCIÓN: | L1: =LIDER!H2 -> 5
B2: =LIDER!C4 -> MATEMATICA | F2: CRITERIOS DE EVALUACIÓN
B3: Estudiantes | F3: =LIDER!E9 -> Calidad de la información recopilada (20%): Se evaluará la calidad de la información recopilada a través del rastreo bibliográfico por medio de fichas bibliográficas para la redacción del resumen. | G3: =LIDER!E10 -> Estructura del Documento (30%): El documento debe incluir los siguientes aspectos: Portada, Introducción, cuerpo del resumen, Bibliografía y Anexos. | H3: =LIDER!E11 -> Claridad de la información recopilada (20%): Se evaluará la claridad de la información recopilada a través del rastreo bibliográfico por medio de fichas bibliográficas para la redacción del resumen. | I3: =LIDER!E12 -> Coherencia de la información recopilada (20%): Se evaluará la coherencia de la información recopilada a través del rastreo de fichas de revisión bibliográfica para la redacción del resumen. | J3: =LIDER!E13 -> Asesorias individuales (10%): Anexo de la hoja de tutoria firmada por docentes del colectivo (3 fimas minimo). | K3: =LIDER!E14 -> 0 | L3: =LIDER!E15 -> 0
F4: =CONCATENATE(LIDER!C4," - ",LIDER!C6," - ",LIDER!C5) -> MATEMATICA - 2157 - CECILIA PAILLIER GONZALEZ
B5: GRUPO#1 | C5: G01 | D5: LIST | E5: DEF | F5: =LIDER!$E$29 -> GRUPO#1
A6: 1 | B6: =LIDER!E43 -> JULIANA SOFIA CARCAMO BLANCO | C6: =C5 -> G01 | E6: =IF(B6=0,0,IF(D6="",$F$6*LIDER!$H$9+$G$6*LIDER!$H$10+$H$6*LIDER!$H$11+$I$6*LIDER!$H$12+$J$6*LIDER!$H$13+$K$6*LIDER!$H$14+$L$6*LIDER!$H$15,"N")) -> 4 | F6: 4 | G6: 4 | H6: 4 | I6: 4 | J6: 4
A7: 2 | B7: =LIDER!E44 -> NATHALY SOFIA SEGOVIA ALVAREZ | C7: =C6 -> G01 | E7: =IF(B7=0,0,IF(D7="",$F$6*LIDER!$H$9+$G$6*LIDER!$H$10+$H$6*LIDER!$H$11+$I$6*LIDER!$H$12+$J$6*LIDER!$H$13+$K$6*LIDER!$H$14+$L$6*LIDER!$H$15,"N")) -> 4
A8: 3 | B8: =LIDER!E45 -> CARLOS ANDRES VERBEL MEDRANO | C8: =C7 -> G01 | E8: =IF(B8=0,0,IF(D8="",$F$6*LIDER!$H$9+$G$6*LIDER!$H$10+$H$6*LIDER!$H$11+$I$6*LIDER!$H$12+$J$6*LIDER!$H$13+$K$6*LIDER!$H$14+$L$6*LIDER!$H$15,"N")) -> 4
A9: 4 | B9: =LIDER!E46 -> 0 | C9: =C8 -> G01 | E9: =IF(B9=0,0,IF(D9="",$F$6*LIDER!$H$9+$G$6*LIDER!$H$10+$H$6*LIDER!$H$11+$I$6*LIDER!$H$12+$J$6*LIDER!$H$13+$K$6*LIDER!$H$14+$L$6*LIDER!$H$15,"N")) -> 0
A10: 5 | B10: =LIDER!E47 -> 0 | C10: =C9 -> G01 | E10: =IF(B10=0,0,IF(D10="",$F$6*LIDER!$H$9+$G$6*LIDER!$H$10+$H$6*LIDER!$H$11+$I$6*LIDER!$H$12+$J$6*LIDER!$H$13+$K$6*LIDER!$H$14+$L$6*LIDER!$H$15,"N")) -> 0
A11: 6 | B11: =LIDER!E48 -> 0 | C11: =C10 -> G01 | E11: =IF(B11=0,0,IF(D11="",$F$6*LIDER!$H$9+$G$6*LIDER!$H$10+$H$6*LIDER!$H$11+$I$6*LIDER!$H$12+$J$6*LIDER!$H$13+$K$6*LIDER!$H$14+$L$6*LIDER!$H$15,"N")) -> 0
B12: GRUPO#2 | C12: G02 | D12: =D5 -> LIST | E12: DEF | F12: =LIDER!$E$30 -> GRUPO#2
A13: 1 | B13: =LIDER!F43 -> VALERIA MEZA RODRIGUEZ | C13: =C12 -> G02 | E13: =IF(B13=0,0,IF(D13="",$F$13*LIDER!$H$9+$G$13*LIDER!$H$10+$H$13*LIDER!$H$11+$I$13*LIDER!$H$12+$J$13*LIDER!$H$13+$K$13*LIDER!$H$14+$L$13*LIDER!$H$15,"N")) -> 4.1 | F13: 4.1 | G13: 4.1 | H13: 4.1 | I13: 4.1 | J13: 4.1
A14: 2 | B14: =LIDER!F44 -> GINA LISSETH RAMIREZ SOTO | C14: =C13 -> G02 | E14: =IF(B14=0,0,IF(D14="",$F$13*LIDER!$H$9+$G$13*LIDER!$H$10+$H$13*LIDER!$H$11+$I$13*LIDER!$H$12+$J$13*LIDER!$H$13+$K$13*LIDER!$H$14+$L$13*LIDER!$H$15,"N")) -> 4.1
A15: 3 | B15: =LIDER!F45 -> ANGGELA LUCIA UPARELA RAMIREZ | C15: =C14 -> G02 | E15: =IF(B15=0,0,IF(D15="",$F$13*LIDER!$H$9+$G$13*LIDER!$H$10+$H$13*LIDER!$H$11+$I$13*LIDER!$H$12+$J$13*LIDER!$H$13+$K$13*LIDER!$H$14+$L$13*LIDER!$H$15,"N")) -> 4.1
A16: 4 | B16: =LIDER!F46 -> 0 | C16: =C15 -> G02 | E16: =IF(B16=0,0,IF(D16="",$F$13*LIDER!$H$9+$G$13*LIDER!$H$10+$H$13*LIDER!$H$11+$I$13*LIDER!$H$12+$J$13*LIDER!$H$13+$K$13*LIDER!$H$14+$L$13*LIDER!$H$15,"N")) -> 0
A17: 5 | B17: =LIDER!F47 -> 0 | C17: =C16 -> G02 | E17: =IF(B17=0,0,IF(D17="",$F$13*LIDER!$H$9+$G$13*LIDER!$H$10+$H$13*LIDER!$H$11+$I$13*LIDER!$H$12+$J$13*LIDER!$H$13+$K$13*LIDER!$H$14+$L$13*LIDER!$H$15,"N")) -> 0
A18: 6 | B18: =LIDER!F48 -> 0 | C18: =C17 -> G02 | E18: =IF(B18=0,0,IF(D18="",$F$13*LIDER!$H$9+$G$13*LIDER!$H$10+$H$13*LIDER!$H$11+$I$13*LIDER!$H$12+$J$13*LIDER!$H$13+$K$13*LIDER!$H$14+$L$13*LIDER!$H$15,"N")) -> 0
B19: GRUPO#3 | C19: G03 | D19: =D12 -> LIST | E19: DEF | F19: =LIDER!$E$31 -> GRUPO#3
A20: 1 | B20: =LIDER!G43 -> YILBER YESID ANGULO ORTEGA | C20: =C19 -> G03 | E20: =IF(B20=0,0,IF(D20="",$F$20*LIDER!$H$9+$G$20*LIDER!$H$10+$H$20*LIDER!$H$11+$I$20*LIDER!$H$12+$J$20*LIDER!$H$13+$K$20*LIDER!$H$14+$L$20*LIDER!$H$15,"N")) -> 3.7 | F20: 3.7 | G20: 3.7 | H20: 3.7 | I20: 3.7 | J20: 3.7
A21: 2 | B21: =LIDER!G44 -> LINDA SOFIA CANTILLO YANGUEZ | C21: =C20 -> G03 | E21: =IF(B21=0,0,IF(D21="",$F$20*LIDER!$H$9+$G$20*LIDER!$H$10+$H$20*LIDER!$H$11+$I$20*LIDER!$H$12+$J$20*LIDER!$H$13+$K$20*LIDER!$H$14+$L$20*LIDER!$H$15,"N")) -> 3.7
A22: 3 | B22: =LIDER!G45 -> DAVID SAM SILVA HERNANDEZ | C22: =C21 -> G03 | E22: =IF(B22=0,0,IF(D22="",$F$20*LIDER!$H$9+$G$20*LIDER!$H$10+$H$20*LIDER!$H$11+$I$20*LIDER!$H$12+$J$20*LIDER!$H$13+$K$20*LIDER!$H$14+$L$20*LIDER!$H$15,"N")) -> 3.7
A23: 4 | B23: =LIDER!G46 -> HANNA SOFIA ROSALES RODRIGUEZ | C23: =C22 -> G03 | D23: N | E23: =IF(B23=0,0,IF(D23="",$F$20*LIDER!$H$9+$G$20*LIDER!$H$10+$H$20*LIDER!$H$11+$I$20*LIDER!$H$12+$J$20*LIDER!$H$13+$K$20*LIDER!$H$14+$L$20*LIDER!$H$15,"N")) -> N
A24: 5 | B24: =LIDER!G47 -> 0 | C24: =C23 -> G03 | E24: =IF(B24=0,0,IF(D24="",$F$20*LIDER!$H$9+$G$20*LIDER!$H$10+$H$20*LIDER!$H$11+$I$20*LIDER!$H$12+$J$20*LIDER!$H$13+$K$20*LIDER!$H$14+$L$20*LIDER!$H$15,"N")) -> 0
A25: 6 | B25: =LIDER!G48 -> 0 | C25: =C24 -> G03 | E25: =IF(B25=0,0,IF(D25="",$F$20*LIDER!$H$9+$G$20*LIDER!$H$10+$H$20*LIDER!$H$11+$I$20*LIDER!$H$12+$J$20*LIDER!$H$13+$K$20*LIDER!$H$14+$L$20*LIDER!$H$15,"N")) -> 0
B26: GRUPO#4 | C26: G04 | D26: =D19 -> LIST | E26: DEF | F26: =LIDER!$E$32 -> GRUPO#4
A27: 1 | B27: =LIDER!H43 -> ADRIAN CAMILO ANGULO LAGARES | C27: =C26 -> G04 | E27: =IF(B27=0,0,IF(D27="",$F$27*LIDER!$H$9+$G$27*LIDER!$H$10+$H$27*LIDER!$H$11+$I$27*LIDER!$H$12+$J$27*LIDER!$H$13+$K$27*LIDER!$H$14+$L$27*LIDER!$H$15,"N")) -> 3.5 | F27: 3.5 | G27: 3.5 | H27: 3.5 | I27: 3.5 | J27: 3.5
A28: 2 | B28: =LIDER!H44 -> JEISON SAMUEL BELTRAN PEREZ | C28: =C27 -> G04 | E28: =IF(B28=0,0,IF(D28="",$F$27*LIDER!$H$9+$G$27*LIDER!$H$10+$H$27*LIDER!$H$11+$I$27*LIDER!$H$12+$J$27*LIDER!$H$13+$K$27*LIDER!$H$14+$L$27*LIDER!$H$15,"N")) -> 3.5
A29: 3 | B29: =LIDER!H45 -> ANDREA CAROLINA BUELVAS GUARDO | C29: =C28 -> G04 | E29: =IF(B29=0,0,IF(D29="",$F$27*LIDER!$H$9+$G$27*LIDER!$H$10+$H$27*LIDER!$H$11+$I$27*LIDER!$H$12+$J$27*LIDER!$H$13+$K$27*LIDER!$H$14+$L$27*LIDER!$H$15,"N")) -> 3.5
A30: 4 | B30: =LIDER!H46 -> MARIA DEL CARMEN NOEL GARCIA | C30: =C29 -> G04 | E30: =IF(B30=0,0,IF(D30="",$F$27*LIDER!$H$9+$G$27*LIDER!$H$10+$H$27*LIDER!$H$11+$I$27*LIDER!$H$12+$J$27*LIDER!$H$13+$K$27*LIDER!$H$14+$L$27*LIDER!$H$15,"N")) -> 3.5
A31: 5 | B31: =LIDER!H47 -> ANDRY JOSE RUBIO CABEZA | C31: =C30 -> G04 | E31: =IF(B31=0,0,IF(D31="",$F$27*LIDER!$H$9+$G$27*LIDER!$H$10+$H$27*LIDER!$H$11+$I$27*LIDER!$H$12+$J$27*LIDER!$H$13+$K$27*LIDER!$H$14+$L$27*LIDER!$H$15,"N")) -> 3.5
A32: 6 | B32: =LIDER!H48 -> 0 | C32: =C31 -> G04 | E32: =IF(B32=0,0,IF(D32="",$F$27*LIDER!$H$9+$G$27*LIDER!$H$10+$H$27*LIDER!$H$11+$I$27*LIDER!$H$12+$J$27*LIDER!$H$13+$K$27*LIDER!$H$14+$L$27*LIDER!$H$15,"N")) -> 0
B33: GRUPO#5 | C33: G05 | D33: =D26 -> LIST | E33: DEF | F33: =LIDER!$E$33 -> GRUPO#5
A34: 1 | B34: =LIDER!E51 -> DANETH MICHELL AGAMEZ VIVANCO | C34: =C33 -> G05 | E34: =IF(B34=0,0,IF(D34="",$F$34*LIDER!$H$9+$G$34*LIDER!$H$10+$H$34*LIDER!$H$11+$I$34*LIDER!$H$12+$J$34*LIDER!$H$13+$K$34*LIDER!$H$14+$L$34*LIDER!$H$15,"N")) -> 4.3 | F34: 4.3 | G34: 4.3 | H34: 4.3 | I34: 4.3 | J34: 4.3
A35: 2 | B35: =LIDER!E52 -> YULEIMIS ALEXANDRA BARÓN SILVA | C35: =C34 -> G05 | E35: =IF(B35=0,0,IF(D35="",$F$34*LIDER!$H$9+$G$34*LIDER!$H$10+$H$34*LIDER!$H$11+$I$34*LIDER!$H$12+$J$34*LIDER!$H$13+$K$34*LIDER!$H$14+$L$34*LIDER!$H$15,"N")) -> 4.3
A36: 3 | B36: =LIDER!E53 -> MARIA CARIDAD CASTILLA OROZCO | C36: =C35 -> G05 | E36: =IF(B36=0,0,IF(D36="",$F$34*LIDER!$H$9+$G$34*LIDER!$H$10+$H$34*LIDER!$H$11+$I$34*LIDER!$H$12+$J$34*LIDER!$H$13+$K$34*LIDER!$H$14+$L$34*LIDER!$H$15,"N")) -> 4.3
A37: 4 | B37: =LIDER!E54 -> ANDRES CAMILO PAEZ DE LA HOZ | C37: =C36 -> G05 | E37: =IF(B37=0,0,IF(D37="",$F$34*LIDER!$H$9+$G$34*LIDER!$H$10+$H$34*LIDER!$H$11+$I$34*LIDER!$H$12+$J$34*LIDER!$H$13+$K$34*LIDER!$H$14+$L$34*LIDER!$H$15,"N")) -> 4.3
A38: 5 | B38: =LIDER!E55 -> 0 | C38: =C37 -> G05 | E38: =IF(B38=0,0,IF(D38="",$F$34*LIDER!$H$9+$G$34*LIDER!$H$10+$H$34*LIDER!$H$11+$I$34*LIDER!$H$12+$J$34*LIDER!$H$13+$K$34*LIDER!$H$14+$L$34*LIDER!$H$15,"N")) -> 0
A39: 6 | B39: =LIDER!E56 -> 0 | C39: =C38 -> G05 | E39: =IF(B39=0,0,IF(D39="",$F$34*LIDER!$H$9+$G$34*LIDER!$H$10+$H$34*LIDER!$H$11+$I$34*LIDER!$H$12+$J$34*LIDER!$H$13+$K$34*LIDER!$H$14+$L$34*LIDER!$H$15,"N")) -> 0
B40: GRUPO#6 | C40: G06 | D40: =D33 -> LIST | E40: DEF | F40: =LIDER!$E$34 -> GRUPO#6
...

Sheet S-ASIG-02
A1: =LIDER!B2 -> TECNOLOGÍA EN GESTIÓN DE NEGOCIOS INTERN | I1: =LIDER!E2 -> SEMESTRE: | J1: =LIDER!F2 -> SEM-01 | K1: =LIDER!G2 -> SECCIÓN: | L1: =LIDER!H2 -> 5
B2: =LIDER!D4 -> CULTURA Y DEPORTE | F2: CRITERIOS DE EVALUACIÓN
B3: Estudiantes | F3: =LIDER!E9 -> Calidad de la información recopilada (20%): Se evaluará la calidad de la información recopilada a través del rastreo bibliográfico por medio de fichas bibliográficas para la redacción del resumen. | G3: =LIDER!E10 -> Estructura del Documento (30%): El documento debe incluir los siguientes aspectos: Portada, Introducción, cuerpo del resumen, Bibliografía y Anexos. | H3: =LIDER!E11 -> Claridad de la información recopilada (20%): Se evaluará la claridad de la información recopilada a través del rastreo bibliográfico por medio de fichas bibliográficas para la redacción del resumen. | I3: =LIDER!E12 -> Coherencia de la información recopilada (20%): Se evaluará la coherencia de la información recopilada a través del rastreo de fichas de revisión bibliográfica para la redacción del resumen. | J3: =LIDER!E13 -> Asesorias individuales (10%): Anexo de la hoja de tutoria firmada por docentes del colectivo (3 fimas minimo). | K3: =LIDER!E14 -> 0 | L3: =LIDER!E15 -> 0
F4: =CONCATENATE(LIDER!D4," - ",LIDER!D6," - ",LIDER!D5) -> CULTURA Y DEPORTE - 2172 - EDWIN FRANCO OSPINO
B5: GRUPO#1 | C5: G01 | D5: LIST | E5: DEF | F5: =LIDER!$E$29 -> GRUPO#1
A6: 1 | B6: =LIDER!E43 -> JULIANA SOFIA CARCAMO BLANCO | C6: =C5 -> G01 | E6: =IF(B6=0,0,IF(D6="",$F$6*LIDER!$H$9+$G$6*LIDER!$H$10+$H$6*LIDER!$H$11+$I$6*LIDER!$H$12+$J$6*LIDER!$H$13+$K$6*LIDER!$H$14+$L$6*LIDER!$H$15,"N")) -> 0
A7: 2 | B7: =LIDER!E44 -> NATHALY SOFIA SEGOVIA ALVAREZ | C7: =C6 -> G01 | E7: =IF(B7=0,0,IF(D7="",$F$6*LIDER!$H$9+$G$6*LIDER!$H$10+$H$6*LIDER!$H$11+$I$6*LIDER!$H$12+$J$6*LIDER!$H$13+$K$6*LIDER!$H$14+$L$6*LIDER!$H$15,"N")) -> 0
A8: 3 | B8: =LIDER!E45 -> CARLOS ANDRES VERBEL MEDRANO | C8: =C7 -> G01 | E8: =IF(B8=0,0,IF(D8="",$F$6*LIDER!$H$9+$G$6*LIDER!$H$10+$H$6*LIDER!$H$11+$I$6*LIDER!$H$12+$J$6*LIDER!$H$13+$K$6*LIDER!$H$14+$L$6*LIDER!$H$15,"N")) -> 0
A9: 4 | B9: =LIDER!E46 -> 0 | C9: =C8 -> G01 | E9: =IF(B9=0,0,IF(D9="",$F$6*LIDER!$H$9+$G$6*LIDER!$H$10+$H$6*LIDER!$H$11+$I$6*LIDER!$H$12+$J$6*LIDER!$H$13+$K$6*LIDER!$H$14+$L$6*LIDER!$H$15,"N")) -> 0
A10: 5 | B10: =LIDER!E47 -> 0 | C10: =C9 -> G01 | E10: =IF(B10=0,0,IF(D10="",$F$6*LIDER!$H$9+$G$6*LIDER!$H$10+$H$6*LIDER!$H$11+$I$6*LIDER!$H$12+$J$6*LIDER!$H$13+$K$6*LIDER!$H$14+$L$6*LIDER!$H$15,"N")) -> 0
A11: 6 | B11: =LIDER!E48 -> 0 | C11: =C10 -> G01 | E11: =IF(B11=0,0,IF(D11="",$F$6*LIDER!$H$9+$G$6*LIDER!$H$10+$H$6*LIDER!$H$11+$I$6*LIDER!$H$12+$J$6*LIDER!$H$13+$K$6*LIDER!$H$14+$L$6*LIDER!$H$15,"N")) -> 0
B12: GRUPO#2 | C12: G02 | D12: =D5 -> LIST | E12: DEF | F12: =LIDER!$E$30 -> GRUPO#2
A13: 1 | B13: =LIDER!F43 -> VALERIA MEZA RODRIGUEZ | C13: =C12 -> G02 | E13: =IF(B13=0,0,IF(D13="",$F$13*LIDER!$H$9+$G$13*LIDER!$H$10+$H$13*LIDER!$H$11+$I$13*LIDER!$H$12+$J$13*LIDER!$H$13+$K$13*LIDER!$H$14+$L$13*LIDER!$H$15,"N")) -> 0
A14: 2 | B14: =LIDER!F44 -> GINA LISSETH RAMIREZ SOTO | C14: =C13 -> G02 | E14: =IF(B14=0,0,IF(D14="",$F$13*LIDER!$H$9+$G$13*LIDER!$H$10+$H$13*LIDER!$H$11+$I$13*LIDER!$H$12+$J$13*LIDER!$H$13+$K$13*LIDER!$H$14+$L$13*LIDER!$H$15,"N")) -> 0
A15: 3 | B15: =LIDER!F45 -> ANGGELA LUCIA UPARELA RAMIREZ | C15: =C14 -> G02 | E15: =IF(B15=0,0,IF(D15="",$F$13*LIDER!$H$9+$G$13*LIDER!$H$10+$H$13*LIDER!$H$11+$I$13*LIDER!$H$12+$J$13*LIDER!$H$13+$K$13*LIDER!$H$14+$L$13*LIDER!$H$15,"N")) -> 0
A16: 4 | B16: =LIDER!F46 -> 0 | C16: =C15 -> G02 | E16: =IF(B16=0,0,IF(D16="",$F$13*LIDER!$H$9+$G$13*LIDER!$H$10+$H$13*LIDER!$H$11+$I$13*LIDER!$H$12+$J$13*LIDER!$H$13+$K$13*LIDER!$H$14+$L$13*LIDER!$H$15,"N")) -> 0
A17: 5 | B17: =LIDER!F47 -> 0 | C17: =C16 -> G02 | E17: =IF(B17=0,0,IF(D17="",$F$13*LIDER!$H$9+$G$13*LIDER!$H$10+$H$13*LIDER!$H$11+$I$13*LIDER!$H$12+$J$13*LIDER!$H$13+$K$13*LIDER!$H$14+$L$13*LIDER!$H$15,"N")) -> 0
A18: 6 | B18: =LIDER!F48 -> 0 | C18: =C17 -> G02 | E18: =IF(B18=0,0,IF(D18="",$F$13*LIDER!$H$9+$G$13*LIDER!$H$10+$H$13*LIDER!$H$11+$I$13*LIDER!$H$12+$J$13*LIDER!$H$13+$K$13*LIDER!$H$14+$L$13*LIDER!$H$15,"N")) -> 0
B19: GRUPO#3 | C19: G03 | D19: =D12 -> LIST | E19: DEF | F19: =LIDER!$E$31 -> GRUPO#3
A20: 1 | B20: =LIDER!G43 -> YILBER YESID ANGULO ORTEGA | C20: =C19 -> G03 | E20: =IF(B20=0,0,IF(D20="",$F$20*LIDER!$H$9+$G$20*LIDER!$H$10+$H$20*LIDER!$H$11+$I$20*LIDER!$H$12+$J$20*LIDER!$H$13+$K$20*LIDER!$H$14+$L$20*LIDER!$H$15,"N")) -> 0
A21: 2 | B21: =LIDER!G44 -> LINDA SOFIA CANTILLO YANGUEZ | C21: =C20 -> G03 | E21: =IF(B21=0,0,IF(D21="",$F$20*LIDER!$H$9+$G$20*LIDER!$H$10+$H$20*LIDER!$H$11+$I$20*LIDER!$H$12+$J$20*LIDER!$H$13+$K$20*LIDER!$H$14+$L$20*LIDER!$H$15,"N")) -> 0
A22: 3 | B22: =LIDER!G45 -> DAVID SAM SILVA HERNANDEZ | C22: =C21 -> G03 | E22: =IF(B22=0,0,IF(D22="",$F$20*LIDER!$H$9+$G$20*LIDER!$H$10+$H$20*LIDER!$H$11+$I$20*LIDER!$H$12+$J$20*LIDER!$H$13+$K$20*LIDER!$H$14+$L$20*LIDER!$H$15,"N")) -> 0
A23: 4 | B23: =LIDER!G46 -> HANNA SOFIA ROSALES RODRIGUEZ | C23: =C22 -> G03 | E23: =IF(B23=0,0,IF(D23="",$F$20*LIDER!$H$9+$G$20*LIDER!$H$10+$H$20*LIDER!$H$11+$I$20*LIDER!$H$12+$J$20*LIDER!$H$13+$K$20*LIDER!$H$14+$L$20*LIDER!$H$15,"N")) -> 0
A24: 5 | B24: =LIDER!G47 -> 0 | C24: =C23 -> G03 | E24: =IF(B24=0,0,IF(D24="",$F$20*LIDER!$H$9+$G$20*LIDER!$H$10+$H$20*LIDER!$H$11+$I$20*LIDER!$H$12+$J$20*LIDER!$H$13+$K$20*LIDER!$H$14+$L$20*LIDER!$H$15,"N")) -> 0
A25: 6 | B25: =LIDER!G48 -> 0 | C25: =C24 -> G03 | E25: =IF(B25=0,0,IF(D25="",$F$20*LIDER!$H$9+$G$20*LIDER!$H$10+$H$20*LIDER!$H$11+$I$20*LIDER!$H$12+$J$20*LIDER!$H$13+$K$20*LIDER!$H$14+$L$20*LIDER!$H$15,"N")) -> 0
B26: GRUPO#4 | C26: G04 | D26: =D19 -> LIST | E26: DEF | F26: =LIDER!$E$32 -> GRUPO#4
A27: 1 | B27: =LIDER!H43 -> ADRIAN CAMILO ANGULO LAGARES | C27: =C26 -> G04 | E27: =IF(B27=0,0,IF(D27="",$F$27*LIDER!$H$9+$G$27*LIDER!$H$10+$H$27*LIDER!$H$11+$I$27*LIDER!$H$12+$J$27*LIDER!$H$13+$K$27*LIDER!$H$14+$L$27*LIDER!$H$15,"N")) -> 0
A28: 2 | B28: =LIDER!H44 -> JEISON SAMUEL BELTRAN PEREZ | C28: =C27 -> G04 | E28: =IF(B28=0,0,IF(D28="",$F$27*LIDER!$H$9+$G$27*LIDER!$H$10+$H$27*LIDER!$H$11+$I$27*LIDER!$H$12+$J$27*LIDER!$H$13+$K$27*LIDER!$H$14+$L$27*LIDER!$H$15,"N")) -> 0
A29: 3 | B29: =LIDER!H45 -> ANDREA CAROLINA BUELVAS GUARDO | C29: =C28 -> G04 | E29: =IF(B29=0,0,IF(D29="",$F$27*LIDER!$H$9+$G$27*LIDER!$H$10+$H$27*LIDER!$H$11+$I$27*LIDER!$H$12+$J$27*LIDER!$H$13+$K$27*LIDER!$H$14+$L$27*LIDER!$H$15,"N")) -> 0
A30: 4 | B30: =LIDER!H46 -> MARIA DEL CARMEN NOEL GARCIA | C30: =C29 -> G04 | E30: =IF(B30=0,0,IF(D30="",$F$27*LIDER!$H$9+$G$27*LIDER!$H$10+$H$27*LIDER!$H$11+$I$27*LIDER!$H$12+$J$27*LIDER!$H$13+$K$27*LIDER!$H$14+$L$27*LIDER!$H$15,"N")) -> 0
A31: 5 | B31: =LIDER!H47 -> ANDRY JOSE RUBIO CABEZA | C31: =C30 -> G04 | E31: =IF(B31=0,0,IF(D31="",$F$27*LIDER!$H$9+$G$27*LIDER!$H$10+$H$27*LIDER!$H$11+$I$27*LIDER!$H$12+$J$27*LIDER!$H$13+$K$27*LIDER!$H$14+$L$27*LIDER!$H$15,"N")) -> 0
A32: 6 | B32: =LIDER!H48 -> 0 | C32: =C31 -> G04 | E32: =IF(B32=0,0,IF(D32="",$F$27*LIDER!$H$9+$G$27*LIDER!$H$10+$H$27*LIDER!$H$11+$I$27*LIDER!$H$12+$J$27*LIDER!$H$13+$K$27*LIDER!$H$14+$L$27*LIDER!$H$15,"N")) -> 0
B33: GRUPO#5 | C33: G05 | D33: =D26 -> LIST | E33: DEF | F33: =LIDER!$E$33 -> GRUPO#5
A34: 1 | B34: =LIDER!E51 -> DANETH MICHELL AGAMEZ VIVANCO | C34: =C33 -> G05 | E34: =IF(B34=0,0,IF(D34="",$F$34*LIDER!$H$9+$G$34*LIDER!$H$10+$H$34*LIDER!$H$11+$I$34*LIDER!$H$12+$J$34*LIDER!$H$13+$K$34*LIDER!$H$14+$L$34*LIDER!$H$15,"N")) -> 0
A35: 2 | B35: =LIDER!E52 -> YULEIMIS ALEXANDRA BARÓN SILVA | C35: =C34 -> G05 | E35: =IF(B35=0,0,IF(D35="",$F$34*LIDER!$H$9+$G$34*LIDER!$H$10+$H$34*LIDER!$H$11+$I$34*LIDER!$H$12+$J$34*LIDER!$H$13+$K$34*LIDER!$H$14+$L$34*LIDER!$H$15,"N")) -> 0
A36: 3 | B36: =LIDER!E53 -> MARIA CARIDAD CASTILLA OROZCO | C36: =C35 -> G05 | E36: =IF(B36=0,0,IF(D36="",$F$34*LIDER!$H$9+$G$34*LIDER!$H$10+$H$34*LIDER!$H$11+$I$34*LIDER!$H$12+$J$34*LIDER!$H$13+$K$34*LIDER!$H$14+$L$34*LIDER!$H$15,"N")) -> 0
A37: 4 | B37: =LIDER!E54 -> ANDRES CAMILO PAEZ DE LA HOZ | C37: =C36 -> G05 | E37: =IF(B37=0,0,IF(D37="",$F$34*LIDER!$H$9+$G$34*LIDER!$H$10+$H$34*LIDER!$H$11+$I$34*LIDER!$H$12+$J$34*LIDER!$H$13+$K$34*LIDER!$H$14+$L$34*LIDER!$H$15,"N")) -> 0
A38: 5 | B38: =LIDER!E55 -> 0 | C38: =C37 -> G05 | E38: =IF(B38=0,0,IF(D38="",$F$34*LIDER!$H$9+$G$34*LIDER!$H$10+$H$34*LIDER!$H$11+$I$34*LIDER!$H$12+$J$34*LIDER!$H$13+$K$34*LIDER!$H$14+$L$34*LIDER!$H$15,"N")) -> 0
A39: 6 | B39: =LIDER!E56 -> 0 | C39: =C38 -> G05 | E39: =IF(B39=0,0,IF(D39="",$F$34*LIDER!$H$9+$G$34*LIDER!$H$10+$H$34*LIDER!$H$11+$I$34*LIDER!$H$12+$J$34*LIDER!$H$13+$K$34*LIDER!$H$14+$L$34*LIDER!$H$15,"N")) -> 0
B40: GRUPO#6 | C40: G06 | D40: =D33 -> LIST | E40: DEF | F40: =LIDER!$E$34 -> GRUPO#6
...

Sheet S-ASIG-03
A1: =LIDER!B2 -> TECNOLOGÍA EN GESTIÓN DE NEGOCIOS INTERN | I1: =LIDER!E2 -> SEMESTRE: | J1: =LIDER!F2 -> SEM-01 | K1: =LIDER!G2 -> SECCIÓN: | L1: =LIDER!H2 -> 5
B2: =LIDER!E4 -> COMUNICACION ORAL Y ESCRITA | F2: CRITERIOS DE EVALUACIÓN
B3: Estudiantes | F3: =LIDER!E9 -> Calidad de la información recopilada (20%): Se evaluará la calidad de la información recopilada a través del rastreo bibliográfico por medio de fichas bibliográficas para la redacción del resumen. | G3: =LIDER!E10 -> Estructura del Documento (30%): El documento debe incluir los siguientes aspectos: Portada, Introducción, cuerpo del resumen, Bibliografía y Anexos. | H3: =LIDER!E11 -> Claridad de la información recopilada (20%): Se evaluará la claridad de la información recopilada a través del rastreo bibliográfico por medio de fichas bibliográficas para la redacción del resumen. | I3: =LIDER!E12 -> Coherencia de la información recopilada (20%): Se evaluará la coherencia de la información recopilada a través del rastreo de fichas de revisión bibliográfica para la redacción del resumen. | J3: =LIDER!E13 -> Asesorias individuales (10%): Anexo de la hoja de tutoria firmada por docentes del colectivo (3 fimas minimo). | K3: =LIDER!E14 -> 0 | L3: =LIDER!E15 -> 0
F4: =CONCATENATE(LIDER!E4," - ",LIDER!E6," - ",LIDER!E5) -> COMUNICACION ORAL Y ESCRITA - 2196 - YASMIN GOMEZ MORENO
B5: GRUPO#1 | C5: G01 | D5: LIST | E5: DEF | F5: =LIDER!$E$29 -> GRUPO#1
A6: 1 | B6: =LIDER!E43 -> JULIANA SOFIA CARCAMO BLANCO | C6: =C5 -> G01 | E6: =IF(B6=0,0,IF(D6="",$F$6*LIDER!$H$9+$G$6*LIDER!$H$10+$H$6*LIDER!$H$11+$I$6*LIDER!$H$12+$J$6*LIDER!$H$13+$K$6*LIDER!$H$14+$L$6*LIDER!$H$15,"N")) -> 4.1 | F6: 4 | G6: 4 | H6: 4 | I6: 4 | J6: 5
A7: 2 | B7: =LIDER!E44 -> NATHALY SOFIA SEGOVIA ALVAREZ | C7: =C6 -> G01 | E7: =IF(B7=0,0,IF(D7="",$F$6*LIDER!$H$9+$G$6*LIDER!$H$10+$H$6*LIDER!$H$11+$I$6*LIDER!$H$12+$J$6*LIDER!$H$13+$K$6*LIDER!$H$14+$L$6*LIDER!$H$15,"N")) -> 4.1
A8: 3 | B8: =LIDER!E45 -> CARLOS ANDRES VERBEL MEDRANO | C8: =C7 -> G01 | E8: =IF(B8=0,0,IF(D8="",$F$6*LIDER!$H$9+$G$6*LIDER!$H$10+$H$6*LIDER!$H$11+$I$6*LIDER!$H$12+$J$6*LIDER!$H$13+$K$6*LIDER!$H$14+$L$6*LIDER!$H$15,"N")) -> 4.1
A9: 4 | B9: =LIDER!E46 -> 0 | C9: =C8 -> G01 | E9: =IF(B9=0,0,IF(D9="",$F$6*LIDER!$H$9+$G$6*LIDER!$H$10+$H$6*LIDER!$H$11+$I$6*LIDER!$H$12+$J$6*LIDER!$H$13+$K$6*LIDER!$H$14+$L$6*LIDER!$H$15,"N")) -> 0
A10: 5 | B10: =LIDER!E47 -> 0 | C10: =C9 -> G01 | E10: =IF(B10=0,0,IF(D10="",$F$6*LIDER!$H$9+$G$6*LIDER!$H$10+$H$6*LIDER!$H$11+$I$6*LIDER!$H$12+$J$6*LIDER!$H$13+$K$6*LIDER!$H$14+$L$6*LIDER!$H$15,"N")) -> 0
A11: 6 | B11: =LIDER!E48 -> 0 | C11: =C10 -> G01 | E11: =IF(B11=0,0,IF(D11="",$F$6*LIDER!$H$9+$G$6*LIDER!$H$10+$H$6*LIDER!$H$11+$I$6*LIDER!$H$12+$J$6*LIDER!$H$13+$K$6*LIDER!$H$14+$L$6*LIDER!$H$15,"N")) -> 0
B12: GRUPO#2 | C12: G02 | D12: =D5 -> LIST | E12: DEF | F12: =LIDER!$E$30 -> GRUPO#2
A13: 1 | B13: =LIDER!F43 -> VALERIA MEZA RODRIGUEZ | C13: =C12 -> G02 | E13: =IF(B13=0,0,IF(D13="",$F$13*LIDER!$H$9+$G$13*LIDER!$H$10+$H$13*LIDER!$H$11+$I$13*LIDER!$H$12+$J$13*LIDER!$H$13+$K$13*LIDER!$H$14+$L$13*LIDER!$H$15,"N")) -> 3.55 | F13: 3.5 | G13: 3.5 | H13: 3.5 | I13: 3.5 | J13: 4
A14: 2 | B14: =LIDER!F44 -> GINA LISSETH RAMIREZ SOTO | C14: =C13 -> G02 | E14: =IF(B14=0,0,IF(D14="",$F$13*LIDER!$H$9+$G$13*LIDER!$H$10+$H$13*LIDER!$H$11+$I$13*LIDER!$H$12+$J$13*LIDER!$H$13+$K$13*LIDER!$H$14+$L$13*LIDER!$H$15,"N")) -> 3.55
A15: 3 | B15: =LIDER!F45 -> ANGGELA LUCIA UPARELA RAMIREZ | C15: =C14 -> G02 | E15: =IF(B15=0,0,IF(D15="",$F$13*LIDER!$H$9+$G$13*LIDER!$H$10+$H$13*LIDER!$H$11+$I$13*LIDER!$H$12+$J$13*LIDER!$H$13+$K$13*LIDER!$H$14+$L$13*LIDER!$H$15,"N")) -> 3.55
A16: 4 | B16: =LIDER!F46 -> 0 | C16: =C15 -> G02 | E16: =IF(B16=0,0,IF(D16="",$F$13*LIDER!$H$9+$G$13*LIDER!$H$10+$H$13*LIDER!$H$11+$I$13*LIDER!$H$12+$J$13*LIDER!$H$13+$K$13*LIDER!$H$14+$L$13*LIDER!$H$15,"N")) -> 0
A17: 5 | B17: =LIDER!F47 -> 0 | C17: =C16 -> G02 | E17: =IF(B17=0,0,IF(D17="",$F$13*LIDER!$H$9+$G$13*LIDER!$H$10+$H$13*LIDER!$H$11+$I$13*LIDER!$H$12+$J$13*LIDER!$H$13+$K$13*LIDER!$H$14+$L$13*LIDER!$H$15,"N")) -> 0
A18: 6 | B18: =LIDER!F48 -> 0 | C18: =C17 -> G02 | E18: =IF(B18=0,0,IF(D18="",$F$13*LIDER!$H$9+$G$13*LIDER!$H$10+$H$13*LIDER!$H$11+$I$13*LIDER!$H$12+$J$13*LIDER!$H$13+$K$13*LIDER!$H$14+$L$13*LIDER!$H$15,"N")) -> 0
B19: GRUPO#3 | C19: G03 | D19: =D12 -> LIST | E19: DEF | F19: =LIDER!$E$31 -> GRUPO#3
A20: 1 | B20: =LIDER!G43 -> YILBER YESID ANGULO ORTEGA | C20: =C19 -> G03 | E20: =IF(B20=0,0,IF(D20="",$F$20*LIDER!$H$9+$G$20*LIDER!$H$10+$H$20*LIDER!$H$11+$I$20*LIDER!$H$12+$J$20*LIDER!$H$13+$K$20*LIDER!$H$14+$L$20*LIDER!$H$15,"N")) -> 3.05 | F20: 3 | G20: 3 | H20: 3 | I20: 3 | J20: 3.5
A21: 2 | B21: =LIDER!G44 -> LINDA SOFIA CANTILLO YANGUEZ | C21: =C20 -> G03 | E21: =IF(B21=0,0,IF(D21="",$F$20*LIDER!$H$9+$G$20*LIDER!$H$10+$H$20*LIDER!$H$11+$I$20*LIDER!$H$12+$J$20*LIDER!$H$13+$K$20*LIDER!$H$14+$L$20*LIDER!$H$15,"N")) -> 3.05
A22: 3 | B22: =LIDER!G45 -> DAVID SAM SILVA HERNANDEZ | C22: =C21 -> G03 | E22: =IF(B22=0,0,IF(D22="",$F$20*LIDER!$H$9+$G$20*LIDER!$H$10+$H$20*LIDER!$H$11+$I$20*LIDER!$H$12+$J$20*LIDER!$H$13+$K$20*LIDER!$H$14+$L$20*LIDER!$H$15,"N")) -> 3.05
A23: 4 | B23: =LIDER!G46 -> HANNA SOFIA ROSALES RODRIGUEZ | C23: =C22 -> G03 | E23: =IF(B23=0,0,IF(D23="",$F$20*LIDER!$H$9+$G$20*LIDER!$H$10+$H$20*LIDER!$H$11+$I$20*LIDER!$H$12+$J$20*LIDER!$H$13+$K$20*LIDER!$H$14+$L$20*LIDER!$H$15,"N")) -> 3.05
A24: 5 | B24: =LIDER!G47 -> 0 | C24: =C23 -> G03 | E24: =IF(B24=0,0,IF(D24="",$F$20*LIDER!$H$9+$G$20*LIDER!$H$10+$H$20*LIDER!$H$11+$I$20*LIDER!$H$12+$J$20*LIDER!$H$13+$K$20*LIDER!$H$14+$L$20*LIDER!$H$15,"N")) -> 0
A25: 6 | B25: =LIDER!G48 -> 0 | C25: =C24 -> G03 | E25: =IF(B25=0,0,IF(D25="",$F$20*LIDER!$H$9+$G$20*LIDER!$H$10+$H$20*LIDER!$H$11+$I$20*LIDER!$H$12+$J$20*LIDER!$H$13+$K$20*LIDER!$H$14+$L$20*LIDER!$H$15,"N")) -> 0
B26: GRUPO#4 | C26: G04 | D26: =D19 -> LIST | E26: DEF | F26: =LIDER!$E$32 -> GRUPO#4
A27: 1 | B27: =LIDER!H43 -> ADRIAN CAMILO ANGULO LAGARES | C27: =C26 -> G04 | E27: =IF(B27=0,0,IF(D27="",$F$27*LIDER!$H$9+$G$27*LIDER!$H$10+$H$27*LIDER!$H$11+$I$27*LIDER!$H$12+$J$27*LIDER!$H$13+$K$27*LIDER!$H$14+$L$27*LIDER!$H$15,"N")) -> 3 | F27: 3 | G27: 3 | H27: 3 | I27: 3 | J27: 3
A28: 2 | B28: =LIDER!H44 -> JEISON SAMUEL BELTRAN PEREZ | C28: =C27 -> G04 | E28: =IF(B28=0,0,IF(D28="",$F$27*LIDER!$H$9+$G$27*LIDER!$H$10+$H$27*LIDER!$H$11+$I$27*LIDER!$H$12+$J$27*LIDER!$H$13+$K$27*LIDER!$H$14+$L$27*LIDER!$H$15,"N")) -> 3
A29: 3 | B29: =LIDER!H45 -> ANDREA CAROLINA BUELVAS GUARDO | C29: =C28 -> G04 | E29: =IF(B29=0,0,IF(D29="",$F$27*LIDER!$H$9+$G$27*LIDER!$H$10+$H$27*LIDER!$H$11+$I$27*LIDER!$H$12+$J$27*LIDER!$H$13+$K$27*LIDER!$H$14+$L$27*LIDER!$H$15,"N")) -> 3
A30: 4 | B30: =LIDER!H46 -> MARIA DEL CARMEN NOEL GARCIA | C30: =C29 -> G04 | E30: =IF(B30=0,0,IF(D30="",$F$27*LIDER!$H$9+$G$27*LIDER!$H$10+$H$27*LIDER!$H$11+$I$27*LIDER!$H$12+$J$27*LIDER!$H$13+$K$27*LIDER!$H$14+$L$27*LIDER!$H$15,"N")) -> 3
A31: 5 | B31: =LIDER!H47 -> ANDRY JOSE RUBIO CABEZA | C31: =C30 -> G04 | E31: =IF(B31=0,0,IF(D31="",$F$27*LIDER!$H$9+$G$27*LIDER!$H$10+$H$27*LIDER!$H$11+$I$27*LIDER!$H$12+$J$27*LIDER!$H$13+$K$27*LIDER!$H$14+$L$27*LIDER!$H$15,"N")) -> 3
A32: 6 | B32: =LIDER!H48 -> 0 | C32: =C31 -> G04 | E32: =IF(B32=0,0,IF(D32="",$F$27*LIDER!$H$9+$G$27*LIDER!$H$10+$H$27*LIDER!$H$11+$I$27*LIDER!$H$12+$J$27*LIDER!$H$13+$K$27*LIDER!$H$14+$L$27*LIDER!$H$15,"N")) -> 0
B33: GRUPO#5 | C33: G05 | D33: =D26 -> LIST | E33: DEF | F33: =LIDER!$E$33 -> GRUPO#5
A34: 1 | B34: =LIDER!E51 -> DANETH MICHELL AGAMEZ VIVANCO | C34: =C33 -> G05 | E34: =IF(B34=0,0,IF(D34="",$F$34*LIDER!$H$9+$G$34*LIDER!$H$10+$H$34*LIDER!$H$11+$I$34*LIDER!$H$12+$J$34*LIDER!$H$13+$K$34*LIDER!$H$14+$L$34*LIDER!$H$15,"N")) -> 4 | F34: 4 | G34: 4 | H34: 4 | I34: 4 | J34: 4
A35: 2 | B35: =LIDER!E52 -> YULEIMIS ALEXANDRA BARÓN SILVA | C35: =C34 -> G05 | E35: =IF(B35=0,0,IF(D35="",$F$34*LIDER!$H$9+$G$34*LIDER!$H$10+$H$34*LIDER!$H$11+$I$34*LIDER!$H$12+$J$34*LIDER!$H$13+$K$34*LIDER!$H$14+$L$34*LIDER!$H$15,"N")) -> 4
A36: 3 | B36: =LIDER!E53 -> MARIA CARIDAD CASTILLA OROZCO | C36: =C35 -> G05 | E36: =IF(B36=0,0,IF(D36="",$F$34*LIDER!$H$9+$G$34*LIDER!$H$10+$H$34*LIDER!$H$11+$I$34*LIDER!$H$12+$J$34*LIDER!$H$13+$K$34*LIDER!$H$14+$L$34*LIDER!$H$15,"N")) -> 4
A37: 4 | B37: =LIDER!E54 -> ANDRES CAMILO PAEZ DE LA HOZ | C37: =C36 -> G05 | E37: =IF(B37=0,0,IF(D37="",$F$34*LIDER!$H$9+$G$34*LIDER!$H$10+$H$34*LIDER!$H$11+$I$34*LIDER!$H$12+$J$34*LIDER!$H$13+$K$34*LIDER!$H$14+$L$34*LIDER!$H$15,"N")) -> 4
A38: 5 | B38: =LIDER!E55 -> 0 | C38: =C37 -> G05 | E38: =IF(B38=0,0,IF(D38="",$F$34*LIDER!$H$9+$G$34*LIDER!$H$10+$H$34*LIDER!$H$11+$I$34*LIDER!$H$12+$J$34*LIDER!$H$13+$K$34*LIDER!$H$14+$L$34*LIDER!$H$15,"N")) -> 0
A39: 6 | B39: =LIDER!E56 -> 0 | C39: =C38 -> G05 | E39: =IF(B39=0,0,IF(D39="",$F$34*LIDER!$H$9+$G$34*LIDER!$H$10+$H$34*LIDER!$H$11+$I$34*LIDER!$H$12+$J$34*LIDER!$H$13+$K$34*LIDER!$H$14+$L$34*LIDER!$H$15,"N")) -> 0
B40: GRUPO#6 | C40: G06 | D40: =D33 -> LIST | E40: DEF | F40: =LIDER!$E$34 -> GRUPO#6
...

Sheet S-ASIG-05
A1: =LIDER!B2 -> TECNOLOGÍA EN GESTIÓN DE NEGOCIOS INTERN | I1: =LIDER!E2 -> SEMESTRE: | J1: =LIDER!F2 -> SEM-01 | K1: =LIDER!G2 -> SECCIÓN: | L1: =LIDER!H2 -> 5
B2: =LIDER!G4 -> CONTABILIDAD GENERAL | F2: CRITERIOS DE EVALUACIÓN
B3: Estudiantes | F3: =LIDER!E9 -> Calidad de la información recopilada (20%): Se evaluará la calidad de la información recopilada a través del rastreo bibliográfico por medio de fichas bibliográficas para la redacción del resumen. | G3: =LIDER!E10 -> Estructura del Documento (30%): El documento debe incluir los siguientes aspectos: Portada, Introducción, cuerpo del resumen, Bibliografía y Anexos. | H3: =LIDER!E11 -> Claridad de la información recopilada (20%): Se evaluará la claridad de la información recopilada a través del rastreo bibliográfico por medio de fichas bibliográficas para la redacción del resumen. | I3: =LIDER!E12 -> Coherencia de la información recopilada (20%): Se evaluará la coherencia de la información recopilada a través del rastreo de fichas de revisión bibliográfica para la redacción del resumen. | J3: =LIDER!E13 -> Asesorias individuales (10%): Anexo de la hoja de tutoria firmada por docentes del colectivo (3 fimas minimo). | K3: =LIDER!E14 -> 0 | L3: =LIDER!E15 -> 0
F4: =CONCATENATE(LIDER!G4," - ",LIDER!G6," - ",LIDER!G5) -> CONTABILIDAD GENERAL - 1401 - ANTONIO CARLOS CANTILLO BELTRAN
B5: GRUPO#1 | C5: G01 | D5: LIST | E5: DEF | F5: =LIDER!$E$29 -> GRUPO#1
A6: 1 | B6: =LIDER!E43 -> JULIANA SOFIA CARCAMO BLANCO | C6: =C5 -> G01 | E6: =IF(B6=0,0,IF(D6="",$F$6*LIDER!$H$9+$G$6*LIDER!$H$10+$H$6*LIDER!$H$11+$I$6*LIDER!$H$12+$J$6*LIDER!$H$13+$K$6*LIDER!$H$14+$L$6*LIDER!$H$15,"N")) -> 4.28 | F6: 4.2 | G6: 4.2 | H6: 4.2 | I6: 4.2 | J6: 5
A7: 2 | B7: =LIDER!E44 -> NATHALY SOFIA SEGOVIA ALVAREZ | C7: =C6 -> G01 | E7: =IF(B7=0,0,IF(D7="",$F$6*LIDER!$H$9+$G$6*LIDER!$H$10+$H$6*LIDER!$H$11+$I$6*LIDER!$H$12+$J$6*LIDER!$H$13+$K$6*LIDER!$H$14+$L$6*LIDER!$H$15,"N")) -> 4.28
A8: 3 | B8: =LIDER!E45 -> CARLOS ANDRES VERBEL MEDRANO | C8: =C7 -> G01 | E8: =IF(B8=0,0,IF(D8="",$F$6*LIDER!$H$9+$G$6*LIDER!$H$10+$H$6*LIDER!$H$11+$I$6*LIDER!$H$12+$J$6*LIDER!$H$13+$K$6*LIDER!$H$14+$L$6*LIDER!$H$15,"N")) -> 4.28
A9: 4 | B9: =LIDER!E46 -> 0 | C9: =C8 -> G01 | E9: =IF(B9=0,0,IF(D9="",$F$6*LIDER!$H$9+$G$6*LIDER!$H$10+$H$6*LIDER!$H$11+$I$6*LIDER!$H$12+$J$6*LIDER!$H$13+$K$6*LIDER!$H$14+$L$6*LIDER!$H$15,"N")) -> 0
A10: 5 | B10: =LIDER!E47 -> 0 | C10: =C9 -> G01 | E10: =IF(B10=0,0,IF(D10="",$F$6*LIDER!$H$9+$G$6*LIDER!$H$10+$H$6*LIDER!$H$11+$I$6*LIDER!$H$12+$J$6*LIDER!$H$13+$K$6*LIDER!$H$14+$L$6*LIDER!$H$15,"N")) -> 0
A11: 6 | B11: =LIDER!E48 -> 0 | C11: =C10 -> G01 | E11: =IF(B11=0,0,IF(D11="",$F$6*LIDER!$H$9+$G$6*LIDER!$H$10+$H$6*LIDER!$H$11+$I$6*LIDER!$H$12+$J$6*LIDER!$H$13+$K$6*LIDER!$H$14+$L$6*LIDER!$H$15,"N")) -> 0
B12: GRUPO#2 | C12: G02 | D12: =D5 -> LIST | E12: DEF | F12: =LIDER!$E$30 -> GRUPO#2
A13: 1 | B13: =LIDER!F43 -> VALERIA MEZA RODRIGUEZ | C13: =C12 -> G02 | E13: =IF(B13=0,0,IF(D13="",$F$13*LIDER!$H$9+$G$13*LIDER!$H$10+$H$13*LIDER!$H$11+$I$13*LIDER!$H$12+$J$13*LIDER!$H$13+$K$13*LIDER!$H$14+$L$13*LIDER!$H$15,"N")) -> 5 | F13: 5 | G13: 5 | H13: 5 | I13: 5 | J13: 5
A14: 2 | B14: =LIDER!F44 -> GINA LISSETH RAMIREZ SOTO | C14: =C13 -> G02 | E14: =IF(B14=0,0,IF(D14="",$F$13*LIDER!$H$9+$G$13*LIDER!$H$10+$H$13*LIDER!$H$11+$I$13*LIDER!$H$12+$J$13*LIDER!$H$13+$K$13*LIDER!$H$14+$L$13*LIDER!$H$15,"N")) -> 5
A15: 3 | B15: =LIDER!F45 -> ANGGELA LUCIA UPARELA RAMIREZ | C15: =C14 -> G02 | E15: =IF(B15=0,0,IF(D15="",$F$13*LIDER!$H$9+$G$13*LIDER!$H$10+$H$13*LIDER!$H$11+$I$13*LIDER!$H$12+$J$13*LIDER!$H$13+$K$13*LIDER!$H$14+$L$13*LIDER!$H$15,"N")) -> 5
A16: 4 | B16: =LIDER!F46 -> 0 | C16: =C15 -> G02 | E16: =IF(B16=0,0,IF(D16="",$F$13*LIDER!$H$9+$G$13*LIDER!$H$10+$H$13*LIDER!$H$11+$I$13*LIDER!$H$12+$J$13*LIDER!$H$13+$K$13*LIDER!$H$14+$L$13*LIDER!$H$15,"N")) -> 0
A17: 5 | B17: =LIDER!F47 -> 0 | C17: =C16 -> G02 | E17: =IF(B17=0,0,IF(D17="",$F$13*LIDER!$H$9+$G$13*LIDER!$H$10+$H$13*LIDER!$H$11+$I$13*LIDER!$H$12+$J$13*LIDER!$H$13+$K$13*LIDER!$H$14+$L$13*LIDER!$H$15,"N")) -> 0
A18: 6 | B18: =LIDER!F48 -> 0 | C18: =C17 -> G02 | E18: =IF(B18=0,0,IF(D18="",$F$13*LIDER!$H$9+$G$13*LIDER!$H$10+$H$13*LIDER!$H$11+$I$13*LIDER!$H$12+$J$13*LIDER!$H$13+$K$13*LIDER!$H$14+$L$13*LIDER!$H$15,"N")) -> 0
B19: GRUPO#3 | C19: G03 | D19: =D12 -> LIST | E19: DEF | F19: =LIDER!$E$31 -> GRUPO#3
A20: 1 | B20: =LIDER!G43 -> YILBER YESID ANGULO ORTEGA | C20: =C19 -> G03 | E20: =IF(B20=0,0,IF(D20="",$F$20*LIDER!$H$9+$G$20*LIDER!$H$10+$H$20*LIDER!$H$11+$I$20*LIDER!$H$12+$J$20*LIDER!$H$13+$K$20*LIDER!$H$14+$L$20*LIDER!$H$15,"N")) -> 4.1 | F20: 4 | G20: 4 | H20: 4 | I20: 4 | J20: 5
A21: 2 | B21: =LIDER!G44 -> LINDA SOFIA CANTILLO YANGUEZ | C21: =C20 -> G03 | E21: =IF(B21=0,0,IF(D21="",$F$20*LIDER!$H$9+$G$20*LIDER!$H$10+$H$20*LIDER!$H$11+$I$20*LIDER!$H$12+$J$20*LIDER!$H$13+$K$20*LIDER!$H$14+$L$20*LIDER!$H$15,"N")) -> 4.1
A22: 3 | B22: =LIDER!G45 -> DAVID SAM SILVA HERNANDEZ | C22: =C21 -> G03 | E22: =IF(B22=0,0,IF(D22="",$F$20*LIDER!$H$9+$G$20*LIDER!$H$10+$H$20*LIDER!$H$11+$I$20*LIDER!$H$12+$J$20*LIDER!$H$13+$K$20*LIDER!$H$14+$L$20*LIDER!$H$15,"N")) -> 4.1
A23: 4 | B23: =LIDER!G46 -> HANNA SOFIA ROSALES RODRIGUEZ | C23: =C22 -> G03 | E23: =IF(B23=0,0,IF(D23="",$F$20*LIDER!$H$9+$G$20*LIDER!$H$10+$H$20*LIDER!$H$11+$I$20*LIDER!$H$12+$J$20*LIDER!$H$13+$K$20*LIDER!$H$14+$L$20*LIDER!$H$15,"N")) -> 4.1
A24: 5 | B24: =LIDER!G47 -> 0 | C24: =C23 -> G03 | E24: =IF(B24=0,0,IF(D24="",$F$20*LIDER!$H$9+$G$20*LIDER!$H$10+$H$20*LIDER!$H$11+$I$20*LIDER!$H$12+$J$20*LIDER!$H$13+$K$20*LIDER!$H$14+$L$20*LIDER!$H$15,"N")) -> 0
A25: 6 | B25: =LIDER!G48 -> 0 | C25: =C24 -> G03 | E25: =IF(B25=0,0,IF(D25="",$F$20*LIDER!$H$9+$G$20*LIDER!$H$10+$H$20*LIDER!$H$11+$I$20*LIDER!$H$12+$J$20*LIDER!$H$13+$K$20*LIDER!$H$14+$L$20*LIDER!$H$15,"N")) -> 0
B26: GRUPO#4 | C26: G04 | D26: =D19 -> LIST | E26: DEF | F26: =LIDER!$E$32 -> GRUPO#4
A27: 1 | B27: =LIDER!H43 -> ADRIAN CAMILO ANGULO LAGARES | C27: =C26 -> G04 | E27: =IF(B27=0,0,IF(D27="",$F$27*LIDER!$H$9+$G$27*LIDER!$H$10+$H$27*LIDER!$H$11+$I$27*LIDER!$H$12+$J$27*LIDER!$H$13+$K$27*LIDER!$H$14+$L$27*LIDER!$H$15,"N")) -> 2.3 | F27: 3 | G27: 0 | H27: 3 | I27: 3 | J27: 5
A28: 2 | B28: =LIDER!H44 -> JEISON SAMUEL BELTRAN PEREZ | C28: =C27 -> G04 | E28: =IF(B28=0,0,IF(D28="",$F$27*LIDER!$H$9+$G$27*LIDER!$H$10+$H$27*LIDER!$H$11+$I$27*LIDER!$H$12+$J$27*LIDER!$H$13+$K$27*LIDER!$H$14+$L$27*LIDER!$H$15,"N")) -> 2.3
A29: 3 | B29: =LIDER!H45 -> ANDREA CAROLINA BUELVAS GUARDO | C29: =C28 -> G04 | E29: =IF(B29=0,0,IF(D29="",$F$27*LIDER!$H$9+$G$27*LIDER!$H$10+$H$27*LIDER!$H$11+$I$27*LIDER!$H$12+$J$27*LIDER!$H$13+$K$27*LIDER!$H$14+$L$27*LIDER!$H$15,"N")) -> 2.3
A30: 4 | B30: =LIDER!H46 -> MARIA DEL CARMEN NOEL GARCIA | C30: =C29 -> G04 | E30: =IF(B30=0,0,IF(D30="",$F$27*LIDER!$H$9+$G$27*LIDER!$H$10+$H$27*LIDER!$H$11+$I$27*LIDER!$H$12+$J$27*LIDER!$H$13+$K$27*LIDER!$H$14+$L$27*LIDER!$H$15,"N")) -> 2.3
A31: 5 | B31: =LIDER!H47 -> ANDRY JOSE RUBIO CABEZA | C31: =C30 -> G04 | E31: =IF(B31=0,0,IF(D31="",$F$27*LIDER!$H$9+$G$27*LIDER!$H$10+$H$27*LIDER!$H$11+$I$27*LIDER!$H$12+$J$27*LIDER!$H$13+$K$27*LIDER!$H$14+$L$27*LIDER!$H$15,"N")) -> 2.3
A32: 6 | B32: =LIDER!H48 -> 0 | C32: =C31 -> G04 | E32: =IF(B32=0,0,IF(D32="",$F$27*LIDER!$H$9+$G$27*LIDER!$H$10+$H$27*LIDER!$H$11+$I$27*LIDER!$H$12+$J$27*LIDER!$H$13+$K$27*LIDER!$H$14+$L$27*LIDER!$H$15,"N")) -> 0
B33: GRUPO#5 | C33: G05 | D33: =D26 -> LIST | E33: DEF | F33: =LIDER!$E$33 -> GRUPO#5
A34: 1 | B34: =LIDER!E51 -> DANETH MICHELL AGAMEZ VIVANCO | C34: =C33 -> G05 | E34: =IF(B34=0,0,IF(D34="",$F$34*LIDER!$H$9+$G$34*LIDER!$H$10+$H$34*LIDER!$H$11+$I$34*LIDER!$H$12+$J$34*LIDER!$H$13+$K$34*LIDER!$H$14+$L$34*LIDER!$H$15,"N")) -> 5 | F34: 5 | G34: 5 | H34: 5 | I34: 5 | J34: 5
A35: 2 | B35: =LIDER!E52 -> YULEIMIS ALEXANDRA BARÓN SILVA | C35: =C34 -> G05 | E35: =IF(B35=0,0,IF(D35="",$F$34*LIDER!$H$9+$G$34*LIDER!$H$10+$H$34*LIDER!$H$11+$I$34*LIDER!$H$12+$J$34*LIDER!$H$13+$K$34*LIDER!$H$14+$L$34*LIDER!$H$15,"N")) -> 5
A36: 3 | B36: =LIDER!E53 -> MARIA CARIDAD CASTILLA OROZCO | C36: =C35 -> G05 | E36: =IF(B36=0,0,IF(D36="",$F$34*LIDER!$H$9+$G$34*LIDER!$H$10+$H$34*LIDER!$H$11+$I$34*LIDER!$H$12+$J$34*LIDER!$H$13+$K$34*LIDER!$H$14+$L$34*LIDER!$H$15,"N")) -> 5
A37: 4 | B37: =LIDER!E54 -> ANDRES CAMILO PAEZ DE LA HOZ | C37: =C36 -> G05 | E37: =IF(B37=0,0,IF(D37="",$F$34*LIDER!$H$9+$G$34*LIDER!$H$10+$H$34*LIDER!$H$11+$I$34*LIDER!$H$12+$J$34*LIDER!$H$13+$K$34*LIDER!$H$14+$L$34*LIDER!$H$15,"N")) -> 5
A38: 5 | B38: =LIDER!E55 -> 0 | C38: =C37 -> G05 | E38: =IF(B38=0,0,IF(D38="",$F$34*LIDER!$H$9+$G$34*LIDER!$H$10+$H$34*LIDER!$H$11+$I$34*LIDER!$H$12+$J$34*LIDER!$H$13+$K$34*LIDER!$H$14+$L$34*LIDER!$H$15,"N")) -> 0
A39: 6 | B39: =LIDER!E56 -> 0 | C39: =C38 -> G05 | E39: =IF(B39=0,0,IF(D39="",$F$34*LIDER!$H$9+$G$34*LIDER!$H$10+$H$34*LIDER!$H$11+$I$34*LIDER!$H$12+$J$34*LIDER!$H$13+$K$34*LIDER!$H$14+$L$34*LIDER!$H$15,"N")) -> 0
B40: GRUPO#6 | C40: G06 | D40: =D33 -> LIST | E40: DEF | F40: =LIDER!$E$34 -> GRUPO#6
...

Sheet S-ASIG-04
A1: =LIDER!B2 -> TECNOLOGÍA EN GESTIÓN DE NEGOCIOS INTERN | I1: =LIDER!E2 -> SEMESTRE: | J1: =LIDER!F2 -> SEM-01 | K1: =LIDER!G2 -> SECCIÓN: | L1: =LIDER!H2 -> 5
B2: =LIDER!F4 -> PROYECTO DE VIDA | F2: CRITERIOS DE EVALUACIÓN
B3: Estudiantes | F3: =LIDER!E9 -> Calidad de la información recopilada (20%): Se evaluará la calidad de la información recopilada a través del rastreo bibliográfico por medio de fichas bibliográficas para la redacción del resumen. | G3: =LIDER!E10 -> Estructura del Documento (30%): El documento debe incluir los siguientes aspectos: Portada, Introducción, cuerpo del resumen, Bibliografía y Anexos. | H3: =LIDER!E11 -> Claridad de la información recopilada (20%): Se evaluará la claridad de la información recopilada a través del rastreo bibliográfico por medio de fichas bibliográficas para la redacción del resumen. | I3: =LIDER!E12 -> Coherencia de la información recopilada (20%): Se evaluará la coherencia de la información recopilada a través del rastreo de fichas de revisión bibliográfica para la redacción del resumen. | J3: =LIDER!E13 -> Asesorias individuales (10%): Anexo de la hoja de tutoria firmada por docentes del colectivo (3 fimas minimo). | K3: =LIDER!E14 -> 0 | L3: =LIDER!E15 -> 0
F4: =CONCATENATE(LIDER!F4," - ",LIDER!F6," - ",LIDER!F5) -> PROYECTO DE VIDA - 3248 - MARINA LLAMAS DURAN
B5: GRUPO#1 | C5: G01 | D5: LIST | E5: DEF | F5: =LIDER!$E$29 -> GRUPO#1
A6: 1 | B6: =LIDER!E43 -> JULIANA SOFIA CARCAMO BLANCO | C6: =C5 -> G01 | E6: =IF(B6=0,0,IF(D6="",$F$6*LIDER!$H$9+$G$6*LIDER!$H$10+$H$6*LIDER!$H$11+$I$6*LIDER!$H$12+$J$6*LIDER!$H$13+$K$6*LIDER!$H$14+$L$6*LIDER!$H$15,"N")) -> 4.22 | F6: 4.5 | G6: 4.2 | H6: 4 | I6: 4.2 | J6: 4.2
A7: 2 | B7: =LIDER!E44 -> NATHALY SOFIA SEGOVIA ALVAREZ | C7: =C6 -> G01 | E7: =IF(B7=0,0,IF(D7="",$F$6*LIDER!$H$9+$G$6*LIDER!$H$10+$H$6*LIDER!$H$11+$I$6*LIDER!$H$12+$J$6*LIDER!$H$13+$K$6*LIDER!$H$14+$L$6*LIDER!$H$15,"N")) -> 4.22
A8: 3 | B8: =LIDER!E45 -> CARLOS ANDRES VERBEL MEDRANO | C8: =C7 -> G01 | E8: =IF(B8=0,0,IF(D8="",$F$6*LIDER!$H$9+$G$6*LIDER!$H$10+$H$6*LIDER!$H$11+$I$6*LIDER!$H$12+$J$6*LIDER!$H$13+$K$6*LIDER!$H$14+$L$6*LIDER!$H$15,"N")) -> 4.22
A9: 4 | B9: =LIDER!E46 -> 0 | C9: =C8 -> G01 | E9: =IF(B9=0,0,IF(D9="",$F$6*LIDER!$H$9+$G$6*LIDER!$H$10+$H$6*LIDER!$H$11+$I$6*LIDER!$H$12+$J$6*LIDER!$H$13+$K$6*LIDER!$H$14+$L$6*LIDER!$H$15,"N")) -> 0
A10: 5 | B10: =LIDER!E47 -> 0 | C10: =C9 -> G01 | E10: =IF(B10=0,0,IF(D10="",$F$6*LIDER!$H$9+$G$6*LIDER!$H$10+$H$6*LIDER!$H$11+$I$6*LIDER!$H$12+$J$6*LIDER!$H$13+$K$6*LIDER!$H$14+$L$6*LIDER!$H$15,"N")) -> 0
A11: 6 | B11: =LIDER!E48 -> 0 | C11: =C10 -> G01 | E11: =IF(B11=0,0,IF(D11="",$F$6*LIDER!$H$9+$G$6*LIDER!$H$10+$H$6*LIDER!$H$11+$I$6*LIDER!$H$12+$J$6*LIDER!$H$13+$K$6*LIDER!$H$14+$L$6*LIDER!$H$15,"N")) -> 0
B12: GRUPO#2 | C12: G02 | D12: =D5 -> LIST | E12: DEF | F12: =LIDER!$E$30 -> GRUPO#2
A13: 1 | B13: =LIDER!F43 -> VALERIA MEZA RODRIGUEZ | C13: =C12 -> G02 | E13: =IF(B13=0,0,IF(D13="",$F$13*LIDER!$H$9+$G$13*LIDER!$H$10+$H$13*LIDER!$H$11+$I$13*LIDER!$H$12+$J$13*LIDER!$H$13+$K$13*LIDER!$H$14+$L$13*LIDER!$H$15,"N")) -> 4.22 | F13: 4.5 | G13: 4.2 | H13: 4 | I13: 4.2 | J13: 4.2
A14: 2 | B14: =LIDER!F44 -> GINA LISSETH RAMIREZ SOTO | C14: =C13 -> G02 | E14: =IF(B14=0,0,IF(D14="",$F$13*LIDER!$H$9+$G$13*LIDER!$H$10+$H$13*LIDER!$H$11+$I$13*LIDER!$H$12+$J$13*LIDER!$H$13+$K$13*LIDER!$H$14+$L$13*LIDER!$H$15,"N")) -> 4.22
A15: 3 | B15: =LIDER!F45 -> ANGGELA LUCIA UPARELA RAMIREZ | C15: =C14 -> G02 | E15: =IF(B15=0,0,IF(D15="",$F$13*LIDER!$H$9+$G$13*LIDER!$H$10+$H$13*LIDER!$H$11+$I$13*LIDER!$H$12+$J$13*LIDER!$H$13+$K$13*LIDER!$H$14+$L$13*LIDER!$H$15,"N")) -> 4.22
A16: 4 | B16: =LIDER!F46 -> 0 | C16: =C15 -> G02 | E16: =IF(B16=0,0,IF(D16="",$F$13*LIDER!$H$9+$G$13*LIDER!$H$10+$H$13*LIDER!$H$11+$I$13*LIDER!$H$12+$J$13*LIDER!$H$13+$K$13*LIDER!$H$14+$L$13*LIDER!$H$15,"N")) -> 0
A17: 5 | B17: =LIDER!F47 -> 0 | C17: =C16 -> G02 | E17: =IF(B17=0,0,IF(D17="",$F$13*LIDER!$H$9+$G$13*LIDER!$H$10+$H$13*LIDER!$H$11+$I$13*LIDER!$H$12+$J$13*LIDER!$H$13+$K$13*LIDER!$H$14+$L$13*LIDER!$H$15,"N")) -> 0
A18: 6 | B18: =LIDER!F48 -> 0 | C18: =C17 -> G02 | E18: =IF(B18=0,0,IF(D18="",$F$13*LIDER!$H$9+$G$13*LIDER!$H$10+$H$13*LIDER!$H$11+$I$13*LIDER!$H$12+$J$13*LIDER!$H$13+$K$13*LIDER!$H$14+$L$13*LIDER!$H$15,"N")) -> 0
B19: GRUPO#3 | C19: G03 | D19: =D12 -> LIST | E19: DEF | F19: =LIDER!$E$31 -> GRUPO#3
A20: 1 | B20: =LIDER!G43 -> YILBER YESID ANGULO ORTEGA | C20: =C19 -> G03 | E20: =IF(B20=0,0,IF(D20="",$F$20*LIDER!$H$9+$G$20*LIDER!$H$10+$H$20*LIDER!$H$11+$I$20*LIDER!$H$12+$J$20*LIDER!$H$13+$K$20*LIDER!$H$14+$L$20*LIDER!$H$15,"N")) -> 4.22 | F20: 4.5 | G20: 4.2 | H20: 4 | I20: 4.2 | J20: 4.2
A21: 2 | B21: =LIDER!G44 -> LINDA SOFIA CANTILLO YANGUEZ | C21: =C20 -> G03 | E21: =IF(B21=0,0,IF(D21="",$F$20*LIDER!$H$9+$G$20*LIDER!$H$10+$H$20*LIDER!$H$11+$I$20*LIDER!$H$12+$J$20*LIDER!$H$13+$K$20*LIDER!$H$14+$L$20*LIDER!$H$15,"N")) -> 4.22
A22: 3 | B22: =LIDER!G45 -> DAVID SAM SILVA HERNANDEZ | C22: =C21 -> G03 | E22: =IF(B22=0,0,IF(D22="",$F$20*LIDER!$H$9+$G$20*LIDER!$H$10+$H$20*LIDER!$H$11+$I$20*LIDER!$H$12+$J$20*LIDER!$H$13+$K$20*LIDER!$H$14+$L$20*LIDER!$H$15,"N")) -> 4.22
A23: 4 | B23: =LIDER!G46 -> HANNA SOFIA ROSALES RODRIGUEZ | C23: =C22 -> G03 | E23: =IF(B23=0,0,IF(D23="",$F$20*LIDER!$H$9+$G$20*LIDER!$H$10+$H$20*LIDER!$H$11+$I$20*LIDER!$H$12+$J$20*LIDER!$H$13+$K$20*LIDER!$H$14+$L$20*LIDER!$H$15,"N")) -> 4.22
A24: 5 | B24: =LIDER!G47 -> 0 | C24: =C23 -> G03 | E24: =IF(B24=0,0,IF(D24="",$F$20*LIDER!$H$9+$G$20*LIDER!$H$10+$H$20*LIDER!$H$11+$I$20*LIDER!$H$12+$J$20*LIDER!$H$13+$K$20*LIDER!$H$14+$L$20*LIDER!$H$15,"N")) -> 0
A25: 6 | B25: =LIDER!G48 -> 0 | C25: =C24 -> G03 | E25: =IF(B25=0,0,IF(D25="",$F$20*LIDER!$H$9+$G$20*LIDER!$H$10+$H$20*LIDER!$H$11+$I$20*LIDER!$H$12+$J$20*LIDER!$H$13+$K$20*LIDER!$H$14+$L$20*LIDER!$H$15,"N")) -> 0
B26: GRUPO#4 | C26: G04 | D26: =D19 -> LIST | E26: DEF | F26: =LIDER!$E$32 -> GRUPO#4
A27: 1 | B27: =LIDER!H43 -> ADRIAN CAMILO ANGULO LAGARES | C27: =C26 -> G04 | E27: =IF(B27=0,0,IF(D27="",$F$27*LIDER!$H$9+$G$27*LIDER!$H$10+$H$27*LIDER!$H$11+$I$27*LIDER!$H$12+$J$27*LIDER!$H$13+$K$27*LIDER!$H$14+$L$27*LIDER!$H$15,"N")) -> 4.5 | F27: 4.5 | G27: 4.5 | H27: 4.5 | I27: 4.5 | J27: 4.5
A28: 2 | B28: =LIDER!H44 -> JEISON SAMUEL BELTRAN PEREZ | C28: =C27 -> G04 | E28: =IF(B28=0,0,IF(D28="",$F$27*LIDER!$H$9+$G$27*LIDER!$H$10+$H$27*LIDER!$H$11+$I$27*LIDER!$H$12+$J$27*LIDER!$H$13+$K$27*LIDER!$H$14+$L$27*LIDER!$H$15,"N")) -> 4.5
A29: 3 | B29: =LIDER!H45 -> ANDREA CAROLINA BUELVAS GUARDO | C29: =C28 -> G04 | E29: =IF(B29=0,0,IF(D29="",$F$27*LIDER!$H$9+$G$27*LIDER!$H$10+$H$27*LIDER!$H$11+$I$27*LIDER!$H$12+$J$27*LIDER!$H$13+$K$27*LIDER!$H$14+$L$27*LIDER!$H$15,"N")) -> 4.5
A30: 4 | B30: =LIDER!H46 -> MARIA DEL CARMEN NOEL GARCIA | C30: =C29 -> G04 | E30: =IF(B30=0,0,IF(D30="",$F$27*LIDER!$H$9+$G$27*LIDER!$H$10+$H$27*LIDER!$H$11+$I$27*LIDER!$H$12+$J$27*LIDER!$H$13+$K$27*LIDER!$H$14+$L$27*LIDER!$H$15,"N")) -> 4.5
A31: 5 | B31: =LIDER!H47 -> ANDRY JOSE RUBIO CABEZA | C31: =C30 -> G04 | E31: =IF(B31=0,0,IF(D31="",$F$27*LIDER!$H$9+$G$27*LIDER!$H$10+$H$27*LIDER!$H$11+$I$27*LIDER!$H$12+$J$27*LIDER!$H$13+$K$27*LIDER!$H$14+$L$27*LIDER!$H$15,"N")) -> 4.5
A32: 6 | B32: =LIDER!H48 -> 0 | C32: =C31 -> G04 | E32: =IF(B32=0,0,IF(D32="",$F$27*LIDER!$H$9+$G$27*LIDER!$H$10+$H$27*LIDER!$H$11+$I$27*LIDER!$H$12+$J$27*LIDER!$H$13+$K$27*LIDER!$H$14+$L$27*LIDER!$H$15,"N")) -> 0
B33: GRUPO#5 | C33: G05 | D33: =D26 -> LIST | E33: DEF | F33: =LIDER!$E$33 -> GRUPO#5
A34: 1 | B34: =LIDER!E51 -> DANETH MICHELL AGAMEZ VIVANCO | C34: =C33 -> G05 | E34: =IF(B34=0,0,IF(D34="",$F$34*LIDER!$H$9+$G$34*LIDER!$H$10+$H$34*LIDER!$H$11+$I$34*LIDER!$H$12+$J$34*LIDER!$H$13+$K$34*LIDER!$H$14+$L$34*LIDER!$H$15,"N")) -> 0
A35: 2 | B35: =LIDER!E52 -> YULEIMIS ALEXANDRA BARÓN SILVA | C35: =C34 -> G05 | E35: =IF(B35=0,0,IF(D35="",$F$34*LIDER!$H$9+$G$34*LIDER!$H$10+$H$34*LIDER!$H$11+$I$34*LIDER!$H$12+$J$34*LIDER!$H$13+$K$34*LIDER!$H$14+$L$34*LIDER!$H$15,"N")) -> 0
A36: 3 | B36: =LIDER!E53 -> MARIA CARIDAD CASTILLA OROZCO | C36: =C35 -> G05 | E36: =IF(B36=0,0,IF(D36="",$F$34*LIDER!$H$9+$G$34*LIDER!$H$10+$H$34*LIDER!$H$11+$I$34*LIDER!$H$12+$J$34*LIDER!$H$13+$K$34*LIDER!$H$14+$L$34*LIDER!$H$15,"N")) -> 0
A37: 4 | B37: =LIDER!E54 -> ANDRES CAMILO PAEZ DE LA HOZ | C37: =C36 -> G05 | E37: =IF(B37=0,0,IF(D37="",$F$34*LIDER!$H$9+$G$34*LIDER!$H$10+$H$34*LIDER!$H$11+$I$34*LIDER!$H$12+$J$34*LIDER!$H$13+$K$34*LIDER!$H$14+$L$34*LIDER!$H$15,"N")) -> 0
A38: 5 | B38: =LIDER!E55 -> 0 | C38: =C37 -> G05 | E38: =IF(B38=0,0,IF(D38="",$F$34*LIDER!$H$9+$G$34*LIDER!$H$10+$H$34*LIDER!$H$11+$I$34*LIDER!$H$12+$J$34*LIDER!$H$13+$K$34*LIDER!$H$14+$L$34*LIDER!$H$15,"N")) -> 0
A39: 6 | B39: =LIDER!E56 -> 0 | C39: =C38 -> G05 | E39: =IF(B39=0,0,IF(D39="",$F$34*LIDER!$H$9+$G$34*LIDER!$H$10+$H$34*LIDER!$H$11+$I$34*LIDER!$H$12+$J$34*LIDER!$H$13+$K$34*LIDER!$H$14+$L$34*LIDER!$H$15,"N")) -> 0
B40: GRUPO#6 | C40: G06 | D40: =D33 -> LIST | E40: DEF | F40: =LIDER!$E$34 -> GRUPO#6
...

Sheet S-ASIG-06
A1: =LIDER!B2 -> TECNOLOGÍA EN GESTIÓN DE NEGOCIOS INTERN | I1: =LIDER!E2 -> SEMESTRE: | J1: =LIDER!F2 -> SEM-01 | K1: =LIDER!G2 -> SECCIÓN: | L1: =LIDER!H2 -> 5
B2: =LIDER!H4 -> FUNDAMENTOS DE DERECHO | F2: CRITERIOS DE EVALUACIÓN
B3: Estudiantes | F3: =LIDER!E9 -> Calidad de la información recopilada (20%): Se evaluará la calidad de la información recopilada a través del rastreo bibliográfico por medio de fichas bibliográficas para la redacción del resumen. | G3: =LIDER!E10 -> Estructura del Documento (30%): El documento debe incluir los siguientes aspectos: Portada, Introducción, cuerpo del resumen, Bibliografía y Anexos. | H3: =LIDER!E11 -> Claridad de la información recopilada (20%): Se evaluará la claridad de la información recopilada a través del rastreo bibliográfico por medio de fichas bibliográficas para la redacción del resumen. | I3: =LIDER!E12 -> Coherencia de la información recopilada (20%): Se evaluará la coherencia de la información recopilada a través del rastreo de fichas de revisión bibliográfica para la redacción del resumen. | J3: =LIDER!E13 -> Asesorias individuales (10%): Anexo de la hoja de tutoria firmada por docentes del colectivo (3 fimas minimo). | K3: =LIDER!E14 -> 0 | L3: =LIDER!E15 -> 0
F4: =CONCATENATE(LIDER!H4," - ",LIDER!H6," - ",LIDER!H5) -> FUNDAMENTOS DE DERECHO - 3243 - MELISSA LOPEZ ROMERO
B5: GRUPO#1 | C5: G01 | D5: LIST | E5: DEF | F5: =LIDER!$E$29 -> GRUPO#1
A6: 1 | B6: =LIDER!E43 -> JULIANA SOFIA CARCAMO BLANCO | C6: =C5 -> G01 | E6: =IF(B6=0,0,IF(D6="",$F$6*LIDER!$H$9+$G$6*LIDER!$H$10+$H$6*LIDER!$H$11+$I$6*LIDER!$H$12+$J$6*LIDER!$H$13+$K$6*LIDER!$H$14+$L$6*LIDER!$H$15,"N")) -> 4.1 | F6: 4 | G6: 4 | H6: 4 | I6: 4 | J6: 5
A7: 2 | B7: =LIDER!E44 -> NATHALY SOFIA SEGOVIA ALVAREZ | C7: =C6 -> G01 | E7: =IF(B7=0,0,IF(D7="",$F$6*LIDER!$H$9+$G$6*LIDER!$H$10+$H$6*LIDER!$H$11+$I$6*LIDER!$H$12+$J$6*LIDER!$H$13+$K$6*LIDER!$H$14+$L$6*LIDER!$H$15,"N")) -> 4.1
A8: 3 | B8: =LIDER!E45 -> CARLOS ANDRES VERBEL MEDRANO | C8: =C7 -> G01 | E8: =IF(B8=0,0,IF(D8="",$F$6*LIDER!$H$9+$G$6*LIDER!$H$10+$H$6*LIDER!$H$11+$I$6*LIDER!$H$12+$J$6*LIDER!$H$13+$K$6*LIDER!$H$14+$L$6*LIDER!$H$15,"N")) -> 4.1
A9: 4 | B9: =LIDER!E46 -> 0 | C9: =C8 -> G01 | E9: =IF(B9=0,0,IF(D9="",$F$6*LIDER!$H$9+$G$6*LIDER!$H$10+$H$6*LIDER!$H$11+$I$6*LIDER!$H$12+$J$6*LIDER!$H$13+$K$6*LIDER!$H$14+$L$6*LIDER!$H$15,"N")) -> 0
A10: 5 | B10: =LIDER!E47 -> 0 | C10: =C9 -> G01 | E10: =IF(B10=0,0,IF(D10="",$F$6*LIDER!$H$9+$G$6*LIDER!$H$10+$H$6*LIDER!$H$11+$I$6*LIDER!$H$12+$J$6*LIDER!$H$13+$K$6*LIDER!$H$14+$L$6*LIDER!$H$15,"N")) -> 0
A11: 6 | B11: =LIDER!E48 -> 0 | C11: =C10 -> G01 | E11: =IF(B11=0,0,IF(D11="",$F$6*LIDER!$H$9+$G$6*LIDER!$H$10+$H$6*LIDER!$H$11+$I$6*LIDER!$H$12+$J$6*LIDER!$H$13+$K$6*LIDER!$H$14+$L$6*LIDER!$H$15,"N")) -> 0
B12: GRUPO#2 | C12: G02 | D12: =D5 -> LIST | E12: DEF | F12: =LIDER!$E$30 -> GRUPO#2
A13: 1 | B13: =LIDER!F43 -> VALERIA MEZA RODRIGUEZ | C13: =C12 -> G02 | E13: =IF(B13=0,0,IF(D13="",$F$13*LIDER!$H$9+$G$13*LIDER!$H$10+$H$13*LIDER!$H$11+$I$13*LIDER!$H$12+$J$13*LIDER!$H$13+$K$13*LIDER!$H$14+$L$13*LIDER!$H$15,"N")) -> 3.85 | F13: 4 | G13: 3.5 | H13: 4 | I13: 4 | J13: 4
A14: 2 | B14: =LIDER!F44 -> GINA LISSETH RAMIREZ SOTO | C14: =C13 -> G02 | E14: =IF(B14=0,0,IF(D14="",$F$13*LIDER!$H$9+$G$13*LIDER!$H$10+$H$13*LIDER!$H$11+$I$13*LIDER!$H$12+$J$13*LIDER!$H$13+$K$13*LIDER!$H$14+$L$13*LIDER!$H$15,"N")) -> 3.85
A15: 3 | B15: =LIDER!F45 -> ANGGELA LUCIA UPARELA RAMIREZ | C15: =C14 -> G02 | E15: =IF(B15=0,0,IF(D15="",$F$13*LIDER!$H$9+$G$13*LIDER!$H$10+$H$13*LIDER!$H$11+$I$13*LIDER!$H$12+$J$13*LIDER!$H$13+$K$13*LIDER!$H$14+$L$13*LIDER!$H$15,"N")) -> 3.85
A16: 4 | B16: =LIDER!F46 -> 0 | C16: =C15 -> G02 | E16: =IF(B16=0,0,IF(D16="",$F$13*LIDER!$H$9+$G$13*LIDER!$H$10+$H$13*LIDER!$H$11+$I$13*LIDER!$H$12+$J$13*LIDER!$H$13+$K$13*LIDER!$H$14+$L$13*LIDER!$H$15,"N")) -> 0
A17: 5 | B17: =LIDER!F47 -> 0 | C17: =C16 -> G02 | E17: =IF(B17=0,0,IF(D17="",$F$13*LIDER!$H$9+$G$13*LIDER!$H$10+$H$13*LIDER!$H$11+$I$13*LIDER!$H$12+$J$13*LIDER!$H$13+$K$13*LIDER!$H$14+$L$13*LIDER!$H$15,"N")) -> 0
A18: 6 | B18: =LIDER!F48 -> 0 | C18: =C17 -> G02 | E18: =IF(B18=0,0,IF(D18="",$F$13*LIDER!$H$9+$G$13*LIDER!$H$10+$H$13*LIDER!$H$11+$I$13*LIDER!$H$12+$J$13*LIDER!$H$13+$K$13*LIDER!$H$14+$L$13*LIDER!$H$15,"N")) -> 0
B19: GRUPO#3 | C19: G03 | D19: =D12 -> LIST | E19: DEF | F19: =LIDER!$E$31 -> GRUPO#3
A20: 1 | B20: =LIDER!G43 -> YILBER YESID ANGULO ORTEGA | C20: =C19 -> G03 | E20: =IF(B20=0,0,IF(D20="",$F$20*LIDER!$H$9+$G$20*LIDER!$H$10+$H$20*LIDER!$H$11+$I$20*LIDER!$H$12+$J$20*LIDER!$H$13+$K$20*LIDER!$H$14+$L$20*LIDER!$H$15,"N")) -> 4.1 | F20: 4 | G20: 4 | H20: 4 | I20: 4 | J20: 5
A21: 2 | B21: =LIDER!G44 -> LINDA SOFIA CANTILLO YANGUEZ | C21: =C20 -> G03 | E21: =IF(B21=0,0,IF(D21="",$F$20*LIDER!$H$9+$G$20*LIDER!$H$10+$H$20*LIDER!$H$11+$I$20*LIDER!$H$12+$J$20*LIDER!$H$13+$K$20*LIDER!$H$14+$L$20*LIDER!$H$15,"N")) -> 4.1
A22: 3 | B22: =LIDER!G45 -> DAVID SAM SILVA HERNANDEZ | C22: =C21 -> G03 | E22: =IF(B22=0,0,IF(D22="",$F$20*LIDER!$H$9+$G$20*LIDER!$H$10+$H$20*LIDER!$H$11+$I$20*LIDER!$H$12+$J$20*LIDER!$H$13+$K$20*LIDER!$H$14+$L$20*LIDER!$H$15,"N")) -> 4.1
A23: 4 | B23: =LIDER!G46 -> HANNA SOFIA ROSALES RODRIGUEZ | C23: =C22 -> G03 | E23: =IF(B23=0,0,IF(D23="",$F$20*LIDER!$H$9+$G$20*LIDER!$H$10+$H$20*LIDER!$H$11+$I$20*LIDER!$H$12+$J$20*LIDER!$H$13+$K$20*LIDER!$H$14+$L$20*LIDER!$H$15,"N")) -> 4.1
A24: 5 | B24: =LIDER!G47 -> 0 | C24: =C23 -> G03 | E24: =IF(B24=0,0,IF(D24="",$F$20*LIDER!$H$9+$G$20*LIDER!$H$10+$H$20*LIDER!$H$11+$I$20*LIDER!$H$12+$J$20*LIDER!$H$13+$K$20*LIDER!$H$14+$L$20*LIDER!$H$15,"N")) -> 0
A25: 6 | B25: =LIDER!G48 -> 0 | C25: =C24 -> G03 | E25: =IF(B25=0,0,IF(D25="",$F$20*LIDER!$H$9+$G$20*LIDER!$H$10+$H$20*LIDER!$H$11+$I$20*LIDER!$H$12+$J$20*LIDER!$H$13+$K$20*LIDER!$H$14+$L$20*LIDER!$H$15,"N")) -> 0
B26: GRUPO#4 | C26: G04 | D26: =D19 -> LIST | E26: DEF | F26: =LIDER!$E$32 -> GRUPO#4
A27: 1 | B27: =LIDER!H43 -> ADRIAN CAMILO ANGULO LAGARES | C27: =C26 -> G04 | E27: =IF(B27=0,0,IF(D27="",$F$27*LIDER!$H$9+$G$27*LIDER!$H$10+$H$27*LIDER!$H$11+$I$27*LIDER!$H$12+$J$27*LIDER!$H$13+$K$27*LIDER!$H$14+$L$27*LIDER!$H$15,"N")) -> 4.1 | F27: 4 | G27: 4 | H27: 4 | I27: 4 | J27: 5
A28: 2 | B28: =LIDER!H44 -> JEISON SAMUEL BELTRAN PEREZ | C28: =C27 -> G04 | E28: =IF(B28=0,0,IF(D28="",$F$27*LIDER!$H$9+$G$27*LIDER!$H$10+$H$27*LIDER!$H$11+$I$27*LIDER!$H$12+$J$27*LIDER!$H$13+$K$27*LIDER!$H$14+$L$27*LIDER!$H$15,"N")) -> 4.1
A29: 3 | B29: =LIDER!H45 -> ANDREA CAROLINA BUELVAS GUARDO | C29: =C28 -> G04 | E29: =IF(B29=0,0,IF(D29="",$F$27*LIDER!$H$9+$G$27*LIDER!$H$10+$H$27*LIDER!$H$11+$I$27*LIDER!$H$12+$J$27*LIDER!$H$13+$K$27*LIDER!$H$14+$L$27*LIDER!$H$15,"N")) -> 4.1
A30: 4 | B30: =LIDER!H46 -> MARIA DEL CARMEN NOEL GARCIA | C30: =C29 -> G04 | E30: =IF(B30=0,0,IF(D30="",$F$27*LIDER!$H$9+$G$27*LIDER!$H$10+$H$27*LIDER!$H$11+$I$27*LIDER!$H$12+$J$27*LIDER!$H$13+$K$27*LIDER!$H$14+$L$27*LIDER!$H$15,"N")) -> 4.1
A31: 5 | B31: =LIDER!H47 -> ANDRY JOSE RUBIO CABEZA | C31: =C30 -> G04 | E31: =IF(B31=0,0,IF(D31="",$F$27*LIDER!$H$9+$G$27*LIDER!$H$10+$H$27*LIDER!$H$11+$I$27*LIDER!$H$12+$J$27*LIDER!$H$13+$K$27*LIDER!$H$14+$L$27*LIDER!$H$15,"N")) -> 4.1
A32: 6 | B32: =LIDER!H48 -> 0 | C32: =C31 -> G04 | E32: =IF(B32=0,0,IF(D32="",$F$27*LIDER!$H$9+$G$27*LIDER!$H$10+$H$27*LIDER!$H$11+$I$27*LIDER!$H$12+$J$27*LIDER!$H$13+$K$27*LIDER!$H$14+$L$27*LIDER!$H$15,"N")) -> 0
B33: GRUPO#5 | C33: G05 | D33: =D26 -> LIST | E33: DEF | F33: =LIDER!$E$33 -> GRUPO#5
A34: 1 | B34: =LIDER!E51 -> DANETH MICHELL AGAMEZ VIVANCO | C34: =C33 -> G05 | E34: =IF(B34=0,0,IF(D34="",$F$34*LIDER!$H$9+$G$34*LIDER!$H$10+$H$34*LIDER!$H$11+$I$34*LIDER!$H$12+$J$34*LIDER!$H$13+$K$34*LIDER!$H$14+$L$34*LIDER!$H$15,"N")) -> 4.1 | F34: 4 | G34: 4 | H34: 4 | I34: 4 | J34: 5
A35: 2 | B35: =LIDER!E52 -> YULEIMIS ALEXANDRA BARÓN SILVA | C35: =C34 -> G05 | E35: =IF(B35=0,0,IF(D35="",$F$34*LIDER!$H$9+$G$34*LIDER!$H$10+$H$34*LIDER!$H$11+$I$34*LIDER!$H$12+$J$34*LIDER!$H$13+$K$34*LIDER!$H$14+$L$34*LIDER!$H$15,"N")) -> 4.1
A36: 3 | B36: =LIDER!E53 -> MARIA CARIDAD CASTILLA OROZCO | C36: =C35 -> G05 | E36: =IF(B36=0,0,IF(D36="",$F$34*LIDER!$H$9+$G$34*LIDER!$H$10+$H$34*LIDER!$H$11+$I$34*LIDER!$H$12+$J$34*LIDER!$H$13+$K$34*LIDER!$H$14+$L$34*LIDER!$H$15,"N")) -> 4.1
A37: 4 | B37: =LIDER!E54 -> ANDRES CAMILO PAEZ DE LA HOZ | C37: =C36 -> G05 | E37: =IF(B37=0,0,IF(D37="",$F$34*LIDER!$H$9+$G$34*LIDER!$H$10+$H$34*LIDER!$H$11+$I$34*LIDER!$H$12+$J$34*LIDER!$H$13+$K$34*LIDER!$H$14+$L$34*LIDER!$H$15,"N")) -> 4.1
A38: 5 | B38: =LIDER!E55 -> 0 | C38: =C37 -> G05 | E38: =IF(B38=0,0,IF(D38="",$F$34*LIDER!$H$9+$G$34*LIDER!$H$10+$H$34*LIDER!$H$11+$I$34*LIDER!$H$12+$J$34*LIDER!$H$13+$K$34*LIDER!$H$14+$L$34*LIDER!$H$15,"N")) -> 0
A39: 6 | B39: =LIDER!E56 -> 0 | C39: =C38 -> G05 | E39: =IF(B39=0,0,IF(D39="",$F$34*LIDER!$H$9+$G$34*LIDER!$H$10+$H$34*LIDER!$H$11+$I$34*LIDER!$H$12+$J$34*LIDER!$H$13+$K$34*LIDER!$H$14+$L$34*LIDER!$H$15,"N")) -> 0
B40: GRUPO#6 | C40: G06 | D40: =D33 -> LIST | E40: DEF | F40: =LIDER!$E$34 -> GRUPO#6
...

Sheet S-ASIG-07
A1: =LIDER!B2 -> TECNOLOGÍA EN GESTIÓN DE NEGOCIOS INTERN | I1: =LIDER!E2 -> SEMESTRE: | J1: =LIDER!F2 -> SEM-01 | K1: =LIDER!G2 -> SECCIÓN: | L1: =LIDER!H2 -> 5
B2: =LIDER!I4 -> FUNDAMENTOS ADMINISTRACIÓN | F2: CRITERIOS DE EVALUACIÓN
B3: Estudiantes | F3: =LIDER!E9 -> Calidad de la información recopilada (20%): Se evaluará la calidad de la información recopilada a través del rastreo bibliográfico por medio de fichas bibliográficas para la redacción del resumen. | G3: =LIDER!E10 -> Estructura del Documento (30%): El documento debe incluir los siguientes aspectos: Portada, Introducción, cuerpo del resumen, Bibliografía y Anexos. | H3: =LIDER!E11 -> Claridad de la información recopilada (20%): Se evaluará la claridad de la información recopilada a través del rastreo bibliográfico por medio de fichas bibliográficas para la redacción del resumen. | I3: =LIDER!E12 -> Coherencia de la información recopilada (20%): Se evaluará la coherencia de la información recopilada a través del rastreo de fichas de revisión bibliográfica para la redacción del resumen. | J3: =LIDER!E13 -> Asesorias individuales (10%): Anexo de la hoja de tutoria firmada por docentes del colectivo (3 fimas minimo). | K3: =LIDER!E14 -> 0 | L3: =LIDER!E15 -> 0
