Workbook

Sheet LIDER
B2: TECNOLOGÍA EN GESTIÓN DE NEGOCIOS INTERN | E2: SEMESTRE: | F2: SEM-04 | G2: SECCIÓN: | H2: 2
C3: LIDER | D3: METODOLÓGICO | E3: DISCIPLINAR#3 | F3: DISCIPLINAR#4 | G3: DISCIPLINAR#5 | H3: DISCIPLINAR#6 | I3: DISCIPLINAR#7
C4: ELECTIVA DE PROFUNDIZACION I | D4: ETICA | E4: IMPORTACIONES Y EXPORTACIONES | F4: ESTADÍSTICA | G4: FUNDAMENTOS DE MERCADEO | H4: FUNDAMENTOS DE FINANZAS
C5: SANDRA MILENA CASTAÑO GIRALDO | D5: LEIDY ENID QUINTERO SÁNCHEZ | E5: JEYSSON STEEVEN ANILLO CARRANZA | F5: ANTONIO OSPINO RODRIGUEZ | G5: GABRIEL EDUARDO CARDONA TUÑON | H5: LEONARDO CARLOS DE ORO BARRIOS
C6: 2413 | D6: 2401 | E6: 1480 | F6: 1924 | G6: 1397 | H6: 1512
C8: LISTA DE ESTUDIANTES | E8: SEGUNDA ENTREGA - CRITERIO DE EVALUACIÓN DOCUMENTO - SEGUNDO CORTE | H8: PONDERACIÓN | I8: ADMINISTRACIÓN DE EMPRESAS C.I
B9: 1 | C9: BARRIOS BENITEZ EMILY | E9: PRESENTACIÓN GENERAL: Adopta la norma APA, tamaño de la hoja, margenes, titulo, portadas, numeración de paginas, tabla de contenido automatizada, ortografia, justificacion del texto, citas automatizadas, listas, figuras,etc. | H9: 0.2 | I9: ADMINTRACIÓN EN SEGURIDAD Y SALUD EN EL TRABAJO
B10: 2 | C10: BARRIOS CUADRADO HEILIN TATIANA | E10: ANTEPROYECTO: Portada, planteamiento del problema, justificacion del trabajo o proyecto de aula, objetivos, marco teorico, diseño metodologico. | H10: 0.2 | I10: CONTADURÍA PÚBLICA
B11: 3 | C11: CARMONA SIERRA YIRLEIS PATRICIA | E11: RESULTADOS: Analiza, integra y aplica de manera coherente los aspectos del análisis del entorno(Variables Macroeconómicas, Factores Sociales y Culturales, Factores Políticos y Legales,Factores Tecnológicos y Factores Ambientales) en el desarrollo de la propuesta investigativa, evidenciando capacidad para generar soluciones viables, pertinentes y sostenibles. | H11: 0.3 | I11: NEGOCIOS INTERNACIONALES PROFESIONAL
B12: 4 | C12: CASTILLO VILLA NELDA SOFIA | E12: BILIOGRAFIA: Las referencias bibliograficas adoptan las normas APA. El documento es producto de un rastreo bibliografico que muestra analisis y sistensis. | H12: 0.2 | I12: TECNOLOGÍA EN GESTIÓN DE NEGOCIOS INTERN
B13: 5 | C13: CASUSOL RODRIGUEZ AYLIN MARIANA | E13: ASESORIAS: Anexó la hoja de tutoria firmada ( 3 fimas minmimo). | H13: 0.1 | I13: TECNOLOGíA EN GESTION CONTABLE
B14: 6 | C14: CHAVEZ ARRIETA EVELYN SHARY | H14: 0 | I14: TECNOLOGÍA EN GESTIÓN DE MARKETING
B15: 7 | C15: DE ARCOS AVENDAÑO SAID JADITH | H15: 0 | I15: TECNOLOGÍA EN GESTIÓN DEL TALENTO HUMANO
B16: 8 | C16: DONADO ALMANZA DAVID | H16: =IF(SUM(H9:H15)>1,"Más del 100%",SUM(H9:H15)) -> 1 | I16: TECNOLOGÍA EN GESTIÓN FINANCIERA
B17: 9 | C17: ESMERAL CORDERO NORIETH CAROLINA | I17: TECNOLOGÍA EN GESTIÓN LOGISTICA Y PORTUARIA
B18: 10 | C18: GARCIA MATUTE VALERIE DANIELA | E18: ENTREGA FINAL - CRITERIO DE EVALUACIÓN SUSTENTACIÓN - TERCER CORTE | H18: PONDERACIÓN | I18: TECNOLOGÍA EN GESTIÓN TURISTICA Y HOTELERA
B19: 11 | C19: GOMEZ JULIO LUIS DANIEL | E19: Evaluación del Documento Final | H19: 0.5
B20: 12 | C20: HERRERA DIAZ OSCAR JOSUE | E20: Sustentación de los Resultados: Se refleja un dominio del tema, la información está delimitada y es clara. Hay una jerarquía y fluidez en las ideas que presenta. | H20: 0.2
B21: 13 | C21: HERRERA TEJEDOR BRENDIS VANESA | E21: Expresión Oral: Se oberva buena vocalización y buen tono de voz durante toda la presentación empleando un lenguaje técnico pertinente con su nivel academico. Su discurso es adecuado en la presentacion de la sustentación de los resultados | H21: 0.1
B22: 14 | C22: JACOME PERALTA DIEGO | E22: Lenguaje no verbal: Tiene una adecuada presentación personal para la ocación, opta por una buena postura y demuestra seguridad en sí mismo(a) durante la sustentación de los resultados. Además, demuestra asertividad y seguridad en las orientaciones o preguntas que hace el colectivo docente | H22: 0.05
B23: 15 | C23: MADRID BORDA JESUS ALBERTO | E23: Tiempo: El uso del tiempo fue apropiado, se ajusta al previsto. Ofrece una conclusión donde condensa las ideas principales del objetivo general y los específicos. | H23: 0.05
B24: 16 | C24: MAGALLANES PEDROZA VALENTINA | E24: Uso de Recursos Audiovisuales Tecnológicos: La sustentación se acompaña de recursos visuales pertinentes, atractivos y de gran calidad | H24: 0.1
B25: 17 | C25: MANJARRES CORREA PAULA ANDREA
B26: 18 | C26: MARTINEZ JULIO YEMILY ALBANIS | H26: =IF(SUM(H19:H25)>1,"Más del 100%",SUM(H19:H25)) -> 1
B27: 19 | C27: MENDOZA MUÑOZ MATEO JAVIER
B28: 20 | C28: MOLINA PÁJARO MARIA DE LOS ÁNGELES | E28: TITULOS DE LOS PROYECTOS DE AULA
B29: 21 | C29: NARVAEZ MORELO WISNEEY | E29: GRUPO#1 Vestidos de Baño en Crochet (Brazil, Estados Unidos y República Dominicana)
B30: 22 | C30: PADILLA MORALES VALERIE SOFIA | E30: GRUPO#2 VINO DE MARACUYA, CHILE , PANAMA Y ESTADOS UNDOS)
B31: 23 | C31: PÁJARO DE LA PEÑA ANGELA ISABEL | E31: GRUPO#3 TRAJES DE BAÑO PARA PERSONAS DE CONTEXTURA GRUESA (
B32: 24 | C32: PEREZ MORENO ANA ISABEL | E32: GRUPO#4 KITS PICKNIC ESPAÑA, BRAZIL Y PERU
B33: 25 | C33: PÉREZ TORRES BRISNEY ALEJANDRA | E33: GRUPO#5 HAMACAS INTERNACIONALES CON COJINES ESTADOS UNIDOS, SUECIA Y ESPAÑA
B34: 26 | C34: RODRIGUEZ ARCIA MARICRUZ | E34: GRUPO#6 COSMETICOS A BASE DE CAFE , ESPAÑA , ESTADOS UNIDOS, CANADA
B35: 27 | C35: RUIZ RIVERO HEILEEN CAROLINA | E35: GRUPO#7
B36: 28 | C36: GOMEZ PINEDA DIEGO ALEJANDRO | E36: GRUPO#8
B37: 29 | C37: ZUÑIGA ARANGO NICOLAS | E37: GRUPO#9
B38: 30 | C38: MARTINEZ SARMIENTO ISAAC DAVID | E38: GRUPO#10
B39: 31 | C39: LOPEZ NAVARRO LUIS ENRIQUE | E39: GRUPO#11
B40: 32 | E40: GRUPO#12
B41: 33
B42: 34 | E42: =MID(E29,1,20) -> GRUPO#1 Vestidos de | F42: =MID(E30,1,20) -> GRUPO#2 VINO DE MAR | G42: =MID(E31,1,20) -> GRUPO#3 TRAJES DE B | H42: =MID(E32,1,20) -> GRUPO#4 KITS PICKNI
...

Sheet S-ASIG-01
A1: =LIDER!B2 -> TECNOLOGÍA EN GESTIÓN DE NEGOCIOS INTERN | I1: =LIDER!E2 -> SEMESTRE: | J1: =LIDER!F2 -> SEM-04 | K1: =LIDER!G2 -> SECCIÓN: | L1: =LIDER!H2 -> 2
B2: =LIDER!C4 -> ELECTIVA DE PROFUNDIZACION I | F2: CRITERIOS DE EVALUACIÓN
B3: Estudiantes | F3: =LIDER!E9 -> PRESENTACIÓN GENERAL: Adopta la norma APA, tamaño de la hoja, margenes, titulo, portadas, numeración de paginas, tabla de contenido automatizada, ortografia, justificacion del texto, citas automatizadas, listas, figuras,etc. | G3: =LIDER!E10 -> ANTEPROYECTO: Portada, planteamiento del problema, justificacion del trabajo o proyecto de aula, objetivos, marco teorico, diseño metodologico. | H3: =LIDER!E11 -> RESULTADOS: Analiza, integra y aplica de manera coherente los aspectos del análisis del entorno(Variables Macroeconómicas, Factores Sociales y Culturales, Factores Políticos y Legales,Factores Tecnológicos y Factores Ambientales) en el desarrollo de la propuesta investigativa, evidenciando capacidad para generar soluciones viables, pertinentes y sostenibles. | I3: =LIDER!E12 -> BILIOGRAFIA: Las referencias bibliograficas adoptan las normas APA. El documento es producto de un rastreo bibliografico que muestra analisis y sistensis. | J3: =LIDER!E13 -> ASESORIAS: Anexó la hoja de tutoria firmada ( 3 fimas minmimo). | K3: =LIDER!E14 -> 0 | L3: =LIDER!E15 -> 0
F4: =CONCATENATE(LIDER!C4," - ",LIDER!C6," - ",LIDER!C5) -> ELECTIVA DE PROFUNDIZACION I - 2413 - SANDRA MILENA CASTAÑO GIRALDO
B5: GRUPO#1 | C5: G01 | D5: LIST | E5: DEF | F5: =LIDER!$E$29 -> GRUPO#1 Vestidos de Baño en Crochet (Brazil, Estados Unidos y República Dominicana)
A6: 1 | B6: =LIDER!E43 -> BARRIOS BENITEZ EMILY | C6: =C5 -> G01 | E6: =IF(B6=0,0,IF(D6="",$F$6*LIDER!$H$9+$G$6*LIDER!$H$10+$H$6*LIDER!$H$11+$I$6*LIDER!$H$12+$J$6*LIDER!$H$13+$K$6*LIDER!$H$14+$L$6*LIDER!$H$15,"N")) -> 4.45 | F6: 4 | G6: 4 | H6: 4.5 | I6: 5 | J6: 5
A7: 2 | B7: =LIDER!E44 -> HERRERA TEJEDOR BRENDIS VANESA | C7: =C6 -> G01 | E7: =IF(B7=0,0,IF(D7="",$F$6*LIDER!$H$9+$G$6*LIDER!$H$10+$H$6*LIDER!$H$11+$I$6*LIDER!$H$12+$J$6*LIDER!$H$13+$K$6*LIDER!$H$14+$L$6*LIDER!$H$15,"N")) -> 4.45
A8: 3 | B8: =LIDER!E45 -> RUIZ RIVERO HEILEEN CAROLINA | C8: =C7 -> G01 | E8: =IF(B8=0,0,IF(D8="",$F$6*LIDER!$H$9+$G$6*LIDER!$H$10+$H$6*LIDER!$H$11+$I$6*LIDER!$H$12+$J$6*LIDER!$H$13+$K$6*LIDER!$H$14+$L$6*LIDER!$H$15,"N")) -> 4.45
A9: 4 | B9: =LIDER!E46 -> DE ARCOS AVENDAÑO SAID JADITH | C9: =C8 -> G01 | E9: =IF(B9=0,0,IF(D9="",$F$6*LIDER!$H$9+$G$6*LIDER!$H$10+$H$6*LIDER!$H$11+$I$6*LIDER!$H$12+$J$6*LIDER!$H$13+$K$6*LIDER!$H$14+$L$6*LIDER!$H$15,"N")) -> 4.45
A10: 5 | B10: =LIDER!E47 -> CASTILLO VILLA NELDA SOFIA | C10: =C9 -> G01 | E10: =IF(B10=0,0,IF(D10="",$F$6*LIDER!$H$9+$G$6*LIDER!$H$10+$H$6*LIDER!$H$11+$I$6*LIDER!$H$12+$J$6*LIDER!$H$13+$K$6*LIDER!$H$14+$L$6*LIDER!$H$15,"N")) -> 4.45
A11: 6 | B11: =LIDER!E48 -> 0 | C11: =C10 -> G01 | E11: =IF(B11=0,0,IF(D11="",$F$6*LIDER!$H$9+$G$6*LIDER!$H$10+$H$6*LIDER!$H$11+$I$6*LIDER!$H$12+$J$6*LIDER!$H$13+$K$6*LIDER!$H$14+$L$6*LIDER!$H$15,"N")) -> 0
B12: GRUPO#2 | C12: G02 | D12: =D5 -> LIST | E12: DEF | F12: =LIDER!$E$30 -> GRUPO#2 VINO DE MARACUYA, CHILE , PANAMA Y ESTADOS UNDOS)
A13: 1 | B13: =LIDER!F43 -> NARVAEZ MORELO WISNEEY | C13: =C12 -> G02 | E13: =IF(B13=0,0,IF(D13="",$F$13*LIDER!$H$9+$G$13*LIDER!$H$10+$H$13*LIDER!$H$11+$I$13*LIDER!$H$12+$J$13*LIDER!$H$13+$K$13*LIDER!$H$14+$L$13*LIDER!$H$15,"N")) -> 4.35 | F13: 4.5 | G13: 4 | H13: 4.5 | I13: 4 | J13: 5
A14: 2 | B14: =LIDER!F44 -> CASUSOL RODRIGUEZ AYLIN MARIANA | C14: =C13 -> G02 | E14: =IF(B14=0,0,IF(D14="",$F$13*LIDER!$H$9+$G$13*LIDER!$H$10+$H$13*LIDER!$H$11+$I$13*LIDER!$H$12+$J$13*LIDER!$H$13+$K$13*LIDER!$H$14+$L$13*LIDER!$H$15,"N")) -> 4.35
A15: 3 | B15: =LIDER!F45 -> CARMONA SIERRA YIRLEIS PATRICIA | C15: =C14 -> G02 | E15: =IF(B15=0,0,IF(D15="",$F$13*LIDER!$H$9+$G$13*LIDER!$H$10+$H$13*LIDER!$H$11+$I$13*LIDER!$H$12+$J$13*LIDER!$H$13+$K$13*LIDER!$H$14+$L$13*LIDER!$H$15,"N")) -> 4.35
A16: 4 | B16: =LIDER!F46 -> MAGALLANES PEDROZA VALENTINA | C16: =C15 -> G02 | E16: =IF(B16=0,0,IF(D16="",$F$13*LIDER!$H$9+$G$13*LIDER!$H$10+$H$13*LIDER!$H$11+$I$13*LIDER!$H$12+$J$13*LIDER!$H$13+$K$13*LIDER!$H$14+$L$13*LIDER!$H$15,"N")) -> 4.35
A17: 5 | B17: =LIDER!F47 -> MOLINA PÁJARO MARIA DE LOS ÁNGELES | C17: =C16 -> G02 | E17: =IF(B17=0,0,IF(D17="",$F$13*LIDER!$H$9+$G$13*LIDER!$H$10+$H$13*LIDER!$H$11+$I$13*LIDER!$H$12+$J$13*LIDER!$H$13+$K$13*LIDER!$H$14+$L$13*LIDER!$H$15,"N")) -> 4.35
A18: 6 | B18: =LIDER!F48 -> ESMERAL CORDERO NORIETH CAROLINA | C18: =C17 -> G02 | E18: =IF(B18=0,0,IF(D18="",$F$13*LIDER!$H$9+$G$13*LIDER!$H$10+$H$13*LIDER!$H$11+$I$13*LIDER!$H$12+$J$13*LIDER!$H$13+$K$13*LIDER!$H$14+$L$13*LIDER!$H$15,"N")) -> 4.35
B19: GRUPO#3 | C19: G03 | D19: =D12 -> LIST | E19: DEF | F19: =LIDER!$E$31 -> GRUPO#3 TRAJES DE BAÑO PARA PERSONAS DE CONTEXTURA GRUESA (
A20: 1 | B20: =LIDER!G43 -> CHAVEZ ARRIETA EVELYN SHARY | C20: =C19 -> G03 | E20: =IF(B20=0,0,IF(D20="",$F$20*LIDER!$H$9+$G$20*LIDER!$H$10+$H$20*LIDER!$H$11+$I$20*LIDER!$H$12+$J$20*LIDER!$H$13+$K$20*LIDER!$H$14+$L$20*LIDER!$H$15,"N")) -> 3.46 | F20: 4 | G20: 4 | H20: 4.2 | I20: 3 | J20: 0
A21: 2 | B21: =LIDER!G44 -> PEREZ MORENO ANA ISABEL | C21: =C20 -> G03 | E21: =IF(B21=0,0,IF(D21="",$F$20*LIDER!$H$9+$G$20*LIDER!$H$10+$H$20*LIDER!$H$11+$I$20*LIDER!$H$12+$J$20*LIDER!$H$13+$K$20*LIDER!$H$14+$L$20*LIDER!$H$15,"N")) -> 3.46
A22: 3 | B22: =LIDER!G45 -> PÁJARO DE LA PEÑA ANGELA ISABEL | C22: =C21 -> G03 | E22: =IF(B22=0,0,IF(D22="",$F$20*LIDER!$H$9+$G$20*LIDER!$H$10+$H$20*LIDER!$H$11+$I$20*LIDER!$H$12+$J$20*LIDER!$H$13+$K$20*LIDER!$H$14+$L$20*LIDER!$H$15,"N")) -> 3.46
A23: 4 | B23: =LIDER!G46 -> 0 | C23: =C22 -> G03 | E23: =IF(B23=0,0,IF(D23="",$F$20*LIDER!$H$9+$G$20*LIDER!$H$10+$H$20*LIDER!$H$11+$I$20*LIDER!$H$12+$J$20*LIDER!$H$13+$K$20*LIDER!$H$14+$L$20*LIDER!$H$15,"N")) -> 0
A24: 5 | B24: =LIDER!G47 -> 0 | C24: =C23 -> G03 | E24: =IF(B24=0,0,IF(D24="",$F$20*LIDER!$H$9+$G$20*LIDER!$H$10+$H$20*LIDER!$H$11+$I$20*LIDER!$H$12+$J$20*LIDER!$H$13+$K$20*LIDER!$H$14+$L$20*LIDER!$H$15,"N")) -> 0
A25: 6 | B25: =LIDER!G48 -> 0 | C25: =C24 -> G03 | E25: =IF(B25=0,0,IF(D25="",$F$20*LIDER!$H$9+$G$20*LIDER!$H$10+$H$20*LIDER!$H$11+$I$20*LIDER!$H$12+$J$20*LIDER!$H$13+$K$20*LIDER!$H$14+$L$20*LIDER!$H$15,"N")) -> 0
B26: GRUPO#4 | C26: G04 | D26: =D19 -> LIST | E26: DEF | F26: =LIDER!$E$32 -> GRUPO#4 KITS PICKNIC ESPAÑA, BRAZIL Y PERU
A27: 1 | B27: =LIDER!H43 -> BARRIOS CUADRADO HEILIN TATIANA | C27: =C26 -> G04 | E27: =IF(B27=0,0,IF(D27="",$F$27*LIDER!$H$9+$G$27*LIDER!$H$10+$H$27*LIDER!$H$11+$I$27*LIDER!$H$12+$J$27*LIDER!$H$13+$K$27*LIDER!$H$14+$L$27*LIDER!$H$15,"N")) -> 3.72 | F27: 4 | G27: 3.8 | H27: 4.2 | I27: 3 | J27: 3
A28: 2 | B28: =LIDER!H44 -> MARTINEZ JULIO YEMILY ALBANIS | C28: =C27 -> G04 | E28: =IF(B28=0,0,IF(D28="",$F$27*LIDER!$H$9+$G$27*LIDER!$H$10+$H$27*LIDER!$H$11+$I$27*LIDER!$H$12+$J$27*LIDER!$H$13+$K$27*LIDER!$H$14+$L$27*LIDER!$H$15,"N")) -> 3.72
A29: 3 | B29: =LIDER!H45 -> MANJARRES CORREA PAULA ANDREA | C29: =C28 -> G04 | E29: =IF(B29=0,0,IF(D29="",$F$27*LIDER!$H$9+$G$27*LIDER!$H$10+$H$27*LIDER!$H$11+$I$27*LIDER!$H$12+$J$27*LIDER!$H$13+$K$27*LIDER!$H$14+$L$27*LIDER!$H$15,"N")) -> 3.72
A30: 4 | B30: =LIDER!H46 -> GARCIA MATUTE VALERIE DANIELA | C30: =C29 -> G04 | E30: =IF(B30=0,0,IF(D30="",$F$27*LIDER!$H$9+$G$27*LIDER!$H$10+$H$27*LIDER!$H$11+$I$27*LIDER!$H$12+$J$27*LIDER!$H$13+$K$27*LIDER!$H$14+$L$27*LIDER!$H$15,"N")) -> 3.72
A31: 5 | B31: =LIDER!H47 -> 0 | C31: =C30 -> G04 | E31: =IF(B31=0,0,IF(D31="",$F$27*LIDER!$H$9+$G$27*LIDER!$H$10+$H$27*LIDER!$H$11+$I$27*LIDER!$H$12+$J$27*LIDER!$H$13+$K$27*LIDER!$H$14+$L$27*LIDER!$H$15,"N")) -> 0
A32: 6 | B32: =LIDER!H48 -> 0 | C32: =C31 -> G04 | E32: =IF(B32=0,0,IF(D32="",$F$27*LIDER!$H$9+$G$27*LIDER!$H$10+$H$27*LIDER!$H$11+$I$27*LIDER!$H$12+$J$27*LIDER!$H$13+$K$27*LIDER!$H$14+$L$27*LIDER!$H$15,"N")) -> 0
B33: GRUPO#5 | C33: G05 | D33: =D26 -> LIST | E33: DEF | F33: =LIDER!$E$33 -> GRUPO#5 HAMACAS INTERNACIONALES CON COJINES ESTADOS UNIDOS, SUECIA Y ESPAÑA
A34: 1 | B34: =LIDER!E51 -> PADILLA MORALES VALERIE SOFIA | C34: =C33 -> G05 | E34: =IF(B34=0,0,IF(D34="",$F$34*LIDER!$H$9+$G$34*LIDER!$H$10+$H$34*LIDER!$H$11+$I$34*LIDER!$H$12+$J$34*LIDER!$H$13+$K$34*LIDER!$H$14+$L$34*LIDER!$H$15,"N")) -> 4.59 | F34: 4.5 | G34: 4.5 | H34: 4.3 | I34: 5 | J34: 5
A35: 2 | B35: =LIDER!E52 -> RODRIGUEZ ARCIA MARICRUZ | C35: =C34 -> G05 | E35: =IF(B35=0,0,IF(D35="",$F$34*LIDER!$H$9+$G$34*LIDER!$H$10+$H$34*LIDER!$H$11+$I$34*LIDER!$H$12+$J$34*LIDER!$H$13+$K$34*LIDER!$H$14+$L$34*LIDER!$H$15,"N")) -> 4.59
A36: 3 | B36: =LIDER!E53 -> DONADO ALMANZA DAVID | C36: =C35 -> G05 | E36: =IF(B36=0,0,IF(D36="",$F$34*LIDER!$H$9+$G$34*LIDER!$H$10+$H$34*LIDER!$H$11+$I$34*LIDER!$H$12+$J$34*LIDER!$H$13+$K$34*LIDER!$H$14+$L$34*LIDER!$H$15,"N")) -> 4.59
A37: 4 | B37: =LIDER!E54 -> 0 | C37: =C36 -> G05 | E37: =IF(B37=0,0,IF(D37="",$F$34*LIDER!$H$9+$G$34*LIDER!$H$10+$H$34*LIDER!$H$11+$I$34*LIDER!$H$12+$J$34*LIDER!$H$13+$K$34*LIDER!$H$14+$L$34*LIDER!$H$15,"N")) -> 0
A38: 5 | B38: =LIDER!E55 -> 0 | C38: =C37 -> G05 | E38: =IF(B38=0,0,IF(D38="",$F$34*LIDER!$H$9+$G$34*LIDER!$H$10+$H$34*LIDER!$H$11+$I$34*LIDER!$H$12+$J$34*LIDER!$H$13+$K$34*LIDER!$H$14+$L$34*LIDER!$H$15,"N")) -> 0
A39: 6 | B39: =LIDER!E56 -> 0 | C39: =C38 -> G05 | E39: =IF(B39=0,0,IF(D39="",$F$34*LIDER!$H$9+$G$34*LIDER!$H$10+$H$34*LIDER!$H$11+$I$34*LIDER!$H$12+$J$34*LIDER!$H$13+$K$34*LIDER!$H$14+$L$34*LIDER!$H$15,"N")) -> 0
B40: GRUPO#6 | C40: G06 | D40: =D33 -> LIST | E40: DEF | F40: =LIDER!$E$34 -> GRUPO#6 COSMETICOS A BASE DE CAFE , ESPAÑA , ESTADOS UNIDOS, CANADA
...

Sheet S-ASIG-02
A1: =LIDER!B2 -> TECNOLOGÍA EN GESTIÓN DE NEGOCIOS INTERN | I1: =LIDER!E2 -> SEMESTRE: | J1: =LIDER!F2 -> SEM-04 | K1: =LIDER!G2 -> SECCIÓN: | L1: =LIDER!H2 -> 2
B2: =LIDER!D4 -> ETICA | F2: CRITERIOS DE EVALUACIÓN
B3: Estudiantes | F3: =LIDER!E9 -> PRESENTACIÓN GENERAL: Adopta la norma APA, tamaño de la hoja, margenes, titulo, portadas, numeración de paginas, tabla de contenido automatizada, ortografia, justificacion del texto, citas automatizadas, listas, figuras,etc. | G3: =LIDER!E10 -> ANTEPROYECTO: Portada, planteamiento del problema, justificacion del trabajo o proyecto de aula, objetivos, marco teorico, diseño metodologico. | H3: =LIDER!E11 -> RESULTADOS: Analiza, integra y aplica de manera coherente los aspectos del análisis del entorno(Variables Macroeconómicas, Factores Sociales y Culturales, Factores Políticos y Legales,Factores Tecnológicos y Factores Ambientales) en el desarrollo de la propuesta investigativa, evidenciando capacidad para generar soluciones viables, pertinentes y sostenibles. | I3: =LIDER!E12 -> BILIOGRAFIA: Las referencias bibliograficas adoptan las normas APA. El documento es producto de un rastreo bibliografico que muestra analisis y sistensis. | J3: =LIDER!E13 -> ASESORIAS: Anexó la hoja de tutoria firmada ( 3 fimas minmimo). | K3: =LIDER!E14 -> 0 | L3: =LIDER!E15 -> 0
F4: =CONCATENATE(LIDER!D4," - ",LIDER!D6," - ",LIDER!D5) -> ETICA - 2401 - LEIDY ENID QUINTERO SÁNCHEZ
B5: GRUPO#1 | C5: G01 | D5: LIST | E5: DEF | F5: =LIDER!$E$29 -> GRUPO#1 Vestidos de Baño en Crochet (Brazil, Estados Unidos y República Dominicana)
A6: 1 | B6: =LIDER!E43 -> BARRIOS BENITEZ EMILY | C6: =C5 -> G01 | E6: =IF(B6=0,0,IF(D6="",$F$6*LIDER!$H$9+$G$6*LIDER!$H$10+$H$6*LIDER!$H$11+$I$6*LIDER!$H$12+$J$6*LIDER!$H$13+$K$6*LIDER!$H$14+$L$6*LIDER!$H$15,"N")) -> 4.32 | F6: 4 | G6: 3.8 | H6: 4.2 | I6: 5 | J6: 5
A7: 2 | B7: =LIDER!E44 -> HERRERA TEJEDOR BRENDIS VANESA | C7: =C6 -> G01 | E7: =IF(B7=0,0,IF(D7="",$F$6*LIDER!$H$9+$G$6*LIDER!$H$10+$H$6*LIDER!$H$11+$I$6*LIDER!$H$12+$J$6*LIDER!$H$13+$K$6*LIDER!$H$14+$L$6*LIDER!$H$15,"N")) -> 4.32
A8: 3 | B8: =LIDER!E45 -> RUIZ RIVERO HEILEEN CAROLINA | C8: =C7 -> G01 | E8: =IF(B8=0,0,IF(D8="",$F$6*LIDER!$H$9+$G$6*LIDER!$H$10+$H$6*LIDER!$H$11+$I$6*LIDER!$H$12+$J$6*LIDER!$H$13+$K$6*LIDER!$H$14+$L$6*LIDER!$H$15,"N")) -> 4.32
A9: 4 | B9: =LIDER!E46 -> DE ARCOS AVENDAÑO SAID JADITH | C9: =C8 -> G01 | E9: =IF(B9=0,0,IF(D9="",$F$6*LIDER!$H$9+$G$6*LIDER!$H$10+$H$6*LIDER!$H$11+$I$6*LIDER!$H$12+$J$6*LIDER!$H$13+$K$6*LIDER!$H$14+$L$6*LIDER!$H$15,"N")) -> 4.32
A10: 5 | B10: =LIDER!E47 -> CASTILLO VILLA NELDA SOFIA | C10: =C9 -> G01 | E10: =IF(B10=0,0,IF(D10="",$F$6*LIDER!$H$9+$G$6*LIDER!$H$10+$H$6*LIDER!$H$11+$I$6*LIDER!$H$12+$J$6*LIDER!$H$13+$K$6*LIDER!$H$14+$L$6*LIDER!$H$15,"N")) -> 4.32
A11: 6 | B11: =LIDER!E48 -> 0 | C11: =C10 -> G01 | E11: =IF(B11=0,0,IF(D11="",$F$6*LIDER!$H$9+$G$6*LIDER!$H$10+$H$6*LIDER!$H$11+$I$6*LIDER!$H$12+$J$6*LIDER!$H$13+$K$6*LIDER!$H$14+$L$6*LIDER!$H$15,"N")) -> 0
B12: GRUPO#2 | C12: G02 | D12: =D5 -> LIST | E12: DEF | F12: =LIDER!$E$30 -> GRUPO#2 VINO DE MARACUYA, CHILE , PANAMA Y ESTADOS UNDOS)
A13: 1 | B13: =LIDER!F43 -> NARVAEZ MORELO WISNEEY | C13: =C12 -> G02 | E13: =IF(B13=0,0,IF(D13="",$F$13*LIDER!$H$9+$G$13*LIDER!$H$10+$H$13*LIDER!$H$11+$I$13*LIDER!$H$12+$J$13*LIDER!$H$13+$K$13*LIDER!$H$14+$L$13*LIDER!$H$15,"N")) -> 4.2 | F13: 4 | G13: 4.5 | H13: 4 | I13: 4 | J13: 5
A14: 2 | B14: =LIDER!F44 -> CASUSOL RODRIGUEZ AYLIN MARIANA | C14: =C13 -> G02 | E14: =IF(B14=0,0,IF(D14="",$F$13*LIDER!$H$9+$G$13*LIDER!$H$10+$H$13*LIDER!$H$11+$I$13*LIDER!$H$12+$J$13*LIDER!$H$13+$K$13*LIDER!$H$14+$L$13*LIDER!$H$15,"N")) -> 4.2
A15: 3 | B15: =LIDER!F45 -> CARMONA SIERRA YIRLEIS PATRICIA | C15: =C14 -> G02 | E15: =IF(B15=0,0,IF(D15="",$F$13*LIDER!$H$9+$G$13*LIDER!$H$10+$H$13*LIDER!$H$11+$I$13*LIDER!$H$12+$J$13*LIDER!$H$13+$K$13*LIDER!$H$14+$L$13*LIDER!$H$15,"N")) -> 4.2
A16: 4 | B16: =LIDER!F46 -> MAGALLANES PEDROZA VALENTINA | C16: =C15 -> G02 | E16: =IF(B16=0,0,IF(D16="",$F$13*LIDER!$H$9+$G$13*LIDER!$H$10+$H$13*LIDER!$H$11+$I$13*LIDER!$H$12+$J$13*LIDER!$H$13+$K$13*LIDER!$H$14+$L$13*LIDER!$H$15,"N")) -> 4.2
A17: 5 | B17: =LIDER!F47 -> MOLINA PÁJARO MARIA DE LOS ÁNGELES | C17: =C16 -> G02 | E17: =IF(B17=0,0,IF(D17="",$F$13*LIDER!$H$9+$G$13*LIDER!$H$10+$H$13*LIDER!$H$11+$I$13*LIDER!$H$12+$J$13*LIDER!$H$13+$K$13*LIDER!$H$14+$L$13*LIDER!$H$15,"N")) -> 4.2
A18: 6 | B18: =LIDER!F48 -> ESMERAL CORDERO NORIETH CAROLINA | C18: =C17 -> G02 | E18: =IF(B18=0,0,IF(D18="",$F$13*LIDER!$H$9+$G$13*LIDER!$H$10+$H$13*LIDER!$H$11+$I$13*LIDER!$H$12+$J$13*LIDER!$H$13+$K$13*LIDER!$H$14+$L$13*LIDER!$H$15,"N")) -> 4.2
B19: GRUPO#3 | C19: G03 | D19: =D12 -> LIST | E19: DEF | F19: =LIDER!$E$31 -> GRUPO#3 TRAJES DE BAÑO PARA PERSONAS DE CONTEXTURA GRUESA (
A20: 1 | B20: =LIDER!G43 -> CHAVEZ ARRIETA EVELYN SHARY | C20: =C19 -> G03 | E20: =IF(B20=0,0,IF(D20="",$F$20*LIDER!$H$9+$G$20*LIDER!$H$10+$H$20*LIDER!$H$11+$I$20*LIDER!$H$12+$J$20*LIDER!$H$13+$K$20*LIDER!$H$14+$L$20*LIDER!$H$15,"N")) -> 2.96 | F20: 3.8 | G20: 4 | H20: 3 | I20: 2.5 | J20: 0
A21: 2 | B21: =LIDER!G44 -> PEREZ MORENO ANA ISABEL | C21: =C20 -> G03 | E21: =IF(B21=0,0,IF(D21="",$F$20*LIDER!$H$9+$G$20*LIDER!$H$10+$H$20*LIDER!$H$11+$I$20*LIDER!$H$12+$J$20*LIDER!$H$13+$K$20*LIDER!$H$14+$L$20*LIDER!$H$15,"N")) -> 2.96
A22: 3 | B22: =LIDER!G45 -> PÁJARO DE LA PEÑA ANGELA ISABEL | C22: =C21 -> G03 | E22: =IF(B22=0,0,IF(D22="",$F$20*LIDER!$H$9+$G$20*LIDER!$H$10+$H$20*LIDER!$H$11+$I$20*LIDER!$H$12+$J$20*LIDER!$H$13+$K$20*LIDER!$H$14+$L$20*LIDER!$H$15,"N")) -> 2.96
A23: 4 | B23: =LIDER!G46 -> 0 | C23: =C22 -> G03 | E23: =IF(B23=0,0,IF(D23="",$F$20*LIDER!$H$9+$G$20*LIDER!$H$10+$H$20*LIDER!$H$11+$I$20*LIDER!$H$12+$J$20*LIDER!$H$13+$K$20*LIDER!$H$14+$L$20*LIDER!$H$15,"N")) -> 0
A24: 5 | B24: =LIDER!G47 -> 0 | C24: =C23 -> G03 | E24: =IF(B24=0,0,IF(D24="",$F$20*LIDER!$H$9+$G$20*LIDER!$H$10+$H$20*LIDER!$H$11+$I$20*LIDER!$H$12+$J$20*LIDER!$H$13+$K$20*LIDER!$H$14+$L$20*LIDER!$H$15,"N")) -> 0
A25: 6 | B25: =LIDER!G48 -> 0 | C25: =C24 -> G03 | E25: =IF(B25=0,0,IF(D25="",$F$20*LIDER!$H$9+$G$20*LIDER!$H$10+$H$20*LIDER!$H$11+$I$20*LIDER!$H$12+$J$20*LIDER!$H$13+$K$20*LIDER!$H$14+$L$20*LIDER!$H$15,"N")) -> 0
B26: GRUPO#4 | C26: G04 | D26: =D19 -> LIST | E26: DEF | F26: =LIDER!$E$32 -> GRUPO#4 KITS PICKNIC ESPAÑA, BRAZIL Y PERU
A27: 1 | B27: =LIDER!H43 -> BARRIOS CUADRADO HEILIN TATIANA | C27: =C26 -> G04 | E27: =IF(B27=0,0,IF(D27="",$F$27*LIDER!$H$9+$G$27*LIDER!$H$10+$H$27*LIDER!$H$11+$I$27*LIDER!$H$12+$J$27*LIDER!$H$13+$K$27*LIDER!$H$14+$L$27*LIDER!$H$15,"N")) -> 3.5 | F27: 3.8 | G27: 3.5 | H27: 3.8 | I27: 3 | J27: 3
A28: 2 | B28: =LIDER!H44 -> MARTINEZ JULIO YEMILY ALBANIS | C28: =C27 -> G04 | E28: =IF(B28=0,0,IF(D28="",$F$27*LIDER!$H$9+$G$27*LIDER!$H$10+$H$27*LIDER!$H$11+$I$27*LIDER!$H$12+$J$27*LIDER!$H$13+$K$27*LIDER!$H$14+$L$27*LIDER!$H$15,"N")) -> 3.5
A29: 3 | B29: =LIDER!H45 -> MANJARRES CORREA PAULA ANDREA | C29: =C28 -> G04 | E29: =IF(B29=0,0,IF(D29="",$F$27*LIDER!$H$9+$G$27*LIDER!$H$10+$H$27*LIDER!$H$11+$I$27*LIDER!$H$12+$J$27*LIDER!$H$13+$K$27*LIDER!$H$14+$L$27*LIDER!$H$15,"N")) -> 3.5
A30: 4 | B30: =LIDER!H46 -> GARCIA MATUTE VALERIE DANIELA | C30: =C29 -> G04 | E30: =IF(B30=0,0,IF(D30="",$F$27*LIDER!$H$9+$G$27*LIDER!$H$10+$H$27*LIDER!$H$11+$I$27*LIDER!$H$12+$J$27*LIDER!$H$13+$K$27*LIDER!$H$14+$L$27*LIDER!$H$15,"N")) -> 3.5
A31: 5 | B31: =LIDER!H47 -> 0 | C31: =C30 -> G04 | E31: =IF(B31=0,0,IF(D31="",$F$27*LIDER!$H$9+$G$27*LIDER!$H$10+$H$27*LIDER!$H$11+$I$27*LIDER!$H$12+$J$27*LIDER!$H$13+$K$27*LIDER!$H$14+$L$27*LIDER!$H$15,"N")) -> 0
A32: 6 | B32: =LIDER!H48 -> 0 | C32: =C31 -> G04 | E32: =IF(B32=0,0,IF(D32="",$F$27*LIDER!$H$9+$G$27*LIDER!$H$10+$H$27*LIDER!$H$11+$I$27*LIDER!$H$12+$J$27*LIDER!$H$13+$K$27*LIDER!$H$14+$L$27*LIDER!$H$15,"N")) -> 0
B33: GRUPO#5 | C33: G05 | D33: =D26 -> LIST | E33: DEF | F33: =LIDER!$E$33 -> GRUPO#5 HAMACAS INTERNACIONALES CON COJINES ESTADOS UNIDOS, SUECIA Y ESPAÑA
A34: 1 | B34: =LIDER!E51 -> PADILLA MORALES VALERIE SOFIA | C34: =C33 -> G05 | E34: =IF(B34=0,0,IF(D34="",$F$34*LIDER!$H$9+$G$34*LIDER!$H$10+$H$34*LIDER!$H$11+$I$34*LIDER!$H$12+$J$34*LIDER!$H$13+$K$34*LIDER!$H$14+$L$34*LIDER!$H$15,"N")) -> 4.46 | F34: 4.4 | G34: 4.4 | H34: 4 | I34: 5 | J34: 5
A35: 2 | B35: =LIDER!E52 -> RODRIGUEZ ARCIA MARICRUZ | C35: =C34 -> G05 | E35: =IF(B35=0,0,IF(D35="",$F$34*LIDER!$H$9+$G$34*LIDER!$H$10+$H$34*LIDER!$H$11+$I$34*LIDER!$H$12+$J$34*LIDER!$H$13+$K$34*LIDER!$H$14+$L$34*LIDER!$H$15,"N")) -> 4.46
A36: 3 | B36: =LIDER!E53 -> DONADO ALMANZA DAVID | C36: =C35 -> G05 | E36: =IF(B36=0,0,IF(D36="",$F$34*LIDER!$H$9+$G$34*LIDER!$H$10+$H$34*LIDER!$H$11+$I$34*LIDER!$H$12+$J$34*LIDER!$H$13+$K$34*LIDER!$H$14+$L$34*LIDER!$H$15,"N")) -> 4.46
A37: 4 | B37: =LIDER!E54 -> 0 | C37: =C36 -> G05 | E37: =IF(B37=0,0,IF(D37="",$F$34*LIDER!$H$9+$G$34*LIDER!$H$10+$H$34*LIDER!$H$11+$I$34*LIDER!$H$12+$J$34*LIDER!$H$13+$K$34*LIDER!$H$14+$L$34*LIDER!$H$15,"N")) -> 0
A38: 5 | B38: =LIDER!E55 -> 0 | C38: =C37 -> G05 | E38: =IF(B38=0,0,IF(D38="",$F$34*LIDER!$H$9+$G$34*LIDER!$H$10+$H$34*LIDER!$H$11+$I$34*LIDER!$H$12+$J$34*LIDER!$H$13+$K$34*LIDER!$H$14+$L$34*LIDER!$H$15,"N")) -> 0
A39: 6 | B39: =LIDER!E56 -> 0 | C39: =C38 -> G05 | E39: =IF(B39=0,0,IF(D39="",$F$34*LIDER!$H$9+$G$34*LIDER!$H$10+$H$34*LIDER!$H$11+$I$34*LIDER!$H$12+$J$34*LIDER!$H$13+$K$34*LIDER!$H$14+$L$34*LIDER!$H$15,"N")) -> 0
B40: GRUPO#6 | C40: G06 | D40: =D33 -> LIST | E40: DEF | F40: =LIDER!$E$34 -> GRUPO#6 COSMETICOS A BASE DE CAFE , ESPAÑA , ESTADOS UNIDOS, CANADA
...

Sheet S-ASIG-03
A1: =LIDER!B2 -> TECNOLOGÍA EN GESTIÓN DE NEGOCIOS INTERN | I1: =LIDER!E2 -> SEMESTRE: | J1: =LIDER!F2 -> SEM-04 | K1: =LIDER!G2 -> SECCIÓN: | L1: =LIDER!H2 -> 2
B2: =LIDER!E4 -> IMPORTACIONES Y EXPORTACIONES | F2: CRITERIOS DE EVALUACIÓN
B3: Estudiantes | F3: =LIDER!E9 -> PRESENTACIÓN GENERAL: Adopta la norma APA, tamaño de la hoja, margenes, titulo, portadas, numeración de paginas, tabla de contenido automatizada, ortografia, justificacion del texto, citas automatizadas, listas, figuras,etc. | G3: =LIDER!E10 -> ANTEPROYECTO: Portada, planteamiento del problema, justificacion del trabajo o proyecto de aula, objetivos, marco teorico, diseño metodologico. | H3: =LIDER!E11 -> RESULTADOS: Analiza, integra y aplica de manera coherente los aspectos del análisis del entorno(Variables Macroeconómicas, Factores Sociales y Culturales, Factores Políticos y Legales,Factores Tecnológicos y Factores Ambientales) en el desarrollo de la propuesta investigativa, evidenciando capacidad para generar soluciones viables, pertinentes y sostenibles. | I3: =LIDER!E12 -> BILIOGRAFIA: Las referencias bibliograficas adoptan las normas APA. El documento es producto de un rastreo bibliografico que muestra analisis y sistensis. | J3: =LIDER!E13 -> ASESORIAS: Anexó la hoja de tutoria firmada ( 3 fimas minmimo). | K3: =LIDER!E14 -> 0 | L3: =LIDER!E15 -> 0
F4: =CONCATENATE(LIDER!E4," - ",LIDER!E6," - ",LIDER!E5) -> IMPORTACIONES Y EXPORTACIONES - 1480 - JEYSSON STEEVEN ANILLO CARRANZA
B5: GRUPO#1 | C5: G01 | D5: LIST | E5: DEF | F5: =LIDER!$E$29 -> GRUPO#1 Vestidos de Baño en Crochet (Brazil, Estados Unidos y República Dominicana)
A6: 1 | B6: =LIDER!E43 -> BARRIOS BENITEZ EMILY | C6: =C5 -> G01 | E6: =IF(B6=0,0,IF(D6="",$F$6*LIDER!$H$9+$G$6*LIDER!$H$10+$H$6*LIDER!$H$11+$I$6*LIDER!$H$12+$J$6*LIDER!$H$13+$K$6*LIDER!$H$14+$L$6*LIDER!$H$15,"N")) -> 4.59 | F6: 4.2 | G6: 4.2 | H6: 4.7 | I6: 5 | J6: 5
A7: 2 | B7: =LIDER!E44 -> HERRERA TEJEDOR BRENDIS VANESA | C7: =C6 -> G01 | E7: =IF(B7=0,0,IF(D7="",$F$6*LIDER!$H$9+$G$6*LIDER!$H$10+$H$6*LIDER!$H$11+$I$6*LIDER!$H$12+$J$6*LIDER!$H$13+$K$6*LIDER!$H$14+$L$6*LIDER!$H$15,"N")) -> 4.59
A8: 3 | B8: =LIDER!E45 -> RUIZ RIVERO HEILEEN CAROLINA | C8: =C7 -> G01 | E8: =IF(B8=0,0,IF(D8="",$F$6*LIDER!$H$9+$G$6*LIDER!$H$10+$H$6*LIDER!$H$11+$I$6*LIDER!$H$12+$J$6*LIDER!$H$13+$K$6*LIDER!$H$14+$L$6*LIDER!$H$15,"N")) -> 4.59
A9: 4 | B9: =LIDER!E46 -> DE ARCOS AVENDAÑO SAID JADITH | C9: =C8 -> G01 | E9: =IF(B9=0,0,IF(D9="",$F$6*LIDER!$H$9+$G$6*LIDER!$H$10+$H$6*LIDER!$H$11+$I$6*LIDER!$H$12+$J$6*LIDER!$H$13+$K$6*LIDER!$H$14+$L$6*LIDER!$H$15,"N")) -> 4.59
A10: 5 | B10: =LIDER!E47 -> CASTILLO VILLA NELDA SOFIA | C10: =C9 -> G01 | E10: =IF(B10=0,0,IF(D10="",$F$6*LIDER!$H$9+$G$6*LIDER!$H$10+$H$6*LIDER!$H$11+$I$6*LIDER!$H$12+$J$6*LIDER!$H$13+$K$6*LIDER!$H$14+$L$6*LIDER!$H$15,"N")) -> 4.59
A11: 6 | B11: =LIDER!E48 -> 0 | C11: =C10 -> G01 | E11: =IF(B11=0,0,IF(D11="",$F$6*LIDER!$H$9+$G$6*LIDER!$H$10+$H$6*LIDER!$H$11+$I$6*LIDER!$H$12+$J$6*LIDER!$H$13+$K$6*LIDER!$H$14+$L$6*LIDER!$H$15,"N")) -> 0
B12: GRUPO#2 | C12: G02 | D12: =D5 -> LIST | E12: DEF | F12: =LIDER!$E$30 -> GRUPO#2 VINO DE MARACUYA, CHILE , PANAMA Y ESTADOS UNDOS)
A13: 1 | B13: =LIDER!F43 -> NARVAEZ MORELO WISNEEY | C13: =C12 -> G02 | E13: =IF(B13=0,0,IF(D13="",$F$13*LIDER!$H$9+$G$13*LIDER!$H$10+$H$13*LIDER!$H$11+$I$13*LIDER!$H$12+$J$13*LIDER!$H$13+$K$13*LIDER!$H$14+$L$13*LIDER!$H$15,"N")) -> 4.45 | F13: 4.7 | G13: 4.4 | H13: 4.5 | I13: 4 | J13: 4.8
A14: 2 | B14: =LIDER!F44 -> CASUSOL RODRIGUEZ AYLIN MARIANA | C14: =C13 -> G02 | E14: =IF(B14=0,0,IF(D14="",$F$13*LIDER!$H$9+$G$13*LIDER!$H$10+$H$13*LIDER!$H$11+$I$13*LIDER!$H$12+$J$13*LIDER!$H$13+$K$13*LIDER!$H$14+$L$13*LIDER!$H$15,"N")) -> 4.45
A15: 3 | B15: =LIDER!F45 -> CARMONA SIERRA YIRLEIS PATRICIA | C15: =C14 -> G02 | E15: =IF(B15=0,0,IF(D15="",$F$13*LIDER!$H$9+$G$13*LIDER!$H$10+$H$13*LIDER!$H$11+$I$13*LIDER!$H$12+$J$13*LIDER!$H$13+$K$13*LIDER!$H$14+$L$13*LIDER!$H$15,"N")) -> 4.45
A16: 4 | B16: =LIDER!F46 -> MAGALLANES PEDROZA VALENTINA | C16: =C15 -> G02 | E16: =IF(B16=0,0,IF(D16="",$F$13*LIDER!$H$9+$G$13*LIDER!$H$10+$H$13*LIDER!$H$11+$I$13*LIDER!$H$12+$J$13*LIDER!$H$13+$K$13*LIDER!$H$14+$L$13*LIDER!$H$15,"N")) -> 4.45
A17: 5 | B17: =LIDER!F47 -> MOLINA PÁJARO MARIA DE LOS ÁNGELES | C17: =C16 -> G02 | E17: =IF(B17=0,0,IF(D17="",$F$13*LIDER!$H$9+$G$13*LIDER!$H$10+$H$13*LIDER!$H$11+$I$13*LIDER!$H$12+$J$13*LIDER!$H$13+$K$13*LIDER!$H$14+$L$13*LIDER!$H$15,"N")) -> 4.45
A18: 6 | B18: =LIDER!F48 -> ESMERAL CORDERO NORIETH CAROLINA | C18: =C17 -> G02 | E18: =IF(B18=0,0,IF(D18="",$F$13*LIDER!$H$9+$G$13*LIDER!$H$10+$H$13*LIDER!$H$11+$I$13*LIDER!$H$12+$J$13*LIDER!$H$13+$K$13*LIDER!$H$14+$L$13*LIDER!$H$15,"N")) -> 4.45
B19: GRUPO#3 | C19: G03 | D19: =D12 -> LIST | E19: DEF | F19: =LIDER!$E$31 -> GRUPO#3 TRAJES DE BAÑO PARA PERSONAS DE CONTEXTURA GRUESA (
A20: 1 | B20: =LIDER!G43 -> CHAVEZ ARRIETA EVELYN SHARY | C20: =C19 -> G03 | E20: =IF(B20=0,0,IF(D20="",$F$20*LIDER!$H$9+$G$20*LIDER!$H$10+$H$20*LIDER!$H$11+$I$20*LIDER!$H$12+$J$20*LIDER!$H$13+$K$20*LIDER!$H$14+$L$20*LIDER!$H$15,"N")) -> 3.74 | F20: 4.2 | G20: 4.2 | H20: 4 | I20: 3.3 | J20: 2
A21: 2 | B21: =LIDER!G44 -> PEREZ MORENO ANA ISABEL | C21: =C20 -> G03 | D21: N | E21: =IF(B21=0,0,IF(D21="",$F$20*LIDER!$H$9+$G$20*LIDER!$H$10+$H$20*LIDER!$H$11+$I$20*LIDER!$H$12+$J$20*LIDER!$H$13+$K$20*LIDER!$H$14+$L$20*LIDER!$H$15,"N")) -> N
A22: 3 | B22: =LIDER!G45 -> PÁJARO DE LA PEÑA ANGELA ISABEL | C22: =C21 -> G03 | E22: =IF(B22=0,0,IF(D22="",$F$20*LIDER!$H$9+$G$20*LIDER!$H$10+$H$20*LIDER!$H$11+$I$20*LIDER!$H$12+$J$20*LIDER!$H$13+$K$20*LIDER!$H$14+$L$20*LIDER!$H$15,"N")) -> 3.74
A23: 4 | B23: =LIDER!G46 -> 0 | C23: =C22 -> G03 | E23: =IF(B23=0,0,IF(D23="",$F$20*LIDER!$H$9+$G$20*LIDER!$H$10+$H$20*LIDER!$H$11+$I$20*LIDER!$H$12+$J$20*LIDER!$H$13+$K$20*LIDER!$H$14+$L$20*LIDER!$H$15,"N")) -> 0
A24: 5 | B24: =LIDER!G47 -> 0 | C24: =C23 -> G03 | E24: =IF(B24=0,0,IF(D24="",$F$20*LIDER!$H$9+$G$20*LIDER!$H$10+$H$20*LIDER!$H$11+$I$20*LIDER!$H$12+$J$20*LIDER!$H$13+$K$20*LIDER!$H$14+$L$20*LIDER!$H$15,"N")) -> 0
A25: 6 | B25: =LIDER!G48 -> 0 | C25: =C24 -> G03 | E25: =IF(B25=0,0,IF(D25="",$F$20*LIDER!$H$9+$G$20*LIDER!$H$10+$H$20*LIDER!$H$11+$I$20*LIDER!$H$12+$J$20*LIDER!$H$13+$K$20*LIDER!$H$14+$L$20*LIDER!$H$15,"N")) -> 0
B26: GRUPO#4 | C26: G04 | D26: =D19 -> LIST | E26: DEF | F26: =LIDER!$E$32 -> GRUPO#4 KITS PICKNIC ESPAÑA, BRAZIL Y PERU
A27: 1 | B27: =LIDER!H43 -> BARRIOS CUADRADO HEILIN TATIANA | C27: =C26 -> G04 | E27: =IF(B27=0,0,IF(D27="",$F$27*LIDER!$H$9+$G$27*LIDER!$H$10+$H$27*LIDER!$H$11+$I$27*LIDER!$H$12+$J$27*LIDER!$H$13+$K$27*LIDER!$H$14+$L$27*LIDER!$H$15,"N")) -> 3.92 | F27: 4.3 | G27: 3.9 | H27: 4.4 | I27: 3.2 | J27: 3.2
A28: 2 | B28: =LIDER!H44 -> MARTINEZ JULIO YEMILY ALBANIS | C28: =C27 -> G04 | E28: =IF(B28=0,0,IF(D28="",$F$27*LIDER!$H$9+$G$27*LIDER!$H$10+$H$27*LIDER!$H$11+$I$27*LIDER!$H$12+$J$27*LIDER!$H$13+$K$27*LIDER!$H$14+$L$27*LIDER!$H$15,"N")) -> 3.92
A29: 3 | B29: =LIDER!H45 -> MANJARRES CORREA PAULA ANDREA | C29: =C28 -> G04 | E29: =IF(B29=0,0,IF(D29="",$F$27*LIDER!$H$9+$G$27*LIDER!$H$10+$H$27*LIDER!$H$11+$I$27*LIDER!$H$12+$J$27*LIDER!$H$13+$K$27*LIDER!$H$14+$L$27*LIDER!$H$15,"N")) -> 3.92
A30: 4 | B30: =LIDER!H46 -> GARCIA MATUTE VALERIE DANIELA | C30: =C29 -> G04 | E30: =IF(B30=0,0,IF(D30="",$F$27*LIDER!$H$9+$G$27*LIDER!$H$10+$H$27*LIDER!$H$11+$I$27*LIDER!$H$12+$J$27*LIDER!$H$13+$K$27*LIDER!$H$14+$L$27*LIDER!$H$15,"N")) -> 3.92
A31: 5 | B31: =LIDER!H47 -> 0 | C31: =C30 -> G04 | E31: =IF(B31=0,0,IF(D31="",$F$27*LIDER!$H$9+$G$27*LIDER!$H$10+$H$27*LIDER!$H$11+$I$27*LIDER!$H$12+$J$27*LIDER!$H$13+$K$27*LIDER!$H$14+$L$27*LIDER!$H$15,"N")) -> 0
A32: 6 | B32: =LIDER!H48 -> 0 | C32: =C31 -> G04 | E32: =IF(B32=0,0,IF(D32="",$F$27*LIDER!$H$9+$G$27*LIDER!$H$10+$H$27*LIDER!$H$11+$I$27*LIDER!$H$12+$J$27*LIDER!$H$13+$K$27*LIDER!$H$14+$L$27*LIDER!$H$15,"N")) -> 0
B33: GRUPO#5 | C33: G05 | D33: =D26 -> LIST | E33: DEF | F33: =LIDER!$E$33 -> GRUPO#5 HAMACAS INTERNACIONALES CON COJINES ESTADOS UNIDOS, SUECIA Y ESPAÑA
A34: 1 | B34: =LIDER!E51 -> PADILLA MORALES VALERIE SOFIA | C34: =C33 -> G05 | E34: =IF(B34=0,0,IF(D34="",$F$34*LIDER!$H$9+$G$34*LIDER!$H$10+$H$34*LIDER!$H$11+$I$34*LIDER!$H$12+$J$34*LIDER!$H$13+$K$34*LIDER!$H$14+$L$34*LIDER!$H$15,"N")) -> 4.63 | F34: 4.7 | G34: 4.7 | H34: 4.5 | I34: 4.5 | J34: 5
A35: 2 | B35: =LIDER!E52 -> RODRIGUEZ ARCIA MARICRUZ | C35: =C34 -> G05 | E35: =IF(B35=0,0,IF(D35="",$F$34*LIDER!$H$9+$G$34*LIDER!$H$10+$H$34*LIDER!$H$11+$I$34*LIDER!$H$12+$J$34*LIDER!$H$13+$K$34*LIDER!$H$14+$L$34*LIDER!$H$15,"N")) -> 4.63
A36: 3 | B36: =LIDER!E53 -> DONADO ALMANZA DAVID | C36: =C35 -> G05 | E36: =IF(B36=0,0,IF(D36="",$F$34*LIDER!$H$9+$G$34*LIDER!$H$10+$H$34*LIDER!$H$11+$I$34*LIDER!$H$12+$J$34*LIDER!$H$13+$K$34*LIDER!$H$14+$L$34*LIDER!$H$15,"N")) -> 4.63
A37: 4 | B37: =LIDER!E54 -> 0 | C37: =C36 -> G05 | E37: =IF(B37=0,0,IF(D37="",$F$34*LIDER!$H$9+$G$34*LIDER!$H$10+$H$34*LIDER!$H$11+$I$34*LIDER!$H$12+$J$34*LIDER!$H$13+$K$34*LIDER!$H$14+$L$34*LIDER!$H$15,"N")) -> 0
A38: 5 | B38: =LIDER!E55 -> 0 | C38: =C37 -> G05 | E38: =IF(B38=0,0,IF(D38="",$F$34*LIDER!$H$9+$G$34*LIDER!$H$10+$H$34*LIDER!$H$11+$I$34*LIDER!$H$12+$J$34*LIDER!$H$13+$K$34*LIDER!$H$14+$L$34*LIDER!$H$15,"N")) -> 0
A39: 6 | B39: =LIDER!E56 -> 0 | C39: =C38 -> G05 | E39: =IF(B39=0,0,IF(D39="",$F$34*LIDER!$H$9+$G$34*LIDER!$H$10+$H$34*LIDER!$H$11+$I$34*LIDER!$H$12+$J$34*LIDER!$H$13+$K$34*LIDER!$H$14+$L$34*LIDER!$H$15,"N")) -> 0
B40: GRUPO#6 | C40: G06 | D40: =D33 -> LIST | E40: DEF | F40: =LIDER!$E$34 -> GRUPO#6 COSMETICOS A BASE DE CAFE , ESPAÑA , ESTADOS UNIDOS, CANADA
...

Sheet S-ASIG-04
A1: =LIDER!B2 -> TECNOLOGÍA EN GESTIÓN DE NEGOCIOS INTERN | I1: =LIDER!E2 -> SEMESTRE: | J1: =LIDER!F2 -> SEM-04 | K1: =LIDER!G2 -> SECCIÓN: | L1: =LIDER!H2 -> 2
B2: =LIDER!F4 -> ESTADÍSTICA | F2: CRITERIOS DE EVALUACIÓN
B3: Estudiantes | F3: =LIDER!E9 -> PRESENTACIÓN GENERAL: Adopta la norma APA, tamaño de la hoja, margenes, titulo, portadas, numeración de paginas, tabla de contenido automatizada, ortografia, justificacion del texto, citas automatizadas, listas, figuras,etc. | G3: =LIDER!E10 -> ANTEPROYECTO: Portada, planteamiento del problema, justificacion del trabajo o proyecto de aula, objetivos, marco teorico, diseño metodologico. | H3: =LIDER!E11 -> RESULTADOS: Analiza, integra y aplica de manera coherente los aspectos del análisis del entorno(Variables Macroeconómicas, Factores Sociales y Culturales, Factores Políticos y Legales,Factores Tecnológicos y Factores Ambientales) en el desarrollo de la propuesta investigativa, evidenciando capacidad para generar soluciones viables, pertinentes y sostenibles. | I3: =LIDER!E12 -> BILIOGRAFIA: Las referencias bibliograficas adoptan las normas APA. El documento es producto de un rastreo bibliografico que muestra analisis y sistensis. | J3: =LIDER!E13 -> ASESORIAS: Anexó la hoja de tutoria firmada ( 3 fimas minmimo). | K3: =LIDER!E14 -> 0 | L3: =LIDER!E15 -> 0
F4: =CONCATENATE(LIDER!F4," - ",LIDER!F6," - ",LIDER!F5) -> ESTADÍSTICA - 1924 - ANTONIO OSPINO RODRIGUEZ
B5: GRUPO#1 | C5: G01 | D5: LIST | E5: DEF | F5: =LIDER!$E$29 -> GRUPO#1 Vestidos de Baño en Crochet (Brazil, Estados Unidos y República Dominicana)
A6: 1 | B6: =LIDER!E43 -> BARRIOS BENITEZ EMILY | C6: =C5 -> G01 | E6: =IF(B6=0,0,IF(D6="",$F$6*LIDER!$H$9+$G$6*LIDER!$H$10+$H$6*LIDER!$H$11+$I$6*LIDER!$H$12+$J$6*LIDER!$H$13+$K$6*LIDER!$H$14+$L$6*LIDER!$H$15,"N")) -> 3.4 | F6: 3.5 | G6: 3.5 | H6: 3.5 | I6: 3 | J6: 3.5
A7: 2 | B7: =LIDER!E44 -> HERRERA TEJEDOR BRENDIS VANESA | C7: =C6 -> G01 | E7: =IF(B7=0,0,IF(D7="",$F$6*LIDER!$H$9+$G$6*LIDER!$H$10+$H$6*LIDER!$H$11+$I$6*LIDER!$H$12+$J$6*LIDER!$H$13+$K$6*LIDER!$H$14+$L$6*LIDER!$H$15,"N")) -> 3.4
A8: 3 | B8: =LIDER!E45 -> RUIZ RIVERO HEILEEN CAROLINA | C8: =C7 -> G01 | E8: =IF(B8=0,0,IF(D8="",$F$6*LIDER!$H$9+$G$6*LIDER!$H$10+$H$6*LIDER!$H$11+$I$6*LIDER!$H$12+$J$6*LIDER!$H$13+$K$6*LIDER!$H$14+$L$6*LIDER!$H$15,"N")) -> 3.4
A9: 4 | B9: =LIDER!E46 -> DE ARCOS AVENDAÑO SAID JADITH | C9: =C8 -> G01 | E9: =IF(B9=0,0,IF(D9="",$F$6*LIDER!$H$9+$G$6*LIDER!$H$10+$H$6*LIDER!$H$11+$I$6*LIDER!$H$12+$J$6*LIDER!$H$13+$K$6*LIDER!$H$14+$L$6*LIDER!$H$15,"N")) -> 3.4
A10: 5 | B10: =LIDER!E47 -> CASTILLO VILLA NELDA SOFIA | C10: =C9 -> G01 | E10: =IF(B10=0,0,IF(D10="",$F$6*LIDER!$H$9+$G$6*LIDER!$H$10+$H$6*LIDER!$H$11+$I$6*LIDER!$H$12+$J$6*LIDER!$H$13+$K$6*LIDER!$H$14+$L$6*LIDER!$H$15,"N")) -> 3.4
A11: 6 | B11: =LIDER!E48 -> 0 | C11: =C10 -> G01 | E11: =IF(B11=0,0,IF(D11="",$F$6*LIDER!$H$9+$G$6*LIDER!$H$10+$H$6*LIDER!$H$11+$I$6*LIDER!$H$12+$J$6*LIDER!$H$13+$K$6*LIDER!$H$14+$L$6*LIDER!$H$15,"N")) -> 0
B12: GRUPO#2 | C12: G02 | D12: =D5 -> LIST | E12: DEF | F12: =LIDER!$E$30 -> GRUPO#2 VINO DE MARACUYA, CHILE , PANAMA Y ESTADOS UNDOS)
A13: 1 | B13: =LIDER!F43 -> NARVAEZ MORELO WISNEEY | C13: =C12 -> G02 | E13: =IF(B13=0,0,IF(D13="",$F$13*LIDER!$H$9+$G$13*LIDER!$H$10+$H$13*LIDER!$H$11+$I$13*LIDER!$H$12+$J$13*LIDER!$H$13+$K$13*LIDER!$H$14+$L$13*LIDER!$H$15,"N")) -> 3.5 | F13: 3.5 | G13: 3.5 | H13: 3.5 | I13: 3.5 | J13: 3.5
A14: 2 | B14: =LIDER!F44 -> CASUSOL RODRIGUEZ AYLIN MARIANA | C14: =C13 -> G02 | E14: =IF(B14=0,0,IF(D14="",$F$13*LIDER!$H$9+$G$13*LIDER!$H$10+$H$13*LIDER!$H$11+$I$13*LIDER!$H$12+$J$13*LIDER!$H$13+$K$13*LIDER!$H$14+$L$13*LIDER!$H$15,"N")) -> 3.5
A15: 3 | B15: =LIDER!F45 -> CARMONA SIERRA YIRLEIS PATRICIA | C15: =C14 -> G02 | E15: =IF(B15=0,0,IF(D15="",$F$13*LIDER!$H$9+$G$13*LIDER!$H$10+$H$13*LIDER!$H$11+$I$13*LIDER!$H$12+$J$13*LIDER!$H$13+$K$13*LIDER!$H$14+$L$13*LIDER!$H$15,"N")) -> 3.5
A16: 4 | B16: =LIDER!F46 -> MAGALLANES PEDROZA VALENTINA | C16: =C15 -> G02 | E16: =IF(B16=0,0,IF(D16="",$F$13*LIDER!$H$9+$G$13*LIDER!$H$10+$H$13*LIDER!$H$11+$I$13*LIDER!$H$12+$J$13*LIDER!$H$13+$K$13*LIDER!$H$14+$L$13*LIDER!$H$15,"N")) -> 3.5
A17: 5 | B17: =LIDER!F47 -> MOLINA PÁJARO MARIA DE LOS ÁNGELES | C17: =C16 -> G02 | E17: =IF(B17=0,0,IF(D17="",$F$13*LIDER!$H$9+$G$13*LIDER!$H$10+$H$13*LIDER!$H$11+$I$13*LIDER!$H$12+$J$13*LIDER!$H$13+$K$13*LIDER!$H$14+$L$13*LIDER!$H$15,"N")) -> 3.5
A18: 6 | B18: =LIDER!F48 -> ESMERAL CORDERO NORIETH CAROLINA | C18: =C17 -> G02 | E18: =IF(B18=0,0,IF(D18="",$F$13*LIDER!$H$9+$G$13*LIDER!$H$10+$H$13*LIDER!$H$11+$I$13*LIDER!$H$12+$J$13*LIDER!$H$13+$K$13*LIDER!$H$14+$L$13*LIDER!$H$15,"N")) -> 3.5
B19: GRUPO#3 | C19: G03 | D19: =D12 -> LIST | E19: DEF | F19: =LIDER!$E$31 -> GRUPO#3 TRAJES DE BAÑO PARA PERSONAS DE CONTEXTURA GRUESA (
A20: 1 | B20: =LIDER!G43 -> CHAVEZ ARRIETA EVELYN SHARY | C20: =C19 -> G03 | E20: =IF(B20=0,0,IF(D20="",$F$20*LIDER!$H$9+$G$20*LIDER!$H$10+$H$20*LIDER!$H$11+$I$20*LIDER!$H$12+$J$20*LIDER!$H$13+$K$20*LIDER!$H$14+$L$20*LIDER!$H$15,"N")) -> 3.5 | F20: 3.5 | G20: 3.5 | H20: 3.5 | I20: 3.5 | J20: 3.5
A21: 2 | B21: =LIDER!G44 -> PEREZ MORENO ANA ISABEL | C21: =C20 -> G03 | E21: =IF(B21=0,0,IF(D21="",$F$20*LIDER!$H$9+$G$20*LIDER!$H$10+$H$20*LIDER!$H$11+$I$20*LIDER!$H$12+$J$20*LIDER!$H$13+$K$20*LIDER!$H$14+$L$20*LIDER!$H$15,"N")) -> 3.5
A22: 3 | B22: =LIDER!G45 -> PÁJARO DE LA PEÑA ANGELA ISABEL | C22: =C21 -> G03 | E22: =IF(B22=0,0,IF(D22="",$F$20*LIDER!$H$9+$G$20*LIDER!$H$10+$H$20*LIDER!$H$11+$I$20*LIDER!$H$12+$J$20*LIDER!$H$13+$K$20*LIDER!$H$14+$L$20*LIDER!$H$15,"N")) -> 3.5
A23: 4 | B23: =LIDER!G46 -> 0 | C23: =C22 -> G03 | E23: =IF(B23=0,0,IF(D23="",$F$20*LIDER!$H$9+$G$20*LIDER!$H$10+$H$20*LIDER!$H$11+$I$20*LIDER!$H$12+$J$20*LIDER!$H$13+$K$20*LIDER!$H$14+$L$20*LIDER!$H$15,"N")) -> 0
A24: 5 | B24: =LIDER!G47 -> 0 | C24: =C23 -> G03 | E24: =IF(B24=0,0,IF(D24="",$F$20*LIDER!$H$9+$G$20*LIDER!$H$10+$H$20*LIDER!$H$11+$I$20*LIDER!$H$12+$J$20*LIDER!$H$13+$K$20*LIDER!$H$14+$L$20*LIDER!$H$15,"N")) -> 0
A25: 6 | B25: =LIDER!G48 -> 0 | C25: =C24 -> G03 | E25: =IF(B25=0,0,IF(D25="",$F$20*LIDER!$H$9+$G$20*LIDER!$H$10+$H$20*LIDER!$H$11+$I$20*LIDER!$H$12+$J$20*LIDER!$H$13+$K$20*LIDER!$H$14+$L$20*LIDER!$H$15,"N")) -> 0
B26: GRUPO#4 | C26: G04 | D26: =D19 -> LIST | E26: DEF | F26: =LIDER!$E$32 -> GRUPO#4 KITS PICKNIC ESPAÑA, BRAZIL Y PERU
A27: 1 | B27: =LIDER!H43 -> BARRIOS CUADRADO HEILIN TATIANA | C27: =C26 -> G04 | E27: =IF(B27=0,0,IF(D27="",$F$27*LIDER!$H$9+$G$27*LIDER!$H$10+$H$27*LIDER!$H$11+$I$27*LIDER!$H$12+$J$27*LIDER!$H$13+$K$27*LIDER!$H$14+$L$27*LIDER!$H$15,"N")) -> 3.45 | F27: 3.5 | G27: 3.5 | H27: 3.5 | I27: 3.5 | J27: 3
A28: 2 | B28: =LIDER!H44 -> MARTINEZ JULIO YEMILY ALBANIS | C28: =C27 -> G04 | E28: =IF(B28=0,0,IF(D28="",$F$27*LIDER!$H$9+$G$27*LIDER!$H$10+$H$27*LIDER!$H$11+$I$27*LIDER!$H$12+$J$27*LIDER!$H$13+$K$27*LIDER!$H$14+$L$27*LIDER!$H$15,"N")) -> 3.45
A29: 3 | B29: =LIDER!H45 -> MANJARRES CORREA PAULA ANDREA | C29: =C28 -> G04 | E29: =IF(B29=0,0,IF(D29="",$F$27*LIDER!$H$9+$G$27*LIDER!$H$10+$H$27*LIDER!$H$11+$I$27*LIDER!$H$12+$J$27*LIDER!$H$13+$K$27*LIDER!$H$14+$L$27*LIDER!$H$15,"N")) -> 3.45
A30: 4 | B30: =LIDER!H46 -> GARCIA MATUTE VALERIE DANIELA | C30: =C29 -> G04 | E30: =IF(B30=0,0,IF(D30="",$F$27*LIDER!$H$9+$G$27*LIDER!$H$10+$H$27*LIDER!$H$11+$I$27*LIDER!$H$12+$J$27*LIDER!$H$13+$K$27*LIDER!$H$14+$L$27*LIDER!$H$15,"N")) -> 3.45
A31: 5 | B31: =LIDER!H47 -> 0 | C31: =C30 -> G04 | E31: =IF(B31=0,0,IF(D31="",$F$27*LIDER!$H$9+$G$27*LIDER!$H$10+$H$27*LIDER!$H$11+$I$27*LIDER!$H$12+$J$27*LIDER!$H$13+$K$27*LIDER!$H$14+$L$27*LIDER!$H$15,"N")) -> 0
A32: 6 | B32: =LIDER!H48 -> 0 | C32: =C31 -> G04 | E32: =IF(B32=0,0,IF(D32="",$F$27*LIDER!$H$9+$G$27*LIDER!$H$10+$H$27*LIDER!$H$11+$I$27*LIDER!$H$12+$J$27*LIDER!$H$13+$K$27*LIDER!$H$14+$L$27*LIDER!$H$15,"N")) -> 0
B33: GRUPO#5 | C33: G05 | D33: =D26 -> LIST | E33: DEF | F33: =LIDER!$E$33 -> GRUPO#5 HAMACAS INTERNACIONALES CON COJINES ESTADOS UNIDOS, SUECIA Y ESPAÑA
A34: 1 | B34: =LIDER!E51 -> PADILLA MORALES VALERIE SOFIA | C34: =C33 -> G05 | E34: =IF(B34=0,0,IF(D34="",$F$34*LIDER!$H$9+$G$34*LIDER!$H$10+$H$34*LIDER!$H$11+$I$34*LIDER!$H$12+$J$34*LIDER!$H$13+$K$34*LIDER!$H$14+$L$34*LIDER!$H$15,"N")) -> 3.69 | F34: 4 | G34: 4 | H34: 3.8 | I34: 3 | J34: 3.5
A35: 2 | B35: =LIDER!E52 -> RODRIGUEZ ARCIA MARICRUZ | C35: =C34 -> G05 | E35: =IF(B35=0,0,IF(D35="",$F$34*LIDER!$H$9+$G$34*LIDER!$H$10+$H$34*LIDER!$H$11+$I$34*LIDER!$H$12+$J$34*LIDER!$H$13+$K$34*LIDER!$H$14+$L$34*LIDER!$H$15,"N")) -> 3.69
A36: 3 | B36: =LIDER!E53 -> DONADO ALMANZA DAVID | C36: =C35 -> G05 | E36: =IF(B36=0,0,IF(D36="",$F$34*LIDER!$H$9+$G$34*LIDER!$H$10+$H$34*LIDER!$H$11+$I$34*LIDER!$H$12+$J$34*LIDER!$H$13+$K$34*LIDER!$H$14+$L$34*LIDER!$H$15,"N")) -> 3.69
A37: 4 | B37: =LIDER!E54 -> 0 | C37: =C36 -> G05 | E37: =IF(B37=0,0,IF(D37="",$F$34*LIDER!$H$9+$G$34*LIDER!$H$10+$H$34*LIDER!$H$11+$I$34*LIDER!$H$12+$J$34*LIDER!$H$13+$K$34*LIDER!$H$14+$L$34*LIDER!$H$15,"N")) -> 0
A38: 5 | B38: =LIDER!E55 -> 0 | C38: =C37 -> G05 | E38: =IF(B38=0,0,IF(D38="",$F$34*LIDER!$H$9+$G$34*LIDER!$H$10+$H$34*LIDER!$H$11+$I$34*LIDER!$H$12+$J$34*LIDER!$H$13+$K$34*LIDER!$H$14+$L$34*LIDER!$H$15,"N")) -> 0
A39: 6 | B39: =LIDER!E56 -> 0 | C39: =C38 -> G05 | E39: =IF(B39=0,0,IF(D39="",$F$34*LIDER!$H$9+$G$34*LIDER!$H$10+$H$34*LIDER!$H$11+$I$34*LIDER!$H$12+$J$34*LIDER!$H$13+$K$34*LIDER!$H$14+$L$34*LIDER!$H$15,"N")) -> 0
B40: GRUPO#6 | C40: G06 | D40: =D33 -> LIST | E40: DEF | F40: =LIDER!$E$34 -> GRUPO#6 COSMETICOS A BASE DE CAFE , ESPAÑA , ESTADOS UNIDOS, CANADA
...

Sheet S-ASIG-05
A1: =LIDER!B2 -> TECNOLOGÍA EN GESTIÓN DE NEGOCIOS INTERN | I1: =LIDER!E2 -> SEMESTRE: | J1: =LIDER!F2 -> SEM-04 | K1: =LIDER!G2 -> SECCIÓN: | L1: =LIDER!H2 -> 2
B2: =LIDER!G4 -> FUNDAMENTOS DE MERCADEO | F2: CRITERIOS DE EVALUACIÓN
B3: Estudiantes | F3: =LIDER!E9 -> PRESENTACIÓN GENERAL: Adopta la norma APA, tamaño de la hoja, margenes, titulo, portadas, numeración de paginas, tabla de contenido automatizada, ortografia, justificacion del texto, citas automatizadas, listas, figuras,etc. | G3: =LIDER!E10 -> ANTEPROYECTO: Portada, planteamiento del problema, justificacion del trabajo o proyecto de aula, objetivos, marco teorico, diseño metodologico. | H3: =LIDER!E11 -> RESULTADOS: Analiza, integra y aplica de manera coherente los aspectos del análisis del entorno(Variables Macroeconómicas, Factores Sociales y Culturales, Factores Políticos y Legales,Factores Tecnológicos y Factores Ambientales) en el desarrollo de la propuesta investigativa, evidenciando capacidad para generar soluciones viables, pertinentes y sostenibles. | I3: =LIDER!E12 -> BILIOGRAFIA: Las referencias bibliograficas adoptan las normas APA. El documento es producto de un rastreo bibliografico que muestra analisis y sistensis. | J3: =LIDER!E13 -> ASESORIAS: Anexó la hoja de tutoria firmada ( 3 fimas minmimo). | K3: =LIDER!E14 -> 0 | L3: =LIDER!E15 -> 0
F4: =CONCATENATE(LIDER!G4," - ",LIDER!G6," - ",LIDER!G5) -> FUNDAMENTOS DE MERCADEO - 1397 - GABRIEL EDUARDO CARDONA TUÑON
B5: GRUPO#1 | C5: G01 | D5: LIST | E5: DEF | F5: =LIDER!$E$29 -> GRUPO#1 Vestidos de Baño en Crochet (Brazil, Estados Unidos y República Dominicana)
A6: 1 | B6: =LIDER!E43 -> BARRIOS BENITEZ EMILY | C6: =C5 -> G01 | E6: =IF(B6=0,0,IF(D6="",$F$6*LIDER!$H$9+$G$6*LIDER!$H$10+$H$6*LIDER!$H$11+$I$6*LIDER!$H$12+$J$6*LIDER!$H$13+$K$6*LIDER!$H$14+$L$6*LIDER!$H$15,"N")) -> 3.5 | F6: 3.5 | G6: 3.5 | H6: 3.5 | I6: 3.5 | J6: 3.5
A7: 2 | B7: =LIDER!E44 -> HERRERA TEJEDOR BRENDIS VANESA | C7: =C6 -> G01 | E7: =IF(B7=0,0,IF(D7="",$F$6*LIDER!$H$9+$G$6*LIDER!$H$10+$H$6*LIDER!$H$11+$I$6*LIDER!$H$12+$J$6*LIDER!$H$13+$K$6*LIDER!$H$14+$L$6*LIDER!$H$15,"N")) -> 3.5
A8: 3 | B8: =LIDER!E45 -> RUIZ RIVERO HEILEEN CAROLINA | C8: =C7 -> G01 | E8: =IF(B8=0,0,IF(D8="",$F$6*LIDER!$H$9+$G$6*LIDER!$H$10+$H$6*LIDER!$H$11+$I$6*LIDER!$H$12+$J$6*LIDER!$H$13+$K$6*LIDER!$H$14+$L$6*LIDER!$H$15,"N")) -> 3.5
A9: 4 | B9: =LIDER!E46 -> DE ARCOS AVENDAÑO SAID JADITH | C9: =C8 -> G01 | E9: =IF(B9=0,0,IF(D9="",$F$6*LIDER!$H$9+$G$6*LIDER!$H$10+$H$6*LIDER!$H$11+$I$6*LIDER!$H$12+$J$6*LIDER!$H$13+$K$6*LIDER!$H$14+$L$6*LIDER!$H$15,"N")) -> 3.5
A10: 5 | B10: =LIDER!E47 -> CASTILLO VILLA NELDA SOFIA | C10: =C9 -> G01 | E10: =IF(B10=0,0,IF(D10="",$F$6*LIDER!$H$9+$G$6*LIDER!$H$10+$H$6*LIDER!$H$11+$I$6*LIDER!$H$12+$J$6*LIDER!$H$13+$K$6*LIDER!$H$14+$L$6*LIDER!$H$15,"N")) -> 3.5
A11: 6 | B11: =LIDER!E48 -> 0 | C11: =C10 -> G01 | E11: =IF(B11=0,0,IF(D11="",$F$6*LIDER!$H$9+$G$6*LIDER!$H$10+$H$6*LIDER!$H$11+$I$6*LIDER!$H$12+$J$6*LIDER!$H$13+$K$6*LIDER!$H$14+$L$6*LIDER!$H$15,"N")) -> 0
B12: GRUPO#2 | C12: G02 | D12: =D5 -> LIST | E12: DEF | F12: =LIDER!$E$30 -> GRUPO#2 VINO DE MARACUYA, CHILE , PANAMA Y ESTADOS UNDOS)
A13: 1 | B13: =LIDER!F43 -> NARVAEZ MORELO WISNEEY | C13: =C12 -> G02 | E13: =IF(B13=0,0,IF(D13="",$F$13*LIDER!$H$9+$G$13*LIDER!$H$10+$H$13*LIDER!$H$11+$I$13*LIDER!$H$12+$J$13*LIDER!$H$13+$K$13*LIDER!$H$14+$L$13*LIDER!$H$15,"N")) -> 4.5 | F13: 4.5 | G13: 4.5 | H13: 4.5 | I13: 4.5 | J13: 4.5
A14: 2 | B14: =LIDER!F44 -> CASUSOL RODRIGUEZ AYLIN MARIANA | C14: =C13 -> G02 | E14: =IF(B14=0,0,IF(D14="",$F$13*LIDER!$H$9+$G$13*LIDER!$H$10+$H$13*LIDER!$H$11+$I$13*LIDER!$H$12+$J$13*LIDER!$H$13+$K$13*LIDER!$H$14+$L$13*LIDER!$H$15,"N")) -> 4.5
A15: 3 | B15: =LIDER!F45 -> CARMONA SIERRA YIRLEIS PATRICIA | C15: =C14 -> G02 | E15: =IF(B15=0,0,IF(D15="",$F$13*LIDER!$H$9+$G$13*LIDER!$H$10+$H$13*LIDER!$H$11+$I$13*LIDER!$H$12+$J$13*LIDER!$H$13+$K$13*LIDER!$H$14+$L$13*LIDER!$H$15,"N")) -> 4.5
A16: 4 | B16: =LIDER!F46 -> MAGALLANES PEDROZA VALENTINA | C16: =C15 -> G02 | E16: =IF(B16=0,0,IF(D16="",$F$13*LIDER!$H$9+$G$13*LIDER!$H$10+$H$13*LIDER!$H$11+$I$13*LIDER!$H$12+$J$13*LIDER!$H$13+$K$13*LIDER!$H$14+$L$13*LIDER!$H$15,"N")) -> 4.5
A17: 5 | B17: =LIDER!F47 -> MOLINA PÁJARO MARIA DE LOS ÁNGELES | C17: =C16 -> G02 | E17: =IF(B17=0,0,IF(D17="",$F$13*LIDER!$H$9+$G$13*LIDER!$H$10+$H$13*LIDER!$H$11+$I$13*LIDER!$H$12+$J$13*LIDER!$H$13+$K$13*LIDER!$H$14+$L$13*LIDER!$H$15,"N")) -> 4.5
A18: 6 | B18: =LIDER!F48 -> ESMERAL CORDERO NORIETH CAROLINA | C18: =C17 -> G02 | E18: =IF(B18=0,0,IF(D18="",$F$13*LIDER!$H$9+$G$13*LIDER!$H$10+$H$13*LIDER!$H$11+$I$13*LIDER!$H$12+$J$13*LIDER!$H$13+$K$13*LIDER!$H$14+$L$13*LIDER!$H$15,"N")) -> 4.5
B19: GRUPO#3 | C19: G03 | D19: =D12 -> LIST | E19: DEF | F19: =LIDER!$E$31 -> GRUPO#3 TRAJES DE BAÑO PARA PERSONAS DE CONTEXTURA GRUESA (
A20: 1 | B20: =LIDER!G43 -> CHAVEZ ARRIETA EVELYN SHARY | C20: =C19 -> G03 | E20: =IF(B20=0,0,IF(D20="",$F$20*LIDER!$H$9+$G$20*LIDER!$H$10+$H$20*LIDER!$H$11+$I$20*LIDER!$H$12+$J$20*LIDER!$H$13+$K$20*LIDER!$H$14+$L$20*LIDER!$H$15,"N")) -> 3.7 | F20: 3.7 | G20: 3.7 | H20: 3.7 | I20: 3.7 | J20: 3.7
A21: 2 | B21: =LIDER!G44 -> PEREZ MORENO ANA ISABEL | C21: =C20 -> G03 | E21: =IF(B21=0,0,IF(D21="",$F$20*LIDER!$H$9+$G$20*LIDER!$H$10+$H$20*LIDER!$H$11+$I$20*LIDER!$H$12+$J$20*LIDER!$H$13+$K$20*LIDER!$H$14+$L$20*LIDER!$H$15,"N")) -> 3.7
A22: 3 | B22: =LIDER!G45 -> PÁJARO DE LA PEÑA ANGELA ISABEL | C22: =C21 -> G03 | E22: =IF(B22=0,0,IF(D22="",$F$20*LIDER!$H$9+$G$20*LIDER!$H$10+$H$20*LIDER!$H$11+$I$20*LIDER!$H$12+$J$20*LIDER!$H$13+$K$20*LIDER!$H$14+$L$20*LIDER!$H$15,"N")) -> 3.7
A23: 4 | B23: =LIDER!G46 -> 0 | C23: =C22 -> G03 | E23: =IF(B23=0,0,IF(D23="",$F$20*LIDER!$H$9+$G$20*LIDER!$H$10+$H$20*LIDER!$H$11+$I$20*LIDER!$H$12+$J$20*LIDER!$H$13+$K$20*LIDER!$H$14+$L$20*LIDER!$H$15,"N")) -> 0
A24: 5 | B24: =LIDER!G47 -> 0 | C24: =C23 -> G03 | E24: =IF(B24=0,0,IF(D24="",$F$20*LIDER!$H$9+$G$20*LIDER!$H$10+$H$20*LIDER!$H$11+$I$20*LIDER!$H$12+$J$20*LIDER!$H$13+$K$20*LIDER!$H$14+$L$20*LIDER!$H$15,"N")) -> 0
A25: 6 | B25: =LIDER!G48 -> 0 | C25: =C24 -> G03 | E25: =IF(B25=0,0,IF(D25="",$F$20*LIDER!$H$9+$G$20*LIDER!$H$10+$H$20*LIDER!$H$11+$I$20*LIDER!$H$12+$J$20*LIDER!$H$13+$K$20*LIDER!$H$14+$L$20*LIDER!$H$15,"N")) -> 0
B26: GRUPO#4 | C26: G04 | D26: =D19 -> LIST | E26: DEF | F26: =LIDER!$E$32 -> GRUPO#4 KITS PICKNIC ESPAÑA, BRAZIL Y PERU
A27: 1 | B27: =LIDER!H43 -> BARRIOS CUADRADO HEILIN TATIANA | C27: =C26 -> G04 | E27: =IF(B27=0,0,IF(D27="",$F$27*LIDER!$H$9+$G$27*LIDER!$H$10+$H$27*LIDER!$H$11+$I$27*LIDER!$H$12+$J$27*LIDER!$H$13+$K$27*LIDER!$H$14+$L$27*LIDER!$H$15,"N")) -> 3.3 | F27: 3.3 | G27: 3.3 | H27: 3.3 | I27: 3.3 | J27: 3.3
A28: 2 | B28: =LIDER!H44 -> MARTINEZ JULIO YEMILY ALBANIS | C28: =C27 -> G04 | E28: =IF(B28=0,0,IF(D28="",$F$27*LIDER!$H$9+$G$27*LIDER!$H$10+$H$27*LIDER!$H$11+$I$27*LIDER!$H$12+$J$27*LIDER!$H$13+$K$27*LIDER!$H$14+$L$27*LIDER!$H$15,"N")) -> 3.3
A29: 3 | B29: =LIDER!H45 -> MANJARRES CORREA PAULA ANDREA | C29: =C28 -> G04 | E29: =IF(B29=0,0,IF(D29="",$F$27*LIDER!$H$9+$G$27*LIDER!$H$10+$H$27*LIDER!$H$11+$I$27*LIDER!$H$12+$J$27*LIDER!$H$13+$K$27*LIDER!$H$14+$L$27*LIDER!$H$15,"N")) -> 3.3
A30: 4 | B30: =LIDER!H46 -> GARCIA MATUTE VALERIE DANIELA | C30: =C29 -> G04 | E30: =IF(B30=0,0,IF(D30="",$F$27*LIDER!$H$9+$G$27*LIDER!$H$10+$H$27*LIDER!$H$11+$I$27*LIDER!$H$12+$J$27*LIDER!$H$13+$K$27*LIDER!$H$14+$L$27*LIDER!$H$15,"N")) -> 3.3
A31: 5 | B31: =LIDER!H47 -> 0 | C31: =C30 -> G04 | E31: =IF(B31=0,0,IF(D31="",$F$27*LIDER!$H$9+$G$27*LIDER!$H$10+$H$27*LIDER!$H$11+$I$27*LIDER!$H$12+$J$27*LIDER!$H$13+$K$27*LIDER!$H$14+$L$27*LIDER!$H$15,"N")) -> 0
A32: 6 | B32: =LIDER!H48 -> 0 | C32: =C31 -> G04 | E32: =IF(B32=0,0,IF(D32="",$F$27*LIDER!$H$9+$G$27*LIDER!$H$10+$H$27*LIDER!$H$11+$I$27*LIDER!$H$12+$J$27*LIDER!$H$13+$K$27*LIDER!$H$14+$L$27*LIDER!$H$15,"N")) -> 0
B33: GRUPO#5 | C33: G05 | D33: =D26 -> LIST | E33: DEF | F33: =LIDER!$E$33 -> GRUPO#5 HAMACAS INTERNACIONALES CON COJINES ESTADOS UNIDOS, SUECIA Y ESPAÑA
A34: 1 | B34: =LIDER!E51 -> PADILLA MORALES VALERIE SOFIA | C34: =C33 -> G05 | E34: =IF(B34=0,0,IF(D34="",$F$34*LIDER!$H$9+$G$34*LIDER!$H$10+$H$34*LIDER!$H$11+$I$34*LIDER!$H$12+$J$34*LIDER!$H$13+$K$34*LIDER!$H$14+$L$34*LIDER!$H$15,"N")) -> 4.6 | F34: 4.6 | G34: 4.6 | H34: 4.6 | I34: 4.6 | J34: 4.6
A35: 2 | B35: =LIDER!E52 -> RODRIGUEZ ARCIA MARICRUZ | C35: =C34 -> G05 | E35: =IF(B35=0,0,IF(D35="",$F$34*LIDER!$H$9+$G$34*LIDER!$H$10+$H$34*LIDER!$H$11+$I$34*LIDER!$H$12+$J$34*LIDER!$H$13+$K$34*LIDER!$H$14+$L$34*LIDER!$H$15,"N")) -> 4.6
A36: 3 | B36: =LIDER!E53 -> DONADO ALMANZA DAVID | C36: =C35 -> G05 | E36: =IF(B36=0,0,IF(D36="",$F$34*LIDER!$H$9+$G$34*LIDER!$H$10+$H$34*LIDER!$H$11+$I$34*LIDER!$H$12+$J$34*LIDER!$H$13+$K$34*LIDER!$H$14+$L$34*LIDER!$H$15,"N")) -> 4.6
A37: 4 | B37: =LIDER!E54 -> 0 | C37: =C36 -> G05 | E37: =IF(B37=0,0,IF(D37="",$F$34*LIDER!$H$9+$G$34*LIDER!$H$10+$H$34*LIDER!$H$11+$I$34*LIDER!$H$12+$J$34*LIDER!$H$13+$K$34*LIDER!$H$14+$L$34*LIDER!$H$15,"N")) -> 0
A38: 5 | B38: =LIDER!E55 -> 0 | C38: =C37 -> G05 | E38: =IF(B38=0,0,IF(D38="",$F$34*LIDER!$H$9+$G$34*LIDER!$H$10+$H$34*LIDER!$H$11+$I$34*LIDER!$H$12+$J$34*LIDER!$H$13+$K$34*LIDER!$H$14+$L$34*LIDER!$H$15,"N")) -> 0
A39: 6 | B39: =LIDER!E56 -> 0 | C39: =C38 -> G05 | E39: =IF(B39=0,0,IF(D39="",$F$34*LIDER!$H$9+$G$34*LIDER!$H$10+$H$34*LIDER!$H$11+$I$34*LIDER!$H$12+$J$34*LIDER!$H$13+$K$34*LIDER!$H$14+$L$34*LIDER!$H$15,"N")) -> 0
B40: GRUPO#6 | C40: G06 | D40: =D33 -> LIST | E40: DEF | F40: =LIDER!$E$34 -> GRUPO#6 COSMETICOS A BASE DE CAFE , ESPAÑA , ESTADOS UNIDOS, CANADA
...

Sheet S-ASIG-06
A1: =LIDER!B2 -> TECNOLOGÍA EN GESTIÓN DE NEGOCIOS INTERN | I1: =LIDER!E2 -> SEMESTRE: | J1: =LIDER!F2 -> SEM-04 | K1: =LIDER!G2 -> SECCIÓN: | L1: =LIDER!H2 -> 2
B2: =LIDER!H4 -> FUNDAMENTOS DE FINANZAS | F2: CRITERIOS DE EVALUACIÓN
B3: Estudiantes | F3: =LIDER!E9 -> PRESENTACIÓN GENERAL: Adopta la norma APA, tamaño de la hoja, margenes, titulo, portadas, numeración de paginas, tabla de contenido automatizada, ortografia, justificacion del texto, citas automatizadas, listas, figuras,etc. | G3: =LIDER!E10 -> ANTEPROYECTO: Portada, planteamiento del problema, justificacion del trabajo o proyecto de aula, objetivos, marco teorico, diseño metodologico. | H3: =LIDER!E11 -> RESULTADOS: Analiza, integra y aplica de manera coherente los aspectos del análisis del entorno(Variables Macroeconómicas, Factores Sociales y Culturales, Factores Políticos y Legales,Factores Tecnológicos y Factores Ambientales) en el desarrollo de la propuesta investigativa, evidenciando capacidad para generar soluciones viables, pertinentes y sostenibles. | I3: =LIDER!E12 -> BILIOGRAFIA: Las referencias bibliograficas adoptan las normas APA. El documento es producto de un rastreo bibliografico que muestra analisis y sistensis. | J3: =LIDER!E13 -> ASESORIAS: Anexó la hoja de tutoria firmada ( 3 fimas minmimo). | K3: =LIDER!E14 -> 0 | L3: =LIDER!E15 -> 0
F4: =CONCATENATE(LIDER!H4," - ",LIDER!H6," - ",LIDER!H5) -> FUNDAMENTOS DE FINANZAS - 1512 - LEONARDO CARLOS DE ORO BARRIOS
B5: GRUPO#1 | C5: G01 | D5: LIST | E5: DEF | F5: =LIDER!$E$29 -> GRUPO#1 Vestidos de Baño en Crochet (Brazil, Estados Unidos y República Dominicana)
A6: 1 | B6: =LIDER!E43 -> BARRIOS BENITEZ EMILY | C6: =C5 -> G01 | E6: =IF(B6=0,0,IF(D6="",$F$6*LIDER!$H$9+$G$6*LIDER!$H$10+$H$6*LIDER!$H$11+$I$6*LIDER!$H$12+$J$6*LIDER!$H$13+$K$6*LIDER!$H$14+$L$6*LIDER!$H$15,"N")) -> 3.53 | F6: 3.7 | G6: 4.2 | H6: 3.5 | I6: 2 | J6: 5
A7: 2 | B7: =LIDER!E44 -> HERRERA TEJEDOR BRENDIS VANESA | C7: =C6 -> G01 | E7: =IF(B7=0,0,IF(D7="",$F$6*LIDER!$H$9+$G$6*LIDER!$H$10+$H$6*LIDER!$H$11+$I$6*LIDER!$H$12+$J$6*LIDER!$H$13+$K$6*LIDER!$H$14+$L$6*LIDER!$H$15,"N")) -> 3.53
A8: 3 | B8: =LIDER!E45 -> RUIZ RIVERO HEILEEN CAROLINA | C8: =C7 -> G01 | D8: N | E8: =IF(B8=0,0,IF(D8="",$F$6*LIDER!$H$9+$G$6*LIDER!$H$10+$H$6*LIDER!$H$11+$I$6*LIDER!$H$12+$J$6*LIDER!$H$13+$K$6*LIDER!$H$14+$L$6*LIDER!$H$15,"N")) -> N
A9: 4 | B9: =LIDER!E46 -> DE ARCOS AVENDAÑO SAID JADITH | C9: =C8 -> G01 | D9: N | E9: =IF(B9=0,0,IF(D9="",$F$6*LIDER!$H$9+$G$6*LIDER!$H$10+$H$6*LIDER!$H$11+$I$6*LIDER!$H$12+$J$6*LIDER!$H$13+$K$6*LIDER!$H$14+$L$6*LIDER!$H$15,"N")) -> N
A10: 5 | B10: =LIDER!E47 -> CASTILLO VILLA NELDA SOFIA | C10: =C9 -> G01 | E10: =IF(B10=0,0,IF(D10="",$F$6*LIDER!$H$9+$G$6*LIDER!$H$10+$H$6*LIDER!$H$11+$I$6*LIDER!$H$12+$J$6*LIDER!$H$13+$K$6*LIDER!$H$14+$L$6*LIDER!$H$15,"N")) -> 3.53
A11: 6 | B11: =LIDER!E48 -> 0 | C11: =C10 -> G01 | E11: =IF(B11=0,0,IF(D11="",$F$6*LIDER!$H$9+$G$6*LIDER!$H$10+$H$6*LIDER!$H$11+$I$6*LIDER!$H$12+$J$6*LIDER!$H$13+$K$6*LIDER!$H$14+$L$6*LIDER!$H$15,"N")) -> 0
B12: GRUPO#2 | C12: G02 | D12: =D5 -> LIST | E12: DEF | F12: =LIDER!$E$30 -> GRUPO#2 VINO DE MARACUYA, CHILE , PANAMA Y ESTADOS UNDOS)
A13: 1 | B13: =LIDER!F43 -> NARVAEZ MORELO WISNEEY | C13: =C12 -> G02 | E13: =IF(B13=0,0,IF(D13="",$F$13*LIDER!$H$9+$G$13*LIDER!$H$10+$H$13*LIDER!$H$11+$I$13*LIDER!$H$12+$J$13*LIDER!$H$13+$K$13*LIDER!$H$14+$L$13*LIDER!$H$15,"N")) -> 4.2 | F13: 4.2 | G13: 4.2 | H13: 4.2 | I13: 4.2 | J13: 4.2
A14: 2 | B14: =LIDER!F44 -> CASUSOL RODRIGUEZ AYLIN MARIANA | C14: =C13 -> G02 | D14: N | E14: =IF(B14=0,0,IF(D14="",$F$13*LIDER!$H$9+$G$13*LIDER!$H$10+$H$13*LIDER!$H$11+$I$13*LIDER!$H$12+$J$13*LIDER!$H$13+$K$13*LIDER!$H$14+$L$13*LIDER!$H$15,"N")) -> N
A15: 3 | B15: =LIDER!F45 -> CARMONA SIERRA YIRLEIS PATRICIA | C15: =C14 -> G02 | E15: =IF(B15=0,0,IF(D15="",$F$13*LIDER!$H$9+$G$13*LIDER!$H$10+$H$13*LIDER!$H$11+$I$13*LIDER!$H$12+$J$13*LIDER!$H$13+$K$13*LIDER!$H$14+$L$13*LIDER!$H$15,"N")) -> 4.2
A16: 4 | B16: =LIDER!F46 -> MAGALLANES PEDROZA VALENTINA | C16: =C15 -> G02 | E16: =IF(B16=0,0,IF(D16="",$F$13*LIDER!$H$9+$G$13*LIDER!$H$10+$H$13*LIDER!$H$11+$I$13*LIDER!$H$12+$J$13*LIDER!$H$13+$K$13*LIDER!$H$14+$L$13*LIDER!$H$15,"N")) -> 4.2
A17: 5 | B17: =LIDER!F47 -> MOLINA PÁJARO MARIA DE LOS ÁNGELES | C17: =C16 -> G02 | E17: =IF(B17=0,0,IF(D17="",$F$13*LIDER!$H$9+$G$13*LIDER!$H$10+$H$13*LIDER!$H$11+$I$13*LIDER!$H$12+$J$13*LIDER!$H$13+$K$13*LIDER!$H$14+$L$13*LIDER!$H$15,"N")) -> 4.2
A18: 6 | B18: =LIDER!F48 -> ESMERAL CORDERO NORIETH CAROLINA | C18: =C17 -> G02 | D18: N | E18: =IF(B18=0,0,IF(D18="",$F$13*LIDER!$H$9+$G$13*LIDER!$H$10+$H$13*LIDER!$H$11+$I$13*LIDER!$H$12+$J$13*LIDER!$H$13+$K$13*LIDER!$H$14+$L$13*LIDER!$H$15,"N")) -> N
B19: GRUPO#3 | C19: G03 | D19: =D12 -> LIST | E19: DEF | F19: =LIDER!$E$31 -> GRUPO#3 TRAJES DE BAÑO PARA PERSONAS DE CONTEXTURA GRUESA (
A20: 1 | B20: =LIDER!G43 -> CHAVEZ ARRIETA EVELYN SHARY | C20: =C19 -> G03 | E20: =IF(B20=0,0,IF(D20="",$F$20*LIDER!$H$9+$G$20*LIDER!$H$10+$H$20*LIDER!$H$11+$I$20*LIDER!$H$12+$J$20*LIDER!$H$13+$K$20*LIDER!$H$14+$L$20*LIDER!$H$15,"N")) -> 3.25 | F20: 4 | G20: 4 | H20: 3.5 | I20: 2.5 | J20: 1
A21: 2 | B21: =LIDER!G44 -> PEREZ MORENO ANA ISABEL | C21: =C20 -> G03 | D21: N | E21: =IF(B21=0,0,IF(D21="",$F$20*LIDER!$H$9+$G$20*LIDER!$H$10+$H$20*LIDER!$H$11+$I$20*LIDER!$H$12+$J$20*LIDER!$H$13+$K$20*LIDER!$H$14+$L$20*LIDER!$H$15,"N")) -> N
A22: 3 | B22: =LIDER!G45 -> PÁJARO DE LA PEÑA ANGELA ISABEL | C22: =C21 -> G03 | E22: =IF(B22=0,0,IF(D22="",$F$20*LIDER!$H$9+$G$20*LIDER!$H$10+$H$20*LIDER!$H$11+$I$20*LIDER!$H$12+$J$20*LIDER!$H$13+$K$20*LIDER!$H$14+$L$20*LIDER!$H$15,"N")) -> 3.25
A23: 4 | B23: =LIDER!G46 -> 0 | C23: =C22 -> G03 | E23: =IF(B23=0,0,IF(D23="",$F$20*LIDER!$H$9+$G$20*LIDER!$H$10+$H$20*LIDER!$H$11+$I$20*LIDER!$H$12+$J$20*LIDER!$H$13+$K$20*LIDER!$H$14+$L$20*LIDER!$H$15,"N")) -> 0
A24: 5 | B24: =LIDER!G47 -> 0 | C24: =C23 -> G03 | E24: =IF(B24=0,0,IF(D24="",$F$20*LIDER!$H$9+$G$20*LIDER!$H$10+$H$20*LIDER!$H$11+$I$20*LIDER!$H$12+$J$20*LIDER!$H$13+$K$20*LIDER!$H$14+$L$20*LIDER!$H$15,"N")) -> 0
A25: 6 | B25: =LIDER!G48 -> 0 | C25: =C24 -> G03 | E25: =IF(B25=0,0,IF(D25="",$F$20*LIDER!$H$9+$G$20*LIDER!$H$10+$H$20*LIDER!$H$11+$I$20*LIDER!$H$12+$J$20*LIDER!$H$13+$K$20*LIDER!$H$14+$L$20*LIDER!$H$15,"N")) -> 0
B26: GRUPO#4 | C26: G04 | D26: =D19 -> LIST | E26: DEF | F26: =LIDER!$E$32 -> GRUPO#4 KITS PICKNIC ESPAÑA, BRAZIL Y PERU
