Workbook

Sheet DEFINITIVAS
G1: =LIDER!B2 -> TECNOLOGÍA EN GESTIÓN DE NEGOCIOS INTERN | N1: =LIDER!E2 -> SEMESTRE: | P1: =LIDER!F2 -> SEM-03 | Q1: =LIDER!G2 -> SECCIÓN: | R1: =LIDER!H2 -> 2
G2: SEGUNDO CORTE | O2: TERCER CORTE
G3: =CONCATENATE("N° : ",LIDER!C6) -> N° : 1412 | H3: =CONCATENATE("N° : ",LIDER!D6) -> N° : 2388 | I3: =CONCATENATE("N° : ",LIDER!E6) -> N° : 2482 | J3: =CONCATENATE("N° : ",LIDER!F6) -> N° : 2490 | K3: =CONCATENATE("N° : ",LIDER!G6) -> N° : 1532 | L3: =CONCATENATE("N° : ",LIDER!H6) -> N° : | M3: =CONCATENATE("N° : ",LIDER!I6) -> N° : | O3: =G3 -> N° : 1412 | P3: =H3 -> N° : 2388 | Q3: =I3 -> N° : 2482 | R3: =J3 -> N° : 2490 | S3: =K3 -> N° : 1532 | T3: =L3 -> N° : | U3: =M3 -> N° :
B4: LISTA DE ESTUDIANTES | C4: GP | D4: SEG-CORTE | E4: TER-CORTE | G4: =MID(LIDER!C4,1,9) -> MATEMÁTIC | H4: =MID(LIDER!D4,1,9) -> TECNOLOGI | I4: =MID(LIDER!E4,1,9) -> INTERNACI | J4: =MID(LIDER!F4,1,9) -> LEGISLACI | K4: =MID(LIDER!G4,1,9) -> MACROECON | L4: =MID(LIDER!H4,1,9) | M4: =MID(LIDER!I4,1,9) | N4: P2 | O4: =G4 -> MATEMÁTIC | P4: =H4 -> TECNOLOGI | Q4: =I4 -> INTERNACI | R4: =J4 -> LEGISLACI | S4: =K4 -> MACROECON | T4: =L4 | U4: =M4 | V4: P3
A5: 1 | B5: =LIDER!C9 -> SARA OYOLA MARTINEZ | C5: =IF(B5=0,"",IFERROR(VLOOKUP(B5,'S-ASIG-01'!$B$5:$E$88,2,0),0)) -> G01 | D5: =IF(B5=0,"",IFERROR(SUMIF(G5:M5,">0",G5:M5)/COUNTIF(G5:M5,">0"),0)) -> 4.508 | E5: =IF(B5=0,"",IFERROR(SUMIF(O5:U5,">0",O5:U5)/COUNTIF(O5:U5,">0"),0)) -> 4.61 | G5: =IF(B5=0,"",IFERROR(VLOOKUP(B5,'S-ASIG-01'!$B$5:$E$88,4,0),0)) -> 4.25 | H5: =IF(B5=0,"",IFERROR(VLOOKUP(B5,'S-ASIG-02'!$B$5:$E$88,4,0),0)) -> 4.5 | I5: =IF(B5=0,"",IFERROR(VLOOKUP(B5,'S-ASIG-03'!$B$5:$E$88,4,0),0)) -> 4.5 | J5: =IF(B5=0,"",IFERROR(VLOOKUP(B5,'S-ASIG-04'!$B$5:$E$88,4,0),0)) -> 4.74 | K5: =IF(B5=0,"",IFERROR(VLOOKUP(B5,'S-ASIG-05'!$B$5:$E$88,4,0),0)) -> 4.55 | L5: =IF(B5=0,"",IFERROR(VLOOKUP(B5,'S-ASIG-06'!$B$5:$E$88,4,0),0)) -> 0 | M5: =IF(B5=0,"",IFERROR(VLOOKUP(B5,'S-ASIG-07'!$B$5:$E$88,4,0),0)) -> 0 | N5: S | O5: =IF(B5=0,"",IFERROR(VLOOKUP(B5,'T-ASIG-01'!$B$5:$D$88,3,0),0)) -> 4.6 | P5: =IF(B5=0,"",IFERROR(VLOOKUP(B5,'T-ASIG-02'!$B$5:$D$88,3,0),0)) -> 4.6 | Q5: =IF(B5=0,"",IFERROR(VLOOKUP(B5,'T-ASIG-03'!$B$5:$D$88,3,0),0)) -> 4.5 | R5: =IF(B5=0,"",IFERROR(VLOOKUP(B5,'T-ASIG-04'!$B$5:$D$88,3,0),0)) -> 4.7 | S5: =IF(B5=0,"",IFERROR(VLOOKUP(B5,'T-ASIG-05'!$B$5:$D$88,3,0),0)) -> 4.65 | T5: =IF(B5=0,"",IFERROR(VLOOKUP(B5,'T-ASIG-06'!$B$5:$D$88,3,0),0)) -> 0 | U5: =IF(B5=0,"",IFERROR(VLOOKUP(B5,'T-ASIG-07'!$B$5:$D$88,3,0),0)) -> 0 | V5: T
A6: 2 | B6: =LIDER!C10 -> YINA MARCELA PÉREZ PINEDA | C6: =IF(B6=0,"",IFERROR(VLOOKUP(B6,'S-ASIG-01'!$B$5:$E$88,2,0),0)) -> G01 | D6: =IF(B6=0,"",IFERROR(SUMIF(G6:M6,">0",G6:M6)/COUNTIF(G6:M6,">0"),0)) -> 4.508 | E6: =IF(B6=0,"",IFERROR(SUMIF(O6:U6,">0",O6:U6)/COUNTIF(O6:U6,">0"),0)) -> 4.61 | G6: =IF(B6=0,"",IFERROR(VLOOKUP(B6,'S-ASIG-01'!$B$5:$E$88,4,0),0)) -> 4.25 | H6: =IF(B6=0,"",IFERROR(VLOOKUP(B6,'S-ASIG-02'!$B$5:$E$88,4,0),0)) -> 4.5 | I6: =IF(B6=0,"",IFERROR(VLOOKUP(B6,'S-ASIG-03'!$B$5:$E$88,4,0),0)) -> 4.5 | J6: =IF(B6=0,"",IFERROR(VLOOKUP(B6,'S-ASIG-04'!$B$5:$E$88,4,0),0)) -> 4.74 | K6: =IF(B6=0,"",IFERROR(VLOOKUP(B6,'S-ASIG-05'!$B$5:$E$88,4,0),0)) -> 4.55 | L6: =IF(B6=0,"",IFERROR(VLOOKUP(B6,'S-ASIG-06'!$B$5:$E$88,4,0),0)) -> 0 | M6: =IF(B6=0,"",IFERROR(VLOOKUP(B6,'S-ASIG-07'!$B$5:$E$88,4,0),0)) -> 0 | N6: S | O6: =IF(B6=0,"",IFERROR(VLOOKUP(B6,'T-ASIG-01'!$B$5:$D$88,3,0),0)) -> 4.6 | P6: =IF(B6=0,"",IFERROR(VLOOKUP(B6,'T-ASIG-02'!$B$5:$D$88,3,0),0)) -> 4.6 | Q6: =IF(B6=0,"",IFERROR(VLOOKUP(B6,'T-ASIG-03'!$B$5:$D$88,3,0),0)) -> 4.5 | R6: =IF(B6=0,"",IFERROR(VLOOKUP(B6,'T-ASIG-04'!$B$5:$D$88,3,0),0)) -> 4.7 | S6: =IF(B6=0,"",IFERROR(VLOOKUP(B6,'T-ASIG-05'!$B$5:$D$88,3,0),0)) -> 4.65 | T6: =IF(B6=0,"",IFERROR(VLOOKUP(B6,'T-ASIG-06'!$B$5:$D$88,3,0),0)) -> 0 | U6: =IF(B6=0,"",IFERROR(VLOOKUP(B6,'T-ASIG-07'!$B$5:$D$88,3,0),0)) -> 0 | V6: T
A7: 3 | B7: =LIDER!C11 -> JABES ELIAS ROSERO VILLA | C7: =IF(B7=0,"",IFERROR(VLOOKUP(B7,'S-ASIG-01'!$B$5:$E$88,2,0),0)) -> G01 | D7: =IF(B7=0,"",IFERROR(SUMIF(G7:M7,">0",G7:M7)/COUNTIF(G7:M7,">0"),0)) -> 4.508 | E7: =IF(B7=0,"",IFERROR(SUMIF(O7:U7,">0",O7:U7)/COUNTIF(O7:U7,">0"),0)) -> 4.61 | G7: =IF(B7=0,"",IFERROR(VLOOKUP(B7,'S-ASIG-01'!$B$5:$E$88,4,0),0)) -> 4.25 | H7: =IF(B7=0,"",IFERROR(VLOOKUP(B7,'S-ASIG-02'!$B$5:$E$88,4,0),0)) -> 4.5 | I7: =IF(B7=0,"",IFERROR(VLOOKUP(B7,'S-ASIG-03'!$B$5:$E$88,4,0),0)) -> 4.5 | J7: =IF(B7=0,"",IFERROR(VLOOKUP(B7,'S-ASIG-04'!$B$5:$E$88,4,0),0)) -> 4.74 | K7: =IF(B7=0,"",IFERROR(VLOOKUP(B7,'S-ASIG-05'!$B$5:$E$88,4,0),0)) -> 4.55 | L7: =IF(B7=0,"",IFERROR(VLOOKUP(B7,'S-ASIG-06'!$B$5:$E$88,4,0),0)) -> 0 | M7: =IF(B7=0,"",IFERROR(VLOOKUP(B7,'S-ASIG-07'!$B$5:$E$88,4,0),0)) -> 0 | N7: S | O7: =IF(B7=0,"",IFERROR(VLOOKUP(B7,'T-ASIG-01'!$B$5:$D$88,3,0),0)) -> 4.6 | P7: =IF(B7=0,"",IFERROR(VLOOKUP(B7,'T-ASIG-02'!$B$5:$D$88,3,0),0)) -> 4.6 | Q7: =IF(B7=0,"",IFERROR(VLOOKUP(B7,'T-ASIG-03'!$B$5:$D$88,3,0),0)) -> 4.5 | R7: =IF(B7=0,"",IFERROR(VLOOKUP(B7,'T-ASIG-04'!$B$5:$D$88,3,0),0)) -> 4.7 | S7: =IF(B7=0,"",IFERROR(VLOOKUP(B7,'T-ASIG-05'!$B$5:$D$88,3,0),0)) -> 4.65 | T7: =IF(B7=0,"",IFERROR(VLOOKUP(B7,'T-ASIG-06'!$B$5:$D$88,3,0),0)) -> 0 | U7: =IF(B7=0,"",IFERROR(VLOOKUP(B7,'T-ASIG-07'!$B$5:$D$88,3,0),0)) -> 0 | V7: T
A8: 4 | B8: =LIDER!C12 -> ISAIAS FERNANDO SALCEDO CAICEDO | C8: =IF(B8=0,"",IFERROR(VLOOKUP(B8,'S-ASIG-01'!$B$5:$E$88,2,0),0)) -> G01 | D8: =IF(B8=0,"",IFERROR(SUMIF(G8:M8,">0",G8:M8)/COUNTIF(G8:M8,">0"),0)) -> 4.508 | E8: =IF(B8=0,"",IFERROR(SUMIF(O8:U8,">0",O8:U8)/COUNTIF(O8:U8,">0"),0)) -> 4.61 | G8: =IF(B8=0,"",IFERROR(VLOOKUP(B8,'S-ASIG-01'!$B$5:$E$88,4,0),0)) -> 4.25 | H8: =IF(B8=0,"",IFERROR(VLOOKUP(B8,'S-ASIG-02'!$B$5:$E$88,4,0),0)) -> 4.5 | I8: =IF(B8=0,"",IFERROR(VLOOKUP(B8,'S-ASIG-03'!$B$5:$E$88,4,0),0)) -> 4.5 | J8: =IF(B8=0,"",IFERROR(VLOOKUP(B8,'S-ASIG-04'!$B$5:$E$88,4,0),0)) -> 4.74 | K8: =IF(B8=0,"",IFERROR(VLOOKUP(B8,'S-ASIG-05'!$B$5:$E$88,4,0),0)) -> 4.55 | L8: =IF(B8=0,"",IFERROR(VLOOKUP(B8,'S-ASIG-06'!$B$5:$E$88,4,0),0)) -> 0 | M8: =IF(B8=0,"",IFERROR(VLOOKUP(B8,'S-ASIG-07'!$B$5:$E$88,4,0),0)) -> 0 | N8: S | O8: =IF(B8=0,"",IFERROR(VLOOKUP(B8,'T-ASIG-01'!$B$5:$D$88,3,0),0)) -> 4.6 | P8: =IF(B8=0,"",IFERROR(VLOOKUP(B8,'T-ASIG-02'!$B$5:$D$88,3,0),0)) -> 4.6 | Q8: =IF(B8=0,"",IFERROR(VLOOKUP(B8,'T-ASIG-03'!$B$5:$D$88,3,0),0)) -> 4.5 | R8: =IF(B8=0,"",IFERROR(VLOOKUP(B8,'T-ASIG-04'!$B$5:$D$88,3,0),0)) -> 4.7 | S8: =IF(B8=0,"",IFERROR(VLOOKUP(B8,'T-ASIG-05'!$B$5:$D$88,3,0),0)) -> 4.65 | T8: =IF(B8=0,"",IFERROR(VLOOKUP(B8,'T-ASIG-06'!$B$5:$D$88,3,0),0)) -> 0 | U8: =IF(B8=0,"",IFERROR(VLOOKUP(B8,'T-ASIG-07'!$B$5:$D$88,3,0),0)) -> 0 | V8: T
A9: 5 | B9: =LIDER!C13 -> JORGE ALBERTO BATISTA TABORDA | C9: =IF(B9=0,"",IFERROR(VLOOKUP(B9,'S-ASIG-01'!$B$5:$E$88,2,0),0)) -> G02 | D9: =IF(B9=0,"",IFERROR(SUMIF(G9:M9,">0",G9:M9)/COUNTIF(G9:M9,">0"),0)) -> 3.924 | E9: =IF(B9=0,"",IFERROR(SUMIF(O9:U9,">0",O9:U9)/COUNTIF(O9:U9,">0"),0)) -> 3.93 | G9: =IF(B9=0,"",IFERROR(VLOOKUP(B9,'S-ASIG-01'!$B$5:$E$88,4,0),0)) -> 3.84 | H9: =IF(B9=0,"",IFERROR(VLOOKUP(B9,'S-ASIG-02'!$B$5:$E$88,4,0),0)) -> 4 | I9: =IF(B9=0,"",IFERROR(VLOOKUP(B9,'S-ASIG-03'!$B$5:$E$88,4,0),0)) -> 4.2 | J9: =IF(B9=0,"",IFERROR(VLOOKUP(B9,'S-ASIG-04'!$B$5:$E$88,4,0),0)) -> 3.46 | K9: =IF(B9=0,"",IFERROR(VLOOKUP(B9,'S-ASIG-05'!$B$5:$E$88,4,0),0)) -> 4.12 | L9: =IF(B9=0,"",IFERROR(VLOOKUP(B9,'S-ASIG-06'!$B$5:$E$88,4,0),0)) -> 0 | M9: =IF(B9=0,"",IFERROR(VLOOKUP(B9,'S-ASIG-07'!$B$5:$E$88,4,0),0)) -> 0 | N9: S | O9: =IF(B9=0,"",IFERROR(VLOOKUP(B9,'T-ASIG-01'!$B$5:$D$88,3,0),0)) -> 4.05 | P9: =IF(B9=0,"",IFERROR(VLOOKUP(B9,'T-ASIG-02'!$B$5:$D$88,3,0),0)) -> 3.75 | Q9: =IF(B9=0,"",IFERROR(VLOOKUP(B9,'T-ASIG-03'!$B$5:$D$88,3,0),0)) -> 4.1 | R9: =IF(B9=0,"",IFERROR(VLOOKUP(B9,'T-ASIG-04'!$B$5:$D$88,3,0),0)) -> 3.5 | S9: =IF(B9=0,"",IFERROR(VLOOKUP(B9,'T-ASIG-05'!$B$5:$D$88,3,0),0)) -> 4.25 | T9: =IF(B9=0,"",IFERROR(VLOOKUP(B9,'T-ASIG-06'!$B$5:$D$88,3,0),0)) -> 0 | U9: =IF(B9=0,"",IFERROR(VLOOKUP(B9,'T-ASIG-07'!$B$5:$D$88,3,0),0)) -> 0 | V9: T
A10: 6 | B10: =LIDER!C14 -> JEREMY MACOLL DIAZ PEREZ | C10: =IF(B10=0,"",IFERROR(VLOOKUP(B10,'S-ASIG-01'!$B$5:$E$88,2,0),0)) -> G02 | D10: =IF(B10=0,"",IFERROR(SUMIF(G10:M10,">0",G10:M10)/COUNTIF(G10:M10,">0"),0)) -> 3.924 | E10: =IF(B10=0,"",IFERROR(SUMIF(O10:U10,">0",O10:U10)/COUNTIF(O10:U10,">0"),0)) -> 3.93 | G10: =IF(B10=0,"",IFERROR(VLOOKUP(B10,'S-ASIG-01'!$B$5:$E$88,4,0),0)) -> 3.84 | H10: =IF(B10=0,"",IFERROR(VLOOKUP(B10,'S-ASIG-02'!$B$5:$E$88,4,0),0)) -> 4 | I10: =IF(B10=0,"",IFERROR(VLOOKUP(B10,'S-ASIG-03'!$B$5:$E$88,4,0),0)) -> 4.2 | J10: =IF(B10=0,"",IFERROR(VLOOKUP(B10,'S-ASIG-04'!$B$5:$E$88,4,0),0)) -> 3.46 | K10: =IF(B10=0,"",IFERROR(VLOOKUP(B10,'S-ASIG-05'!$B$5:$E$88,4,0),0)) -> 4.12 | L10: =IF(B10=0,"",IFERROR(VLOOKUP(B10,'S-ASIG-06'!$B$5:$E$88,4,0),0)) -> 0 | M10: =IF(B10=0,"",IFERROR(VLOOKUP(B10,'S-ASIG-07'!$B$5:$E$88,4,0),0)) -> 0 | N10: S | O10: =IF(B10=0,"",IFERROR(VLOOKUP(B10,'T-ASIG-01'!$B$5:$D$88,3,0),0)) -> 4.05 | P10: =IF(B10=0,"",IFERROR(VLOOKUP(B10,'T-ASIG-02'!$B$5:$D$88,3,0),0)) -> 3.75 | Q10: =IF(B10=0,"",IFERROR(VLOOKUP(B10,'T-ASIG-03'!$B$5:$D$88,3,0),0)) -> 4.1 | R10: =IF(B10=0,"",IFERROR(VLOOKUP(B10,'T-ASIG-04'!$B$5:$D$88,3,0),0)) -> 3.5 | S10: =IF(B10=0,"",IFERROR(VLOOKUP(B10,'T-ASIG-05'!$B$5:$D$88,3,0),0)) -> 4.25 | T10: =IF(B10=0,"",IFERROR(VLOOKUP(B10,'T-ASIG-06'!$B$5:$D$88,3,0),0)) -> 0 | U10: =IF(B10=0,"",IFERROR(VLOOKUP(B10,'T-ASIG-07'!$B$5:$D$88,3,0),0)) -> 0 | V10: T
A11: 7 | B11: =LIDER!C15 -> DARIANY PEÑARANDA LLACH | C11: =IF(B11=0,"",IFERROR(VLOOKUP(B11,'S-ASIG-01'!$B$5:$E$88,2,0),0)) -> G02 | D11: =IF(B11=0,"",IFERROR(SUMIF(G11:M11,">0",G11:M11)/COUNTIF(G11:M11,">0"),0)) -> 3.924 | E11: =IF(B11=0,"",IFERROR(SUMIF(O11:U11,">0",O11:U11)/COUNTIF(O11:U11,">0"),0)) -> 3.93 | G11: =IF(B11=0,"",IFERROR(VLOOKUP(B11,'S-ASIG-01'!$B$5:$E$88,4,0),0)) -> 3.84 | H11: =IF(B11=0,"",IFERROR(VLOOKUP(B11,'S-ASIG-02'!$B$5:$E$88,4,0),0)) -> 4 | I11: =IF(B11=0,"",IFERROR(VLOOKUP(B11,'S-ASIG-03'!$B$5:$E$88,4,0),0)) -> 4.2 | J11: =IF(B11=0,"",IFERROR(VLOOKUP(B11,'S-ASIG-04'!$B$5:$E$88,4,0),0)) -> 3.46 | K11: =IF(B11=0,"",IFERROR(VLOOKUP(B11,'S-ASIG-05'!$B$5:$E$88,4,0),0)) -> 4.12 | L11: =IF(B11=0,"",IFERROR(VLOOKUP(B11,'S-ASIG-06'!$B$5:$E$88,4,0),0)) -> 0 | M11: =IF(B11=0,"",IFERROR(VLOOKUP(B11,'S-ASIG-07'!$B$5:$E$88,4,0),0)) -> 0 | N11: S | O11: =IF(B11=0,"",IFERROR(VLOOKUP(B11,'T-ASIG-01'!$B$5:$D$88,3,0),0)) -> 4.05 | P11: =IF(B11=0,"",IFERROR(VLOOKUP(B11,'T-ASIG-02'!$B$5:$D$88,3,0),0)) -> 3.75 | Q11: =IF(B11=0,"",IFERROR(VLOOKUP(B11,'T-ASIG-03'!$B$5:$D$88,3,0),0)) -> 4.1 | R11: =IF(B11=0,"",IFERROR(VLOOKUP(B11,'T-ASIG-04'!$B$5:$D$88,3,0),0)) -> 3.5 | S11: =IF(B11=0,"",IFERROR(VLOOKUP(B11,'T-ASIG-05'!$B$5:$D$88,3,0),0)) -> 4.25 | T11: =IF(B11=0,"",IFERROR(VLOOKUP(B11,'T-ASIG-06'!$B$5:$D$88,3,0),0)) -> 0 | U11: =IF(B11=0,"",IFERROR(VLOOKUP(B11,'T-ASIG-07'!$B$5:$D$88,3,0),0)) -> 0 | V11: T
A12: 8 | B12: =LIDER!C16 -> MARIANGEL ROMERO VANEGAS | C12: =IF(B12=0,"",IFERROR(VLOOKUP(B12,'S-ASIG-01'!$B$5:$E$88,2,0),0)) -> G02 | D12: =IF(B12=0,"",IFERROR(SUMIF(G12:M12,">0",G12:M12)/COUNTIF(G12:M12,">0"),0)) -> 3.924 | E12: =IF(B12=0,"",IFERROR(SUMIF(O12:U12,">0",O12:U12)/COUNTIF(O12:U12,">0"),0)) -> 3.85 | G12: =IF(B12=0,"",IFERROR(VLOOKUP(B12,'S-ASIG-01'!$B$5:$E$88,4,0),0)) -> 3.84 | H12: =IF(B12=0,"",IFERROR(VLOOKUP(B12,'S-ASIG-02'!$B$5:$E$88,4,0),0)) -> 4 | I12: =IF(B12=0,"",IFERROR(VLOOKUP(B12,'S-ASIG-03'!$B$5:$E$88,4,0),0)) -> 4.2 | J12: =IF(B12=0,"",IFERROR(VLOOKUP(B12,'S-ASIG-04'!$B$5:$E$88,4,0),0)) -> 3.46 | K12: =IF(B12=0,"",IFERROR(VLOOKUP(B12,'S-ASIG-05'!$B$5:$E$88,4,0),0)) -> 4.12 | L12: =IF(B12=0,"",IFERROR(VLOOKUP(B12,'S-ASIG-06'!$B$5:$E$88,4,0),0)) -> 0 | M12: =IF(B12=0,"",IFERROR(VLOOKUP(B12,'S-ASIG-07'!$B$5:$E$88,4,0),0)) -> 0 | N12: S | O12: =IF(B12=0,"",IFERROR(VLOOKUP(B12,'T-ASIG-01'!$B$5:$D$88,3,0),0)) -> 4.05 | P12: =IF(B12=0,"",IFERROR(VLOOKUP(B12,'T-ASIG-02'!$B$5:$D$88,3,0),0)) -> 3.75 | Q12: =IF(B12=0,"",IFERROR(VLOOKUP(B12,'T-ASIG-03'!$B$5:$D$88,3,0),0)) -> 4.1 | R12: =IF(B12=0,"",IFERROR(VLOOKUP(B12,'T-ASIG-04'!$B$5:$D$88,3,0),0)) -> 3.5 | S12: =IF(B12=0,"",IFERROR(VLOOKUP(B12,'T-ASIG-05'!$B$5:$D$88,3,0),0)) -> 0 | T12: =IF(B12=0,"",IFERROR(VLOOKUP(B12,'T-ASIG-06'!$B$5:$D$88,3,0),0)) -> 0 | U12: =IF(B12=0,"",IFERROR(VLOOKUP(B12,'T-ASIG-07'!$B$5:$D$88,3,0),0)) -> 0 | V12: T
A13: 9 | B13: =LIDER!C17 -> 0 | C13: =IF(B13=0,"",IFERROR(VLOOKUP(B13,'S-ASIG-01'!$B$5:$E$88,2,0),0)) | D13: =IF(B13=0,"",IFERROR(SUMIF(G13:M13,">0",G13:M13)/COUNTIF(G13:M13,">0"),0)) | E13: =IF(B13=0,"",IFERROR(SUMIF(O13:U13,">0",O13:U13)/COUNTIF(O13:U13,">0"),0)) | G13: =IF(B13=0,"",IFERROR(VLOOKUP(B13,'S-ASIG-01'!$B$5:$E$88,4,0),0)) | H13: =IF(B13=0,"",IFERROR(VLOOKUP(B13,'S-ASIG-02'!$B$5:$E$88,4,0),0)) | I13: =IF(B13=0,"",IFERROR(VLOOKUP(B13,'S-ASIG-03'!$B$5:$E$88,4,0),0)) | J13: =IF(B13=0,"",IFERROR(VLOOKUP(B13,'S-ASIG-04'!$B$5:$E$88,4,0),0)) | K13: =IF(B13=0,"",IFERROR(VLOOKUP(B13,'S-ASIG-05'!$B$5:$E$88,4,0),0)) | L13: =IF(B13=0,"",IFERROR(VLOOKUP(B13,'S-ASIG-06'!$B$5:$E$88,4,0),0)) | M13: =IF(B13=0,"",IFERROR(VLOOKUP(B13,'S-ASIG-07'!$B$5:$E$88,4,0),0)) | N13: S | O13: =IF(B13=0,"",IFERROR(VLOOKUP(B13,'T-ASIG-01'!$B$5:$D$88,3,0),0)) | P13: =IF(B13=0,"",IFERROR(VLOOKUP(B13,'T-ASIG-02'!$B$5:$D$88,3,0),0)) | Q13: =IF(B13=0,"",IFERROR(VLOOKUP(B13,'T-ASIG-03'!$B$5:$D$88,3,0),0)) | R13: =IF(B13=0,"",IFERROR(VLOOKUP(B13,'T-ASIG-04'!$B$5:$D$88,3,0),0)) | S13: =IF(B13=0,"",IFERROR(VLOOKUP(B13,'T-ASIG-05'!$B$5:$D$88,3,0),0)) | T13: =IF(B13=0,"",IFERROR(VLOOKUP(B13,'T-ASIG-06'!$B$5:$D$88,3,0),0)) | U13: =IF(B13=0,"",IFERROR(VLOOKUP(B13,'T-ASIG-07'!$B$5:$D$88,3,0),0)) | V13: T
A14: 10 | B14: =LIDER!C18 -> 0 | C14: =IF(B14=0,"",IFERROR(VLOOKUP(B14,'S-ASIG-01'!$B$5:$E$88,2,0),0)) | D14: =IF(B14=0,"",IFERROR(SUMIF(G14:M14,">0",G14:M14)/COUNTIF(G14:M14,">0"),0)) | E14: =IF(B14=0,"",IFERROR(SUMIF(O14:U14,">0",O14:U14)/COUNTIF(O14:U14,">0"),0)) | G14: =IF(B14=0,"",IFERROR(VLOOKUP(B14,'S-ASIG-01'!$B$5:$E$88,4,0),0)) | H14: =IF(B14=0,"",IFERROR(VLOOKUP(B14,'S-ASIG-02'!$B$5:$E$88,4,0),0)) | I14: =IF(B14=0,"",IFERROR(VLOOKUP(B14,'S-ASIG-03'!$B$5:$E$88,4,0),0)) | J14: =IF(B14=0,"",IFERROR(VLOOKUP(B14,'S-ASIG-04'!$B$5:$E$88,4,0),0)) | K14: =IF(B14=0,"",IFERROR(VLOOKUP(B14,'S-ASIG-05'!$B$5:$E$88,4,0),0)) | L14: =IF(B14=0,"",IFERROR(VLOOKUP(B14,'S-ASIG-06'!$B$5:$E$88,4,0),0)) | M14: =IF(B14=0,"",IFERROR(VLOOKUP(B14,'S-ASIG-07'!$B$5:$E$88,4,0),0)) | N14: S | O14: =IF(B14=0,"",IFERROR(VLOOKUP(B14,'T-ASIG-01'!$B$5:$D$88,3,0),0)) | P14: =IF(B14=0,"",IFERROR(VLOOKUP(B14,'T-ASIG-02'!$B$5:$D$88,3,0),0)) | Q14: =IF(B14=0,"",IFERROR(VLOOKUP(B14,'T-ASIG-03'!$B$5:$D$88,3,0),0)) | R14: =IF(B14=0,"",IFERROR(VLOOKUP(B14,'T-ASIG-04'!$B$5:$D$88,3,0),0)) | S14: =IF(B14=0,"",IFERROR(VLOOKUP(B14,'T-ASIG-05'!$B$5:$D$88,3,0),0)) | T14: =IF(B14=0,"",IFERROR(VLOOKUP(B14,'T-ASIG-06'!$B$5:$D$88,3,0),0)) | U14: =IF(B14=0,"",IFERROR(VLOOKUP(B14,'T-ASIG-07'!$B$5:$D$88,3,0),0)) | V14: T
A15: 11 | B15: =LIDER!C19 -> 0 | C15: =IF(B15=0,"",IFERROR(VLOOKUP(B15,'S-ASIG-01'!$B$5:$E$88,2,0),0)) | D15: =IF(B15=0,"",IFERROR(SUMIF(G15:M15,">0",G15:M15)/COUNTIF(G15:M15,">0"),0)) | E15: =IF(B15=0,"",IFERROR(SUMIF(O15:U15,">0",O15:U15)/COUNTIF(O15:U15,">0"),0)) | G15: =IF(B15=0,"",IFERROR(VLOOKUP(B15,'S-ASIG-01'!$B$5:$E$88,4,0),0)) | H15: =IF(B15=0,"",IFERROR(VLOOKUP(B15,'S-ASIG-02'!$B$5:$E$88,4,0),0)) | I15: =IF(B15=0,"",IFERROR(VLOOKUP(B15,'S-ASIG-03'!$B$5:$E$88,4,0),0)) | J15: =IF(B15=0,"",IFERROR(VLOOKUP(B15,'S-ASIG-04'!$B$5:$E$88,4,0),0)) | K15: =IF(B15=0,"",IFERROR(VLOOKUP(B15,'S-ASIG-05'!$B$5:$E$88,4,0),0)) | L15: =IF(B15=0,"",IFERROR(VLOOKUP(B15,'S-ASIG-06'!$B$5:$E$88,4,0),0)) | M15: =IF(B15=0,"",IFERROR(VLOOKUP(B15,'S-ASIG-07'!$B$5:$E$88,4,0),0)) | N15: S | O15: =IF(B15=0,"",IFERROR(VLOOKUP(B15,'T-ASIG-01'!$B$5:$D$88,3,0),0)) | P15: =IF(B15=0,"",IFERROR(VLOOKUP(B15,'T-ASIG-02'!$B$5:$D$88,3,0),0)) | Q15: =IF(B15=0,"",IFERROR(VLOOKUP(B15,'T-ASIG-03'!$B$5:$D$88,3,0),0)) | R15: =IF(B15=0,"",IFERROR(VLOOKUP(B15,'T-ASIG-04'!$B$5:$D$88,3,0),0)) | S15: =IF(B15=0,"",IFERROR(VLOOKUP(B15,'T-ASIG-05'!$B$5:$D$88,3,0),0)) | T15: =IF(B15=0,"",IFERROR(VLOOKUP(B15,'T-ASIG-06'!$B$5:$D$88,3,0),0)) | U15: =IF(B15=0,"",IFERROR(VLOOKUP(B15,'T-ASIG-07'!$B$5:$D$88,3,0),0)) | V15: T
A16: 12 | B16: =LIDER!C20 -> 0 | C16: =IF(B16=0,"",IFERROR(VLOOKUP(B16,'S-ASIG-01'!$B$5:$E$88,2,0),0)) | D16: =IF(B16=0,"",IFERROR(SUMIF(G16:M16,">0",G16:M16)/COUNTIF(G16:M16,">0"),0)) | E16: =IF(B16=0,"",IFERROR(SUMIF(O16:U16,">0",O16:U16)/COUNTIF(O16:U16,">0"),0)) | G16: =IF(B16=0,"",IFERROR(VLOOKUP(B16,'S-ASIG-01'!$B$5:$E$88,4,0),0)) | H16: =IF(B16=0,"",IFERROR(VLOOKUP(B16,'S-ASIG-02'!$B$5:$E$88,4,0),0)) | I16: =IF(B16=0,"",IFERROR(VLOOKUP(B16,'S-ASIG-03'!$B$5:$E$88,4,0),0)) | J16: =IF(B16=0,"",IFERROR(VLOOKUP(B16,'S-ASIG-04'!$B$5:$E$88,4,0),0)) | K16: =IF(B16=0,"",IFERROR(VLOOKUP(B16,'S-ASIG-05'!$B$5:$E$88,4,0),0)) | L16: =IF(B16=0,"",IFERROR(VLOOKUP(B16,'S-ASIG-06'!$B$5:$E$88,4,0),0)) | M16: =IF(B16=0,"",IFERROR(VLOOKUP(B16,'S-ASIG-07'!$B$5:$E$88,4,0),0)) | N16: S | O16: =IF(B16=0,"",IFERROR(VLOOKUP(B16,'T-ASIG-01'!$B$5:$D$88,3,0),0)) | P16: =IF(B16=0,"",IFERROR(VLOOKUP(B16,'T-ASIG-02'!$B$5:$D$88,3,0),0)) | Q16: =IF(B16=0,"",IFERROR(VLOOKUP(B16,'T-ASIG-03'!$B$5:$D$88,3,0),0)) | R16: =IF(B16=0,"",IFERROR(VLOOKUP(B16,'T-ASIG-04'!$B$5:$D$88,3,0),0)) | S16: =IF(B16=0,"",IFERROR(VLOOKUP(B16,'T-ASIG-05'!$B$5:$D$88,3,0),0)) | T16: =IF(B16=0,"",IFERROR(VLOOKUP(B16,'T-ASIG-06'!$B$5:$D$88,3,0),0)) | U16: =IF(B16=0,"",IFERROR(VLOOKUP(B16,'T-ASIG-07'!$B$5:$D$88,3,0),0)) | V16: T
... A54: 50 | B54: =LIDER!C58 -> 0 | C54: =IF(B54=0,"",IFERROR(VLOOKUP(B54,'S-ASIG-01'!$B$5:$E$88,2,0),0)) | D54: =IF(B54=0,"",IFERROR(SUMIF(G54:M54,">0",G54:M54)/COUNTIF(G54:M54,">0"),0)) | E54: =IF(B54=0,"",IFERROR(SUMIF(O54:U54,">0",O54:U54)/COUNTIF(O54:U54,">0"),0)) | G54: =IF(B54=0,"",IFERROR(VLOOKUP(B54,'S-ASIG-01'!$B$5:$E$88,4,0),0)) | H54: =IF(B54=0,"",IFERROR(VLOOKUP(B54,'S-ASIG-02'!$B$5:$E$88,4,0),0)) | I54: =IF(B54=0,"",IFERROR(VLOOKUP(B54,'S-ASIG-03'!$B$5:$E$88,4,0),0)) | J54: =IF(B54=0,"",IFERROR(VLOOKUP(B54,'S-ASIG-04'!$B$5:$E$88,4,0),0)) | K54: =IF(B54=0,"",IFERROR(VLOOKUP(B54,'S-ASIG-05'!$B$5:$E$88,4,0),0)) | L54: =IF(B54=0,"",IFERROR(VLOOKUP(B54,'S-ASIG-06'!$B$5:$E$88,4,0),0)) | M54: =IF(B54=0,"",IFERROR(VLOOKUP(B54,'S-ASIG-07'!$B$5:$E$88,4,0),0)) | N54: S | O54: =IF(B54=0,"",IFERROR(VLOOKUP(B54,'T-ASIG-01'!$B$5:$D$88,3,0),0)) | P54: =IF(B54=0,"",IFERROR(VLOOKUP(B54,'T-ASIG-02'!$B$5:$D$88,3,0),0)) | Q54: =IF(B54=0,"",IFERROR(VLOOKUP(B54,'T-ASIG-03'!$B$5:$D$88,3,0),0)) | R54: =IF(B54=0,"",IFERROR(VLOOKUP(B54,'T-ASIG-04'!$B$5:$D$88,3,0),0)) | S54: =IF(B54=0,"",IFERROR(VLOOKUP(B54,'T-ASIG-05'!$B$5:$D$88,3,0),0)) | T54: =IF(B54=0,"",IFERROR(VLOOKUP(B54,'T-ASIG-06'!$B$5:$D$88,3,0),0)) | U54: =IF(B54=0,"",IFERROR(VLOOKUP(B54,'T-ASIG-07'!$B$5:$D$88,3,0),0)) | V54: T

Sheet LIDER
B2: TECNOLOGÍA EN GESTIÓN DE NEGOCIOS INTERN | E2: SEMESTRE: | F2: SEM-03 | G2: SECCIÓN: | H2: 2
C3: LIDER | D3: METODOLÓGICO | E3: DISCIPLINAR#3 | F3: DISCIPLINAR#4 | G3: DISCIPLINAR#5 | H3: DISCIPLINAR#6 | I3: DISCIPLINAR#7
C4: MATEMÁTICAS FINANCIERAS | D4: TECNOLOGIA APLICADA | E4: INTERNACIONALIZACION | F4: LEGISLACION PARA EL COMERCIO | G4: MACROECONOMÍA
C5: JAVIER MARTINEZ PEREZ | D5: ARMANDO ACOSTA JULIO | E5: TATIANA MILENA ROJAS AROCA | F5: ANGELICA PAOLA DOMINGUEZ CASTELLAR | G5: GENIS PATRON ANTEQUERA
C6: 1412 | D6: 2388 | E6: 2482 | F6: 2490 | G6: 1532
C8: LISTA DE ESTUDIANTES | E8: SEGUNDA ENTREGA - CRITERIO DE EVALUACIÓN DOCUMENTO - SEGUNDO CORTE | H8: PONDERACIÓN | I8: ADMINISTRACIÓN DE EMPRESAS C.I
B9: 1 | C9: SARA OYOLA MARTINEZ | E9: PRESENTACIÓN GENERAL: Adopta la norma APA, tamaño de la hoja, margenes, titulo, portadas, numeración de paginas, tabla de contenido automatizada, ortografia, justificacion del texto, citas automatizadas, listas, figuras,etc. | H9: 0.2 | I9: ADMINTRACIÓN EN SEGURIDAD Y SALUD EN EL TRABAJO
B10: 2 | C10: YINA MARCELA PÉREZ PINEDA | E10: ANTEPROYECTO: Portada, planteamiento del problema, justificacion del trabajo o proyecto de aula, objetivos, marco teorico, diseño metodologico. | H10: 0.2 | I10: CONTADURÍA PÚBLICA
B11: 3 | C11: JABES ELIAS ROSERO VILLA | E11: RESULTADOS: Analiza, integra y aplica de manera coherente los aspectos legales-tributarios, administrativos y tecnológicos en el desarrollo de la propuesta investigativa, evidenciando capacidad para generar soluciones viables, pertinentes y sostenibles. | H11: 0.3 | I11: NEGOCIOS INTERNACIONALES PROFESIONAL
B12: 4 | C12: ISAIAS FERNANDO SALCEDO CAICEDO | E12: BILIOGRAFIA: Las referencias bibliograficas: adoptan las normas APA. El documento es producto de un rastreo bibliografico que muestra analisis y sistensis. | H12: 0.2 | I12: TECNOLOGÍA EN GESTIÓN DE NEGOCIOS INTERN
B13: 5 | C13: JORGE ALBERTO BATISTA TABORDA | E13: ASESORIAS: Anexó la hoja de tutoria firmada ( 3 fimas minmimo). | H13: 0.1 | I13: TECNOLOGíA EN GESTION CONTABLE
B14: 6 | C14: JEREMY MACOLL DIAZ PEREZ | H14: 0 | I14: TECNOLOGÍA EN GESTIÓN DE MARKETING
B15: 7 | C15: DARIANY PEÑARANDA LLACH | H15: 0 | I15: TECNOLOGÍA EN GESTIÓN DEL TALENTO HUMANO
B16: 8 | C16: MARIANGEL ROMERO VANEGAS | H16: =IF(SUM(H9:H15)>1,"Más del 100%",SUM(H9:H15)) -> 1 | I16: TECNOLOGÍA EN GESTIÓN FINANCIERA
B17: 9 | I17: TECNOLOGÍA EN GESTIÓN LOGISTICA Y PORTUARIA
B18: 10 | E18: ENTREGA FINAL - CRITERIO DE EVALUACIÓN SUSTENTACIÓN - TERCER CORTE | H18: PONDERACIÓN | I18: TECNOLOGÍA EN GESTIÓN TURISTICA Y HOTELERA
B19: 11 | E19: Evaluación del Documento Final | H19: 0.5
B20: 12 | E20: Sustentación de los Resultados: Se refleja un dominio del tema, la información está delimitada y es clara. Hay una jerarquía y fluidez en las ideas que presenta. | H20: 0.2
B21: 13 | E21: Expresión Oral: Se oberva buena vocalización y buen tono de voz durante toda la presentación empleando un lenguaje técnico pertinente con su nivel academico. Su discurso es adecuado en la presentacion de la sustentación de los resultados | H21: 0.1
B22: 14 | E22: Lenguaje no verbal: Tiene una adecuada presentación personal para la ocación, opta por una buena postura y demuestra seguridad en sí mismo(a) durante la sustentación de los resultados. Además, demuestra asertividad y seguridad en las orientaciones o preguntas que hace el colectivo docente | H22: 0.05
B23: 15 | E23: Tiempo: El uso del tiempo fue apropiado, se ajusta al previsto. Ofrece una conclusión donde condensa las ideas principales del objetivo general y los específicos. | H23: 0.05
B24: 16 | E24: Uso de Recursos Audiovisuales Tecnológicos: La sustentación se acompaña de recursos visuales pertinentes, atractivos y de gran calidad | H24: 0.1
B25: 17
B26: 18 | H26: =IF(SUM(H19:H25)>1,"Más del 100%",SUM(H19:H25)) -> 1
B27: 19
B28: 20 | E28: TITULOS DE LOS PROYECTOS DE AULA
B29: 21 | E29: GRUPO#1. Identificación de los aspectos legales, tributarios, administrativos, macroeconómicos, aduaneros, tecnológicos e internacionales que definen el perfil de Yara Colombia S.A. en los negocios internacionales
B30: 22 | E30: GRUPO#2. Identificación de los aspectos legales, tributarios, administrativos, macroeconómicos, aduaneros, tecnológicos e internacionales que definen el perfil de Grupo Familia en los negocios internacionales con enfoque en la exportación hacia Estados Unidos.
B31: 23 | E31: GRUPO#3
B32: 24 | E32: GRUPO#4
B33: 25 | E33: GRUPO#5
B34: 26 | E34: GRUPO#6
B35: 27 | E35: GRUPO#7
B36: 28 | E36: GRUPO#8
B37: 29 | E37: GRUPO#9
B38: 30 | E38: GRUPO#10
B39: 31 | E39: GRUPO#11
B40: 32 | E40: GRUPO#12
B41: 33
B42: 34 | E42: =MID(E29,1,20) -> GRUPO#1. Identificac | F42: =MID(E30,1,20) -> GRUPO#2. Identificac | G42: =MID(E31,1,20) -> GRUPO#3 | H42: =MID(E32,1,20) -> GRUPO#4
...

Sheet S-ASIG-01
A1: =LIDER!B2 -> TECNOLOGÍA EN GESTIÓN DE NEGOCIOS INTERN | I1: =LIDER!E2 -> SEMESTRE: | J1: =LIDER!F2 -> SEM-03 | K1: =LIDER!G2 -> SECCIÓN: | L1: =LIDER!H2 -> 2
B2: =LIDER!C4 -> MATEMÁTICAS FINANCIERAS | F2: CRITERIOS DE EVALUACIÓN
B3: Estudiantes | F3: =LIDER!E9 -> PRESENTACIÓN GENERAL: Adopta la norma APA, tamaño de la hoja, margenes, titulo, portadas, numeración de paginas, tabla de contenido automatizada, ortografia, justificacion del texto, citas automatizadas, listas, figuras,etc. | G3: =LIDER!E10 -> ANTEPROYECTO: Portada, planteamiento del problema, justificacion del trabajo o proyecto de aula, objetivos, marco teorico, diseño metodologico. | H3: =LIDER!E11 -> RESULTADOS: Analiza, integra y aplica de manera coherente los aspectos legales-tributarios, administrativos y tecnológicos en el desarrollo de la propuesta investigativa, evidenciando capacidad para generar soluciones viables, pertinentes y sostenibles. | I3: =LIDER!E12 -> BILIOGRAFIA: Las referencias bibliograficas: adoptan las normas APA. El documento es producto de un rastreo bibliografico que muestra analisis y sistensis. | J3: =LIDER!E13 -> ASESORIAS: Anexó la hoja de tutoria firmada ( 3 fimas minmimo). | K3: =LIDER!E14 -> 0 | L3: =LIDER!E15 -> 0
F4: =CONCATENATE(LIDER!C4," - ",LIDER!C6," - ",LIDER!C5) -> MATEMÁTICAS FINANCIERAS - 1412 - JAVIER MARTINEZ PEREZ
B5: GRUPO#1 | C5: G01 | D5: LIST | E5: DEF | F5: =LIDER!$E$29 -> GRUPO#1. Identificación de los aspectos legales, tributarios, administrativos, macroeconómicos, aduaneros, tecnológicos e internacionales que definen el perfil de Yara Colombia S.A. en los negocios internacionales
A6: 1 | B6: =LIDER!E43 -> SARA OYOLA MARTINEZ | C6: =C5 -> G01 | E6: =IF(B6=0,0,IF(D6="",$F$6*LIDER!$H$9+$G$6*LIDER!$H$10+$H$6*LIDER!$H$11+$I$6*LIDER!$H$12+$J$6*LIDER!$H$13+$K$6*LIDER!$H$14+$L$6*LIDER!$H$15,"N")) -> 4.25 | F6: 4.5 | G6: 4 | H6: 4.5 | I6: 4 | J6: 4
A7: 2 | B7: =LIDER!E44 -> YINA MARCELA PÉREZ PINEDA | C7: =C6 -> G01 | E7: =IF(B7=0,0,IF(D7="",$F$6*LIDER!$H$9+$G$6*LIDER!$H$10+$H$6*LIDER!$H$11+$I$6*LIDER!$H$12+$J$6*LIDER!$H$13+$K$6*LIDER!$H$14+$L$6*LIDER!$H$15,"N")) -> 4.25
A8: 3 | B8: =LIDER!E45 -> JABES ELIAS ROSERO VILLA | C8: =C7 -> G01 | E8: =IF(B8=0,0,IF(D8="",$F$6*LIDER!$H$9+$G$6*LIDER!$H$10+$H$6*LIDER!$H$11+$I$6*LIDER!$H$12+$J$6*LIDER!$H$13+$K$6*LIDER!$H$14+$L$6*LIDER!$H$15,"N")) -> 4.25
A9: 4 | B9: =LIDER!E46 -> ISAIAS FERNANDO SALCEDO CAICEDO | C9: =C8 -> G01 | E9: =IF(B9=0,0,IF(D9="",$F$6*LIDER!$H$9+$G$6*LIDER!$H$10+$H$6*LIDER!$H$11+$I$6*LIDER!$H$12+$J$6*LIDER!$H$13+$K$6*LIDER!$H$14+$L$6*LIDER!$H$15,"N")) -> 4.25
A10: 5 | B10: =LIDER!E47 -> 0 | C10: =C9 -> G01 | E10: =IF(B10=0,0,IF(D10="",$F$6*LIDER!$H$9+$G$6*LIDER!$H$10+$H$6*LIDER!$H$11+$I$6*LIDER!$H$12+$J$6*LIDER!$H$13+$K$6*LIDER!$H$14+$L$6*LIDER!$H$15,"N")) -> 0
A11: 6 | B11: =LIDER!E48 -> 0 | C11: =C10 -> G01 | E11: =IF(B11=0,0,IF(D11="",$F$6*LIDER!$H$9+$G$6*LIDER!$H$10+$H$6*LIDER!$H$11+$I$6*LIDER!$H$12+$J$6*LIDER!$H$13+$K$6*LIDER!$H$14+$L$6*LIDER!$H$15,"N")) -> 0
B12: GRUPO#2 | C12: G02 | D12: =D5 -> LIST | E12: DEF | F12: =LIDER!$E$30 -> GRUPO#2. Identificación de los aspectos legales, tributarios, administrativos, macroeconómicos, aduaneros, tecnológicos e internacionales que definen el perfil de Grupo Familia en los negocios internacionales con enfoque en la exportación hacia Estados Unidos.
A13: 1 | B13: =LIDER!F43 -> JORGE ALBERTO BATISTA TABORDA | C13: =C12 -> G02 | E13: =IF(B13=0,0,IF(D13="",$F$13*LIDER!$H$9+$G$13*LIDER!$H$10+$H$13*LIDER!$H$11+$I$13*LIDER!$H$12+$J$13*LIDER!$H$13+$K$13*LIDER!$H$14+$L$13*LIDER!$H$15,"N")) -> 3.84 | F13: 3.5 | G13: 4 | H13: 3.8 | I13: 4 | J13: 4
A14: 2 | B14: =LIDER!F44 -> JEREMY MACOLL DIAZ PEREZ | C14: =C13 -> G02 | E14: =IF(B14=0,0,IF(D14="",$F$13*LIDER!$H$9+$G$13*LIDER!$H$10+$H$13*LIDER!$H$11+$I$13*LIDER!$H$12+$J$13*LIDER!$H$13+$K$13*LIDER!$H$14+$L$13*LIDER!$H$15,"N")) -> 3.84
A15: 3 | B15: =LIDER!F45 -> DARIANY PEÑARANDA LLACH | C15: =C14 -> G02 | E15: =IF(B15=0,0,IF(D15="",$F$13*LIDER!$H$9+$G$13*LIDER!$H$10+$H$13*LIDER!$H$11+$I$13*LIDER!$H$12+$J$13*LIDER!$H$13+$K$13*LIDER!$H$14+$L$13*LIDER!$H$15,"N")) -> 3.84
A16: 4 | B16: =LIDER!F46 -> MARIANGEL ROMERO VANEGAS | C16: =C15 -> G02 | E16: =IF(B16=0,0,IF(D16="",$F$13*LIDER!$H$9+$G$13*LIDER!$H$10+$H$13*LIDER!$H$11+$I$13*LIDER!$H$12+$J$13*LIDER!$H$13+$K$13*LIDER!$H$14+$L$13*LIDER!$H$15,"N")) -> 3.84
A17: 5 | B17: =LIDER!F47 -> 0 | C17: =C16 -> G02 | E17: =IF(B17=0,0,IF(D17="",$F$13*LIDER!$H$9+$G$13*LIDER!$H$10+$H$13*LIDER!$H$11+$I$13*LIDER!$H$12+$J$13*LIDER!$H$13+$K$13*LIDER!$H$14+$L$13*LIDER!$H$15,"N")) -> 0
A18: 6 | B18: =LIDER!F48 -> 0 | C18: =C17 -> G02 | E18: =IF(B18=0,0,IF(D18="",$F$13*LIDER!$H$9+$G$13*LIDER!$H$10+$H$13*LIDER!$H$11+$I$13*LIDER!$H$12+$J$13*LIDER!$H$13+$K$13*LIDER!$H$14+$L$13*LIDER!$H$15,"N")) -> 0
B19: GRUPO#3 | C19: G03 | D19: =D12 -> LIST | E19: DEF | F19: =LIDER!$E$31 -> GRUPO#3
A20: 1 | B20: =LIDER!G43 -> 0 | C20: =C19 -> G03 | E20: =IF(B20=0,0,IF(D20="",$F$20*LIDER!$H$9+$G$20*LIDER!$H$10+$H$20*LIDER!$H$11+$I$20*LIDER!$H$12+$J$20*LIDER!$H$13+$K$20*LIDER!$H$14+$L$20*LIDER!$H$15,"N")) -> 0
A21: 2 | B21: =LIDER!G44 -> 0 | C21: =C20 -> G03 | E21: =IF(B21=0,0,IF(D21="",$F$20*LIDER!$H$9+$G$20*LIDER!$H$10+$H$20*LIDER!$H$11+$I$20*LIDER!$H$12+$J$20*LIDER!$H$13+$K$20*LIDER!$H$14+$L$20*LIDER!$H$15,"N")) -> 0
A22: 3 | B22: =LIDER!G45 -> 0 | C22: =C21 -> G03 | E22: =IF(B22=0,0,IF(D22="",$F$20*LIDER!$H$9+$G$20*LIDER!$H$10+$H$20*LIDER!$H$11+$I$20*LIDER!$H$12+$J$20*LIDER!$H$13+$K$20*LIDER!$H$14+$L$20*LIDER!$H$15,"N")) -> 0
A23: 4 | B23: =LIDER!G46 -> 0 | C23: =C22 -> G03 | E23: =IF(B23=0,0,IF(D23="",$F$20*LIDER!$H$9+$G$20*LIDER!$H$10+$H$20*LIDER!$H$11+$I$20*LIDER!$H$12+$J$20*LIDER!$H$13+$K$20*LIDER!$H$14+$L$20*LIDER!$H$15,"N")) -> 0
A24: 5 | B24: =LIDER!G47 -> 0 | C24: =C23 -> G03 | E24: =IF(B24=0,0,IF(D24="",$F$20*LIDER!$H$9+$G$20*LIDER!$H$10+$H$20*LIDER!$H$11+$I$20*LIDER!$H$12+$J$20*LIDER!$H$13+$K$20*LIDER!$H$14+$L$20*LIDER!$H$15,"N")) -> 0
A25: 6 | B25: =LIDER!G48 -> 0 | C25: =C24 -> G03 | E25: =IF(B25=0,0,IF(D25="",$F$20*LIDER!$H$9+$G$20*LIDER!$H$10+$H$20*LIDER!$H$11+$I$20*LIDER!$H$12+$J$20*LIDER!$H$13+$K$20*LIDER!$H$14+$L$20*LIDER!$H$15,"N")) -> 0
B26: GRUPO#4 | C26: G04 | D26: =D19 -> LIST | E26: DEF | F26: =LIDER!$E$32 -> GRUPO#4
A27: 1 | B27: =LIDER!H43 -> 0 | C27: =C26 -> G04 | E27: =IF(B27=0,0,IF(D27="",$F$27*LIDER!$H$9+$G$27*LIDER!$H$10+$H$27*LIDER!$H$11+$I$27*LIDER!$H$12+$J$27*LIDER!$H$13+$K$27*LIDER!$H$14+$L$27*LIDER!$H$15,"N")) -> 0
A28: 2 | B28: =LIDER!H44 -> 0 | C28: =C27 -> G04 | E28: =IF(B28=0,0,IF(D28="",$F$27*LIDER!$H$9+$G$27*LIDER!$H$10+$H$27*LIDER!$H$11+$I$27*LIDER!$H$12+$J$27*LIDER!$H$13+$K$27*LIDER!$H$14+$L$27*LIDER!$H$15,"N")) -> 0
A29: 3 | B29: =LIDER!H45 -> 0 | C29: =C28 -> G04 | E29: =IF(B29=0,0,IF(D29="",$F$27*LIDER!$H$9+$G$27*LIDER!$H$10+$H$27*LIDER!$H$11+$I$27*LIDER!$H$12+$J$27*LIDER!$H$13+$K$27*LIDER!$H$14+$L$27*LIDER!$H$15,"N")) -> 0
A30: 4 | B30: =LIDER!H46 -> 0 | C30: =C29 -> G04 | E30: =IF(B30=0,0,IF(D30="",$F$27*LIDER!$H$9+$G$27*LIDER!$H$10+$H$27*LIDER!$H$11+$I$27*LIDER!$H$12+$J$27*LIDER!$H$13+$K$27*LIDER!$H$14+$L$27*LIDER!$H$15,"N")) -> 0
A31: 5 | B31: =LIDER!H47 -> 0 | C31: =C30 -> G04 | E31: =IF(B31=0,0,IF(D31="",$F$27*LIDER!$H$9+$G$27*LIDER!$H$10+$H$27*LIDER!$H$11+$I$27*LIDER!$H$12+$J$27*LIDER!$H$13+$K$27*LIDER!$H$14+$L$27*LIDER!$H$15,"N")) -> 0
A32: 6 | B32: =LIDER!H48 -> 0 | C32: =C31 -> G04 | E32: =IF(B32=0,0,IF(D32="",$F$27*LIDER!$H$9+$G$27*LIDER!$H$10+$H$27*LIDER!$H$11+$I$27*LIDER!$H$12+$J$27*LIDER!$H$13+$K$27*LIDER!$H$14+$L$27*LIDER!$H$15,"N")) -> 0
B33: GRUPO#5 | C33: G05 | D33: =D26 -> LIST | E33: DEF | F33: =LIDER!$E$33 -> GRUPO#5
A34: 1 | B34: =LIDER!E51 -> 0 | C34: =C33 -> G05 | E34: =IF(B34=0,0,IF(D34="",$F$34*LIDER!$H$9+$G$34*LIDER!$H$10+$H$34*LIDER!$H$11+$I$34*LIDER!$H$12+$J$34*LIDER!$H$13+$K$34*LIDER!$H$14+$L$34*LIDER!$H$15,"N")) -> 0
A35: 2 | B35: =LIDER!E52 -> 0 | C35: =C34 -> G05 | E35: =IF(B35=0,0,IF(D35="",$F$34*LIDER!$H$9+$G$34*LIDER!$H$10+$H$34*LIDER!$H$11+$I$34*LIDER!$H$12+$J$34*LIDER!$H$13+$K$34*LIDER!$H$14+$L$34*LIDER!$H$15,"N")) -> 0
A36: 3 | B36: =LIDER!E53 -> 0 | C36: =C35 -> G05 | E36: =IF(B36=0,0,IF(D36="",$F$34*LIDER!$H$9+$G$34*LIDER!$H$10+$H$34*LIDER!$H$11+$I$34*LIDER!$H$12+$J$34*LIDER!$H$13+$K$34*LIDER!$H$14+$L$34*LIDER!$H$15,"N")) -> 0
A37: 4 | B37: =LIDER!E54 -> 0 | C37: =C36 -> G05 | E37: =IF(B37=0,0,IF(D37="",$F$34*LIDER!$H$9+$G$34*LIDER!$H$10+$H$34*LIDER!$H$11+$I$34*LIDER!$H$12+$J$34*LIDER!$H$13+$K$34*LIDER!$H$14+$L$34*LIDER!$H$15,"N")) -> 0
A38: 5 | B38: =LIDER!E55 -> 0 | C38: =C37 -> G05 | E38: =IF(B38=0,0,IF(D38="",$F$34*LIDER!$H$9+$G$34*LIDER!$H$10+$H$34*LIDER!$H$11+$I$34*LIDER!$H$12+$J$34*LIDER!$H$13+$K$34*LIDER!$H$14+$L$34*LIDER!$H$15,"N")) -> 0
A39: 6 | B39: =LIDER!E56 -> 0 | C39: =C38 -> G05 | E39: =IF(B39=0,0,IF(D39="",$F$34*LIDER!$H$9+$G$34*LIDER!$H$10+$H$34*LIDER!$H$11+$I$34*LIDER!$H$12+$J$34*LIDER!$H$13+$K$34*LIDER!$H$14+$L$34*LIDER!$H$15,"N")) -> 0
B40: GRUPO#6 | C40: G06 | D40: =D33 -> LIST | E40: DEF | F40: =LIDER!$E$34 -> GRUPO#6
...

Sheet S-ASIG-02
A1: =LIDER!B2 -> TECNOLOGÍA EN GESTIÓN DE NEGOCIOS INTERN | I1: =LIDER!E2 -> SEMESTRE: | J1: =LIDER!F2 -> SEM-03 | K1: =LIDER!G2 -> SECCIÓN: | L1: =LIDER!H2 -> 2
B2: =LIDER!D4 -> TECNOLOGIA APLICADA | F2: CRITERIOS DE EVALUACIÓN
B3: Estudiantes | F3: =LIDER!E9 -> PRESENTACIÓN GENERAL: Adopta la norma APA, tamaño de la hoja, margenes, titulo, portadas, numeración de paginas, tabla de contenido automatizada, ortografia, justificacion del texto, citas automatizadas, listas, figuras,etc. | G3: =LIDER!E10 -> ANTEPROYECTO: Portada, planteamiento del problema, justificacion del trabajo o proyecto de aula, objetivos, marco teorico, diseño metodologico. | H3: =LIDER!E11 -> RESULTADOS: Analiza, integra y aplica de manera coherente los aspectos legales-tributarios, administrativos y tecnológicos en el desarrollo de la propuesta investigativa, evidenciando capacidad para generar soluciones viables, pertinentes y sostenibles. | I3: =LIDER!E12 -> BILIOGRAFIA: Las referencias bibliograficas: adoptan las normas APA. El documento es producto de un rastreo bibliografico que muestra analisis y sistensis. | J3: =LIDER!E13 -> ASESORIAS: Anexó la hoja de tutoria firmada ( 3 fimas minmimo). | K3: =LIDER!E14 -> 0 | L3: =LIDER!E15 -> 0
F4: =CONCATENATE(LIDER!D4," - ",LIDER!D6," - ",LIDER!D5) -> TECNOLOGIA APLICADA - 2388 - ARMANDO ACOSTA JULIO
B5: GRUPO#1 | C5: G01 | D5: LIST | E5: DEF | F5: =LIDER!$E$29 -> GRUPO#1. Identificación de los aspectos legales, tributarios, administrativos, macroeconómicos, aduaneros, tecnológicos e internacionales que definen el perfil de Yara Colombia S.A. en los negocios internacionales
A6: 1 | B6: =LIDER!E43 -> SARA OYOLA MARTINEZ | C6: =C5 -> G01 | E6: =IF(B6=0,0,IF(D6="",$F$6*LIDER!$H$9+$G$6*LIDER!$H$10+$H$6*LIDER!$H$11+$I$6*LIDER!$H$12+$J$6*LIDER!$H$13+$K$6*LIDER!$H$14+$L$6*LIDER!$H$15,"N")) -> 4.5 | F6: 4.5 | G6: 4.5 | H6: 4.5 | I6: 4.5 | J6: 4.5
A7: 2 | B7: =LIDER!E44 -> YINA MARCELA PÉREZ PINEDA | C7: =C6 -> G01 | E7: =IF(B7=0,0,IF(D7="",$F$6*LIDER!$H$9+$G$6*LIDER!$H$10+$H$6*LIDER!$H$11+$I$6*LIDER!$H$12+$J$6*LIDER!$H$13+$K$6*LIDER!$H$14+$L$6*LIDER!$H$15,"N")) -> 4.5
A8: 3 | B8: =LIDER!E45 -> JABES ELIAS ROSERO VILLA | C8: =C7 -> G01 | E8: =IF(B8=0,0,IF(D8="",$F$6*LIDER!$H$9+$G$6*LIDER!$H$10+$H$6*LIDER!$H$11+$I$6*LIDER!$H$12+$J$6*LIDER!$H$13+$K$6*LIDER!$H$14+$L$6*LIDER!$H$15,"N")) -> 4.5
A9: 4 | B9: =LIDER!E46 -> ISAIAS FERNANDO SALCEDO CAICEDO | C9: =C8 -> G01 | E9: =IF(B9=0,0,IF(D9="",$F$6*LIDER!$H$9+$G$6*LIDER!$H$10+$H$6*LIDER!$H$11+$I$6*LIDER!$H$12+$J$6*LIDER!$H$13+$K$6*LIDER!$H$14+$L$6*LIDER!$H$15,"N")) -> 4.5
A10: 5 | B10: =LIDER!E47 -> 0 | C10: =C9 -> G01 | E10: =IF(B10=0,0,IF(D10="",$F$6*LIDER!$H$9+$G$6*LIDER!$H$10+$H$6*LIDER!$H$11+$I$6*LIDER!$H$12+$J$6*LIDER!$H$13+$K$6*LIDER!$H$14+$L$6*LIDER!$H$15,"N")) -> 0
A11: 6 | B11: =LIDER!E48 -> 0 | C11: =C10 -> G01 | E11: =IF(B11=0,0,IF(D11="",$F$6*LIDER!$H$9+$G$6*LIDER!$H$10+$H$6*LIDER!$H$11+$I$6*LIDER!$H$12+$J$6*LIDER!$H$13+$K$6*LIDER!$H$14+$L$6*LIDER!$H$15,"N")) -> 0
B12: GRUPO#2 | C12: G02 | D12: =D5 -> LIST | E12: DEF | F12: =LIDER!$E$30 -> GRUPO#2. Identificación de los aspectos legales, tributarios, administrativos, macroeconómicos, aduaneros, tecnológicos e internacionales que definen el perfil de Grupo Familia en los negocios internacionales con enfoque en la exportación hacia Estados Unidos.
A13: 1 | B13: =LIDER!F43 -> JORGE ALBERTO BATISTA TABORDA | C13: =C12 -> G02 | E13: =IF(B13=0,0,IF(D13="",$F$13*LIDER!$H$9+$G$13*LIDER!$H$10+$H$13*LIDER!$H$11+$I$13*LIDER!$H$12+$J$13*LIDER!$H$13+$K$13*LIDER!$H$14+$L$13*LIDER!$H$15,"N")) -> 4 | F13: 4 | G13: 4 | H13: 4 | I13: 4 | J13: 4
A14: 2 | B14: =LIDER!F44 -> JEREMY MACOLL DIAZ PEREZ | C14: =C13 -> G02 | E14: =IF(B14=0,0,IF(D14="",$F$13*LIDER!$H$9+$G$13*LIDER!$H$10+$H$13*LIDER!$H$11+$I$13*LIDER!$H$12+$J$13*LIDER!$H$13+$K$13*LIDER!$H$14+$L$13*LIDER!$H$15,"N")) -> 4
A15: 3 | B15: =LIDER!F45 -> DARIANY PEÑARANDA LLACH | C15: =C14 -> G02 | E15: =IF(B15=0,0,IF(D15="",$F$13*LIDER!$H$9+$G$13*LIDER!$H$10+$H$13*LIDER!$H$11+$I$13*LIDER!$H$12+$J$13*LIDER!$H$13+$K$13*LIDER!$H$14+$L$13*LIDER!$H$15,"N")) -> 4
A16: 4 | B16: =LIDER!F46 -> MARIANGEL ROMERO VANEGAS | C16: =C15 -> G02 | E16: =IF(B16=0,0,IF(D16="",$F$13*LIDER!$H$9+$G$13*LIDER!$H$10+$H$13*LIDER!$H$11+$I$13*LIDER!$H$12+$J$13*LIDER!$H$13+$K$13*LIDER!$H$14+$L$13*LIDER!$H$15,"N")) -> 4
A17: 5 | B17: =LIDER!F47 -> 0 | C17: =C16 -> G02 | E17: =IF(B17=0,0,IF(D17="",$F$13*LIDER!$H$9+$G$13*LIDER!$H$10+$H$13*LIDER!$H$11+$I$13*LIDER!$H$12+$J$13*LIDER!$H$13+$K$13*LIDER!$H$14+$L$13*LIDER!$H$15,"N")) -> 0
A18: 6 | B18: =LIDER!F48 -> 0 | C18: =C17 -> G02 | E18: =IF(B18=0,0,IF(D18="",$F$13*LIDER!$H$9+$G$13*LIDER!$H$10+$H$13*LIDER!$H$11+$I$13*LIDER!$H$12+$J$13*LIDER!$H$13+$K$13*LIDER!$H$14+$L$13*LIDER!$H$15,"N")) -> 0
B19: GRUPO#3 | C19: G03 | D19: =D12 -> LIST | E19: DEF | F19: =LIDER!$E$31 -> GRUPO#3
A20: 1 | B20: =LIDER!G43 -> 0 | C20: =C19 -> G03 | E20: =IF(B20=0,0,IF(D20="",$F$20*LIDER!$H$9+$G$20*LIDER!$H$10+$H$20*LIDER!$H$11+$I$20*LIDER!$H$12+$J$20*LIDER!$H$13+$K$20*LIDER!$H$14+$L$20*LIDER!$H$15,"N")) -> 0
A21: 2 | B21: =LIDER!G44 -> 0 | C21: =C20 -> G03 | E21: =IF(B21=0,0,IF(D21="",$F$20*LIDER!$H$9+$G$20*LIDER!$H$10+$H$20*LIDER!$H$11+$I$20*LIDER!$H$12+$J$20*LIDER!$H$13+$K$20*LIDER!$H$14+$L$20*LIDER!$H$15,"N")) -> 0
A22: 3 | B22: =LIDER!G45 -> 0 | C22: =C21 -> G03 | E22: =IF(B22=0,0,IF(D22="",$F$20*LIDER!$H$9+$G$20*LIDER!$H$10+$H$20*LIDER!$H$11+$I$20*LIDER!$H$12+$J$20*LIDER!$H$13+$K$20*LIDER!$H$14+$L$20*LIDER!$H$15,"N")) -> 0
A23: 4 | B23: =LIDER!G46 -> 0 | C23: =C22 -> G03 | E23: =IF(B23=0,0,IF(D23="",$F$20*LIDER!$H$9+$G$20*LIDER!$H$10+$H$20*LIDER!$H$11+$I$20*LIDER!$H$12+$J$20*LIDER!$H$13+$K$20*LIDER!$H$14+$L$20*LIDER!$H$15,"N")) -> 0
A24: 5 | B24: =LIDER!G47 -> 0 | C24: =C23 -> G03 | E24: =IF(B24=0,0,IF(D24="",$F$20*LIDER!$H$9+$G$20*LIDER!$H$10+$H$20*LIDER!$H$11+$I$20*LIDER!$H$12+$J$20*LIDER!$H$13+$K$20*LIDER!$H$14+$L$20*LIDER!$H$15,"N")) -> 0
A25: 6 | B25: =LIDER!G48 -> 0 | C25: =C24 -> G03 | E25: =IF(B25=0,0,IF(D25="",$F$20*LIDER!$H$9+$G$20*LIDER!$H$10+$H$20*LIDER!$H$11+$I$20*LIDER!$H$12+$J$20*LIDER!$H$13+$K$20*LIDER!$H$14+$L$20*LIDER!$H$15,"N")) -> 0
B26: GRUPO#4 | C26: G04 | D26: =D19 -> LIST | E26: DEF | F26: =LIDER!$E$32 -> GRUPO#4
A27: 1 | B27: =LIDER!H43 -> 0 | C27: =C26 -> G04 | E27: =IF(B27=0,0,IF(D27="",$F$27*LIDER!$H$9+$G$27*LIDER!$H$10+$H$27*LIDER!$H$11+$I$27*LIDER!$H$12+$J$27*LIDER!$H$13+$K$27*LIDER!$H$14+$L$27*LIDER!$H$15,"N")) -> 0
A28: 2 | B28: =LIDER!H44 -> 0 | C28: =C27 -> G04 | E28: =IF(B28=0,0,IF(D28="",$F$27*LIDER!$H$9+$G$27*LIDER!$H$10+$H$27*LIDER!$H$11+$I$27*LIDER!$H$12+$J$27*LIDER!$H$13+$K$27*LIDER!$H$14+$L$27*LIDER!$H$15,"N")) -> 0
A29: 3 | B29: =LIDER!H45 -> 0 | C29: =C28 -> G04 | E29: =IF(B29=0,0,IF(D29="",$F$27*LIDER!$H$9+$G$27*LIDER!$H$10+$H$27*LIDER!$H$11+$I$27*LIDER!$H$12+$J$27*LIDER!$H$13+$K$27*LIDER!$H$14+$L$27*LIDER!$H$15,"N")) -> 0
A30: 4 | B30: =LIDER!H46 -> 0 | C30: =C29 -> G04 | E30: =IF(B30=0,0,IF(D30="",$F$27*LIDER!$H$9+$G$27*LIDER!$H$10+$H$27*LIDER!$H$11+$I$27*LIDER!$H$12+$J$27*LIDER!$H$13+$K$27*LIDER!$H$14+$L$27*LIDER!$H$15,"N")) -> 0
A31: 5 | B31: =LIDER!H47 -> 0 | C31: =C30 -> G04 | E31: =IF(B31=0,0,IF(D31="",$F$27*LIDER!$H$9+$G$27*LIDER!$H$10+$H$27*LIDER!$H$11+$I$27*LIDER!$H$12+$J$27*LIDER!$H$13+$K$27*LIDER!$H$14+$L$27*LIDER!$H$15,"N")) -> 0
A32: 6 | B32: =LIDER!H48 -> 0 | C32: =C31 -> G04 | E32: =IF(B32=0,0,IF(D32="",$F$27*LIDER!$H$9+$G$27*LIDER!$H$10+$H$27*LIDER!$H$11+$I$27*LIDER!$H$12+$J$27*LIDER!$H$13+$K$27*LIDER!$H$14+$L$27*LIDER!$H$15,"N")) -> 0
B33: GRUPO#5 | C33: G05 | D33: =D26 -> LIST | E33: DEF | F33: =LIDER!$E$33 -> GRUPO#5
A34: 1 | B34: =LIDER!E51 -> 0 | C34: =C33 -> G05 | E34: =IF(B34=0,0,IF(D34="",$F$34*LIDER!$H$9+$G$34*LIDER!$H$10+$H$34*LIDER!$H$11+$I$34*LIDER!$H$12+$J$34*LIDER!$H$13+$K$34*LIDER!$H$14+$L$34*LIDER!$H$15,"N")) -> 0
A35: 2 | B35: =LIDER!E52 -> 0 | C35: =C34 -> G05 | E35: =IF(B35=0,0,IF(D35="",$F$34*LIDER!$H$9+$G$34*LIDER!$H$10+$H$34*LIDER!$H$11+$I$34*LIDER!$H$12+$J$34*LIDER!$H$13+$K$34*LIDER!$H$14+$L$34*LIDER!$H$15,"N")) -> 0
A36: 3 | B36: =LIDER!E53 -> 0 | C36: =C35 -> G05 | E36: =IF(B36=0,0,IF(D36="",$F$34*LIDER!$H$9+$G$34*LIDER!$H$10+$H$34*LIDER!$H$11+$I$34*LIDER!$H$12+$J$34*LIDER!$H$13+$K$34*LIDER!$H$14+$L$34*LIDER!$H$15,"N")) -> 0
A37: 4 | B37: =LIDER!E54 -> 0 | C37: =C36 -> G05 | E37: =IF(B37=0,0,IF(D37="",$F$34*LIDER!$H$9+$G$34*LIDER!$H$10+$H$34*LIDER!$H$11+$I$34*LIDER!$H$12+$J$34*LIDER!$H$13+$K$34*LIDER!$H$14+$L$34*LIDER!$H$15,"N")) -> 0
A38: 5 | B38: =LIDER!E55 -> 0 | C38: =C37 -> G05 | E38: =IF(B38=0,0,IF(D38="",$F$34*LIDER!$H$9+$G$34*LIDER!$H$10+$H$34*LIDER!$H$11+$I$34*LIDER!$H$12+$J$34*LIDER!$H$13+$K$34*LIDER!$H$14+$L$34*LIDER!$H$15,"N")) -> 0
A39: 6 | B39: =LIDER!E56 -> 0 | C39: =C38 -> G05 | E39: =IF(B39=0,0,IF(D39="",$F$34*LIDER!$H$9+$G$34*LIDER!$H$10+$H$34*LIDER!$H$11+$I$34*LIDER!$H$12+$J$34*LIDER!$H$13+$K$34*LIDER!$H$14+$L$34*LIDER!$H$15,"N")) -> 0
B40: GRUPO#6 | C40: G06 | D40: =D33 -> LIST | E40: DEF | F40: =LIDER!$E$34 -> GRUPO#6
...

Sheet S-ASIG-04
A1: =LIDER!B2 -> TECNOLOGÍA EN GESTIÓN DE NEGOCIOS INTERN | I1: =LIDER!E2 -> SEMESTRE: | J1: =LIDER!F2 -> SEM-03 | K1: =LIDER!G2 -> SECCIÓN: | L1: =LIDER!H2 -> 2
B2: =LIDER!F4 -> LEGISLACION PARA EL COMERCIO | F2: CRITERIOS DE EVALUACIÓN
B3: Estudiantes | F3: =LIDER!E9 -> PRESENTACIÓN GENERAL: Adopta la norma APA, tamaño de la hoja, margenes, titulo, portadas, numeración de paginas, tabla de contenido automatizada, ortografia, justificacion del texto, citas automatizadas, listas, figuras,etc. | G3: =LIDER!E10 -> ANTEPROYECTO: Portada, planteamiento del problema, justificacion del trabajo o proyecto de aula, objetivos, marco teorico, diseño metodologico. | H3: =LIDER!E11 -> RESULTADOS: Analiza, integra y aplica de manera coherente los aspectos legales-tributarios, administrativos y tecnológicos en el desarrollo de la propuesta investigativa, evidenciando capacidad para generar soluciones viables, pertinentes y sostenibles. | I3: =LIDER!E12 -> BILIOGRAFIA: Las referencias bibliograficas: adoptan las normas APA. El documento es producto de un rastreo bibliografico que muestra analisis y sistensis. | J3: =LIDER!E13 -> ASESORIAS: Anexó la hoja de tutoria firmada ( 3 fimas minmimo). | K3: =LIDER!E14 -> 0 | L3: =LIDER!E15 -> 0
F4: =CONCATENATE(LIDER!F4," - ",LIDER!F6," - ",LIDER!F5) -> LEGISLACION PARA EL COMERCIO - 2490 - ANGELICA PAOLA DOMINGUEZ CASTELLAR
B5: GRUPO#1 | C5: G01 | D5: LIST | E5: DEF | F5: =LIDER!$E$29 -> GRUPO#1. Identificación de los aspectos legales, tributarios, administrativos, macroeconómicos, aduaneros, tecnológicos e internacionales que definen el perfil de Yara Colombia S.A. en los negocios internacionales
A6: 1 | B6: =LIDER!E43 -> SARA OYOLA MARTINEZ | C6: =C5 -> G01 | E6: =IF(B6=0,0,IF(D6="",$F$6*LIDER!$H$9+$G$6*LIDER!$H$10+$H$6*LIDER!$H$11+$I$6*LIDER!$H$12+$J$6*LIDER!$H$13+$K$6*LIDER!$H$14+$L$6*LIDER!$H$15,"N")) -> 4.74 | F6: 4.5 | G6: 4.5 | H6: 4.8 | I6: 5 | J6: 5
A7: 2 | B7: =LIDER!E44 -> YINA MARCELA PÉREZ PINEDA | C7: =C6 -> G01 | E7: =IF(B7=0,0,IF(D7="",$F$6*LIDER!$H$9+$G$6*LIDER!$H$10+$H$6*LIDER!$H$11+$I$6*LIDER!$H$12+$J$6*LIDER!$H$13+$K$6*LIDER!$H$14+$L$6*LIDER!$H$15,"N")) -> 4.74
A8: 3 | B8: =LIDER!E45 -> JABES ELIAS ROSERO VILLA | C8: =C7 -> G01 | E8: =IF(B8=0,0,IF(D8="",$F$6*LIDER!$H$9+$G$6*LIDER!$H$10+$H$6*LIDER!$H$11+$I$6*LIDER!$H$12+$J$6*LIDER!$H$13+$K$6*LIDER!$H$14+$L$6*LIDER!$H$15,"N")) -> 4.74
A9: 4 | B9: =LIDER!E46 -> ISAIAS FERNANDO SALCEDO CAICEDO | C9: =C8 -> G01 | E9: =IF(B9=0,0,IF(D9="",$F$6*LIDER!$H$9+$G$6*LIDER!$H$10+$H$6*LIDER!$H$11+$I$6*LIDER!$H$12+$J$6*LIDER!$H$13+$K$6*LIDER!$H$14+$L$6*LIDER!$H$15,"N")) -> 4.74
A10: 5 | B10: =LIDER!E47 -> 0 | C10: =C9 -> G01 | E10: =IF(B10=0,0,IF(D10="",$F$6*LIDER!$H$9+$G$6*LIDER!$H$10+$H$6*LIDER!$H$11+$I$6*LIDER!$H$12+$J$6*LIDER!$H$13+$K$6*LIDER!$H$14+$L$6*LIDER!$H$15,"N")) -> 0
A11: 6 | B11: =LIDER!E48 -> 0 | C11: =C10 -> G01 | E11: =IF(B11=0,0,IF(D11="",$F$6*LIDER!$H$9+$G$6*LIDER!$H$10+$H$6*LIDER!$H$11+$I$6*LIDER!$H$12+$J$6*LIDER!$H$13+$K$6*LIDER!$H$14+$L$6*LIDER!$H$15,"N")) -> 0
B12: GRUPO#2 | C12: G02 | D12: =D5 -> LIST | E12: DEF | F12: =LIDER!$E$30 -> GRUPO#2. Identificación de los aspectos legales, tributarios, administrativos, macroeconómicos, aduaneros, tecnológicos e internacionales que definen el perfil de Grupo Familia en los negocios internacionales con enfoque en la exportación hacia Estados Unidos.
A13: 1 | B13: =LIDER!F43 -> JORGE ALBERTO BATISTA TABORDA | C13: =C12 -> G02 | E13: =IF(B13=0,0,IF(D13="",$F$13*LIDER!$H$9+$G$13*LIDER!$H$10+$H$13*LIDER!$H$11+$I$13*LIDER!$H$12+$J$13*LIDER!$H$13+$K$13*LIDER!$H$14+$L$13*LIDER!$H$15,"N")) -> 3.46 | F13: 2.5 | G13: 2.8 | H13: 3 | I13: 5 | J13: 5
A14: 2 | B14: =LIDER!F44 -> JEREMY MACOLL DIAZ PEREZ | C14: =C13 -> G02 | E14: =IF(B14=0,0,IF(D14="",$F$13*LIDER!$H$9+$G$13*LIDER!$H$10+$H$13*LIDER!$H$11+$I$13*LIDER!$H$12+$J$13*LIDER!$H$13+$K$13*LIDER!$H$14+$L$13*LIDER!$H$15,"N")) -> 3.46
A15: 3 | B15: =LIDER!F45 -> DARIANY PEÑARANDA LLACH | C15: =C14 -> G02 | E15: =IF(B15=0,0,IF(D15="",$F$13*LIDER!$H$9+$G$13*LIDER!$H$10+$H$13*LIDER!$H$11+$I$13*LIDER!$H$12+$J$13*LIDER!$H$13+$K$13*LIDER!$H$14+$L$13*LIDER!$H$15,"N")) -> 3.46
A16: 4 | B16: =LIDER!F46 -> MARIANGEL ROMERO VANEGAS | C16: =C15 -> G02 | E16: =IF(B16=0,0,IF(D16="",$F$13*LIDER!$H$9+$G$13*LIDER!$H$10+$H$13*LIDER!$H$11+$I$13*LIDER!$H$12+$J$13*LIDER!$H$13+$K$13*LIDER!$H$14+$L$13*LIDER!$H$15,"N")) -> 3.46
A17: 5 | B17: =LIDER!F47 -> 0 | C17: =C16 -> G02 | E17: =IF(B17=0,0,IF(D17="",$F$13*LIDER!$H$9+$G$13*LIDER!$H$10+$H$13*LIDER!$H$11+$I$13*LIDER!$H$12+$J$13*LIDER!$H$13+$K$13*LIDER!$H$14+$L$13*LIDER!$H$15,"N")) -> 0
A18: 6 | B18: =LIDER!F48 -> 0 | C18: =C17 -> G02 | E18: =IF(B18=0,0,IF(D18="",$F$13*LIDER!$H$9+$G$13*LIDER!$H$10+$H$13*LIDER!$H$11+$I$13*LIDER!$H$12+$J$13*LIDER!$H$13+$K$13*LIDER!$H$14+$L$13*LIDER!$H$15,"N")) -> 0
B19: GRUPO#3 | C19: G03 | D19: =D12 -> LIST | E19: DEF | F19: =LIDER!$E$31 -> GRUPO#3
A20: 1 | B20: =LIDER!G43 -> 0 | C20: =C19 -> G03 | E20: =IF(B20=0,0,IF(D20="",$F$20*LIDER!$H$9+$G$20*LIDER!$H$10+$H$20*LIDER!$H$11+$I$20*LIDER!$H$12+$J$20*LIDER!$H$13+$K$20*LIDER!$H$14+$L$20*LIDER!$H$15,"N")) -> 0
A21: 2 | B21: =LIDER!G44 -> 0 | C21: =C20 -> G03 | E21: =IF(B21=0,0,IF(D21="",$F$20*LIDER!$H$9+$G$20*LIDER!$H$10+$H$20*LIDER!$H$11+$I$20*LIDER!$H$12+$J$20*LIDER!$H$13+$K$20*LIDER!$H$14+$L$20*LIDER!$H$15,"N")) -> 0
A22: 3 | B22: =LIDER!G45 -> 0 | C22: =C21 -> G03 | E22: =IF(B22=0,0,IF(D22="",$F$20*LIDER!$H$9+$G$20*LIDER!$H$10+$H$20*LIDER!$H$11+$I$20*LIDER!$H$12+$J$20*LIDER!$H$13+$K$20*LIDER!$H$14+$L$20*LIDER!$H$15,"N")) -> 0
A23: 4 | B23: =LIDER!G46 -> 0 | C23: =C22 -> G03 | E23: =IF(B23=0,0,IF(D23="",$F$20*LIDER!$H$9+$G$20*LIDER!$H$10+$H$20*LIDER!$H$11+$I$20*LIDER!$H$12+$J$20*LIDER!$H$13+$K$20*LIDER!$H$14+$L$20*LIDER!$H$15,"N")) -> 0
A24: 5 | B24: =LIDER!G47 -> 0 | C24: =C23 -> G03 | E24: =IF(B24=0,0,IF(D24="",$F$20*LIDER!$H$9+$G$20*LIDER!$H$10+$H$20*LIDER!$H$11+$I$20*LIDER!$H$12+$J$20*LIDER!$H$13+$K$20*LIDER!$H$14+$L$20*LIDER!$H$15,"N")) -> 0
A25: 6 | B25: =LIDER!G48 -> 0 | C25: =C24 -> G03 | E25: =IF(B25=0,0,IF(D25="",$F$20*LIDER!$H$9+$G$20*LIDER!$H$10+$H$20*LIDER!$H$11+$I$20*LIDER!$H$12+$J$20*LIDER!$H$13+$K$20*LIDER!$H$14+$L$20*LIDER!$H$15,"N")) -> 0
B26: GRUPO#4 | C26: G04 | D26: =D19 -> LIST | E26: DEF | F26: =LIDER!$E$32 -> GRUPO#4
A27: 1 | B27: =LIDER!H43 -> 0 | C27: =C26 -> G04 | E27: =IF(B27=0,0,IF(D27="",$F$27*LIDER!$H$9+$G$27*LIDER!$H$10+$H$27*LIDER!$H$11+$I$27*LIDER!$H$12+$J$27*LIDER!$H$13+$K$27*LIDER!$H$14+$L$27*LIDER!$H$15,"N")) -> 0
A28: 2 | B28: =LIDER!H44 -> 0 | C28: =C27 -> G04 | E28: =IF(B28=0,0,IF(D28="",$F$27*LIDER!$H$9+$G$27*LIDER!$H$10+$H$27*LIDER!$H$11+$I$27*LIDER!$H$12+$J$27*LIDER!$H$13+$K$27*LIDER!$H$14+$L$27*LIDER!$H$15,"N")) -> 0
A29: 3 | B29: =LIDER!H45 -> 0 | C29: =C28 -> G04 | E29: =IF(B29=0,0,IF(D29="",$F$27*LIDER!$H$9+$G$27*LIDER!$H$10+$H$27*LIDER!$H$11+$I$27*LIDER!$H$12+$J$27*LIDER!$H$13+$K$27*LIDER!$H$14+$L$27*LIDER!$H$15,"N")) -> 0
A30: 4 | B30: =LIDER!H46 -> 0 | C30: =C29 -> G04 | E30: =IF(B30=0,0,IF(D30="",$F$27*LIDER!$H$9+$G$27*LIDER!$H$10+$H$27*LIDER!$H$11+$I$27*LIDER!$H$12+$J$27*LIDER!$H$13+$K$27*LIDER!$H$14+$L$27*LIDER!$H$15,"N")) -> 0
A31: 5 | B31: =LIDER!H47 -> 0 | C31: =C30 -> G04 | E31: =IF(B31=0,0,IF(D31="",$F$27*LIDER!$H$9+$G$27*LIDER!$H$10+$H$27*LIDER!$H$11+$I$27*LIDER!$H$12+$J$27*LIDER!$H$13+$K$27*LIDER!$H$14+$L$27*LIDER!$H$15,"N")) -> 0
A32: 6 | B32: =LIDER!H48 -> 0 | C32: =C31 -> G04 | E32: =IF(B32=0,0,IF(D32="",$F$27*LIDER!$H$9+$G$27*LIDER!$H$10+$H$27*LIDER!$H$11+$I$27*LIDER!$H$12+$J$27*LIDER!$H$13+$K$27*LIDER!$H$14+$L$27*LIDER!$H$15,"N")) -> 0
B33: GRUPO#5 | C33: G05 | D33: =D26 -> LIST | E33: DEF | F33: =LIDER!$E$33 -> GRUPO#5
A34: 1 | B34: =LIDER!E51 -> 0 | C34: =C33 -> G05 | E34: =IF(B34=0,0,IF(D34="",$F$34*LIDER!$H$9+$G$34*LIDER!$H$10+$H$34*LIDER!$H$11+$I$34*LIDER!$H$12+$J$34*LIDER!$H$13+$K$34*LIDER!$H$14+$L$34*LIDER!$H$15,"N")) -> 0
A35: 2 | B35: =LIDER!E52 -> 0 | C35: =C34 -> G05 | E35: =IF(B35=0,0,IF(D35="",$F$34*LIDER!$H$9+$G$34*LIDER!$H$10+$H$34*LIDER!$H$11+$I$34*LIDER!$H$12+$J$34*LIDER!$H$13+$K$34*LIDER!$H$14+$L$34*LIDER!$H$15,"N")) -> 0
A36: 3 | B36: =LIDER!E53 -> 0 | C36: =C35 -> G05 | E36: =IF(B36=0,0,IF(D36="",$F$34*LIDER!$H$9+$G$34*LIDER!$H$10+$H$34*LIDER!$H$11+$I$34*LIDER!$H$12+$J$34*LIDER!$H$13+$K$34*LIDER!$H$14+$L$34*LIDER!$H$15,"N")) -> 0
A37: 4 | B37: =LIDER!E54 -> 0 | C37: =C36 -> G05 | E37: =IF(B37=0,0,IF(D37="",$F$34*LIDER!$H$9+$G$34*LIDER!$H$10+$H$34*LIDER!$H$11+$I$34*LIDER!$H$12+$J$34*LIDER!$H$13+$K$34*LIDER!$H$14+$L$34*LIDER!$H$15,"N")) -> 0
A38: 5 | B38: =LIDER!E55 -> 0 | C38: =C37 -> G05 | E38: =IF(B38=0,0,IF(D38="",$F$34*LIDER!$H$9+$G$34*LIDER!$H$10+$H$34*LIDER!$H$11+$I$34*LIDER!$H$12+$J$34*LIDER!$H$13+$K$34*LIDER!$H$14+$L$34*LIDER!$H$15,"N")) -> 0
A39: 6 | B39: =LIDER!E56 -> 0 | C39: =C38 -> G05 | E39: =IF(B39=0,0,IF(D39="",$F$34*LIDER!$H$9+$G$34*LIDER!$H$10+$H$34*LIDER!$H$11+$I$34*LIDER!$H$12+$J$34*LIDER!$H$13+$K$34*LIDER!$H$14+$L$34*LIDER!$H$15,"N")) -> 0
B40: GRUPO#6 | C40: G06 | D40: =D33 -> LIST | E40: DEF | F40: =LIDER!$E$34 -> GRUPO#6
...

Sheet S-ASIG-03
A1: =LIDER!B2 -> TECNOLOGÍA EN GESTIÓN DE NEGOCIOS INTERN | I1: =LIDER!E2 -> SEMESTRE: | J1: =LIDER!F2 -> SEM-03 | K1: =LIDER!G2 -> SECCIÓN: | L1: =LIDER!H2 -> 2
B2: =LIDER!E4 -> INTERNACIONALIZACION | F2: CRITERIOS DE EVALUACIÓN
B3: Estudiantes | F3: =LIDER!E9 -> PRESENTACIÓN GENERAL: Adopta la norma APA, tamaño de la hoja, margenes, titulo, portadas, numeración de paginas, tabla de contenido automatizada, ortografia, justificacion del texto, citas automatizadas, listas, figuras,etc. | G3: =LIDER!E10 -> ANTEPROYECTO: Portada, planteamiento del problema, justificacion del trabajo o proyecto de aula, objetivos, marco teorico, diseño metodologico. | H3: =LIDER!E11 -> RESULTADOS: Analiza, integra y aplica de manera coherente los aspectos legales-tributarios, administrativos y tecnológicos en el desarrollo de la propuesta investigativa, evidenciando capacidad para generar soluciones viables, pertinentes y sostenibles. | I3: =LIDER!E12 -> BILIOGRAFIA: Las referencias bibliograficas: adoptan las normas APA. El documento es producto de un rastreo bibliografico que muestra analisis y sistensis. | J3: =LIDER!E13 -> ASESORIAS: Anexó la hoja de tutoria firmada ( 3 fimas minmimo). | K3: =LIDER!E14 -> 0 | L3: =LIDER!E15 -> 0
F4: =CONCATENATE(LIDER!E4," - ",LIDER!E6," - ",LIDER!E5) -> INTERNACIONALIZACION - 2482 - TATIANA MILENA ROJAS AROCA
B5: GRUPO#1 | C5: G01 | D5: LIST | E5: DEF | F5: =LIDER!$E$29 -> GRUPO#1. Identificación de los aspectos legales, tributarios, administrativos, macroeconómicos, aduaneros, tecnológicos e internacionales que definen el perfil de Yara Colombia S.A. en los negocios internacionales
A6: 1 | B6: =LIDER!E43 -> SARA OYOLA MARTINEZ | C6: =C5 -> G01 | E6: =IF(B6=0,0,IF(D6="",$F$6*LIDER!$H$9+$G$6*LIDER!$H$10+$H$6*LIDER!$H$11+$I$6*LIDER!$H$12+$J$6*LIDER!$H$13+$K$6*LIDER!$H$14+$L$6*LIDER!$H$15,"N")) -> 4.5 | F6: 4.5 | G6: 4.5 | H6: 4.5 | I6: 4.5 | J6: 4.5
A7: 2 | B7: =LIDER!E44 -> YINA MARCELA PÉREZ PINEDA | C7: =C6 -> G01 | E7: =IF(B7=0,0,IF(D7="",$F$6*LIDER!$H$9+$G$6*LIDER!$H$10+$H$6*LIDER!$H$11+$I$6*LIDER!$H$12+$J$6*LIDER!$H$13+$K$6*LIDER!$H$14+$L$6*LIDER!$H$15,"N")) -> 4.5
A8: 3 | B8: =LIDER!E45 -> JABES ELIAS ROSERO VILLA | C8: =C7 -> G01 | E8: =IF(B8=0,0,IF(D8="",$F$6*LIDER!$H$9+$G$6*LIDER!$H$10+$H$6*LIDER!$H$11+$I$6*LIDER!$H$12+$J$6*LIDER!$H$13+$K$6*LIDER!$H$14+$L$6*LIDER!$H$15,"N")) -> 4.5
A9: 4 | B9: =LIDER!E46 -> ISAIAS FERNANDO SALCEDO CAICEDO | C9: =C8 -> G01 | E9: =IF(B9=0,0,IF(D9="",$F$6*LIDER!$H$9+$G$6*LIDER!$H$10+$H$6*LIDER!$H$11+$I$6*LIDER!$H$12+$J$6*LIDER!$H$13+$K$6*LIDER!$H$14+$L$6*LIDER!$H$15,"N")) -> 4.5
A10: 5 | B10: =LIDER!E47 -> 0 | C10: =C9 -> G01 | E10: =IF(B10=0,0,IF(D10="",$F$6*LIDER!$H$9+$G$6*LIDER!$H$10+$H$6*LIDER!$H$11+$I$6*LIDER!$H$12+$J$6*LIDER!$H$13+$K$6*LIDER!$H$14+$L$6*LIDER!$H$15,"N")) -> 0
A11: 6 | B11: =LIDER!E48 -> 0 | C11: =C10 -> G01 | E11: =IF(B11=0,0,IF(D11="",$F$6*LIDER!$H$9+$G$6*LIDER!$H$10+$H$6*LIDER!$H$11+$I$6*LIDER!$H$12+$J$6*LIDER!$H$13+$K$6*LIDER!$H$14+$L$6*LIDER!$H$15,"N")) -> 0
B12: GRUPO#2 | C12: G02 | D12: =D5 -> LIST | E12: DEF | F12: =LIDER!$E$30 -> GRUPO#2. Identificación de los aspectos legales, tributarios, administrativos, macroeconómicos, aduaneros, tecnológicos e internacionales que definen el perfil de Grupo Familia en los negocios internacionales con enfoque en la exportación hacia Estados Unidos.
A13: 1 | B13: =LIDER!F43 -> JORGE ALBERTO BATISTA TABORDA | C13: =C12 -> G02 | E13: =IF(B13=0,0,IF(D13="",$F$13*LIDER!$H$9+$G$13*LIDER!$H$10+$H$13*LIDER!$H$11+$I$13*LIDER!$H$12+$J$13*LIDER!$H$13+$K$13*LIDER!$H$14+$L$13*LIDER!$H$15,"N")) -> 4.2 | F13: 4.2 | G13: 4.2 | H13: 4.2 | I13: 4.2 | J13: 4.2
A14: 2 | B14: =LIDER!F44 -> JEREMY MACOLL DIAZ PEREZ | C14: =C13 -> G02 | E14: =IF(B14=0,0,IF(D14="",$F$13*LIDER!$H$9+$G$13*LIDER!$H$10+$H$13*LIDER!$H$11+$I$13*LIDER!$H$12+$J$13*LIDER!$H$13+$K$13*LIDER!$H$14+$L$13*LIDER!$H$15,"N")) -> 4.2
A15: 3 | B15: =LIDER!F45 -> DARIANY PEÑARANDA LLACH | C15: =C14 -> G02 | E15: =IF(B15=0,0,IF(D15="",$F$13*LIDER!$H$9+$G$13*LIDER!$H$10+$H$13*LIDER!$H$11+$I$13*LIDER!$H$12+$J$13*LIDER!$H$13+$K$13*LIDER!$H$14+$L$13*LIDER!$H$15,"N")) -> 4.2
A16: 4 | B16: =LIDER!F46 -> MARIANGEL ROMERO VANEGAS | C16: =C15 -> G02 | E16: =IF(B16=0,0,IF(D16="",$F$13*LIDER!$H$9+$G$13*LIDER!$H$10+$H$13*LIDER!$H$11+$I$13*LIDER!$H$12+$J$13*LIDER!$H$13+$K$13*LIDER!$H$14+$L$13*LIDER!$H$15,"N")) -> 4.2
A17: 5 | B17: =LIDER!F47 -> 0 | C17: =C16 -> G02 | E17: =IF(B17=0,0,IF(D17="",$F$13*LIDER!$H$9+$G$13*LIDER!$H$10+$H$13*LIDER!$H$11+$I$13*LIDER!$H$12+$J$13*LIDER!$H$13+$K$13*LIDER!$H$14+$L$13*LIDER!$H$15,"N")) -> 0
A18: 6 | B18: =LIDER!F48 -> 0 | C18: =C17 -> G02 | E18: =IF(B18=0,0,IF(D18="",$F$13*LIDER!$H$9+$G$13*LIDER!$H$10+$H$13*LIDER!$H$11+$I$13*LIDER!$H$12+$J$13*LIDER!$H$13+$K$13*LIDER!$H$14+$L$13*LIDER!$H$15,"N")) -> 0
B19: GRUPO#3 | C19: G03 | D19: =D12 -> LIST | E19: DEF | F19: =LIDER!$E$31 -> GRUPO#3
A20: 1 | B20: =LIDER!G43 -> 0 | C20: =C19 -> G03 | E20: =IF(B20=0,0,IF(D20="",$F$20*LIDER!$H$9+$G$20*LIDER!$H$10+$H$20*LIDER!$H$11+$I$20*LIDER!$H$12+$J$20*LIDER!$H$13+$K$20*LIDER!$H$14+$L$20*LIDER!$H$15,"N")) -> 0
A21: 2 | B21: =LIDER!G44 -> 0 | C21: =C20 -> G03 | E21: =IF(B21=0,0,IF(D21="",$F$20*LIDER!$H$9+$G$20*LIDER!$H$10+$H$20*LIDER!$H$11+$I$20*LIDER!$H$12+$J$20*LIDER!$H$13+$K$20*LIDER!$H$14+$L$20*LIDER!$H$15,"N")) -> 0
A22: 3 | B22: =LIDER!G45 -> 0 | C22: =C21 -> G03 | E22: =IF(B22=0,0,IF(D22="",$F$20*LIDER!$H$9+$G$20*LIDER!$H$10+$H$20*LIDER!$H$11+$I$20*LIDER!$H$12+$J$20*LIDER!$H$13+$K$20*LIDER!$H$14+$L$20*LIDER!$H$15,"N")) -> 0
A23: 4 | B23: =LIDER!G46 -> 0 | C23: =C22 -> G03 | E23: =IF(B23=0,0,IF(D23="",$F$20*LIDER!$H$9+$G$20*LIDER!$H$10+$H$20*LIDER!$H$11+$I$20*LIDER!$H$12+$J$20*LIDER!$H$13+$K$20*LIDER!$H$14+$L$20*LIDER!$H$15,"N")) -> 0
A24: 5 | B24: =LIDER!G47 -> 0 | C24: =C23 -> G03 | E24: =IF(B24=0,0,IF(D24="",$F$20*LIDER!$H$9+$G$20*LIDER!$H$10+$H$20*LIDER!$H$11+$I$20*LIDER!$H$12+$J$20*LIDER!$H$13+$K$20*LIDER!$H$14+$L$20*LIDER!$H$15,"N")) -> 0
A25: 6 | B25: =LIDER!G48 -> 0 | C25: =C24 -> G03 | E25: =IF(B25=0,0,IF(D25="",$F$20*LIDER!$H$9+$G$20*LIDER!$H$10+$H$20*LIDER!$H$11+$I$20*LIDER!$H$12+$J$20*LIDER!$H$13+$K$20*LIDER!$H$14+$L$20*LIDER!$H$15,"N")) -> 0
B26: GRUPO#4 | C26: G04 | D26: =D19 -> LIST | E26: DEF | F26: =LIDER!$E$32 -> GRUPO#4
A27: 1 | B27: =LIDER!H43 -> 0 | C27: =C26 -> G04 | E27: =IF(B27=0,0,IF(D27="",$F$27*LIDER!$H$9+$G$27*LIDER!$H$10+$H$27*LIDER!$H$11+$I$27*LIDER!$H$12+$J$27*LIDER!$H$13+$K$27*LIDER!$H$14+$L$27*LIDER!$H$15,"N")) -> 0
A28: 2 | B28: =LIDER!H44 -> 0 | C28: =C27 -> G04 | E28: =IF(B28=0,0,IF(D28="",$F$27*LIDER!$H$9+$G$27*LIDER!$H$10+$H$27*LIDER!$H$11+$I$27*LIDER!$H$12+$J$27*LIDER!$H$13+$K$27*LIDER!$H$14+$L$27*LIDER!$H$15,"N")) -> 0
A29: 3 | B29: =LIDER!H45 -> 0 | C29: =C28 -> G04 | E29: =IF(B29=0,0,IF(D29="",$F$27*LIDER!$H$9+$G$27*LIDER!$H$10+$H$27*LIDER!$H$11+$I$27*LIDER!$H$12+$J$27*LIDER!$H$13+$K$27*LIDER!$H$14+$L$27*LIDER!$H$15,"N")) -> 0
A30: 4 | B30: =LIDER!H46 -> 0 | C30: =C29 -> G04 | E30: =IF(B30=0,0,IF(D30="",$F$27*LIDER!$H$9+$G$27*LIDER!$H$10+$H$27*LIDER!$H$11+$I$27*LIDER!$H$12+$J$27*LIDER!$H$13+$K$27*LIDER!$H$14+$L$27*LIDER!$H$15,"N")) -> 0
A31: 5 | B31: =LIDER!H47 -> 0 | C31: =C30 -> G04 | E31: =IF(B31=0,0,IF(D31="",$F$27*LIDER!$H$9+$G$27*LIDER!$H$10+$H$27*LIDER!$H$11+$I$27*LIDER!$H$12+$J$27*LIDER!$H$13+$K$27*LIDER!$H$14+$L$27*LIDER!$H$15,"N")) -> 0
A32: 6 | B32: =LIDER!H48 -> 0 | C32: =C31 -> G04 | E32: =IF(B32=0,0,IF(D32="",$F$27*LIDER!$H$9+$G$27*LIDER!$H$10+$H$27*LIDER!$H$11+$I$27*LIDER!$H$12+$J$27*LIDER!$H$13+$K$27*LIDER!$H$14+$L$27*LIDER!$H$15,"N")) -> 0
B33: GRUPO#5 | C33: G05 | D33: =D26 -> LIST | E33: DEF | F33: =LIDER!$E$33 -> GRUPO#5
A34: 1 | B34: =LIDER!E51 -> 0 | C34: =C33 -> G05 | E34: =IF(B34=0,0,IF(D34="",$F$34*LIDER!$H$9+$G$34*LIDER!$H$10+$H$34*LIDER!$H$11+$I$34*LIDER!$H$12+$J$34*LIDER!$H$13+$K$34*LIDER!$H$14+$L$34*LIDER!$H$15,"N")) -> 0
A35: 2 | B35: =LIDER!E52 -> 0 | C35: =C34 -> G05 | E35: =IF(B35=0,0,IF(D35="",$F$34*LIDER!$H$9+$G$34*LIDER!$H$10+$H$34*LIDER!$H$11+$I$34*LIDER!$H$12+$J$34*LIDER!$H$13+$K$34*LIDER!$H$14+$L$34*LIDER!$H$15,"N")) -> 0
A36: 3 | B36: =LIDER!E53 -> 0 | C36: =C35 -> G05 | E36: =IF(B36=0,0,IF(D36="",$F$34*LIDER!$H$9+$G$34*LIDER!$H$10+$H$34*LIDER!$H$11+$I$34*LIDER!$H$12+$J$34*LIDER!$H$13+$K$34*LIDER!$H$14+$L$34*LIDER!$H$15,"N")) -> 0
A37: 4 | B37: =LIDER!E54 -> 0 | C37: =C36 -> G05 | E37: =IF(B37=0,0,IF(D37="",$F$34*LIDER!$H$9+$G$34*LIDER!$H$10+$H$34*LIDER!$H$11+$I$34*LIDER!$H$12+$J$34*LIDER!$H$13+$K$34*LIDER!$H$14+$L$34*LIDER!$H$15,"N")) -> 0
A38: 5 | B38: =LIDER!E55 -> 0 | C38: =C37 -> G05 | E38: =IF(B38=0,0,IF(D38="",$F$34*LIDER!$H$9+$G$34*LIDER!$H$10+$H$34*LIDER!$H$11+$I$34*LIDER!$H$12+$J$34*LIDER!$H$13+$K$34*LIDER!$H$14+$L$34*LIDER!$H$15,"N")) -> 0
A39: 6 | B39: =LIDER!E56 -> 0 | C39: =C38 -> G05 | E39: =IF(B39=0,0,IF(D39="",$F$34*LIDER!$H$9+$G$34*LIDER!$H$10+$H$34*LIDER!$H$11+$I$34*LIDER!$H$12+$J$34*LIDER!$H$13+$K$34*LIDER!$H$14+$L$34*LIDER!$H$15,"N")) -> 0
B40: GRUPO#6 | C40: G06 | D40: =D33 -> LIST | E40: DEF | F40: =LIDER!$E$34 -> GRUPO#6
...

Sheet S-ASIG-05
A1: =LIDER!B2 -> TECNOLOGÍA EN GESTIÓN DE NEGOCIOS INTERN | I1: =LIDER!E2 -> SEMESTRE: | J1: =LIDER!F2 -> SEM-03 | K1: =LIDER!G2 -> SECCIÓN: | L1: =LIDER!H2 -> 2
B2: =LIDER!G4 -> MACROECONOMÍA | F2: CRITERIOS DE EVALUACIÓN
